Workbook

Sheet 개요
A1: Roma 이탈리아어 낭독 교재 — 캐릭터 바이블 (부활자 특별편)
A2: v1.0 · 로마 배경 13부작 옴니버스(156화) · 부활 7인 = Cesare·Machiavelli·Garibaldi·Dante·Gramsci·Galileo·Montessori
B4: 기본 설정
B5: 부 수 | C5: 13 | D5: 1 사무소(Testaccio, 개소 1개월 후, 6사건×2화) → 2~5 각자의 과거 → 6 만남 → 7 전면전 → 8 창당 → 9 시의회·주의회 → 10 총선·총리 선출 → 11 국정 I(EU 협상·Cesare 사망) → 12 국정 II(장례·유고 메모 승계) → 13 귀환(원형 구조)
B6: 부당 화 수 | C6: 12 | D6: 각 부 12화
B7: 총 화 수 | C7: =C5*C6 -> 156 | D7: 부 수 × 부당 화 수 (자동 계산)
B8: 등장인물 수 | C8: =COUNTA(캐릭터!$D$5:$D$19) -> 15 | D8: 캐릭터 시트의 약칭 개수
B9: 남성 인물 수 | C9: =COUNTIF(캐릭터!$G$5:$G$19,"남") -> 10 | D9: 부활 7인 중 6인이 남성인 역사 인물이라 남 10 : 여 5. 여성 화자(Giulia·Chiara·Rosa·Sofia·Montessori)의 대사 비중을 높게 유지해 음색 균형을 맞춘다.
B10: 여성 인물 수 | C10: =COUNTIF(캐릭터!$G$5:$G$19,"여") -> 5
B11: 1부→11부 경과 연수 (가정) | C11: 6 | D11: 가정값: Cesare가 1부 55세(암살 당시 나이로 부활) → 11부 약 61세가 되도록 잡음. 확정 시 이 셀만 수정하면 캐릭터 시트의 나이가 자동 갱신. (캐릭터 시트 '나이(11부)' 열)
B12: 배경·언어 | C12: 로마 (테스타초) | D12: 표준 이탈리아어: 친한 사이 tu, 공식 석상은 Lei/공식 호칭. Rosa·Paolo의 로마 사투리(romanesco)는 양념 수준으로.
B13: 형식 | C13: 전 화 100% 대화문, 화당 120턴 | D13: ="지문(narrazione) 없음. 화당 "&턴_설계!$B$5&"턴 × "&C7&"화 = "&TEXT(C7*턴_설계!$B$5,"#,##0")&"턴. 상세는 '대화문규칙'·'턴_설계' 시트." -> 지문(narrazione) 없음. 화당 120턴 × 156화 = 18,720턴. 상세는 '대화문규칙'·'턴_설계' 시트.
B15: 그룹별 인원
B16: 주력 4인 | C16: =COUNTIF(캐릭터!$B$5:$B$19,B16) -> 4 | D16: Marco(변호사)·Giulia(의사)·Alessandro(회계사)·Chiara(컨설턴트)
B17: 부활 7인 | C17: =COUNTIF(캐릭터!$B$5:$B$19,B17) -> 7 | D17: Cesare(전 독재관)·Machiavelli(정치사상가)·Garibaldi(통일운동가)·Dante(시인)·Gramsci(사상가)·Galileo(과학자)·Montessori(교육학자) ※ 각자의 시대에 죽었다가 이유 없이 현재 로마에 되살아나 사무소에 합류
B18: 서민·청년 | C18: =COUNTIF(캐릭터!$B$5:$B$19,B18) -> 3 | D18: Rosa(트라토리아 사장)·Paolo(노조위원장)·Sofia M.(인턴)
B19: 금융 | C19: =COUNTIF(캐릭터!$B$5:$B$19,B19) -> 1 | D19: Francesco(전 은행 지점장)
B22: 시트 안내 (클릭하면 이동)
B23: 캐릭터 | C23: 기준표 | D23: 15인의 이름·나이·결핍·말투·시그니처·낭독 포인트·대화문 장치·직책·현안 담당
B24: 등장비중 | C24: 기준표 | D24: 13부 배분표, 합계·비중·등급(수식), 조연 단독 중심 화 목표
B25: 턴_설계 | C25: 기준표 | D25: 화당 120턴 설계: 13부 × 화자 점유율(턴 기준), 평균 단어/턴, 화당 단어·낭독 시간(수식), 화 유형별 턴 구성, 집필 규칙
B26: 13부_구성 | C26: 구조 | D26: 13부 한눈에 보기: 배경·핵심 내용·난이도(CEFR)·반영 제도
B27: 아크_구성계획 | C27: 구성 계획 | D27: 1~13부 아크별 구성 계획: 서사 기능·로그라인·비트·인물 아크·복선·현안·언어 설계
B28: 화별목차_전체 | C28: 목차 | D28: 1~13부 156화의 서사 기능·제목(이탈리아어)·핵심 사건·반영 제도·인물·현안 (필터 가능)
B29: 복선_회수 | C29: 구성 계획 | D29: 복선 설치→회수 28건과 간격(부)을 수식으로 계산
B30: 현안_배치 | C30: 현안 | D30: 이탈리아 현안 18개를 어느 화에 어떻게 녹일지 배치, 균형 유의, 현실 기준값(ISTAT 등)
B31: 현안_분포 | C31: 현안 | D31: 부 × 현안 분포표: 전용 화(●)와 곁가지(○)를 수식으로 집계
B32: 정치제도 | C32: 현실 제도 | D32: 정당·선거·양원·정부 구성·주(Regione)·사법·EU 제도 기준표 (확인 상태 표시)
B33: 정치경로_의석 | C33: 현실 제도 | D33: 창당→총리 경로와 가상 의석·표결 시뮬레이션(수식): 하원·상원 신임 투표, 불신임안
B34: 호칭규칙 | C34: 규칙 | D34: tu / Lei / voi / Loro, 양원·시의회 공식 호칭, 대통령
... B39: 변경이력_미결 | C39: 관리 | D39: 변경 이력(스페인판→이탈리아판 대응표 포함)과 확정이 필요한 미결 사항
B42: 범례
B43: 파란 글씨 | C43: 직접 입력한 값 (수정 가능)
B44: 노란 배경 | C44: 가정 · 확정이 필요한 값
B45: 검정 글씨 | C45: 수식으로 계산되는 값 (직접 수정하지 말 것)
B47: 주의: 성별·나이·기관명은 기획용 가상 설정입니다. 법령 번호·조항은 교재에 넣기 전에 Normattiva(normattiva.it)·Gazzetta Ufficiale의 현행 통합본으로 확인하세요.

Sheet 캐릭터
A1: 캐릭터 바이블 — 15인 (Roma 이탈리아어 낭독 교재 — 캐릭터 바이블 (부활자 특별편))
A2: v1.0 · 로마 배경 13부작 옴니버스(156화) · 부활 7인 = Cesare·Machiavelli·Garibaldi·Dante·Gramsci·Galileo·Montessori
A4: No | B4: 그룹 | C4: 이름 | D4: 약칭 | E4: 나이 (1부) | F4: 나이 (11부) | G4: 성별 | H4: 직업·신분 | I4: 전 소속 (가상) | J4: 결핍 (Herida) | K4: 말투 | L4: 시그니처 표현 | M4: 낭독 포인트 | N4: 대화문 장치 (지문 대체) | O4: 정치 직책 (8~12부, 제안) | P4: 1부 등장 방식 | Q4: 등장 화 수 | R4: 등급 | S4: 현안 담당 (ID)
A5: 1 | B5: 주력 4인 | C5: Marco Ferrari | D5: Marco | E5: 39 | F5: =E5+개요!$C$11 -> 45 | G5: 남 | H5: 변호사 (기업·규제 전문) | I5: Ferrari & Colombo Studio Legale (전 파트너 후보) | J5: 승소율은 높지만, 강제퇴거 소송에서 이긴 사건 하나가 계속 마음에 걸린다. | K5: 문장이 완결되고 격식체. 초반엔 차갑게 조항을 인용, 후반엔 연설가로 성장. | L5: Andiamo con ordine.\nCon tutto il rispetto, la legge non dice questo.\n(후반) Non vi chiedo di credermi. Vi chiedo di leggere il testo. | M5: 또박또박, 중저음. | N5: 법조문을 소리 내어 읽어 상황을 설명한다. | O5: 당 대표(8부) → 하원의원·총리 후보(10부) → 총리 | P5: 본격 | Q5: =INDEX(등장비중!$O$5:$O$19,MATCH($D5,등장비중!$A$5:$A$19,0)) -> 108 | R5: =INDEX(등장비중!$Q$5:$Q$19,MATCH($D5,등장비중!$A$5:$A$19,0)) -> 주연 | S5: P1·P3·E1·N4
A6: 2 | B6: 주력 4인 | C6: Giulia Romano | D6: Giulia | E6: 41 | F6: =E6+개요!$C$11 -> 47 | G6: 여 | H6: 응급의학과 전문의 | I6: Ospedale San Camillo (가상) | J6: 살리지 못한 환자의 이름을 전부 외우고 있다. | K6: 짧고 명령형, 블랙유머. | L6: Questa non è una statistica, è una persona.\nPrima, respira.\nHo visto di peggio in un martedì qualsiasi. | M6: 빠른 템포, 짧은 호흡. | N6: 명령형으로 행동을 말하며 진행한다. | O6: 주의회 의원(9부) → 보건부 장관 | P6: 본격 | Q6: =INDEX(등장비중!$O$5:$O$19,MATCH($D6,등장비중!$A$5:$A$19,0)) -> 98 | R6: =INDEX(등장비중!$Q$5:$Q$19,MATCH($D6,등장비중!$A$5:$A$19,0)) -> 준주연 | S6: S3·S4·S2·N8
A7: 3 | B7: 주력 4인 | C7: Alessandro Conti | D7: Alessandro | E7: 37 | F7: =E7+개요!$C$11 -> 43 | G7: 남 | H7: 공인회계사 (감사) | I7: Conti Revisori (전 시니어 파트너) | J7: 부정을 발견하고도 서명했던 기억. | K7: 건조하고 정확, 비꼬는 유머. | L7: Fammi vedere le carte.\nQuesto non torna.\nMostrami i numeri e ti dirò chi sei. | M7: 일정한 속도, 결론에서 톤을 낮춘다. | N7: 숫자를 소리 내어 읽는다. | O7: 시의원(9부) → 경제재정부 장관 | P7: 본격 | Q7: =INDEX(등장비중!$O$5:$O$19,MATCH($D7,등장비중!$A$5:$A$19,0)) -> 109 | R7: =INDEX(등장비중!$Q$5:$Q$19,MATCH($D7,등장비중!$A$5:$A$19,0)) -> 주연 | S7: E3·E1·N2
A8: 4 | B8: 주력 4인 | C8: Chiara Bianchi | D8: Chiara | E8: 36 | F8: =E8+개요!$C$11 -> 42 | G8: 여 | H8: 전략 컨설턴트 | I8: Zenit Consulting (전 소속) | J8: 구조조정 표 한 칸이 수백 명의 해고였음을 뒤늦게 안다. | K8: 영어식 경영 용어가 섞인 빠른 말투, 후반 쉬운 말로 성장. | L8: Mettiamolo in una matrice.\n(후반) Ok, senza slide: cosa ti serve davvero? | M8: 초반 숨 가쁜 톤, 후반 솔직한 톤. | N8: 프레젠테이션식 브리핑. | O8: 캠프 참모(8~10부) → 총리실 실장 | P8: 본격 | Q8: =INDEX(등장비중!$O$5:$O$19,MATCH($D8,등장비중!$A$5:$A$19,0)) -> 101 | R8: =INDEX(등장비중!$Q$5:$Q$19,MATCH($D8,등장비중!$A$5:$A$19,0)) -> 준주연 | S8: P1·E2·S1
A9: 5 | B9: 부활 7인 | C9: Gaio Giulio Cesare | D9: Cesare | E9: 55 | F9: =E9+개요!$C$11 -> 61 | G9: 남 | H9: 부활한 정치가·장군 (기원전 100–44) | I9: 로마 공화정 종신독재관 | J9: 자신이 암살당하던 순간의 배신을 잊지 못하며, 누구든 너무 가까이 다가오면 본능적으로 경계한다. | K9: 위엄 있고 명령조, 3인칭으로 자기 자신을 지칭하는 버릇이 있다 (『갈리아 전기』식 문체). | L9: Cesare è venuto, ha visto, ha vinto — questa riunione durerà di meno, spero.\n(현대 용어 오해) Un „server“? Cesare capisce: un servo che non dorme mai. Molto romano.\n„Firewall“? Ai miei tempi si chiamava assedio. | M9: 느리고 육중한 리듬, 문장 끝에서 상대를 지그시 본다. | N9: '내가 갈리아에 있을 때는…' 식 회상으로 현재를 평가한다. | O9: 외교·안보 자문 (11부 12화, 브뤼셀 협상 직후 두 번째 죽음) | P9: 준본격 (겨울 복선) | Q9: =INDEX(등장비중!$O$5:$O$19,MATCH($D9,등장비중!$A$5:$A$19,0)) -> 65 | R9: =INDEX(등장비중!$Q$5:$Q$19,MATCH($D9,등장비중!$A$5:$A$19,0)) -> 핵심 조연 | S9: N3·E3
A10: 6 | B10: 부활 7인 | C10: Niccolò Machiavelli | D10: Machiavelli | E10: 58 | F10: =E10+개요!$C$11 -> 64 | G10: 남 | H10: 부활한 정치사상가 (1469–1527) | I10: 피렌체 공화국 서기관, 『군주론』 저자 | J10: 자신의 이름이 '마키아벨리즘'이라는 욕설로 남은 것에 대한 억울함을 냉소로 눌러 담는다. | K10: 건조하고 분석적, 이상과 현실을 항상 구분해서 말한다. | L10: (고전 인용) È meglio essere temuti che amati, se non si può essere entrambe le cose.\n(현대 용어 재해석) „Personal branding“? Un nome elegante per: il Principe che si vende da solo. | M10: 낮고 냉정한 톤. | N10: 상황을 '이상 vs 현실' 두 갈래로 나눠 분석해 설명한다. | O10: 정치 전략 자문 | P10: 카메오 | Q10: =INDEX(등장비중!$O$5:$O$19,MATCH($D10,등장비중!$A$5:$A$19,0)) -> 64 | R10: =INDEX(등장비중!$Q$5:$Q$19,MATCH($D10,등장비중!$A$5:$A$19,0)) -> 핵심 조연 | S10: P1·P2
A11: 7 | B11: 부활 7인 | C11: Giuseppe Garibaldi | D11: Garibaldi | E11: 74 | F11: =E11+개요!$C$11 -> 80 | G11: 남 | H11: 부활한 통일운동가 (1807–1882) | I11: 이탈리아 통일전쟁 의용군 지휘관 | J11: 통일시킨 나라가 다시 갈라지는 걸 보는 게 가장 두렵다 — 지역 갈등 이야기만 나오면 정색한다. | K11: 열정적이고 직설, 행동가 화법. 회의보다 거리로 나가고 싶어 한다. | L11: Obbedisco — ma solo quando ha senso.\n(현대 용어 오해) „Trending“? Vuol dire che il popolo si muove. Verso dove, andiamo a vedere. | M11: 빠르고 격정적. | N11: 집회 연설조로 대중의 분위기를 전달한다. | O11: 정당 창당 전략가(8부) → 지역통합 담당 장관 | P11: 카메오 | Q11: =INDEX(등장비중!$O$5:$O$19,MATCH($D11,등장비중!$A$5:$A$19,0)) -> 63 | R11: =INDEX(등장비중!$Q$5:$Q$19,MATCH($D11,등장비중!$A$5:$A$19,0)) -> 핵심 조연 | S11: P2·S3·N1·N5
A12: 8 | B12: 부활 7인 | C12: Dante Alighieri | D12: Dante | E12: 56 | F12: =E12+개요!$C$11 -> 62 | G12: 남 | H12: 부활한 시인 (1265–1321) | I12: 피렌체 추방자, 『신곡』 저자 | J12: 평생 고향에서 추방된 채 죽었다 — 지금도 '고향'이라는 말에 예민하게 반응한다. | K12: 장엄하고 상징적인 문어체, 인물마다 지옥·연옥·천국의 어느 층에 어울리는지 비유한다(개그). | L12: (현대 용어 오해) Un „influencer“? Suona come un nuovo venditore di indulgenze — li ho già messi in un girone apposito.\n„Podcast“? Una predica senza chiesa. | M12: 느리고 낭송하듯. | N12: 상대의 행동을 단테식 지옥/연옥 비유로 풍자해 설명한다. | O12: 메시지·공보 자문 | P12: 카메오 | Q12: =INDEX(등장비중!$O$5:$O$19,MATCH($D12,등장비중!$A$5:$A$19,0)) -> 54 | R12: =INDEX(등장비중!$Q$5:$Q$19,MATCH($D12,등장비중!$A$5:$A$19,0)) -> 조연 | S12: N3·N6·N5
A13: 9 | B13: 부활 7인 | C13: Antonio Gramsci | D13: Gramsci | E13: 46 | F13: =E13+개요!$C$11 -> 52 | G13: 남 | H13: 부활한 사상가 (1891–1937) | I13: 이탈리아 공산당 창립자, 파시스트 정권 옥사 | J13: 감옥에서 쓴 노트가 자신이 세상을 못 보고 죽은 채 유일하게 남긴 목소리였다는 걸 안다 — 말 한마디의 무게에 집착한다. | K13: 낮고 신중, 권력의 문화적 지배(헤게모니) 개념으로 모든 걸 분석한다. | L13: (현대 용어 재해석) „Storytelling aziendale“? Un nome nuovo per l'egemonia culturale — io l'avevo già capito in cella.\nLa crisi consiste appunto nel fatto che il vecchio muore e il nuovo non può nascere. | M13: 느리고 낮은 톤, 침묵이 길다. | N13: 현상을 '누가 문화적 헤게모니를 쥐고 있는가'로 재해석해 설명한다. | O13: 출처·기록 담당(카드) → 사회·문화 정책 자문, 스파이웨어 조사 자문(12부) | P13: 카메오 (고서점·아카이브 단골) | Q13: =INDEX(등장비중!$O$5:$O$19,MATCH($D13,등장비중!$A$5:$A$19,0)) -> 58 | R13: =INDEX(등장비중!$Q$5:$Q$19,MATCH($D13,등장비중!$A$5:$A$19,0)) -> 조연 | S13: P3·N7·N2
A14: 10 | B14: 부활 7인 | C14: Galileo Galilei | D14: Galileo | E14: 77 | F14: =E14+개요!$C$11 -> 83 | G14: 남 | H14: 부활한 과학자 (1564–1642) | I14: 종교재판에 회부됐던 천문학자 | J14: 한때 자기 눈으로 본 진실을 부정해야 목숨을 부지할 수 있었던 기억 — 지금도 침묵을 강요받으면 몸이 굳는다. | K14: 차분하고 실증적, '그래도 그것은 돈다(Eppur si muove)'는 태도로 조용히 밀어붙인다. | L14: (현대 용어 오해) „Wi-Fi“? Onde invisibili — finalmente qualcuno mi crede senza processo.\nEppur si muove — anche questa riunione, se insistiamo. | M14: 느리고 담담한 톤. | N14: 관찰과 증거로 상황을 설명한다 — 의견이 아니라 데이터로 말한다. | O14: 사무소 공론화·검증 담당 → 정부 대변인(11부~) | P14: 카메오 | Q14: =INDEX(등장비중!$O$5:$O$19,MATCH($D14,등장비중!$A$5:$A$19,0)) -> 46 | R14: =INDEX(등장비중!$Q$5:$Q$19,MATCH($D14,등장비중!$A$5:$A$19,0)) -> 조연 | S14: P3·N7·N4
A15: 11 | B15: 서민·청년 | C15: Rosa Esposito | D15: Rosa | E15: 63 | F15: =E15+개요!$C$11 -> 69 | G15: 여 | H15: 트라토리아 사장 (Trattoria da Rosa, 30년 운영) | I15: Trattoria da Rosa, Testaccio → 사무소 1층으로 이전 | J15: 임대료 폭등으로 가게를 잃었다. | K15: 로마 토박이 구어체, 누구에게나 tu, 'amore/tesoro'. | L15: Sedetevi, che vi porto qualcosa.\nA stomaco vuoto non si pensa bene.\nOffre la casa. | M15: 따뜻하고 넉넉한 톤. | N15: 시간·장소·식사를 말로 알린다. | O15: 소상공인 정책 자문 (비공식) | P15: 본격 | Q15: =INDEX(등장비중!$O$5:$O$19,MATCH($D15,등장비중!$A$5:$A$19,0)) -> 69 | R15: =INDEX(등장비중!$Q$5:$Q$19,MATCH($D15,등장비중!$A$5:$A$19,0)) -> 핵심 조연 | S15: E1·S2·E2
A16: 12 | B16: 서민·청년 | C16: Paolo Greco | D16: Paolo | E16: 55 | F16: =E16+개요!$C$11 -> 61 | G16: 남 | H16: 전 대중교통 노조위원장 | I16: 로마 대중교통 노조 (파업 책임으로 해고) | J16: 파업 책임으로 해고되어 블랙리스트에 올랐지만 후회하지 않는다. | K16: 거칠고 직설적, 구호형 문장. | L16: Qui non si arrende nessuno!\nQuesto si risolve in strada.\nNon mi rompere. | M16: 큰 볼륨, 강한 억양. | N16: 구호와 함성으로 현장 분위기를 전달한다. | O16: 사회적 대화 자문 | P16: 카메오 | Q16: =INDEX(등장비중!$O$5:$O$19,MATCH($D16,등장비중!$A$5:$A$19,0)) -> 58 | R16: =INDEX(등장비중!$Q$5:$Q$19,MATCH($D16,등장비중!$A$5:$A$19,0)) -> 조연 | S16: S1·N6·P1
... A19: 15 | B19: 부활 7인 | C19: Maria Montessori | D19: Montessori | E19: 81 | F19: =E19+개요!$C$11 -> 87 | G19: 여 | H19: 부활한 교육학자·의사 (1870–1952) | I19: 몬테소리 교육법 창시자, 이탈리아 최초 여성 의사 중 한 명 | J19: 자신의 교육법이 세계로 퍼졌지만 정작 자국 파시스트 정권에는 탄압받았던 기억이 있다. | K19: 차분하고 관찰적, 아이 대하듯 사람을 존중하며 말하지만 할 말은 다 한다. | L19: Aiutami a fare da solo.\n(현대 용어 오해) „App“? Uno strumento — ma lo strumento non deve mai sostituire la mano che impara. | M19: 부드럽고 낮은 톤. | N19: 상대의 말을 관찰하듯 되짚어 정리해 준다. | O19: 사무소 상담 담당 → 교육·청년 정신건강 정책 자문 | P19: 카메오 | Q19: =INDEX(등장비중!$O$5:$O$19,MATCH($D19,등장비중!$A$5:$A$19,0)) -> 53 | R19: =INDEX(등장비중!$Q$5:$Q$19,MATCH($D19,등장비중!$A$5:$A$19,0)) -> 조연 | S19: N8·N4·S2

Sheet 등장비중
A1: 인물별 등장 비중 (부별 등장 화 수)
A2: 등장 화 = 대사가 있는 화 수 (기획용 초안). 파란 숫자는 직접 입력값이며 수정하면 합계·비중·등급이 자동 갱신됩니다.
A4: 인물 (약칭) | B4: 1부 사무소 | C4: 2부 Marco | D4: 3부 Giulia | E4: 4부 Alessandro | F4: 5부 Chiara | G4: 6부 만남 | H4: 7부 전면전 | I4: 8부 창당 | J4: 9부 시·주 의회 | K4: 10부 총선·총리 | L4: 11부 국정 I | M4: 12부 국정 II | N4: 13부 귀환 | O4: 합계 | P4: 비중 | Q4: 등급 | R4: 검증 (≤부당 화 수) | S4: 단독 중심 화 목표 (조연)
A5: Marco | B5: 7 | C5: 12 | D5: 3 | E5: 3 | F5: 3 | G5: 12 | H5: 11 | I5: 12 | J5: 11 | K5: 11 | L5: 10 | M5: 3 | N5: 10 | O5: =SUM(B5:N5) -> 108 | P5: =O5/개요!$C$7 -> 0.69230769 | Q5: =IF(P5>=$B$23,"주연",IF(P5>=$B$24,"준주연",IF(P5>=$B$25,"핵심 조연","조연"))) -> 주연 | R5: =IF(MAX(B5:N5)<=개요!$C$6,"OK","확인") -> OK | S5: —
A6: Giulia | B6: 6 | C6: 3 | D6: 12 | E6: 3 | F6: 3 | G6: 12 | H6: 10 | I6: 10 | J6: 8 | K6: 10 | L6: 10 | M6: 2 | N6: 9 | O6: =SUM(B6:N6) -> 98 | P6: =O6/개요!$C$7 -> 0.62820513 | Q6: =IF(P6>=$B$23,"주연",IF(P6>=$B$24,"준주연",IF(P6>=$B$25,"핵심 조연","조연"))) -> 준주연 | R6: =IF(MAX(B6:N6)<=개요!$C$6,"OK","확인") -> OK | S6: —
A7: Alessandro | B7: 7 | C7: 3 | D7: 3 | E7: 12 | F7: 3 | G7: 12 | H7: 11 | I7: 10 | J7: 10 | K7: 11 | L7: 10 | M7: 8 | N7: 9 | O7: =SUM(B7:N7) -> 109 | P7: =O7/개요!$C$7 -> 0.69871795 | Q7: =IF(P7>=$B$23,"주연",IF(P7>=$B$24,"준주연",IF(P7>=$B$25,"핵심 조연","조연"))) -> 주연 | R7: =IF(MAX(B7:N7)<=개요!$C$6,"OK","확인") -> OK | S7: —
A8: Chiara | B8: 6 | C8: 3 | D8: 3 | E8: 3 | F8: 12 | G8: 12 | H8: 10 | I8: 11 | J8: 10 | K8: 10 | L8: 9 | M8: 3 | N8: 9 | O8: =SUM(B8:N8) -> 101 | P8: =O8/개요!$C$7 -> 0.6474359 | Q8: =IF(P8>=$B$23,"주연",IF(P8>=$B$24,"준주연",IF(P8>=$B$25,"핵심 조연","조연"))) -> 준주연 | R8: =IF(MAX(B8:N8)<=개요!$C$6,"OK","확인") -> OK | S8: —
A9: Cesare | B9: 4 | C9: 2 | D9: 2 | E9: 2 | F9: 2 | G9: 7 | H9: 9 | I9: 7 | J9: 9 | K9: 9 | L9: 9 | M9: 0 | N9: 3 | O9: =SUM(B9:N9) -> 65 | P9: =O9/개요!$C$7 -> 0.41666667 | Q9: =IF(P9>=$B$23,"주연",IF(P9>=$B$24,"준주연",IF(P9>=$B$25,"핵심 조연","조연"))) -> 핵심 조연 | R9: =IF(MAX(B9:N9)<=개요!$C$6,"OK","확인") -> OK | S9: —
A10: Machiavelli | B10: 3 | C10: 1 | D10: 1 | E10: 1 | F10: 1 | G10: 6 | H10: 8 | I10: 9 | J10: 8 | K10: 8 | L10: 7 | M10: 4 | N10: 7 | O10: =SUM(B10:N10) -> 64 | P10: =O10/개요!$C$7 -> 0.41025641 | Q10: =IF(P10>=$B$23,"주연",IF(P10>=$B$24,"준주연",IF(P10>=$B$25,"핵심 조연","조연"))) -> 핵심 조연 | R10: =IF(MAX(B10:N10)<=개요!$C$6,"OK","확인") -> OK | S10: —
A11: Garibaldi | B11: 2 | C11: 1 | D11: 1 | E11: 3 | F11: 1 | G11: 5 | H11: 10 | I11: 7 | J11: 8 | K11: 8 | L11: 7 | M11: 3 | N11: 7 | O11: =SUM(B11:N11) -> 63 | P11: =O11/개요!$C$7 -> 0.40384615 | Q11: =IF(P11>=$B$23,"주연",IF(P11>=$B$24,"준주연",IF(P11>=$B$25,"핵심 조연","조연"))) -> 핵심 조연 | R11: =IF(MAX(B11:N11)<=개요!$C$6,"OK","확인") -> OK | S11: —
A12: Dante | B12: 1 | C12: 1 | D12: 2 | E12: 1 | F12: 2 | G12: 4 | H12: 7 | I12: 8 | J12: 6 | K12: 7 | L12: 6 | M12: 2 | N12: 7 | O12: =SUM(B12:N12) -> 54 | P12: =O12/개요!$C$7 -> 0.34615385 | Q12: =IF(P12>=$B$23,"주연",IF(P12>=$B$24,"준주연",IF(P12>=$B$25,"핵심 조연","조연"))) -> 조연 | R12: =IF(MAX(B12:N12)<=개요!$C$6,"OK","확인") -> OK | S12: —
A13: Gramsci | B13: 1 | C13: 1 | D13: 1 | E13: 1 | F13: 1 | G13: 4 | H13: 6 | I13: 9 | J13: 7 | K13: 9 | L13: 7 | M13: 4 | N13: 7 | O13: =SUM(B13:N13) -> 58 | P13: =O13/개요!$C$7 -> 0.37179487 | Q13: =IF(P13>=$B$23,"주연",IF(P13>=$B$24,"준주연",IF(P13>=$B$25,"핵심 조연","조연"))) -> 조연 | R13: =IF(MAX(B13:N13)<=개요!$C$6,"OK","확인") -> OK | S13: —
A14: Galileo | B14: 2 | C14: 1 | D14: 1 | E14: 2 | F14: 1 | G14: 4 | H14: 6 | I14: 6 | J14: 5 | K14: 6 | L14: 6 | M14: 1 | N14: 5 | O14: =SUM(B14:N14) -> 46 | P14: =O14/개요!$C$7 -> 0.29487179 | Q14: =IF(P14>=$B$23,"주연",IF(P14>=$B$24,"준주연",IF(P14>=$B$25,"핵심 조연","조연"))) -> 조연 | R14: =IF(MAX(B14:N14)<=개요!$C$6,"OK","확인") -> OK | S14: —
A15: Rosa | B15: 12 | C15: 2 | D15: 2 | E15: 2 | F15: 2 | G15: 5 | H15: 8 | I15: 6 | J15: 4 | K15: 5 | L15: 8 | M15: 3 | N15: 10 | O15: =SUM(B15:N15) -> 69 | P15: =O15/개요!$C$7 -> 0.44230769 | Q15: =IF(P15>=$B$23,"주연",IF(P15>=$B$24,"준주연",IF(P15>=$B$25,"핵심 조연","조연"))) -> 핵심 조연 | R15: =IF(MAX(B15:N15)<=개요!$C$6,"OK","확인") -> OK | S15: —
A16: Paolo | B16: 2 | C16: 1 | D16: 2 | E16: 1 | F16: 3 | G16: 5 | H16: 9 | I16: 8 | J16: 6 | K16: 6 | L16: 7 | M16: 2 | N16: 6 | O16: =SUM(B16:N16) -> 58 | P16: =O16/개요!$C$7 -> 0.37179487 | Q16: =IF(P16>=$B$23,"주연",IF(P16>=$B$24,"준주연",IF(P16>=$B$25,"핵심 조연","조연"))) -> 조연 | R16: =IF(MAX(B16:N16)<=개요!$C$6,"OK","확인") -> OK | S16: —
... A19: Montessori | B19: 1 | C19: 1 | D19: 1 | E19: 3 | F19: 1 | G19: 5 | H19: 8 | I19: 5 | J19: 6 | K19: 6 | L19: 9 | M19: 1 | N19: 6 | O19: =SUM(B19:N19) -> 53 | P19: =O19/개요!$C$7 -> 0.33974359 | Q19: =IF(P19>=$B$23,"주연",IF(P19>=$B$24,"준주연",IF(P19>=$B$25,"핵심 조연","조연"))) -> 조연 | R19: =IF(MAX(B19:N19)<=개요!$C$6,"OK","확인") -> OK | S19: —
A20: 부별 연인원 (합계) | B20: =SUM(B5:B19) -> 68 | C20: =SUM(C5:C19) -> 37 | D20: =SUM(D5:D19) -> 39 | E20: =SUM(E5:E19) -> 44 | F20: =SUM(F5:F19) -> 40 | G20: =SUM(G5:G19) -> 106 | H20: =SUM(H5:H19) -> 131 | I20: =SUM(I5:I19) -> 123 | ... O20: =SUM(O5:O19) -> 1101 | S20: =SUM(S5:S19) -> 0
A23: 주연 | B23: 0.69 | C23: ="← 기준값은 제안값입니다. 현재 구분: 주연 "&COUNTIF($Q$5:$Q$19,"주연")&" / 준주연 "&COUNTIF($Q$5:$Q$19,"준주연")&" / 핵심 조연 "&COUNTIF($Q$5:$Q$19,"핵심 조연")&" / 조연 "&COUNTIF($Q$5:$Q$19,"조연")&" (자동 계산)" -> ← 기준값은 제안값입니다. 현재 구분: 주연 2 / 준주연 3 / 핵심 조연 4 / 조연 6 (자동 계산)
A24: 준주연 | B24: 0.6
A25: 핵심 조연 | B25: 0.4
A26: 조연 | B26: 그 미만
A28: 배분 원칙
A29: 1. 1부는 개소 1개월 후 시점: Sofia·Rosa가 전 화에, 주력 4인은 사건별로 교대 등장(전원 겹치지 않음). Cesare 4화, Machiavelli 3화로 자주 얼굴을 비추고 '이번 겨울이 마지막' 복선을 1화부터 깐다. 나머지는 사건마다 다른 조합으로 카메오.
A30: 2. 2~5부: 각 주인공이 자기 부 12화 전부에 나오고, 다른 주력 3인은 3화씩 스쳐 지나가며 6부 만남을 예고. Sofia는 4화씩 '사무소에서 이야기를 듣는 프레임'으로 등장해 회상을 잇는다.
A31: 3. 부활자·조연은 과거와 겹치는 곳에만 배치: Paolo-5부(Chiara의 구조조정 현장), Francesco·Galileo-4부(Alessandro의 감사 사건), Montessori-3부·5부(되받기·번아웃 상담), Garibaldi-4부(지역 회계 회상 카메오).
A32: 4. 부활자·조연 본격 비중은 7~10부에서 최고치: 7부 Galileo·Paolo·Garibaldi(공론화·현장 조직), 8부 Dante·Machiavelli·Gramsci(선언문·전략·출처), 10부 Dante·Galileo·Gramsci(취임 연설·대변인·정보 감독).
A33: 5. 11부(국정 I)는 Cesare가 9~12화에서 브뤼셀 직접 협상을 이끌며 최고치(9화)를 찍고 12화에서 사망한다. Francesco는 앞선 주거·금융 국내 현안 화에서 정점.
A34: 6. 12부(국정 II)는 Cesare 사후(0화): 1화 장례식에 Garibaldi·Gramsci·Machiavelli가 몰리고, Alessandro·Dante가 유작 메모를 이어받는 2·3화에서 비중이 오른다.
A35: 7. 13부(귀환)는 원형 구조: Sofia 12화 전부, Rosa 10화. Cesare는 유언장·회상으로 3화, 주력 4인은 사무소의 손님으로 9~10화 등장.
A36: 8. Cesare는 11부 12화(브뤼셀 승리 직후)에서 두 번째 죽음을 맞는다. 12부 1화 장례식, 2·3화 유작 메모 승계, 13부 2화 유언장까지 이어진다.
A37: 9. 등장 화 수와 대사량은 다르다: Sofia는 약 67%지만 문장이 짧아 대사량은 Marco의 절반 이하가 되게 하고, Cesare·Dante는 화당 대사가 길어도 된다.
A38: 10. 조연 11인은 화 전체의 중심이 되는 에피소드를 각자 2개 이상 배정(S열 목표). 자기 이야기가 한 번도 없으면 얇은 인물이 된다.
A39: 11. Montessori·Galileo가 가장 얇다: 3·5부 상담 장면을 늘리거나, 12부 Cesare 애도 상담(Montessori)·스파이웨어 검증(Galileo)을 맡겨 서사를 넓히는 안을 검토.

Sheet 턴_설계
A1: 대화량 설계: 화당 120턴
A2: 한 화 = 대화 120턴, 전체 156화 = 18,720턴. 점유율·평균 단어/턴·배율·낭독 속도는 가정값(파란 숫자)이며 수정하면 아래 표가 자동 갱신됩니다.
A4: 1. 기본 설정
A5: 화당 대화 턴 | B5: 120
A6: 낭독 속도 (단어/분, 가정) | B6: 130
A7: 총 화 수 | B7: =개요!$C$7 -> 156
A8: 총 대화 턴 | B8: =B5*B7 -> 18720
A9: 턴 정의 | B9: 화자 표기 한 줄 = 1턴 (화자가 바뀌면 새 턴). 연설·조항·기사 낭독처럼 긴 발화도 1턴으로 센다.
A11: 2. 부별 화자 점유율 (턴 기준, 각 부의 합 = 100%)
A12: 인물 | B12: 평균 단어/턴 | C12: 1부 | D12: 2부 | E12: 3부 | F12: 4부 | G12: 5부 | H12: 6부 | I12: 7부 | J12: 8부 | K12: 9부 | L12: 10부 | M12: 11부 | N12: 12부 | O12: 13부
A13: Marco | B13: 13 | C13: 0.13 | D13: 0.48 | E13: 0.03 | F13: 0.02 | G13: 0.02 | H13: 0.13 | I13: 0.14 | J13: 0.14 | K13: 0.08 | L13: 0.17 | M13: 0.14 | N13: 0.15 | O13: 0.07
A14: Giulia | B14: 8 | C14: 0.12 | D14: 0.03 | E14: 0.46 | F14: 0.04 | G14: 0.03 | H14: 0.12 | I14: 0.07 | J14: 0.07 | K14: 0.11 | L14: 0.06 | M14: 0.09 | N14: 0.09 | O14: 0.06
A15: Alessandro | B15: 11 | C15: 0.12 | D15: 0.04 | E15: 0.04 | F15: 0.46 | G15: 0.04 | H15: 0.12 | I15: 0.1 | J15: 0.08 | K15: 0.14 | L15: 0.07 | M15: 0.1 | N15: 0.11 | O15: 0.07
A16: Chiara | B16: 12 | C16: 0.12 | D16: 0.05 | E16: 0.03 | F16: 0.03 | G16: 0.46 | H16: 0.12 | I16: 0.06 | J16: 0.08 | K16: 0.08 | L16: 0.1 | M16: 0.08 | N16: 0.08 | O16: 0.07
A17: Cesare | B17: 14 | C17: 0.08 | D17: 0.04 | E17: 0.04 | F17: 0.04 | G17: 0.04 | H17: 0.04 | I17: 0.06 | J17: 0.05 | K17: 0.04 | L17: 0.06 | M17: 0.04 | N17: 0 | O17: 0.02
A18: Machiavelli | B18: 11 | C18: 0.02 | D18: 0.01 | E18: 0.01 | F18: 0.01 | G18: 0.01 | H18: 0.03 | I18: 0.04 | J18: 0.06 | K18: 0.04 | L18: 0.06 | M18: 0.04 | N18: 0.05 | O18: 0.03
A19: Garibaldi | B19: 7 | C19: 0.02 | D19: 0.01 | E19: 0.01 | F19: 0.01 | G19: 0.01 | H19: 0.05 | I19: 0.06 | J19: 0.06 | K19: 0.04 | L19: 0.08 | M19: 0.07 | N19: 0.07 | O19: 0.06
A20: Dante | B20: 12 | C20: 0.02 | D20: 0.01 | E20: 0.01 | F20: 0.01 | G20: 0.01 | H20: 0.03 | I20: 0.03 | J20: 0.07 | K20: 0.05 | L20: 0.07 | M20: 0.05 | N20: 0.05 | O20: 0.05
A21: Gramsci | B21: 9 | C21: 0.02 | D21: 0.01 | E21: 0.01 | F21: 0.01 | G21: 0.01 | H21: 0.03 | I21: 0.06 | J21: 0.03 | K21: 0.04 | L21: 0.03 | M21: 0.05 | N21: 0.05 | O21: 0.08
A22: Galileo | B22: 10 | C22: 0.02 | D22: 0.01 | E22: 0.03 | F22: 0.04 | G22: 0.01 | H22: 0.03 | I22: 0.08 | J22: 0.06 | K22: 0.07 | L22: 0.05 | M22: 0.06 | N22: 0.06 | O22: 0.05
A23: Rosa | B23: 9 | C23: 0.12 | D23: 0.04 | E23: 0.03 | F23: 0.03 | G23: 0.03 | H23: 0.05 | I23: 0.04 | J23: 0.05 | K23: 0.03 | L23: 0.04 | M23: 0.04 | N23: 0.04 | O23: 0.13
A24: Paolo | B24: 10 | C24: 0.01 | D24: 0.02 | E24: 0.01 | F24: 0.01 | G24: 0.09 | H24: 0.05 | I24: 0.06 | J24: 0.08 | K24: 0.08 | L24: 0.06 | M24: 0.05 | N24: 0.05 | O24: 0.05
... A28: 엑스트라(가상) | B28: 10 | C28: 0.02 | D28: 0.14 | E28: 0.16 | F28: 0.12 | G28: 0.11 | H28: 0.04 | I28: 0.03 | J28: 0.02 | K28: 0.02 | L28: 0.02 | M28: 0.02 | N28: 0.03 | O28: 0.02
A29: 합계 | C29: =SUM(C13:C28) -> 1 | D29: =SUM(D13:D28) -> 1 | E29: =SUM(E13:E28) -> 1 | F29: =SUM(F13:F28) -> 1 | G29: =SUM(G13:G28) -> 1 | H29: =SUM(H13:H28) -> 1 | I29: =SUM(I13:I28) -> 1 | J29: =SUM(J13:J28) -> 1 | ... O29: =SUM(O13:O28) -> 1
A30: 검증 | C30: =IF(ROUND(C29,4)=1,"OK","확인") -> OK | D30: =IF(ROUND(D29,4)=1,"OK","확인") -> OK | E30: =IF(ROUND(E29,4)=1,"OK","확인") -> OK | F30: =IF(ROUND(F29,4)=1,"OK","확인") -> OK | G30: =IF(ROUND(G29,4)=1,"OK","확인") -> OK | H30: =IF(ROUND(H29,4)=1,"OK","확인") -> OK | I30: =IF(ROUND(I29,4)=1,"OK","확인") -> OK | J30: =IF(ROUND(J29,4)=1,"OK","확인") -> OK | ... O30: =IF(ROUND(O29,4)=1,"OK","확인") -> OK
A32: 3. 부별 턴·단어·낭독 시간 (수식)
A33: 부 | B33: 난이도 배율 | C33: 화당 턴 | D33: 부 총 턴 | E33: 평균 단어/턴 | F33: 화당 단어 | G33: 부 총 단어 | H33: 화당 낭독 (분) | I33: 부 총 낭독 (시간)
A34: 1부 | B34: 0.8 | C34: =$B$5 -> 120 | D34: =C34*개요!$C$6 -> 1440 | E34: =SUMPRODUCT(C$13:C$28,$B$13:$B$28)*B34 -> 8.168 | F34: =C34*E34 -> 980.16 | G34: =F34*개요!$C$6 -> 11761.92 | H34: =F34/$B$6 -> 7.5396923 | I34: =H34*개요!$C$6/60 -> 1.5079385
A35: 2부 | B35: 1 | C35: =$B$5 -> 120 | D35: =C35*개요!$C$6 -> 1440 | E35: =SUMPRODUCT(D$13:D$28,$B$13:$B$28)*B35 -> 11.4 | F35: =C35*E35 -> 1368 | G35: =F35*개요!$C$6 -> 16416 | H35: =F35/$B$6 -> 10.523077 | I35: =H35*개요!$C$6/60 -> 2.1046154
A36: 3부 | B36: 1 | C36: =$B$5 -> 120 | D36: =C36*개요!$C$6 -> 1440 | E36: =SUMPRODUCT(E$13:E$28,$B$13:$B$28)*B36 -> 9.12 | F36: =C36*E36 -> 1094.4 | G36: =F36*개요!$C$6 -> 13132.8 | H36: =F36/$B$6 -> 8.4184615 | I36: =H36*개요!$C$6/60 -> 1.6836923
A37: 4부 | B37: 1 | C37: =$B$5 -> 120 | D37: =C37*개요!$C$6 -> 1440 | E37: =SUMPRODUCT(F$13:F$28,$B$13:$B$28)*B37 -> 10.45 | F37: =C37*E37 -> 1254 | G37: =F37*개요!$C$6 -> 15048 | H37: =F37/$B$6 -> 9.6461538 | I37: =H37*개요!$C$6/60 -> 1.9292308
A38: 5부 | B38: 1 | C38: =$B$5 -> 120 | D38: =C38*개요!$C$6 -> 1440 | E38: =SUMPRODUCT(G$13:G$28,$B$13:$B$28)*B38 -> 10.81 | F38: =C38*E38 -> 1297.2 | G38: =F38*개요!$C$6 -> 15566.4 | H38: =F38/$B$6 -> 9.9784615 | I38: =H38*개요!$C$6/60 -> 1.9956923
A39: 6부 | B39: 1 | C39: =$B$5 -> 120 | D39: =C39*개요!$C$6 -> 1440 | E39: =SUMPRODUCT(H$13:H$28,$B$13:$B$28)*B39 -> 10.19 | F39: =C39*E39 -> 1222.8 | G39: =F39*개요!$C$6 -> 14673.6 | H39: =F39/$B$6 -> 9.4061538 | I39: =H39*개요!$C$6/60 -> 1.8812308
A40: 7부 | B40: 1 | C40: =$B$5 -> 120 | D40: =C40*개요!$C$6 -> 1440 | E40: =SUMPRODUCT(I$13:I$28,$B$13:$B$28)*B40 -> 10.39 | F40: =C40*E40 -> 1246.8 | G40: =F40*개요!$C$6 -> 14961.6 | H40: =F40/$B$6 -> 9.5907692 | I40: =H40*개요!$C$6/60 -> 1.9181538
A41: 8부 | B41: 1.1 | C41: =$B$5 -> 120 | D41: =C41*개요!$C$6 -> 1440 | E41: =SUMPRODUCT(J$13:J$28,$B$13:$B$28)*B41 -> 11.495 | F41: =C41*E41 -> 1379.4 | G41: =F41*개요!$C$6 -> 16552.8 | H41: =F41/$B$6 -> 10.610769 | I41: =H41*개요!$C$6/60 -> 2.1221538
A42: 9부 | B42: 1.1 | C42: =$B$5 -> 120 | D42: =C42*개요!$C$6 -> 1440 | E42: =SUMPRODUCT(K$13:K$28,$B$13:$B$28)*B42 -> 11.187 | F42: =C42*E42 -> 1342.44 | G42: =F42*개요!$C$6 -> 16109.28 | H42: =F42/$B$6 -> 10.326462 | I42: =H42*개요!$C$6/60 -> 2.0652923
A43: 10부 | B43: 1.2 | C43: =$B$5 -> 120 | D43: =C43*개요!$C$6 -> 1440 | E43: =SUMPRODUCT(L$13:L$28,$B$13:$B$28)*B43 -> 12.744 | F43: =C43*E43 -> 1529.28 | G43: =F43*개요!$C$6 -> 18351.36 | H43: =F43/$B$6 -> 11.763692 | I43: =H43*개요!$C$6/60 -> 2.3527385
A44: 11부 | B44: 1.2 | C44: =$B$5 -> 120 | D44: =C44*개요!$C$6 -> 1440 | E44: =SUMPRODUCT(M$13:M$28,$B$13:$B$28)*B44 -> 12.324 | F44: =C44*E44 -> 1478.88 | G44: =F44*개요!$C$6 -> 17746.56 | H44: =F44/$B$6 -> 11.376 | I44: =H44*개요!$C$6/60 -> 2.2752
A45: 12부 | B45: 1.2 | C45: =$B$5 -> 120 | D45: =C45*개요!$C$6 -> 1440 | E45: =SUMPRODUCT(N$13:N$28,$B$13:$B$28)*B45 -> 12.192 | F45: =C45*E45 -> 1463.04 | G45: =F45*개요!$C$6 -> 17556.48 | H45: =F45/$B$6 -> 11.254154 | I45: =H45*개요!$C$6/60 -> 2.2508308
A46: 13부 | B46: 0.8 | C46: =$B$5 -> 120 | D46: =C46*개요!$C$6 -> 1440 | E46: =SUMPRODUCT(O$13:O$28,$B$13:$B$28)*B46 -> 7.664 | F46: =C46*E46 -> 919.68 | G46: =F46*개요!$C$6 -> 11036.16 | H46: =F46/$B$6 -> 7.0744615 | I46: =H46*개요!$C$6/60 -> 1.4148923
...

Sheet 13부_구성
A1: 13부 구성 (13부 × 12화 = 156화)
A2: 정치 파트(8~12부)는 이탈리아의 현실 정치 제도에 맞춰 재설계했습니다. 화별 목차는 '화별목차_전체', 제도 근거는 '정치제도' 시트.
A4: 부 | B4: 제목 (IT) | C4: 한국어 | D4: 배경 | E4: 핵심 내용 | F4: 난이도 (CEFR) | G4: 반영 제도·전문 영역 | H4: 시점
A5: 1 | B5: Lo Studio di Testaccio | C5: 테스타초 사무소 | D5: Testaccio의 작은 사무실 (1층은 Rosa의 트라토리아), 개소 1개월 후 | E5: 이미 한 달째 좌충우돌 중인 팀이 이웃들의 사건 6개를 2화씩(도입→해결) 풀어 간다. 자기소개 대신 '이 사람들이 어쩌다 이렇게 됐지?' 하는 궁금증(In medias res)으로 시작. | F5: B1 | G5: 생활 법률·노동·의료·금융 기초 어휘, 반복되는 말다툼, Sofia 1차 폭발(6화) | H5: 현재(개소 후 1개월)
A6: 2 | B6: L'Avvocato | C6: 변호사 | D6: Prati(Piazza Cavour 법원가)의 대형 로펌 | E6: 승소율 100%의 이면: 갱신 거절로 비운 건물이 Marco의 결핍이 된다. | F6: B2~C1 | G6: 임대차(legge 431/1998), 소송, 퇴거 확인 절차(convalida di sfratto) | H6: 과거
A7: 3 | B7: La Dottoressa | C7: 의사 | D7: San Camillo 응급실 (가상 설정) | E7: 예산 삭감과 외주 압박 속에서 치료받지 못하는 환자들. Giulia의 이름 목록. | F7: B2~C1 | G7: 의학·보건행정, 주 보건서비스(SSR Lazio·ASL), 병원 외주(esternalizzazione) | H7: 과거
A8: 4 | B8: Il Revisore | C8: 회계사 | D8: Conti Revisori | E8: 역외 탈세·자금세탁 정황을 발견하지만 조직의 묵인 압박. 서명하지 않겠다는 다짐의 기원. | F8: B2~C1 | G8: 법정 감사(d.lgs. 39/2010), 자금세탁방지(d.lgs. 231/2007) | H8: 과거
A9: 5 | B9: La Consulente | C9: 컨설턴트 | D9: Zenit Consulting (EUR 오피스 타워 32층) | E9: 구조조정 엑셀 한 칸이 수백 명의 실직이었음을 깨닫는다. Paolo와의 첫 접점. | F9: B2~C1 | G9: 경영 전략, 집단해고(legge 223/1991), 노동법 | H9: 과거
A10: 6 | B10: L'Incontro | C10: 운명적 만남 | D10: Quarticciolo의 서민 주거 단지, 작은 바 | E10: 강제 퇴거와 의료 방치가 한 건으로 얽힌 사건에서 네 사람이 만나 사무소를 차리기로 한다. | F10: B2 | G10: 협상·설득 구어체 | H10: 현재로 수렴
A11: 7 | B11: La Rete della Resistenza | C11: 사무소 2탄: 전면전 | D11: 법원(Piazzale Clodio), Campidoglio 앞, 로마 전역 | E11: 부당 해고·의료 사고·탈세 대기업 상대 집단 대응. 내부 제보자를 보호하고 검찰에 고발한다. | F11: B2~C1 | G11: 검찰 고발(esposto-denuncia), 민사 당사자(parte civile), ANAC, 내부고발자 보호(d.lgs. 24/2023) | H11: 과거→현재
A12: 8 | B12: Il Risveglio Civico | C12: 정치적 각성과 창당 | D12: Piazza San Giovanni, 시민 집회 | E12: 폐지 국민투표가 정족수에 막히자 스스로 정당 «Casa Comune»를 창당해 첫 로마 시의회·라치오 주의회 선거에 나선다. | F12: B2~C1 | G12: 집회 사전 통지, 폐지 국민투표(헌법 제75조), 정당 등록부(d.l. 149/2013), 정당 재정, 선거운동 규칙 | H12: 정치
A13: 9 | B13: In Campidoglio e alla Pisana | C13: 시의회와 주의회 | D13: Campidoglio(Assemblea Capitolina), 라치오 주의회(Via della Pisana) | E13: Alessandro는 시의회에서 예산을, Giulia는 주의회에서 보건을 파고든다. 스캔들 폭로와 Sofia의 2차 폭발. | F13: C1 | G13: 시의회 운영(TUEL), 시 예산, 공공계약(d.lgs. 36/2023), 주 권한(보건·도시계획), 검찰 고발 | H13: 정치
A14: 10 | B14: Verso Palazzo Chigi | C14: 총선에서 총리 취임까지 | D14: Montecitorio, Palazzo Madama, Quirinale, Palazzo Chigi | E14: 해산·총선·개원·대통령 협의·첫 정부의 신임 부결·탐색 위임·재선거·상원 1표 차 신임. | F14: C1~C2 | G14: 선거 절차(legge 165/2017), 개원, 조각 위임(헌법 제92조), 신임(제94조), 해산(제88조), Quirinale 선서 | H14: 정치
A15: 11 | B15: La Grande Battaglia Sociale I | C15: 사회 현안 전투 I | D15: Palazzo Chigi, Consiglio dei Ministri, 브뤼셀 | E15: 연립 정부로 주거·보건·이민·청년·물가 국내 현안을 돌파한 뒤, Cesare가 직접 브뤼셀 협상(NATO 방위비·EU 재정규칙)에 나서 승리하고 귀국 직후 두 번째 죽음을 맞는다. | F15: C1~C2 | G15: Consiglio dei Ministri, 국가–주 협의회, NATO 방위비 목표(2025 헤이그 합의), EU 과도한 재정적자 절차 | H15: 정치
A16: 12 | B16: La Grande Battaglia Sociale II | C16: 사회 현안 전투 II | D16: Palazzo Chigi, 브뤼셀, 홍수 현장 | E16: 장례식으로 열고 Cesare의 유작 메모로 브뤼셀 후속 협상을 마무리한다. 플랫폼 노동·스파이웨어·청년 정신건강 등 새 현안과 불신임안 방어, 홍수 재난, 예산안까지. | F16: C1~C2 | G16: 메모 승계, decreto-legge vs 법률, 헌법재판소, 불신임안, 민방위(d.lgs. 1/2018), 예산 | H16: 정치
A17: 13 | B17: Ritorno a Testaccio | C17: 귀환 | D17: Testaccio, Trattoria da Rosa | E17: 1부 1화와 같은 대사로 시작해 원을 닫는다. Cesare의 유언장, 새 인턴, 이제 설명하는 쪽이 된 Sofia. | F17: B1~B2 | G17: 유언(notaio, esecutore testamentario), 정부 구성원 이해충돌 제한, 재단 전환, 원형 구조 | H17: 귀환
A19: 흐름: 현재(1) → 과거(2~5) → 교차(6) → 전면전(7) → 정치(8 창당 → 9 시·주 의회 → 10 총선·총리) → 국정(11~12) → 귀환(13, 원형 구조). 난이도는 B1 → C1/C2 → B1~B2로 올라갔다 내려와 마무리가 부드럽고, 13부에서 1부 장면을 다시 읽으면 낭독 실력의 성장을 스스로 확인할 수 있다.

Sheet 아크_구성계획
A1: 아크별 구성 계획 (1~13부)
A2: 각 부(아크)의 서사 기능, 변화, 비트(발단→결말), 인물 아크, 복선, 현안·제도, 언어 설계를 한 블록으로 정리. 화별 세부는 '화별목차_전체', 복선 추적은 '복선_회수'.
A4: 1부 | B4: Lo Studio di Testaccio — 테스타초 사무소 | 난이도 B1 | 사무소 개소 1개월 후(6부 12화로부터 약 4주). Testaccio 사무소와 1층 Rosa의 트라토리아.
A5: 서사 기능 | B5: 독자 진입 장치. 이미 굴러가는(그러나 여전히 좌충우돌하는) 사무소를 보여 주어 '이 사람들이 어쩌다 이렇게 됐지?' 하는 궁금증을 만든다. 자기소개 대신 여섯 사건을 통해 인물의 습관과 리듬을 익히게 한다. 부활한 역사 인물들이 아무렇지 않게 섞여 있는 일상이 첫 웃음 포인트.
A6: 로그라인 | B6: 개소 한 달째, 여전히 순서 하나 못 정하고 매번 다투는 네 전문가와 팀이 그래도 이웃들의 사건 여섯 개를 하나씩 해결해 나가지만, 마지막 사건의 서류에서 Marco의 옛 로펌 이름이 튀어나온다.
A7: 변화 (시작 → 끝) | B7: '한 달이나 됐는데 아직도 이 모양' → 그래도 매번 어떻게든 해결하는 팀이라는 신뢰. 그러나 각자의 과거는 여전히 미해결이고, 옛 로펌 이름이 도착한다.
A8: 핵심 갈등 | B8: 전문가의 말투 vs 이웃의 삶 / 여전히 못 정한 방법 / 각자 숨기는 과거
A9: 비트 1 | B9: 사건1 임대료 인상, 1~2화(Fatima): 도입에서 여전히 자리 못 잡은 한 달 차 팀의 말다툼을 보여 주고, 해결에서 Gramsci의 카드 #1(legge 431/1998)로 부당 인상을 막는다.
A10: 비트 2 | B10: 사건2 퇴거 집행, 3~4화: 밤 여덟 시 급보 → 아침 집행 연기. Garibaldi·Paolo 첫 카메오, 넷의 역할 분담(서류·건강·숫자·동선)이 처음으로 손발이 맞는다.
A11: 비트 3 | B11: 사건3 임금 체불·위장 인턴, 5~6화: Chiara의 컨설팅 용어가 청년 노동자를 지치게 하고, 협상 중 Sofia가 1차 폭발한다. 폭발 후 쉬운 말로 다시 협상해 해결.
A12: 비트 4 | B12: 사건4 의료 접근, 7~8화: 체류 서류 없는 가족의 아이가 진료를 못 받는다. Montessori·Dante 카메오, Cesare의 가짜 무릎이 진짜 아픈 아이 앞에서 조용해지는 대비. STP 코드로 해결.
A13: 비트 5 | B13: 사건5 금융 사기, 9~10화: 저축을 잃은 이웃을 두고 Alessandro가 장부를, 낯선 Francesco가 계좌 흐름을 추적한다. Galileo 카메오. Francesco는 설명 없이 사라지고 Alessandro는 은행 이름에 말없이 굳는다.
A14: 비트 6 | B14: 사건6 오래된 서류·훅, 11~12화: 수십 년 전 퇴거 서류의 절차 오류를 바로잡다가 서명란에서 Marco의 옛 로펌 이름을 발견한다. Marco가 얼어붙고 금요일 이야기(2부)가 예고된다.
A15: 인물 아크 | B15: Sofia=독자의 대리인(질문), 한 달이 지나도 Marco에게 Lei 유지. Cesare=심술과 복선(매년 하는 소리라는 게 드러남). Rosa=정서적 중심. 카메오는 사건별로 분산: Gramsci(1·2·6화), Machiavelli(1·5·12화), Garibaldi·Paolo(3·4화), Montessori·Dante(7화), Francesco·Galileo(9·10·11화). 폭발 화(6화)에는 Garibaldi·Rosa·Gramsci의 고정 반응만 남기고 Paolo의 욕은 9부 2차 폭발로 이관해 과밀을 해소.
... A19: 언어 설계 | B19: B1. 한 줄 15단어 이내, 현재·명령형·근과거(passato prossimo). tu·voi 중심. 낭독: 빠른 티키타카로 입 풀기. Marco·Cesare의 격식체는 한두 줄 맛보기. 매 사건 2화(도입→해결) 리듬을 반복해 구조를 익히게 한다. Rosa의 로마 사투리(romanesco)는 한 화에 한두 마디만.
A20: 대화량 (화당 120턴) | B20: ="화당 "&턴_설계!$B$5&"턴 · 부 총 "&TEXT(턴_설계!D34,"#,##0")&"턴 · 화당 약 "&TEXT(턴_설계!F34,"#,##0")&"단어 · 낭독 약 "&TEXT(턴_설계!H34,"0.0")&"분 (평균 "&TEXT(턴_설계!E34,"0.0")&"단어/턴)" -> 화당 120턴 · 부 총 1,440턴 · 화당 약 980단어 · 낭독 약 7.5분 (평균 8.2단어/턴)
A21: Sofia 질문·Gramsci 카드 | B21: Sofia: 임대·노동·의료·금융 기초 용어(deposito cauzionale, contratto a termine, tirocinio, codice STP, conto corrente). 카드: legge 431/1998, 사전(Treccani·Accademia della Crusca).
A22: 다음 부 연결 | B22: 2부: 금요일마다 한 명씩 과거를 이야기하는 규칙 — 첫 번째는 Marco.
A24: 2부 | B24: L'Avvocato — 변호사 | 난이도 B2~C1 | 프레임: 1부와 같은 첫 겨울의 금요일 밤. 과거: 약 5년 전, Prati(Piazza Cavour 법원가)의 대형 로펌.
A25: 서사 기능 | B25: 첫 과거 회상. 공동 악역 Gruppo Meridiano를 도입하고 '법을 잘 쓰는 것과 옳은 것은 다르다'는 이 이야기의 첫 질문을 던진다. 프레임(Rosa의 식탁)과 과거를 오가는 구조 실험.
A26: 로그라인 | B26: 승소율 100%의 파트너 후보가 대형 고객의 주택 포트폴리오를 비우는 갱신 거절 전략을 설계해 재판에서 이기고, 그 승리가 한 노인의 죽음이 되었음을 알게 된다.
A27: 변화 (시작 → 끝) | B27: 자랑스러운 승자 → 자기 승리에 사직서를 낸 사람.
A28: 핵심 갈등 | B28: 잘 쓰는 법 vs 옳은 것 / 파트너 승진 vs 양심
A29: 비트 1 | B29: 발단(1~3화): 금요일 프레임, 프라티의 월요일(편의점의 Dante), VIP 고객 Santoro.
A30: 비트 2 | B30: 전개(4~5화): 실사에서 Testaccio 건물 발견 / 프레임에서 그곳이 Rosa의 거리였음이 드러남.
A31: 비트 3 | B31: 미드포인트(6화): 조항 설계 — Marco가 스스로 함정을 만든다.
A32: 비트 4 | B32: 위기(7~9화): 세입자 총회(Assunta), 재판 승소, 프레임에서 Marco의 말이 막힘.
A33: 비트 5 | B33: 절정(10~11화): 파리올리 축하 만찬 중 부고, 손녀 Marina의 방문.
... A39: 언어 설계 | B39: B2~C1. 접속법 현재·과거(congiuntivo), 수동태, 법률 문어체. 과거 장면은 격식 문어, 프레임 장면은 B1로 두어 톤을 대비. 발성: 또박또박, 중저음.
A40: 대화량 (화당 120턴) | B40: ="화당 "&턴_설계!$B$5&"턴 · 부 총 "&TEXT(턴_설계!D35,"#,##0")&"턴 · 화당 약 "&TEXT(턴_설계!F35,"#,##0")&"단어 · 낭독 약 "&TEXT(턴_설계!H35,"0.0")&"분 (평균 "&TEXT(턴_설계!E35,"0.0")&"단어/턴)" -> 화당 120턴 · 부 총 1,440턴 · 화당 약 1,368단어 · 낭독 약 10.5분 (평균 11.4단어/턴)
A41: Sofia 질문·Gramsci 카드 | B41: Sofia: citazione·sentenza·clausola 등 법률 용어. 카드: Conservatoria dei Registri Immobiliari, legge 431/1998, 민사소송법의 퇴거 확인 절차(convalida di sfratto).
A42: 다음 부 연결 | B42: 3부: 응급실에서 쓰러진 Marco — 다음 금요일은 Giulia의 이야기.
A44: 3부 | B44: La Dottoressa — 의사 | 난이도 B2~C1 | 프레임: 금요일 밤. 과거: 약 4년 전, San Camillo 응급실(가상 설정).
A45: 서사 기능 | B45: 인간의 생명과 공공 보건이라는 정서적 무게. Gruppo Meridiano의 두 번째 얼굴(병원 외주)을 보여 주고, 폭염·고령 환자·서류 없는 환자 등 현안을 응급실에서 체감하게 한다.
A46: 로그라인 | B46: 응급의가 예산 삭감과 병원 외주 속에서 환자를 잃기 시작하고, 이름을 적어 두다가 내부 보고를 올리지만 징계로 돌아온다.
A47: 변화 (시작 → 끝) | B47: 시스템을 믿는 의사 → 이름 명단만 든 사직자.
A48: 핵심 갈등 | B48: 의료 윤리 vs 관리 효율 / 침묵하는 동료들
A49: 비트 1 | B49: 발단(1~3화): 금요일 프레임, 야간 근무(Marco 진료), 폭염 환자 폭증.
A50: 비트 2 | B50: 전개(4~5화): 병원 외주 발표(컨설턴트 Chiara 등장), 프레임에서 수첩 명단과 Cesare의 부은 발목(«Sono i calzari.»).
A51: 비트 3 | B51: 미드포인트(6화): '명단의 첫 번째' — 서류 없는 환자가 병상 지연으로 숨진다.
...

Sheet 화별목차_전체
A1: 전체 화별 목차 (1~13부, 156화)
A2: 현실 제도와 현안(ID는 '현안_배치' 시트)을 반영한 초안. 의석 수·결과는 가상 수치. 모든 화는 지문 없이 대화문으로만 진행한다.
A4: 부 | B4: 화 | C4: 서사 기능 | D4: 제목 (IT) | E4: 한국어 | F4: 핵심 사건 | G4: 반영 제도·전문 영역 | H4: 주요 인물 | I4: 반영 현안 (ID) | J4: 턴 수
A5: 1 | B5: 1 | C5: 사건1 도입 | D5: Un'altra lettera | E5: 또 다른 편지 | F5: 사무소 개소 1개월 후. 다섯 시, 여전히 방법을 못 정한 채 매일 다투는 팀. Fatima가 두 번째로 찾아와 새 임대료 인상 통지서와 퇴거 경고장을 보인다. Sofia는 여전히 Marco에게 Lei를 쓴다. Gramsci가 지나가며 «날짜를 세어 보라»는 힌트만 던지고, Machiavelli는 «이 집의 진짜 주인이 누구인가»만 묻는다. 계약서가 없어 다음 날로 미뤄진다. | G5: 생활 법률 구어체, 반복되는 말다툼 (B1) | H5: Rosa, Marco, Giulia, Alessandro, Chiara, Sofia, Cesare, Fatima, Gramsci, Machiavelli | I5: E1 | J5: =턴_설계!$B$5 -> 120
A6: 1 | B6: 2 | C6: 사건1 해결 | D6: La clausola che non sale | E6: 오르지 않는 조항 | F6: [사건1 해결] Fatima와 Sofia가 계약서를 가져온다. Gramsci의 카드 #1(legge 431/1998)로 계약에 정한 ISTAT 물가 연동 한도를 넘는 인상이 부당함을 확인하고, 기한 안에 등기우편(raccomandata) 답장을 쓴다. 사무소의 첫 번째 규칙(가난한 이웃에겐 돈을 받지 않는다)이 확인된다. | G6: 주거 임대차(legge 431/1998), ISTAT 물가 연동 조정(aggiornamento ISTAT), 기한·답변 | H6: Marco, Alessandro, Chiara, Fatima, Gramsci, Sofia, Rosa | I6: E1 | J6: =턴_설계!$B$5 -> 120
A7: 1 | B7: 3 | C7: 사건2 도입 | D7: L'avviso delle otto | E7: 여덟 시의 통지 | F7: [사건2 도입] 밤 여덟 시, 퇴거 집행(sfratto)이 다음 날 아침으로 잡혔다는 급보가 온다. Garibaldi가 주민을 '의용대'처럼 조직하고 Paolo가 이웃들을 모은다. 네 사람이 각자 서류·건강·숫자·동선을 맡아 밤새 준비하지만 승산은 불투명하다. | G7: 퇴거 집행 예고(preavviso di rilascio), 긴급 동원, 이웃 조직 | H7: Marco, Giulia, Alessandro, Chiara, Garibaldi, Paolo, Sofia, Rosa | I7: E1 | J7: =턴_설계!$B$5 -> 120
A8: 1 | B8: 4 | C8: 사건2 해결 | D8: Il furgone che non arrivò | E8: 오지 않은 트럭 | F8: [사건2 해결] 집행 당일 아침. Marco의 집행 연기 신청, Giulia의 취약계층 진단서, Alessandro의 체납액 계산과 비귀책 체납 기금 신청, Chiara의 동선 배치가 맞물려 집행관이 집행을 연기한다. Garibaldi의 «Nulla da segnalare» 보고로 마무리된다. | G8: 집행 연기(rinvio dell'esecuzione), 비귀책 체납 기금(Fondo morosità incolpevole), 집행관(ufficiale giudiziario) 대응 | H8: Marco, Giulia, Alessandro, Chiara, Garibaldi, Paolo, Sofia, Rosa | I8: E1 | J8: =턴_설계!$B$5 -> 120
A9: 1 | B9: 5 | C9: 사건3 도입 | D9: Lo stagista della fabbrica | E9: 공장의 인턴 | F9: [사건3 도입] 임금 체불과 무급 초과근무에 지친 청년 노동자 Davide(가상)가 찾아온다. 서류상 '인턴(tirocinio)'이지만 실제로는 정규직 일을 한다. Chiara가 컨설팅 용어로 상황을 분석하려 하고 Sofia가 통역하듯 애쓰지만 Davide는 점점 지쳐 간다. | G9: 위장 인턴(tirocinio), 기간제 계약, 초과근무, 경영 용어의 벽 | H9: Chiara, Sofia, Alessandro, Rosa, Machiavelli, Davide(가상) | I9: S1 | J9: =턴_설계!$B$5 -> 120
A10: 1 | B10: 6 | C10: 사건3 해결(폭발) | D10: Basta! | E10: 그만! | F10: [사건3 해결] 협상 자리에서 Chiara의 용어가 한 시간째 이어지자 Sofia가 폭발한다(1차 폭발). Giulia·Garibaldi·Rosa·Gramsci의 고정 반응, Cesare의 «Stolta… Domanda.», Alessandro의 «Traduco io.» 이후 쉬운 말로 다시 협상해 밀린 임금 지급과 정식 계약 전환에 합의한다. | G10: 감정 표현, 전문 용어 → 쉬운 말, 임금 체불 합의(conciliazione) | H10: Sofia, Chiara, Alessandro, Giulia, Cesare, Garibaldi, Rosa, Gramsci, Davide(가상) | I10: S1 | J10: =턴_설계!$B$5 -> 120
A11: 1 | B11: 7 | C11: 사건4 도입 | D11: La bambina con la febbre | E11: 열이 나는 아이 | F11: [사건4 도입] 체류 서류가 없어 소아과 주치의(pediatra)를 배정받지 못하는 가족이 찾아온다. Giulia가 나서고 Montessori가 들러 «E questo come ti fa sentire?»를 처음 선보인다. 마침 들른 Dante는 Cesare에게 원고를 놀림받다 «Niente male.»라는 최고의 칭찬을 듣는다. 정작 진짜 아픈 아이 앞에서 Cesare는 자기 무릎 타령을 멈춘다. | G11: 서류 없는 가족의 의료 접근, 증상 표현 | H11: Giulia, Montessori, Cesare, Dante, Sofia, Rosa, 가족(가상: Amina·Noa) | I11: S2 | J11: =턴_설계!$B$5 -> 120
A12: 1 | B12: 8 | C12: 사건4 해결 | D12: Un codice per tutti | E12: 모두를 위한 코드 | F12: [사건4 해결] Marco와 Giulia가 STP 코드(체류 서류 없는 외국인의 긴급·필수 진료 코드)와 미성년자 소아과 등록 경로를 찾아내 아이가 진료를 받는다. Cesare가 평소와 달리 조용히 커피를 마신다. | G12: STP 코드(d.lgs. 286/1998 제35조), 미성년자 소아과 등록, 진료 의뢰서(impegnativa) | H12: Giulia, Marco, Sofia, Rosa, 가족(가상) | I12: S2 | J12: =턴_설계!$B$5 -> 120
A13: 1 | B13: 9 | C13: 사건5 도입 | D13: La vedova del quinto piano | E13: 5층의 미망인 | F13: [사건5 도입] 가짜 투자에 저축을 잃은 노년의 이웃 Iolanda(가상)가 찾아온다. Alessandro가 장부를 살피는 동안, 양복 입은 낯선 남자 Francesco가 나타나 은행 쪽 흐름을 봐 주겠다고 하면서도 자기 이야기는 하지 않는다. Galileo가 '관찰 대상'이라며 기웃거린다. | G13: 저축·투자 사기, 은행 계좌 기초 어휘 | H13: Alessandro, Francesco, Galileo, Sofia, Rosa, Iolanda(가상) | I13: E3 | J13: =턴_설계!$B$5 -> 120
A14: 1 | B14: 10 | C14: 사건5 해결 | D14: Segui il denaro | E14: 돈을 따라가라 | F14: [사건5 해결] Francesco의 계좌 흐름 추적과 Alessandro의 장부 대조로 사기 계좌를 찾아 돈 일부를 되찾는다. Francesco는 설명 없이 떠나고, Alessandro는 «Banca Adriatica»라는 이름에 말없이 굳는다. | G14: 자금 흐름 추적, 계좌·송금(bonifico) 어휘 | H14: Alessandro, Francesco, Sofia, Rosa, Iolanda(가상) | I14: E3 | J14: =턴_설계!$B$5 -> 120
A15: 1 | B15: 11 | C15: 사건6 도입 | D15: Una carta di anni fa | E15: 수년 전 서류 | F15: [사건6 도입] Fatima의 남편 Karim(가상)이 수십 년 전 다른 건물에서 받은 낡은 퇴거 서류를 들고 온다. 당장 급한 사안은 아니지만 오래된 절차 오류가 보인다. Galileo가 «증거가 두 개면 기사가 된다»며 흥미를 보인다. | G15: 오래된 서류 판독, 절차 하자 | H15: Marco, Galileo, Sofia, Rosa, Karim(가상) | I15: E1 | J15: =턴_설계!$B$5 -> 120
A16: 1 | B16: 12 | C16: 사건6 해결(훅) | D16: La firma | E16: 서명 | F16: [사건6 해결·훅] 절차 오류를 바로잡아 오래된 기록을 정정하지만, 진짜 충격은 서류 맨 아래: Marco의 옛 로펌 «Ferrari & Colombo»의 서명이다. Marco가 얼어붙고 Rosa가 «Sedetevi, che vi porto qualcosa.»로 분위기를 잇는다. 금요일에는 Marco의 이야기가 시작된다. | G16: 서명·기록 정정, 이름 확인 | H16: Marco, Rosa, Sofia, Cesare, Machiavelli, Karim(가상) | I16: E1 | J16: =턴_설계!$B$5 -> 120
A17: 2 | B17: 1 | C17: 발단 | D17: Venerdì di storie | E17: 금요일의 이야기 | F17: (프레임) Rosa의 식탁에서 금요일마다 한 사람이 과거를 이야기하는 규칙이 시작된다. Sofia가 Marco에게 왜 로펌을 그만뒀느냐고 묻고 Marco는 «Andiamo con ordine.»로 시작한다. | G17: 격식체(Lei)와 tu의 대비, 과거 이야기 도입 | H17: Sofia, Marco, Rosa, Cesare | I17: E1 | J17: =턴_설계!$B$5 -> 120
A18: 2 | B18: 2 | C18: 발단 | D18: Un lunedì in Prati | E18: 프라티의 월요일 | F18: (과거) 승소율 100%의 파트너 후보 Marco의 하루. 새벽 편의점에서 계산대에 선 채 『신곡』을 중얼거리는 야간 점원 Dante와 마주친다. 상사 Colombo(가상)가 파트너 승진을 암시한다. | G18: 로펌 어휘: socio, parcella, portafoglio clienti | H18: Marco, Dante, Colombo(가상) | J18: =턴_설계!$B$5 -> 120
A19: 2 | B19: 3 | C19: 발단 | D19: Il cliente d'oro | E19: VIP 고객 | F19: 대형 고객 Gruppo Meridiano의 회장 Santoro(가상)를 소개받는다. 회의석에는 고객 측 컨설턴트 Chiara와 매각 은행 지점장 Francesco가 있다. | G19: 인수합병 어휘: acquisizione, portafoglio, clausola | H19: Marco, Chiara, Francesco, Santoro(가상) | I19: E1 | J19: =턴_설계!$B$5 -> 120
A20: 2 | B20: 4 | C20: 전개 | D20: Il portafoglio di Testaccio | E20: 테스타초 자산 포트폴리오 | F20: 실사(due diligence). 포트폴리오에 Testaccio 건물 12채가 들어 있다. 감사인 Alessandro가 «Questo non torna»를 흘리고, Piazza Borghese 고서 노점에서 등기 자료를 찾던 Marco에게 Gramsci가 «Cercalo tu.» | G20: 실사, 부동산 등기(Conservatoria dei Registri Immobiliari)·토지대장(Catasto), 임차인 명부 | H20: Marco, Alessandro, Gramsci | I20: E1 | J20: =턴_설계!$B$5 -> 120
A21: 2 | B21: 5 | C21: 전개 | D21: Venerdì: la via di Rosa | E21: 금요일: Rosa의 거리 | F21: (프레임) 그 포트폴리오에 Rosa의 트라토리아가 있던 건물이 들어 있었음이 밝혀진다. Sofia는 놀라 Lei를 놓치고 Marco는 잠시 침묵한다. | G21: 감정 표현, 놀람 | H21: Rosa, Marco, Sofia | I21: E1 | J21: =턴_설계!$B$5 -> 120
A22: 2 | B22: 6 | C22: 미드포인트 | D22: La clausola | E22: 조항 | F22: 임차인을 비우는 가장 '깨끗한' 방법으로 Marco가 «첫 만기 때 리모델링을 이유로 갱신을 거절하는(diniego di rinnovo per ristrutturazione)» 조항 전략을 설계한다. Chiara의 재무 모델이 이를 뒷받침한다. | G22: 갱신 거절 사유(legge 431/1998 제3조), 리모델링 사유, 통지 요건(만기 6개월 전) | H22: Marco, Chiara, Colombo(가상) | I22: E1 | J22: =턴_설계!$B$5 -> 120
A23: 2 | B23: 7 | C23: 위기 | D23: L'assemblea degli inquilini | E23: 세입자 총회 | F23: 세입자들이 총회를 연다. 노조 출신 Paolo가 이끌고, 응급실 의사 Giulia가 공황을 일으킨 노인을 돌본다. Marco는 78세 Assunta(가상)를 만난다. | G23: 총회·발언·동의, 항의 표현 | H23: Marco, Paolo, Giulia, Assunta(가상) | I23: E1 | J23: =턴_설계!$B$5 -> 120
A24: 2 | B24: 8 | C24: 위기 | D24: Il processo | E24: 재판 | F24: 심리(udienza)와 판결. Marco가 승소한다. 방청석의 Galileo가 «È orgoglioso?»라고 묻는다. 감사인 Alessandro는 고객의 장부를 보고 고개를 젓는다. | G24: 소송: citazione, udienza, sentenza, spese processuali | H24: Marco, Galileo, Alessandro, 판사(가상) | I24: E1·P3 | J24: =턴_설계!$B$5 -> 120
A25: 2 | B25: 9 | C25: 위기 | D25: Venerdì: continua | E25: 금요일: 계속해 | F25: (프레임) Marco가 말을 잇지 못하자 Cesare가 «Quando Cesare era in Gallia…»로 시간을 벌어 주고 Rosa가 «Continua.»라고 한다. Sofia는 «E lei?»라고 묻는다. Machiavelli는 말없이 메모한다. | G25: 위로·재촉 표현 | H25: Marco, Cesare, Rosa, Sofia, Machiavelli | J25: =턴_설계!$B$5 -> 120
A26: 2 | B26: 10 | C26: 절정 | D26: Una cena ai Parioli | E26: 파리올리의 저녁 | F26: 승소 축하 만찬. 파트너들이 건배하는 동안 Santoro가 다음 포트폴리오를 건넨다. Marco의 휴대전화가 울린다. | G26: 고급 식당 표현, 건배·축하(brindisi) | H26: Marco, Colombo(가상), Santoro(가상), Alessandro | J26: =턴_설계!$B$5 -> 120
A27: 2 | B27: 11 | C27: 절정 | D27: La nipote di Assunta | E27: Assunta의 손녀 | F27: Assunta가 퇴거 석 달 뒤 세상을 떠났다는 소식. 손녀 Marina(가상)가 사무실로 찾아와 조용히 묻는다: «Ha vinto Lei?» | G27: 조의·항의, 문서 vs 사람 | H27: Marco, Marina(가상) | I27: E1 | J27: =턴_설계!$B$5 -> 120
A28: 2 | B28: 12 | C28: 결말·훅 | D28: Venerdì: le dimissioni | E28: 금요일: 사직 | F28: (프레임+과거) Marco가 다음 포트폴리오 서명을 거부하고 사직서를 낸다. 짐 상자를 든 채 응급실 대기실에서 쓰러지고 Giulia가 그를 진료한다. Sofia는 여전히 Lei를 쓴다. | G28: 사직·거절 표현, 접속법(congiuntivo) | H28: Marco, Giulia, Sofia, Rosa | J28: =턴_설계!$B$5 -> 120
A29: 3 | B29: 1 | C29: 발단 | D29: Venerdì: i nomi | E29: 금요일: 이름들 | F29: (프레임) Giulia가 «Questa non è una statistica, è una persona.»라며 이야기를 시작한다. Cesare가 계단을 오르내리다 숨을 고르는 것을 Giulia가 흘끗 본다. | G29: 의학 어휘 도입 | H29: Giulia, Sofia, Cesare, Rosa | J29: =턴_설계!$B$5 -> 120
A30: 3 | B30: 2 | C30: 발단 | D30: Turno di notte | E30: 야간 근무 | F30: (과거) San Camillo 응급실(가상 설정)의 야간 근무. 분류(triage), 병상, 간호사 Loredana(가상)와의 호흡. 가슴 통증으로 실려 온 Marco를 진료한다. | G30: triage(긴급도 코드 1~5), parametri vitali, barella, box | H30: Giulia, Loredana(가상), Marco | J30: =턴_설계!$B$5 -> 120
A31: 3 | B31: 3 | C31: 발단 | D31: L'ondata di calore | E31: 폭염 | F31: 폭염 경보(bollino rosso)에 고령 환자가 몰려 응급실이 넘친다. 산소·수액·얼음. Giulia는 밤새 환자 이름을 외운다. | G31: 열사병(colpo di calore), 탈수, 고령 환자 | H31: Giulia, Loredana(가상) | I31: S4·S3 | J31: =턴_설계!$B$5 -> 120
A32: 3 | B32: 4 | C32: 전개 | D32: Un contratto che nessuno legge | E32: 읽히지 않는 계약 | F32: 병원이 검사·병상 관리를 Meridiano Salute에 외주한다고 발표한다. 원장 회의에서 컨설턴트 Chiara가 '효율' 발표를 한다. | G32: 외주(esternalizzazione)·민간 위탁, 예산, 입찰(gara d'appalto) | H32: Giulia, 원장(가상), Chiara | I32: S3 | J32: =턴_설계!$B$5 -> 120
A33: 3 | B33: 5 | C33: 전개 | D33: Venerdì: la lista | E33: 금요일: 명단 | F33: (프레임) Sofia가 Giulia의 수첩 명단을 본다. Giulia는 «Ho visto di peggio in un martedì qualsiasi.»로 넘긴다. Cesare는 발목이 부었냐는 물음에 «Sono i calzari.» | G33: 명단·숫자 읽기 | H33: Giulia, Sofia, Cesare | J33: =턴_설계!$B$5 -> 120
A34: 3 | B34: 6 | C34: 미드포인트 | D34: La prima della lista | E34: 명단의 첫 번째 | F34: 체류 서류 없는 20대 여성이 패혈증으로 실려 오지만 병상 배정이 아홉 시간 지연되어 숨진다. 외주 병상관리가 '비용 검토' 중이었다. Giulia가 수첩에 첫 이름을 쓴다. | G34: 패혈증(sepsi), 병상 관리(bed management), 서류 없는 환자의 접근권(STP 코드) | H34: Giulia, Loredana(가상), 원장(가상) | I34: S2·S3 | J34: =턴_설계!$B$5 -> 120
A35: 3 | B35: 7 | C35: 위기 | D35: I numeri del direttore | E35: 원장의 숫자 | F35: 원장(direttore generale)이 '대기 시간 개선' 통계를 발표한다. 외주 업체의 재무를 자문하는 Alessandro가 배석한다. Giulia가 내부 사망 사례 보고서를 제출한다. | G35: 통계 읽기, 보고서 어휘 | H35: Giulia, 원장(가상), Alessandro | I35: P3 | J35: =턴_설계!$B$5 -> 120
A36: 3 | B36: 8 | C36: 위기 | D36: Il procedimento | E36: 징계 절차 | F36: 보고서 유출 의혹으로 징계 절차가 시작된다. 취재하는 Galileo에게 Giulia가 «Questo non esce da qui.»라고 못 박는다. | G36: 징계(procedimento disciplinare), 비밀유지 | H36: Giulia, Galileo, 원장(가상) | I36: P3 | J36: =턴_설계!$B$5 -> 120
A37: 3 | B37: 9 | C37: 위기 | D37: Venerdì: e come ti fa sentire? | E37: 금요일: 기분이 어때요? | F37: (프레임) Montessori가 Giulia에게 감정을 되묻는다. Giulia는 «Prima, respira.»로 받아친다. Sofia가 Montessori의 화법을 흉내 낸다. | G37: 감정 표현, 되받기 화법 | H37: Giulia, Montessori, Sofia | J37: =턴_설계!$B$5 -> 120
A38: 3 | B38: 10 | C38: 절정 | D38: Una notte senza letti | E38: 병상 없는 밤 | F38: 버스 사고와 폭염이 겹친 밤. 병상이 없어 복도까지 환자가 찬다. Giulia가 즉흥으로 일곱 명을 살리고 한 명을 잃는다. | G38: 대량 환자(maxi-emergenza), 우선순위, 명령형(imperativo) | H38: Giulia, Loredana(가상) | I38: S4 | J38: =턴_설계!$B$5 -> 120
A39: 3 | B39: 11 | C39: 절정 | D39: Le dimissioni della dottoressa | E39: 의사의 사직 | F39: 징계 통보와 마지막 근무. 수첩을 덮고 사직서를 낸다. Loredana가 «Dottoressa, non se ne vada.» | G39: 사직서, 작별 | H39: Giulia, Loredana(가상), 원장(가상) | J39: =턴_설계!$B$5 -> 120
A40: 3 | B40: 12 | C40: 결말·훅 | D40: Venerdì: una firma | E40: 금요일: 한 사람의 서명 | F40: (프레임) Giulia가 «La relazione di revisione sul contratto aveva una firma.»라고 말한다. Alessandro가 조용히 «Tocca a me.» | G40: 서명·책임 표현 | H40: Giulia, Alessandro, Sofia, Cesare | J40: =턴_설계!$B$5 -> 120
A41: 4 | B41: 1 | C41: 발단 | D41: Venerdì: ho firmato io | E41: 금요일: 내가 서명했다 | F41: (프레임) Alessandro가 «Fammi vedere le carte.»를 습관처럼 하다가 «Ho firmato io.»라고 시작한다. Sofia가 숫자를 못 읽어 질문한다. | G41: 회계 어휘 도입 | H41: Alessandro, Sofia, Giulia, Cesare | J41: =턴_설계!$B$5 -> 120
...

Sheet 복선_회수
A1: 복선 설치와 회수 (Setup → Payoff)
A2: 설치 부와 회수 부의 간격(부 수)은 수식으로 계산됩니다. 간격이 클수록 오래 기다린 복선이라 낭독 시 기억에 남습니다.
A4: No | B4: 복선(설치) | C4: 유형 | D4: 설치 부 | E4: 설치 위치 | F4: 회수 부 | G4: 간격(부) | H4: 회수 위치와 효과 | I4: 관련 인물
A5: 1 | B5: Cesare의 «Questo sarà il mio ultimo inverno» 반복 | C5: 대사 | D5: 1 | E5: 1부 1화 | F5: 11 | G5: =F5-D5 -> 10 | H5: 11부 12화 — 양치기 소년 개그가 진짜 (두 번째) 죽음이 되는 낙차 | I5: Cesare
A6: 2 | B6: Cesare가 Sofia에게 우산을 물려준다고 말한다 | C6: 소품 | D6: 1 | E6: 1부 1화 | F6: 13 | G6: =F6-D6 -> 12 | H6: 13부 2화 — 유언장에서 우산이 진짜 유산으로 돌아옴 | I6: Cesare, Sofia
A7: 3 | B7: Cesare의 부은 발목·숨참 («Sono i calzari.») | C7: 설정 | D7: 3 | E7: 3부 1·5화 | F7: 11 | G7: =F7-D7 -> 8 | H7: 11부 4~6화 — Giulia가 진단을 알고도 침묵한 이유가 드러남 | I7: Giulia, Cesare
A8: 4 | B8: Cesare의 최고 칭찬 «Niente male.» | C8: 대사 | D8: 1 | E8: 1부 7화(Dante에게 1회) | F8: 11 | G8: =F8-D8 -> 10 | H8: 11부 12화 — Sofia에게 처음이자 마지막 칭찬, 브뤼셀 승리 직후라 더 무겁다 | I8: Cesare, Sofia
A9: 5 | B9: Sofia의 1차 폭발 | C9: 사건 | D9: 1 | E9: 1부 6화 | F9: 9 | G9: =F9-D9 -> 8 | H9: 9부 6화 — 몰라서 화내던 Sofia → 알아서 화내는 Sofia | I9: Sofia
A10: 6 | B10: Sofia의 Lei (Cesare에게) | C10: 호칭 | D10: 1 | E10: 1부 1화 | F10: 12 | G10: =F10-D10 -> 11 | H10: 12부 1화 — 조사에서 처음 tu — 호칭 전환이 곧 애도 | I10: Sofia, Cesare
A11: 7 | B11: Gramsci의 카드 #1과 «Cercalo tu.» | C11: 대사 | D11: 1 | E11: 1부 2화 | F11: 13 | G11: =F11-D11 -> 12 | H11: 13부 10화 — 끝까지 결론을 말하지 않던 그가 처음 답을 말함 | I11: Gramsci, Sofia
A12: 8 | B12: Marco의 «갱신 거절(diniego di rinnovo)» 조항 | C12: 사건 | D12: 2 | E12: 2부 6화 | F12: 11 | G12: =F12-D12 -> 9 | H12: 11부 3화 — 자기가 쓰던 조항 전략을 국정에서 봉쇄 | I12: Marco
A13: 9 | B13: Alessandro의 «Questo non torna» | C13: 대사 | D13: 2 | E13: 2부 4화 | F13: 4 | G13: =F13-D13 -> 2 | H13: 4부 4화 — 감사인의 눈이 처음 이상을 발견한 순간의 원점 | I13: Alessandro
A14: 10 | B14: Alessandro의 복사본 USB | C14: 소품 | D14: 4 | E14: 4부 10화 | F14: 7 | G14: =F14-D14 -> 3 | H14: 7부 5~6화 — 서명의 죄가 고발의 증거로 바뀜 | I14: Alessandro, Marco
A15: 11 | B15: Alessandro의 «다시는 서명하지 않는다» | C15: 인물 | D15: 4 | E15: 4부 11화 | F15: 11 | G15: =F15-D15 -> 7 | H15: 11부 10화 — «Io firmo solo ciò che ho verificato.» — 브뤼셀 합의문 서명으로 회수 | I15: Alessandro
A16: 12 | B16: Chiara의 C47 셀 | C16: 소품 | D16: 5 | E16: 5부 6화 | F16: 11 | G16: =F16-D16 -> 6 | H16: 11부 9화 — 사람을 지우던 셀이 해고 없는 통합 모델로 | I16: Chiara
... A32: 28 | B32: Galileo의 «Mi servono due fonti indipendenti» | C32: 대사 | D32: 1 | E32: 1부 11화 | F32: 9 | G32: =F32-D32 -> 8 | H32: 9부 8화 — 폭로 기사에서 두 개의 독립 출처를 갖추는 장면 | I32: Galileo, Gramsci
B34: 평균 간격(부) | G34: =AVERAGE(G5:G32) -> 7.3571429
B35: 가장 긴 복선(부) | G35: =MAX(G5:G32) -> 12
B36: 복선 개수 | G36: =COUNTA(B5:B32) -> 28

Sheet 현안_배치
A1: 이탈리아 현안 18개 배치표
A2: 현재 이탈리아의 쟁점을 이야기 곳곳에 녹이는 계획. 현실의 정당·정치인·참사 희생자는 특정하지 않고 가상 설정으로 각색하며, 제도와 통계만 현실 기준으로 쓴다.
A4: ID | B4: 분야 | C4: 현안 | D4: 이탈리아어 키워드 | E4: 이야기 속 가상 설정 | F4: 주요 배치 (전용 화) | G4: 곁가지 배치 | H4: 주요 인물 | I4: 권한 소재 | J4: 관련 제도·법 | K4: 낭독 어휘 | L4: 균형·민감도 유의 | M4: 현실 기준값·확인
A5: P1 | B5: 정치 | C5: 정부 불안정과 연정 협상 | D5: governo, fiducia, maggioranza, rimpasto, crisi di governo | E5: 어떤 정당도 과반이 안 되는 의회. 법안마다 협상 비용이 든다. Casa Comune도 연립 정부로 표결마다 파트너의 이탈을 걱정해야 한다. 공화국 역사상 짧은 정부 수명이 '이탈리아식 불안정'으로 대사에 등장한다. | F5: 9부 5화 불편한 동맹, 10부 8화 탐색 위임, 12부 7화 모자란 불신임안 | G5: 7부 11화, 8부 6화(왜 새 정당인가: 거대 정당 피로), 11부 1화, 12부 9화 | H5: Chiara, Marco, Paolo, Machiavelli | I5: 하원·상원·시의회 | J5: 헌법 제88·92·94조, 연정 협약 | K5: maggioranza, fiducia, crisi di governo, rimpasto, voto di sfiducia | L5: 특정 실존 정당·인물을 비난하는 대사 금지. 가상 정당(CC·UCN·PPS·IU·TA·TB)으로만. | M5: 현실은 2022년 이후 우파 연립 다수 정부(2026-09 기준). 이야기에는 쓰지 않음
A6: P2 | B6: 정치 | C6: 남북 격차와 차등 자치 | D6: autonomia differenziata, LEP, Mezzogiorno, questione meridionale, residuo fiscale | E6: 북부 주 연합 TB가 지지의 대가로 차등 자치(더 많은 권한과 세수 이양) 가속을 요구한다. 남부의 필수 공공서비스 수준(LEP)은 어떻게 보장하나. 나라를 통일한 Garibaldi가 가장 예민하게 반응한다. | F6: 10부 11화 연정 협상 | G6: 10부 3화(TV 토론 공격), 12부 7화(불신임안에서 TB의 기권) | H6: Garibaldi, Marco, Paolo, Chiara | I6: 의회, 헌법재판소, 주 | J6: 헌법 제116조 3항·제117조, legge 86/2024(차등 자치), 헌법재판소 2024년 판결 192호 | K6: autonomia differenziata, LEP, perequazione, Mezzogiorno, coesione | L6: 가장 민감. 북부의 효율 논거와 남부의 형평 논거를 각 인물이 나눠 말하게 하고 결론은 열어 둔다(Marco는 헌법 우려, Garibaldi는 통일의 가치, Chiara는 현실 협상). | M6: 헌법재판소가 2024년 legge 86/2024 일부를 위헌 판단. 이후 입법·협상 진행 상황은 반영 전 확인
A7: P3 | B7: 정치 | C7: 사법 개혁과 정치적 대립 | D7: separazione delle carriere, CSM, prescrizione, intercettazioni, lentezza della giustizia | E7: 사법 개혁과 도청 제한을 둘러싼 대립 속에 스캔들 수사가 표류한다. 재판 지연과 공소시효가 사무소의 고발을 무력하게 만든다. | F7: 7부(고발·GIP 결정·보복), 9부 9화 고발장 | G7: 2부 8화(재판), 3부(징계·외주), 4부 7화, 8부 3~4화(국민투표), 10부 11화(협상 조건), 12부 7화 | H7: Marco, Galileo, Gramsci | I7: 의회, 사법 최고회의(CSM), 사법부 | J7: 헌법 제104~112조, 형사소송법, 형법 제2조 | K7: CSM, magistratura, prescrizione, intercettazioni, abolitio criminis | L7: 여야 모두가 사법부를 압박한다는 비판을 각각 담는다. 실제 재판 결과를 단정하지 않는다. | M7: 검사·판사 경력 분리 개헌은 2026년 3월 국민투표에서 부결(반대 약 53.6%, 투표율 약 58.9%). 이후 논의는 반영 전 확인
A8: E1 | B8: 경제 | C8: 주거난과 단기 관광 임대 | D8: emergenza abitativa, affitti brevi, sfratto, canone concordato, overtourism | E8: 로마 중심가 월세가 임금보다 빨리 오르고 단기 관광 임대가 동네를 비운다. 소규모 임대인의 입장(Rosa의 친구)도 대사에 넣는다. | F8: 2부 6화(조항 설계), 6부 1·3·8·10화(Quarticciolo), 9부 6화(임대료 보조 삭감·단기임대 조항), 11부 2·3화 | G8: 1부 1·2·11·12화(Fatima), 8부 1·9화, 13부 | H8: Rosa, Sofia, Alessandro, Marco | I8: 국가(임대차 기본법·세제), 주(관광·주거 정책), 시(도시계획·인허가) | J8: legge 431/1998, 단기임대 CIN 코드(d.l. 145/2023), 비귀책 체납 기금 | K8: affitti brevi, sfratto, canone, piccolo proprietario, CIN | L8: 임차인만 피해자로 그리지 않는다. 소규모 임대인·대형 보유자(펀드)를 구분해서 말한다. | M8: 단기임대 규제와 로마 시 조치의 세부는 반영 전 확인
A9: E2 | B9: 경제 | C9: 저생산성과 영세·가족 기업 구조 | D9: microimpresa, PMI, produttività, impresa familiare, passaggio generazionale | E9: Chiara가 컨설팅한 규모의 경제 없는 가족 공방들: 해고 없이 살릴 길을 못 찾았던 과거. 11부에서 영세 기업 통합·R&D 전환 사업을 설계한다. | F9: 5부 3화 Ruggeri 공방 | G9: 8부 9화(골목 상권), 11부 9화, 13부 | H9: Chiara, Rosa, Paolo | I9: 국가·주 | J9: R&D 세액공제, 기업 지원 제도(확인), 집단해고법 | K9: produttività, scalare, aggregazione, ricerca e sviluppo | L9: '영세 기업이 문제'라는 식의 낙인 대신 구조 문제로 설명한다. | M9: 통계 수치는 반영 전 확인
A10: E3 | B10: 경제 | C10: 국가 부채와 재정 건전성 | D10: debito pubblico, spread, deficit, procedura per deficit eccessivo, pensioni | E10: GDP의 130%를 넘는 부채, 과도한 재정적자 절차, 연금 지출 증가 사이의 줄타기. Alessandro가 숫자로 설명하고 Sofia가 되묻는다. | F10: 11부 10화(EU 재정규칙), 12부 11~12화(예산안) | G10: 12부 3화, 13부 7화 | H10: Alessandro, Cesare(메모), Francesco | I10: 국가·EU | J10: EU 재정규칙과 중기 재정구조계획, TFUE 제126조, 헌법 제81조 | K10: debito, deficit, spread, sostenibilità, pensioni | L10: 긴축 vs 확대 양쪽 논거를 모두 숫자로 제시한다. | M10: 부채 GDP 대비 137.1%(2025년 말, ISTAT), 2025년 적자 3.1%로 과도한 재정적자 절차 조기 졸업 불발
A11: S1 | B11: 사회 | C11: 청년 고용 불안과 두뇌 유출 | D11: tirocinio, contratto a termine, NEET, salario minimo, fuga dei cervelli | E11: 무급·저임금 인턴과 기간제 계약으로 청년의 자립이 늦어지고, 많은 청년이 해외로 떠난다. 법정 최저임금이 없는 나라에서 Sofia가 그 당사자이자 질문자다. | F11: 11부 6화, 13부 5·6화 | G11: 1부 5·6화(Davide), 5부(Chiara의 인력 감축), 7부 2화, 8부, 10부 3화 | H11: Sofia, Paolo, Chiara | I11: 국가(노동법)·단체협약·주(인턴 규율) | J11: 사회적 대화, 단체협약, 인턴 규율(주별 지침) | K11: tirocinio, contratto, salario minimo, precariato, NEET | L11: 청년 vs 기성세대 구도로 몰지 않는다(Paolo도 Cesare도 청년의 편에서 돕는다). | M11: 청년(15~24세) 실업률 18.9%, 전체 5.8% (2026년 7월, ISTAT 잠정)
A12: S2 | B12: 사회 | C12: 이민·난민과 수용 분담 | D12: permesso di soggiorno, protezione speciale, accoglienza, MSNA, cittadinanza | E12: Testaccio·Esquilino는 다국적 동네다. 서류 없는 이웃, 체류허가 사건, 람페두사 도착과 수용 과부하, 보호자 없는 미성년자 비용을 둘러싼 떠넘기기. | F12: 6부 8·9화(퇴거 저지·서류 없는 이웃), 7부 4화(체류허가), 11부 5화 분담 | G12: 1부 7·8화, 3부 6화(서류 없는 환자), 8부(투표권 없는 이웃), 10부 3화 | H12: Rosa, Giulia, Marco, Paolo, Montessori | I12: 국가(이민·국경·수용), 지자체(SAI·아동 보호) | J12: d.lgs. 286/1998, legge 47/2017, 수용 체계(CAS·SAI) | K12: permesso di soggiorno, accoglienza, minore non accompagnato, richiesta d'asilo, cittadinanza | L12: 반이민 여론(IU)과 수용 부담 지역의 실제 어려움을 함께 담고, 이주민을 배경이 아닌 화자로 세운다. | M12: 알바니아 수용 시설 협정, 시민권 요건 국민투표(2025년 정족수 미달) 등 최신 상황은 반영 전 확인
A13: S3 | B13: 사회 | C13: 고령화와 내륙 과소지역(aree interne) | D13: spopolamento, aree interne, denatalità, guardia medica, piccoli comuni | E13: 내륙 마을의 야간 진료소가 문을 닫고 주는 병원 외주를 늘린다(9부). Garibaldi가 말년을 보낸 사르데냐 일대의 과소 마을을 캠페인이 지나며 일자리·의료·연금 문제가 되풀이된다(10부). | F13: 9부 7화 주의회에서의 보건 | G13: 3부(응급실 고령 환자), 10부 2화(사르데냐 내륙), 11부 4화, 13부 | H13: Garibaldi, Giulia, Sofia | I13: 주·시·국가 | J13: 내륙 지역 국가 전략(SNAI), 주 보건서비스 | K13: spopolamento, invecchiamento, natalità, guardia medica | L13: '텅 빈 마을'을 동정하지 않고 마을 사람들이 직접 말하게 한다. | M13: 출생률·인구 통계는 반영 전 확인
A14: S4 | B14: 사회 | C14: 가뭄·폭염과 에너지 전환 부담 | D14: siccità, ondata di calore, bollino rosso, bollette, transizione energetica | E14: 폭염 경보에 응급실이 넘치고(3부), 저수지가 마른 남부 마을을 지나며(10부), 횡재세 재원을 전환 비용과 전기요금에 쓸지 논쟁한다(11부). | F14: 3부 3·10화(폭염 응급실) | G14: 10부 2화, 11부 4·8화, 12부 8화 | H14: Giulia, Garibaldi, Alessandro | I14: 국가·주·유역 관리 기구 | J14: 폭염 경보 체계, 수자원 관리(확인) | K14: siccità, ondata di calore, bollino rosso, bolletta, transizione energetica | L14: 기후를 정치적 구호로 쓰지 않고 현장 사건으로 보여 준다. | M14: 최신 가뭄·폭염 통계 확인
A15: N1 | B15: 재난 | C15: 홍수와 수리·지반 취약성 | D15: alluvione, allerta rossa, IT-alert, Protezione Civile, dissesto idrogeologico | E15: 가상의 중부 지방에 집중호우와 하천 범람이 덮친다. 경보·대피 지연, 주–중앙정부 책임 공방, 국가 비상사태 선포, 민방위·군 투입, 복구와 보상. | F15: 12부 8화 L'alluvione | G15: 13부(복구 결산) | H15: Garibaldi, Giulia, Marco, Galileo, Dante | I15: 주·시(1차 대응), 국가(비상사태·민방위 국), EU | J15: d.lgs. 1/2018(민방위법), EU 연대기금 | K15: protezione civile, allerta rossa, stato di emergenza, sfollati | L15: 실제 참사와 희생자를 연상시키므로 추모의 톤을 지키고, 특정 정치인 비난 없이 제도의 공백을 보여 준다. | M15: 실제 홍수(에밀리아로마냐 2023 등) 후속 조치는 반영 전 확인
... A22: N8 | B22: 사회 | C22: 청년 정신건강 위기 | D22: salute mentale, ansia, liste d'attesa, bonus psicologo, CSM | E22: 청년 정신건강 상담 대기가 몇 달씩 밀린다. Montessori가 현장에서, Sofia가 자신의 불안을 처음 인정하며 함께 부딪힌다. | F22: 12부 6화 Le liste d'attesa | G22: 1부(Sofia의 폭발과 연결 가능, 곁가지) | H22: Montessori, Sofia, Giulia | I22: 주(정신건강 서비스)·국가(지원 예산) | J22: 공공 심리 지원(bonus psicologo), 지역 정신건강센터 | K22: salute mentale, ansia, terapia, lista d'attesa | L22: 청년 정신건강을 극적 소재로만 소비하지 않는다. 낙인 없이, 도움을 구하는 것이 자연스럽다는 톤으로. | M22: 청년 불안장애·상담 대기 증가는 이탈리아에서 널리 보도된 추세. 최신 통계는 확인 필요
A24: 현실 기준값 (확인일 2026-09-24)
A25: No | B25: 구분 | C25: 항목 | D25: 값 | E25: 출처·비고
A26: 1 | B26: 경제 | C26: 정부 부채 / GDP | D26: 137.1% (2025년 말), 2025년 적자 3.1% | E26: ISTAT 2026년 1차 EU 통보. 과도한 재정적자 절차(2024~)는 2027년 졸업 전망 보도.
A27: 2 | B27: 사회 | C27: 청년(15~24세) 실업률 | D27: 18.9% (2026년 7월), 전체 5.8% | E27: ISTAT 월간 잠정치(트레이딩이코노믹스 인용 포함). 청년 실업은 전체의 약 3.3배.
A28: 3 | B28: 정치 | C28: 현 정부 형태 | D28: 우파 연립 다수 정부(2022~) | E28: 이야기에는 실존 정당·인물을 쓰지 않는다. 이야기 속은 '연립 정부'와 '소수 야당'.
A29: 4 | B29: 확인 필요 | C29: 변동이 잦은 항목 | D29: 차등 자치 입법, 사법 개혁 후속, NATO 경로, 이민 협정, PNRR 결산, '동의' 기준 개정 | E29: 교재에 넣기 직전 최신 상태를 확인한다. (확인일 2026-09-24)

Sheet 현안_분포
A1: 현안 분포표 (부 × 현안)
A2: ● = 그 화의 주된 사건(전용 화), ○ = 곁가지(대사·서브플롯). 기호를 바꾸면 아래 집계가 자동 갱신됩니다.
A4: ID | B4: 현안 | C4: 1부 | D4: 2부 | E4: 3부 | F4: 4부 | G4: 5부 | H4: 6부 | I4: 7부 | J4: 8부 | K4: 9부 | L4: 10부 | M4: 11부 | N4: 12부 | O4: 13부 | P4: ● 수 | Q4: ○ 수
A5: P1 | B5: 정부 불안정·연정 협상 | I5: ○ | J5: ○ | K5: ● | L5: ● | M5: ○ | N5: ● | P5: =COUNTIF(C5:O5,"●") -> 3 | Q5: =COUNTIF(C5:O5,"○") -> 3
A6: P2 | B6: 남북 격차·차등 자치 | L6: ● | N6: ○ | P6: =COUNTIF(C6:O6,"●") -> 1 | Q6: =COUNTIF(C6:O6,"○") -> 1
A7: P3 | B7: 사법 개혁·정치 대립 | D7: ○ | E7: ○ | F7: ○ | I7: ● | J7: ○ | K7: ● | L7: ○ | N7: ○ | P7: =COUNTIF(C7:O7,"●") -> 2 | Q7: =COUNTIF(C7:O7,"○") -> 6
A8: E1 | B8: 주거난·단기 관광 임대 | C8: ○ | D8: ● | H8: ● | J8: ○ | K8: ● | M8: ● | O8: ○ | P8: =COUNTIF(C8:O8,"●") -> 4 | Q8: =COUNTIF(C8:O8,"○") -> 3
A9: E2 | B9: 저생산성·영세 기업 | G9: ● | J9: ○ | M9: ○ | O9: ○ | P9: =COUNTIF(C9:O9,"●") -> 1 | Q9: =COUNTIF(C9:O9,"○") -> 3
A10: E3 | B10: 부채·재정·연금 | M10: ● | N10: ● | O10: ○ | P10: =COUNTIF(C10:O10,"●") -> 2 | Q10: =COUNTIF(C10:O10,"○") -> 1
A11: S1 | B11: 청년 고용·두뇌 유출 | C11: ○ | G11: ○ | I11: ○ | J11: ○ | L11: ○ | M11: ● | O11: ● | P11: =COUNTIF(C11:O11,"●") -> 2 | Q11: =COUNTIF(C11:O11,"○") -> 5
A12: S2 | B12: 이민·난민·수용 분담 | C12: ○ | E12: ○ | H12: ● | I12: ● | J12: ○ | L12: ○ | M12: ● | P12: =COUNTIF(C12:O12,"●") -> 3 | Q12: =COUNTIF(C12:O12,"○") -> 4
A13: S3 | B13: 고령화·내륙 과소지역 | E13: ○ | K13: ● | L13: ○ | M13: ○ | O13: ○ | P13: =COUNTIF(C13:O13,"●") -> 1 | Q13: =COUNTIF(C13:O13,"○") -> 4
A14: S4 | B14: 가뭄·폭염·에너지 전환 | E14: ● | L14: ○ | M14: ○ | N14: ○ | P14: =COUNTIF(C14:O14,"●") -> 1 | Q14: =COUNTIF(C14:O14,"○") -> 3
A15: N1 | B15: 홍수·지반 취약성 | N15: ● | O15: ○ | P15: =COUNTIF(C15:O15,"●") -> 1 | Q15: =COUNTIF(C15:O15,"○") -> 1
A16: N2 | B16: PNRR 집행 | K16: ● | M16: ○ | N16: ○ | P16: =COUNTIF(C16:O16,"●") -> 1 | Q16: =COUNTIF(C16:O16,"○") -> 2
A17: N3 | B17: 국방비·NATO | L17: ○ | M17: ● | N17: ● | O17: ○ | P17: =COUNTIF(C17:O17,"●") -> 2 | Q17: =COUNTIF(C17:O17,"○") -> 2
A18: N4 | B18: 성폭력 법·재판 지연 | I18: ● | J18: ○ | L18: ○ | P18: =COUNTIF(C18:O18,"●") -> 1 | Q18: =COUNTIF(C18:O18,"○") -> 2
A19: N5 | B19: 녹색 대 녹색 | L19: ● | M19: ○ | O19: ○ | P19: =COUNTIF(C19:O19,"●") -> 1 | Q19: =COUNTIF(C19:O19,"○") -> 2
A20: N6 | B20: 플랫폼 노동(라이더) | G20: ○ | N20: ● | P20: =COUNTIF(C20:O20,"●") -> 1 | Q20: =COUNTIF(C20:O20,"○") -> 1
A21: N7 | B21: 스파이웨어·정보기관 감시 | I21: ○ | N21: ● | P21: =COUNTIF(C21:O21,"●") -> 1 | Q21: =COUNTIF(C21:O21,"○") -> 1
A22: N8 | B22: 청년 정신건강 | C22: ○ | N22: ● | P22: =COUNTIF(C22:O22,"●") -> 1 | Q22: =COUNTIF(C22:O22,"○") -> 1
B23: 부별 ● 수 | C23: =COUNTIF(C5:C22,"●") -> 0 | D23: =COUNTIF(D5:D22,"●") -> 1 | E23: =COUNTIF(E5:E22,"●") -> 1 | F23: =COUNTIF(F5:F22,"●") -> 0 | G23: =COUNTIF(G5:G22,"●") -> 1 | H23: =COUNTIF(H5:H22,"●") -> 2 | I23: =COUNTIF(I5:I22,"●") -> 3 | J23: =COUNTIF(J5:J22,"●") -> 0 | ... O23: =COUNTIF(O5:O22,"●") -> 1 | P23: =SUM(P5:P22) -> 29
B24: 부별 ○ 수 | C24: =COUNTIF(C5:C22,"○") -> 4 | D24: =COUNTIF(D5:D22,"○") -> 1 | E24: =COUNTIF(E5:E22,"○") -> 3 | F24: =COUNTIF(F5:F22,"○") -> 1 | G24: =COUNTIF(G5:G22,"○") -> 2 | H24: =COUNTIF(H5:H22,"○") -> 0 | I24: =COUNTIF(I5:I22,"○") -> 3 | J24: =COUNTIF(J5:J22,"○") -> 7 | ... O24: =COUNTIF(O5:O22,"○") -> 7 | Q24: =SUM(Q5:Q22) -> 45
A26: 읽는 법: 1~5부는 곁가지 중심이라 B1~B2 난이도를 지키고, 9~12부에서 전용 화가 몰린다. 화당 전용 현안은 1개(+곁가지 1~2개)로 제한해 낭독 분량을 지킨다. N6~N8은 12부의 신규 현안으로 각 1개 전용 화를 받는다.
A27: 현안 ID와 설명은 '현안_배치' 시트, 화별 반영은 '화별목차_전체'의 '반영 현안' 열을 참고.

Sheet 정치제도
A1: 현실 정치 제도 기준표 (이탈리아)
A2: 8~12부에 반영한 실제 제도. 정당·정치인은 전부 가상이며 실존 정치인의 대사는 쓰지 않는다. '검색 확인' 표시는 2026-09-24 기준 자료로 확인한 항목.
A4: 영역 | B4: 제도·규칙 | C4: 핵심 내용 | D4: 근거 | E4: 이야기 반영 | F4: 낭독 어휘 | G4: 확인 상태
A5: 정당·선거 | B5: 정당 설립 | C5: 이탈리아 정당은 대개 법인격 없는 사단(associazione non riconosciuta)으로, 공증인 앞에서 설립 문서(atto costitutivo)와 정관(statuto)을 작성해 만든다. 국가 정당 등록부에 등록하면 2x1000 기부 등 혜택 자격을 얻는다. | D5: 헌법 제49조, 민법 제36조, d.l. 149/2013 제4조 | E5: 8부 5화 | F5: atto costitutivo, statuto, iscrizione, associazione | G5: 기획 시점 지식 — Normattiva 확인 필요
A6: 정당·선거 | B6: 정당의 민주적 내부 운영 | C6: 시민은 '민주적 방법으로' 국가 정책 결정에 참여하기 위해 정당을 결성한다. 등록 정당의 정관은 기관 구성·당원 권리·후보 선출 절차 등을 명시해야 한다. | D6: 헌법 제49조, d.l. 149/2013 제3조 | E6: 8부 6화 | F6: metodo democratico, statuto, iscritto, organi | G6: 기획 시점 지식 — Normattiva 확인 필요
