Workbook

Sheet 개요
A1: São Paulo 포르투갈어 낭독 교재 — 캐릭터 바이블 (부활자 특별편)
A2: v2.0 · 상파울루 배경 13부작 옴니버스(156화) · 10부 대선 이후 브라질리아·상파울루 · 부활 6인 = Dom Pedro·Machado·Zumbi·Dumont·Freire·Isabel
B4: 기본 설정
B5: 부 수 | C5: 13 | D5: 1 사무소(Bixiga, 개소 1개월 후, 6사건×2화) → 2~5 각자의 과거 → 6 만남 → 7 전면전 → 8 창당·시장/시의원 선거 → 9 시의회 → 10 대선(1차·결선)·대통령 취임 → 11 국정 I(Mercosul–EU 협상·Dom Pedro 사망) → 12 국정 II(장례·유고 메모 승계·탄핵 방어·대홍수) → 13 귀환(원형 구조)
B6: 부당 화 수 | C6: 12 | D6: 각 부 12화
B7: 총 화 수 | C7: =C5*C6 -> 156 | D7: 부 수 × 부당 화 수 (자동 계산)
B8: 등장인물 수 | C8: =COUNTA(캐릭터!$D$5:$D$18) -> 14 | D8: 캐릭터 시트의 약칭 개수
B9: 남성 인물 수 | C9: =COUNTIF(캐릭터!$G$5:$G$18,"남") -> 9 | D9: 음색이 다양할수록 화자 구분이 쉬워 남 9 : 여 5로 배분 (부활 6인 중 여성은 Isabel 1명)
B10: 여성 인물 수 | C10: =COUNTIF(캐릭터!$G$5:$G$18,"여") -> 5
B11: 1부→11부 경과 연수 (가정) | C11: 6 | D11: 가정값: Dom Pedro가 1부 65세 → 11부 약 71세가 되도록 잡음. 확정 시 이 셀만 수정하면 캐릭터 시트의 나이가 자동 갱신. (캐릭터 시트 '나이(11부)' 열)
B12: 배경·언어 | C12: 상파울루 (Bixiga) → 10부 대선 이후 브라질리아·상파울루 | D12: 표준 브라질 포르투갈어(상파울루 억양): 친한 사이 você, 공식 석상은 o senhor/a senhora, 의회에서는 Vossa Excelência. 구어의 'a gente', 'tá', 'meu'는 인물별로 조절.
B13: 형식 | C13: 전 화 100% 대화문, 화당 120턴 | D13: ="지문(narração) 없음. 화당 "&턴_설계!$B$5&"턴 × "&C7&"화 = "&TEXT(C7*턴_설계!$B$5,"#,##0")&"턴. 상세는 '대화문규칙'·'턴_설계' 시트." -> 지문(narração) 없음. 화당 120턴 × 156화 = 18,720턴. 상세는 '대화문규칙'·'턴_설계' 시트.
B15: 그룹별 인원
B16: 주력 4인 | C16: =COUNTIF(캐릭터!$B$5:$B$18,B16) -> 4 | D16: Rafael(변호사)·Camila(의사)·Bruno(회계사)·Juliana(컨설턴트)
B17: 부활 6인 | C17: =COUNTIF(캐릭터!$B$5:$B$18,B17) -> 6 | D17: Dom Pedro(전 황제)·Machado(소설가)·Zumbi(저항 지도자)·Dumont(항공 개척자)·Freire(교육학자)·Isabel(황녀) ※ 각자의 시대에 죽었다가 이유 없이 현재 상파울루에 되살아나 사무소에 합류
B18: 서민·청년 | C18: =COUNTIF(캐릭터!$B$5:$B$18,B18) -> 3 | D18: Marta(바 사장)·Edson(노조위원장)·Larissa(인턴)
B19: 금융 | C19: =COUNTIF(캐릭터!$B$5:$B$18,B19) -> 1 | D19: Sérgio(전 은행 지점장)
B22: 시트 안내 (클릭하면 이동)
B23: 캐릭터 | C23: 기준표 | D23: 14인의 이름·나이·결핍·말투·시그니처·낭독 포인트·대화문 장치·직책·현안 담당
B24: 등장비중 | C24: 기준표 | D24: 13부 배분표, 합계·비중·등급(수식), 조연 단독 중심 화 목표
B25: 턴_설계 | C25: 기준표 | D25: 화당 120턴 설계: 부별 화자 점유율(턴 기준), 평균 단어/턴, 화당 단어·낭독 시간(수식), 화 유형별 턴 구성, 집필 규칙
B26: 12부_구성 | C26: 구조 | D26: 13부 한눈에 보기: 배경·핵심 내용·난이도(CEFR)·반영 제도
B27: 아크_구성계획 | C27: 구성 계획 | D27: 1~13부 아크별 구성 계획: 서사 기능·로그라인·비트·인물 아크·복선·현안·언어 설계
B28: 화별목차_전체 | C28: 목차 | D28: 1~13부 156화의 서사 기능·제목(PT-BR)·핵심 사건·반영 제도·인물·현안 (필터 가능)
B29: 복선_회수 | C29: 구성 계획 | D29: 복선 설치→회수 28건과 간격(부)을 수식으로 계산
B30: 현안_배치 | C30: 현안 | D30: 브라질 현안 18개를 어느 화에 어떻게 녹일지 배치, 균형 유의, 현실 기준값
B31: 현안_분포 | C31: 현안 | D31: 부 × 현안 분포표: 전용 화(●)와 곁가지(○)를 수식으로 집계
B32: 정치제도 | C32: 현실 제도 | D32: 정당·선거·의회·대통령·연방·사법·통상 제도 기준표 (확인 상태 표시)
B33: 정치경로_의석 | C33: 현실 제도 | D33: 창당→대통령 경로와 가상 득표·의석 시뮬레이션(수식): 대선 1차·결선, 탄핵 개시 표결
B34: 호칭규칙 | C34: 규칙 | D34: você / o senhor·a senhora / vocês / os senhores, 의회·대통령·시의회 공식 호칭
... B40: 변경이력_미결 | C40: 관리 | D40: 지금까지의 변경 이력과 확정이 필요한 미결 사항
B42: 범례
B43: 파란 글씨 | C43: 직접 입력한 값 (수정 가능)
B44: 노란 배경 | C44: 가정 · 확정이 필요한 값
B45: 검정 글씨 | C45: 수식으로 계산되는 값 (직접 수정하지 말 것)
B47: 주의: 성별·나이·기관명은 기획용 가상 설정입니다. 법령 번호·조항은 교재에 넣기 전에 Planalto 법령 사이트(planalto.gov.br/legislacao)의 현행 통합본(texto compilado)으로 확인하세요.

Sheet 캐릭터
A1: 캐릭터 바이블 — 14인 (São Paulo 포르투갈어 낭독 교재 — 캐릭터 바이블 (부활자 특별편))
A2: v2.0 · 상파울루 배경 13부작 옴니버스(156화) · 10부 대선 이후 브라질리아·상파울루 · 부활 6인 = Dom Pedro·Machado·Zumbi·Dumont·Freire·Isabel
A4: No | B4: 그룹 | C4: 이름 | D4: 약칭 | E4: 나이 (1부) | F4: 나이 (11부) | G4: 성별 | H4: 직업·신분 | I4: 전 소속 (가상) | J4: 결핍 (Herida) | K4: 말투 | L4: 시그니처 표현 | M4: 낭독 포인트 | N4: 대화문 장치 (지문 대체) | O4: 정치 직책 (8~12부, 제안) | P4: 1부 등장 방식 | Q4: 등장 화 수 | R4: 등급 | S4: 현안 담당 (ID)
A5: 1 | B5: 주력 4인 | C5: Rafael Costa | D5: Rafael | E5: 39 | F5: =E5+개요!$C$11 -> 45 | G5: 남 | H5: 변호사 (기업·규제 전문) | I5: Aguiar & Salgado Advogados, Faria Lima (전 파트너 후보) | J5: 승소율은 높지만, 강제퇴거 소송에서 이긴 사건 하나가 계속 마음에 걸린다. | K5: 문장이 완결되고 격식체. 초반엔 차갑게 법조문을 인용, 후반엔 연설가로 성장. | L5: Vamos por partes.\nCom todo respeito, a lei não diz isso.\n(후반) Não peço que acreditem em mim. Peço que leiam o texto. | M5: 또박또박, 중저음. | N5: 법조문을 소리 내어 읽어 상황을 설명한다. | O5: 당 대표·상파울루 시장 후보(8부, 3위) → 대통령 후보(10부) → 대통령 | P5: 본격 | Q5: =INDEX(등장비중!$O$5:$O$18,MATCH($D5,등장비중!$A$5:$A$18,0)) -> 108 | R5: =INDEX(등장비중!$Q$5:$Q$18,MATCH($D5,등장비중!$A$5:$A$18,0)) -> 주연 | S5: E1, P1, N4
A6: 2 | B6: 주력 4인 | C6: Camila Alves | D6: Camila | E6: 41 | F6: =E6+개요!$C$11 -> 47 | G6: 여 | H6: 응급의학과 전문의 | I6: Hospital Municipal São Bartolomeu (가상, OSS 위탁 운영) | J6: 살리지 못한 환자의 이름을 전부 외우고 있다. | K6: 짧고 명령형, 블랙유머. 화나면 오히려 조용해진다. | L6: Isso não é estatística, é uma pessoa.\nPrimeiro, respira.\nJá vi coisa pior numa terça qualquer. | M6: 빠른 템포, 짧은 호흡. | N6: 명령형으로 행동을 말하며 진행한다. | O6: 시의원(9부, 보건위원회) → 보건부 장관 | P6: 본격 | Q6: =INDEX(등장비중!$O$5:$O$18,MATCH($D6,등장비중!$A$5:$A$18,0)) -> 98 | R6: =INDEX(등장비중!$Q$5:$Q$18,MATCH($D6,등장비중!$A$5:$A$18,0)) -> 준주연 | S6: S3, S4, N8
A7: 3 | B7: 주력 4인 | C7: Bruno Almeida | D7: Bruno | E7: 37 | F7: =E7+개요!$C$11 -> 43 | G7: 남 | H7: 공인회계사 (감사) | I7: Barros & Teixeira Auditores (전 시니어 파트너) | J7: 부정을 발견하고도 서명했던 기억. 다시는 서명하지 않겠다는 다짐. | K7: 건조하고 정확, 비꼬는 유머. | L7: Deixa eu ver os papéis.\nIsso não fecha.\nMostra os números e eu digo quem você é. | M7: 일정한 속도, 결론에서 톤을 낮춘다. | N7: 숫자를 소리 내어 읽으며 상황을 설명한다. | O7: 시의원(9부, 재정위원회) → 재무부 장관 | P7: 본격 | Q7: =INDEX(등장비중!$O$5:$O$18,MATCH($D7,등장비중!$A$5:$A$18,0)) -> 109 | R7: =INDEX(등장비중!$Q$5:$Q$18,MATCH($D7,등장비중!$A$5:$A$18,0)) -> 주연 | S7: E3, N2, N3
A8: 4 | B8: 주력 4인 | C8: Juliana Pereira | D8: Juliana | E8: 36 | F8: =E8+개요!$C$11 -> 42 | G8: 여 | H8: 전략 컨설턴트 | I8: Zênite Consultoria, Faria Lima (전 소속) | J8: 자신이 짠 구조조정 표 한 칸이 수백 명의 해고였음을 뒤늦게 안다. | K8: 영어식 경영 용어가 섞인 빠른 말투. 후반엔 쉬운 말로 성장. | L8: Vamos colocar isso numa matriz.\n(후반) Beleza, sem slide: o que você precisa? | M8: 초반 숨 가쁜 프레젠테이션 톤, 후반 솔직한 톤. | N8: 프레젠테이션식 브리핑으로 상황을 설명한다. | O8: 캠프 참모(8~10부) → 수석장관(Casa Civil, 정부 조정·정보청 관할) | P8: 본격 | Q8: =INDEX(등장비중!$O$5:$O$18,MATCH($D8,등장비중!$A$5:$A$18,0)) -> 101 | R8: =INDEX(등장비중!$Q$5:$Q$18,MATCH($D8,등장비중!$A$5:$A$18,0)) -> 준주연 | S8: E2, P1, N7
A9: 5 | B9: 부활 6인 | C9: Dom Pedro II | D9: Dom Pedro | E9: 65 | F9: =E9+개요!$C$11 -> 71 | G9: 남 | H9: 부활한 전 황제 (1825–1891) | I9: 브라질 제국 (1889년 공화정 쿠데타로 폐위, 저항 없이 파리로 망명) | J9: 나라를 위해 저항하지 않고 떠났다는 걸 아무도 기억해 주지 않는다는 서운함을 위엄으로 감춘다. 이번엔 조국에서 죽고 싶다. | K9: 위엄 있고 완곡, 학자풍 — 여러 언어와 과학에 능통했던 황제답게 박식하다. 19세기식 격식체(대명사 후치 dir-lhe-ei)와 커피 불평이 버릇. 정중하게 독을 뿌리는 심술. | L9: Não é ruim. (최고의 칭찬 — 복선)\nEste será o meu último inverno. Anotem no meu testamento.\n(현대 용어 오해) Um „servidor“ que nunca dorme? Isso lembra minha própria corte.\n„Aplicativo“? Ah, um novo tipo de decreto imperial, presumo. | M9: 느리고 품위 있는 리듬. | N9: 'Quando eu reinava…' 회상으로 현재를 냉소적으로 비교한다. | O9: 비공식 외교 자문 → 대외협상 특사(11부 9~11화, Mercosul–EU) → 11부 12화 귀국 직후 두 번째 죽음(이번엔 조국에서) | P9: 준본격 (겨울·우산 복선) | Q9: =INDEX(등장비중!$O$5:$O$18,MATCH($D9,등장비중!$A$5:$A$18,0)) -> 65 | R9: =INDEX(등장비중!$Q$5:$Q$18,MATCH($D9,등장비중!$A$5:$A$18,0)) -> 핵심 조연 | S9: N3, P2
A10: 6 | B10: 부활 6인 | C10: Machado de Assis | D10: Machado | E10: 69 | F10: =E10+개요!$C$11 -> 75 | G10: 남 | H10: 부활한 소설가 (1839–1908) | I10: 브라질 문학 아카데미(ABL) 창립자 | J10: 자신이 흑인·혼혈이라는 이유로 평가절하됐던 시대를 지나, 이제 와 '국민 작가'로 추앙받는 아이러니를 냉소로 곱씹는다. | K10: 아이러니와 여백이 많은 문어체. 인물들의 위선을 곁눈질로 짚어낸다. | L10: (고전 인용) Ao vencedor, as batatas.\n(현대 용어 오해) „Viral“? Como um folhetim que se espalha sozinho — já inventei isso, sabia? | M10: 느긋하고 아이러니한 톤. | N10: 연설문·성명서를 낭독하며 은근한 비평을 섞는다. | O10: 연설·메시지 자문 → 대통령 연설비서관 | P10: 카메오 | Q10: =INDEX(등장비중!$O$5:$O$18,MATCH($D10,등장비중!$A$5:$A$18,0)) -> 64 | R10: =INDEX(등장비중!$Q$5:$Q$18,MATCH($D10,등장비중!$A$5:$A$18,0)) -> 핵심 조연 | S10: P1, N6
A11: 7 | B11: 부활 6인 | C11: Zumbi dos Palmares | D11: Zumbi | E11: 40 | F11: =E11+개요!$C$11 -> 46 | G11: 남 | H11: 부활한 저항 지도자 (1655–1695) | I11: 킬롬부 두스 팔마리스 지도자 | J11: 자유 공동체가 결국 무너지는 걸 지켜봤던 사람 — '이번엔 안 무너진다'는 조급함이 있다. | K11: 단호하고 직설적, 연설조. 관료주의·타협을 보면 참지 못한다. | L11: Quem não luta já perdeu.\n(현대 용어 오해) „Cancelar“? Finalmente — quem cancelamos primeiro? | M11: 빠르고 격정적. | N11: 집회 연설조로 상황과 대중의 분위기를 전달하고, 현장 보고는 «Sem novidade no quilombo.»로 끝낸다. | O11: 현장 조직·캠프 총괄(7~10부) → 통합·지역개발부 장관(국가 민방위 총괄) | P11: 카메오 | Q11: =INDEX(등장비중!$O$5:$O$18,MATCH($D11,등장비중!$A$5:$A$18,0)) -> 63 | R11: =INDEX(등장비중!$Q$5:$Q$18,MATCH($D11,등장비중!$A$5:$A$18,0)) -> 핵심 조연 | S11: N1, N5, S3
A12: 8 | B12: 부활 6인 | C12: Santos Dumont | D12: Dumont | E12: 59 | F12: =E12+개요!$C$11 -> 65 | G12: 남 | H12: 부활한 항공 개척자 (1873–1932) | I12: 비행선·비행기 발명가 → 부활 후 독립 팟캐스트·뉴스레터 «Diário de Bordo» 운영 (공론화 담당) | J12: 자신의 발명이 훗날 전쟁 무기로 쓰인 것에 죄책감을 느껴 만년에 스스로 목숨을 끊었던 기억을 안고 있다. | K12: 소탈하고 섬세, 기계·비행 비유를 즐겨 쓴다. | L12: (현대 용어 오해) „Wi-Fi“? Ondas invisíveis — isso eu já sonhava em 1900.\n„Drone“? Um bom nome para meu 14-bis, não acha? | M12: 느리고 소탈한 톤. | N12: 기사·팟캐스트 원고를 소리 내어 읽고, 비행·기계 비유로 복잡한 사안을 쉽게 풀어준다. 취재 원칙: «Preciso de duas fontes.» | O12: 공론화·미디어(7~10부) → 대통령 대변인 겸 과학기술 자문 | P12: 카메오 | Q12: =INDEX(등장비중!$O$5:$O$18,MATCH($D12,등장비중!$A$5:$A$18,0)) -> 54 | R12: =INDEX(등장비중!$Q$5:$Q$18,MATCH($D12,등장비중!$A$5:$A$18,0)) -> 조연 | S12: N7, S4
A13: 9 | B13: 부활 6인 | C13: Paulo Freire | D13: Freire | E13: 75 | F13: =E13+개요!$C$11 -> 81 | G13: 남 | H13: 부활한 교육학자 (1921–1997) | I13: 『페다고지아 두 오프리미두』 저자, 군사정권 때 투옥 후 망명 → 부활 후 헌책방(sebo) 단골, 사무소의 '출처 안내' 담당 | J13: 교육이 억압의 도구로도, 해방의 도구로도 쓰일 수 있다는 걸 알아서, 모든 정책을 그 잣대로 냉정하게 재단한다. | K13: 낮고 또박또박, 결론을 말하지 않고 질문과 출처로 상대가 스스로 답을 찾게 만든다. | L13: Ninguém liberta ninguém, ninguém se liberta sozinho.\nNão te dou a resposta. Te digo onde ela mora.\n(현대 용어 재해석) „Startup“? Um nome bonito para: novo proletariado, nova corrente. | M13: 차분하고 낮은 톤. | N13: 카드(ficha)를 구술하며 검색어·출처·서가 위치를 알려 준다 (Freire_출처 시트). | O13: 출처·교육 자문 → 정보기관 감독 개혁 자문 (정부 직책은 끝내 거절) | P13: 카메오 | Q13: =INDEX(등장비중!$O$5:$O$18,MATCH($D13,등장비중!$A$5:$A$18,0)) -> 56 | R13: =INDEX(등장비중!$Q$5:$Q$18,MATCH($D13,등장비중!$A$5:$A$18,0)) -> 조연 | S13: N7, S1
A14: 10 | B14: 서민·청년 | C14: Dona Marta Nascimento | D14: Marta | E14: 63 | F14: =E14+개요!$C$11 -> 69 | G14: 여 | H14: 바 사장 (Bar da Marta, 30년 운영) | I14: Bar da Marta, Bixiga → 사무소 1층으로 이전 | J14: 임대료 폭등으로 Bixiga의 옛 가게를 잃었다. 사무소 1층이 새 아지트가 된다. | K14: Bixiga 토박이 파울리스타나 구어체(이탈리아계 할머니에게 배운 손짓 포함). 누구에게나 você, 'meu filho/minha filha'. | L14: Senta aí, que eu trago alguma coisa.\nDe estômago vazio não se pensa direito.\nA casa paga. | M14: 따뜻하고 넉넉한 톤. | N14: 시간·장소·식사를 말로 알려 장면을 연다. | O14: 소상공인 정책 자문 (비공식) → 13부 재단 공동 운영 | P14: 본격 | Q14: =INDEX(등장비중!$O$5:$O$18,MATCH($D14,등장비중!$A$5:$A$18,0)) -> 69 | R14: =INDEX(등장비중!$Q$5:$Q$18,MATCH($D14,등장비중!$A$5:$A$18,0)) -> 핵심 조연 | S14: E1, E2, S2
A15: 11 | B15: 서민·청년 | C15: Edson Ferreira | D15: Edson | E15: 55 | F15: =E15+개요!$C$11 -> 61 | G15: 남 | H15: 전 대중교통 노조위원장 | I15: 상파울루 지하철(Metrô) 노조 (파업 책임으로 해고) | J15: 파업 책임으로 해고되어 블랙리스트에 올랐지만 후회하지 않는다. | K15: 거칠고 직설적, 구호형 문장. | L15: Aqui ninguém se entrega!\nIsso se resolve na rua.\nNão enche o saco. | M15: 큰 볼륨, 강한 억양. | N15: 구호와 함성으로 현장의 분위기를 전달한다. | O15: 사회적 대화 자문 → 13부 재단 공동 운영 | P15: 카메오 | Q15: =INDEX(등장비중!$O$5:$O$18,MATCH($D15,등장비중!$A$5:$A$18,0)) -> 58 | R15: =INDEX(등장비중!$Q$5:$Q$18,MATCH($D15,등장비중!$A$5:$A$18,0)) -> 조연 | S15: S1, N6, E2
A16: 12 | B16: 서민·청년 | C16: Larissa Souza | D16: Larissa | E16: 23 | F16: =E16+개요!$C$11 -> 29 | G16: 여 | H16: 신입 인턴 (독자의 대리인) | I16: 대기업 인턴 출신 (부당 해고), 월세 밀림, Brás 14번 블록 세입자 | J16: 대기업 인턴에서 부당하게 쫓겨났고 월세가 밀려 있다. | K16: Z세대 구어체 (mano, tipo assim, surtei). 어른들에겐 격식체, 성장하며 편하게. | L16: Desculpa, o que isso significa?\nExplica como se eu tivesse cinco anos?\nCHEGA! Não entendo nada! (폭발 — 1부·9부 각 1회) | M16: 빠르고 밝은 톤. | N16: 질문으로 용어와 배경을 끌어낸다. | O16: 시의원 보좌(9부) → 청년정책 자문관 | P16: 본격 | Q16: =INDEX(등장비중!$O$5:$O$18,MATCH($D16,등장비중!$A$5:$A$18,0)) -> 99 | R16: =INDEX(등장비중!$Q$5:$Q$18,MATCH($D16,등장비중!$A$5:$A$18,0)) -> 준주연 | S16: S1, N8
... A18: 14 | B18: 부활 6인 | C18: Princesa Isabel | D18: Isabel | E18: 75 | F18: =E18+개요!$C$11 -> 81 | G18: 여 | H18: 부활한 황녀 (1846–1921) | I18: 황금법(Lei Áurea) 서명자, 노예제 폐지 → 부활 후 생명존중 상담 전화(CVV) 자원봉사자 | J18: 자신의 서명 하나로 역사에 남았지만, 그 이후 해방된 이들의 삶은 국가가 책임지지 않았다는 걸 뒤늦게 알았다. | K18: 부드럽지만 단호, 도덕적 확신이 강하다. 상담 교육을 받은 뒤 «E como isso faz você se sentir?»를 입버릇처럼 써서 모두를 질색하게 한다. | L18: Assinei uma lei. Não assinei o fim do problema.\n(현대 용어 오해) „Influencer“? Parece um novo tipo de vendedor de indulgências. | M18: 느리고 진지한 톤. | N18: 상대의 말을 되받아 감정을 이름 붙여 준다 (되받기 화법). | O18: 상담·인권 자문 → 청년 정신건강 태스크포스(12부) | P18: 카메오 | Q18: =INDEX(등장비중!$O$5:$O$18,MATCH($D18,등장비중!$A$5:$A$18,0)) -> 54 | R18: =INDEX(등장비중!$Q$5:$Q$18,MATCH($D18,등장비중!$A$5:$A$18,0)) -> 조연 | S18: N8, N4, S2

Sheet 등장비중
A1: 인물별 등장 비중 (부별 등장 화 수)
A2: 등장 화 = 대사가 있는 화 수 (기획용 초안). 파란 숫자는 직접 입력값이며 수정하면 합계·비중·등급이 자동 갱신됩니다.
A4: 인물 (약칭) | B4: 1부 사무소 | C4: 2부 Rafael | D4: 3부 Camila | E4: 4부 Bruno | F4: 5부 Juliana | G4: 6부 만남 | H4: 7부 전면전 | I4: 8부 창당 | J4: 9부 시의회 | K4: 10부 대선·대통령 | L4: 11부 국정 I | M4: 12부 국정 II | N4: 13부 귀환 | O4: 합계 | P4: 비중 | Q4: 등급 | R4: 검증 (≤부당 화 수) | S4: 단독 중심 화 목표 (조연)
A5: Rafael | B5: 7 | C5: 12 | D5: 3 | E5: 3 | F5: 3 | G5: 12 | H5: 11 | I5: 12 | J5: 11 | K5: 11 | L5: 10 | M5: 3 | N5: 10 | O5: =SUM(B5:N5) -> 108 | P5: =O5/개요!$C$7 -> 0.69230769 | Q5: =IF(P5>=$B$23,"주연",IF(P5>=$B$24,"준주연",IF(P5>=$B$25,"핵심 조연","조연"))) -> 주연 | R5: =IF(MAX(B5:N5)<=개요!$C$6,"OK","확인") -> OK | S5: —
A6: Camila | B6: 6 | C6: 3 | D6: 12 | E6: 3 | F6: 3 | G6: 12 | H6: 10 | I6: 10 | J6: 8 | K6: 10 | L6: 10 | M6: 2 | N6: 9 | O6: =SUM(B6:N6) -> 98 | P6: =O6/개요!$C$7 -> 0.62820513 | Q6: =IF(P6>=$B$23,"주연",IF(P6>=$B$24,"준주연",IF(P6>=$B$25,"핵심 조연","조연"))) -> 준주연 | R6: =IF(MAX(B6:N6)<=개요!$C$6,"OK","확인") -> OK | S6: —
A7: Bruno | B7: 7 | C7: 3 | D7: 3 | E7: 12 | F7: 3 | G7: 12 | H7: 11 | I7: 10 | J7: 10 | K7: 11 | L7: 10 | M7: 8 | N7: 9 | O7: =SUM(B7:N7) -> 109 | P7: =O7/개요!$C$7 -> 0.69871795 | Q7: =IF(P7>=$B$23,"주연",IF(P7>=$B$24,"준주연",IF(P7>=$B$25,"핵심 조연","조연"))) -> 주연 | R7: =IF(MAX(B7:N7)<=개요!$C$6,"OK","확인") -> OK | S7: —
A8: Juliana | B8: 6 | C8: 3 | D8: 3 | E8: 3 | F8: 12 | G8: 12 | H8: 10 | I8: 11 | J8: 10 | K8: 10 | L8: 9 | M8: 3 | N8: 9 | O8: =SUM(B8:N8) -> 101 | P8: =O8/개요!$C$7 -> 0.6474359 | Q8: =IF(P8>=$B$23,"주연",IF(P8>=$B$24,"준주연",IF(P8>=$B$25,"핵심 조연","조연"))) -> 준주연 | R8: =IF(MAX(B8:N8)<=개요!$C$6,"OK","확인") -> OK | S8: —
A9: Dom Pedro | B9: 4 | C9: 2 | D9: 2 | E9: 2 | F9: 2 | G9: 7 | H9: 9 | I9: 7 | J9: 9 | K9: 9 | L9: 9 | M9: 0 | N9: 3 | O9: =SUM(B9:N9) -> 65 | P9: =O9/개요!$C$7 -> 0.41666667 | Q9: =IF(P9>=$B$23,"주연",IF(P9>=$B$24,"준주연",IF(P9>=$B$25,"핵심 조연","조연"))) -> 핵심 조연 | R9: =IF(MAX(B9:N9)<=개요!$C$6,"OK","확인") -> OK | S9: —
A10: Machado | B10: 3 | C10: 1 | D10: 1 | E10: 1 | F10: 1 | G10: 6 | H10: 8 | I10: 9 | J10: 8 | K10: 8 | L10: 7 | M10: 4 | N10: 7 | O10: =SUM(B10:N10) -> 64 | P10: =O10/개요!$C$7 -> 0.41025641 | Q10: =IF(P10>=$B$23,"주연",IF(P10>=$B$24,"준주연",IF(P10>=$B$25,"핵심 조연","조연"))) -> 핵심 조연 | R10: =IF(MAX(B10:N10)<=개요!$C$6,"OK","확인") -> OK | S10: —
A11: Zumbi | B11: 2 | C11: 1 | D11: 1 | E11: 3 | F11: 1 | G11: 5 | H11: 10 | I11: 7 | J11: 8 | K11: 8 | L11: 7 | M11: 3 | N11: 7 | O11: =SUM(B11:N11) -> 63 | P11: =O11/개요!$C$7 -> 0.40384615 | Q11: =IF(P11>=$B$23,"주연",IF(P11>=$B$24,"준주연",IF(P11>=$B$25,"핵심 조연","조연"))) -> 핵심 조연 | R11: =IF(MAX(B11:N11)<=개요!$C$6,"OK","확인") -> OK | S11: —
A12: Dumont | B12: 1 | C12: 1 | D12: 2 | E12: 1 | F12: 2 | G12: 4 | H12: 7 | I12: 8 | J12: 6 | K12: 7 | L12: 6 | M12: 2 | N12: 7 | O12: =SUM(B12:N12) -> 54 | P12: =O12/개요!$C$7 -> 0.34615385 | Q12: =IF(P12>=$B$23,"주연",IF(P12>=$B$24,"준주연",IF(P12>=$B$25,"핵심 조연","조연"))) -> 조연 | R12: =IF(MAX(B12:N12)<=개요!$C$6,"OK","확인") -> OK | S12: —
A13: Freire | B13: 2 | C13: 1 | D13: 1 | E13: 3 | F13: 1 | G13: 5 | H13: 8 | I13: 5 | J13: 7 | K13: 7 | L13: 9 | M13: 1 | N13: 6 | O13: =SUM(B13:N13) -> 56 | P13: =O13/개요!$C$7 -> 0.35897436 | Q13: =IF(P13>=$B$23,"주연",IF(P13>=$B$24,"준주연",IF(P13>=$B$25,"핵심 조연","조연"))) -> 조연 | R13: =IF(MAX(B13:N13)<=개요!$C$6,"OK","확인") -> OK | S13: —
A14: Marta | B14: 12 | C14: 2 | D14: 2 | E14: 2 | F14: 2 | G14: 5 | H14: 8 | I14: 6 | J14: 4 | K14: 5 | L14: 8 | M14: 3 | N14: 10 | O14: =SUM(B14:N14) -> 69 | P14: =O14/개요!$C$7 -> 0.44230769 | Q14: =IF(P14>=$B$23,"주연",IF(P14>=$B$24,"준주연",IF(P14>=$B$25,"핵심 조연","조연"))) -> 핵심 조연 | R14: =IF(MAX(B14:N14)<=개요!$C$6,"OK","확인") -> OK | S14: —
A15: Edson | B15: 2 | C15: 1 | D15: 2 | E15: 1 | F15: 3 | G15: 5 | H15: 9 | I15: 8 | J15: 6 | K15: 6 | L15: 7 | M15: 2 | N15: 6 | O15: =SUM(B15:N15) -> 58 | P15: =O15/개요!$C$7 -> 0.37179487 | Q15: =IF(P15>=$B$23,"주연",IF(P15>=$B$24,"준주연",IF(P15>=$B$25,"핵심 조연","조연"))) -> 조연 | R15: =IF(MAX(B15:N15)<=개요!$C$6,"OK","확인") -> OK | S15: —
A16: Larissa | B16: 12 | C16: 4 | D16: 4 | E16: 4 | F16: 4 | G16: 8 | H16: 10 | I16: 10 | J16: 9 | K16: 9 | L16: 10 | M16: 3 | N16: 12 | O16: =SUM(B16:N16) -> 99 | P16: =O16/개요!$C$7 -> 0.63461538 | Q16: =IF(P16>=$B$23,"주연",IF(P16>=$B$24,"준주연",IF(P16>=$B$25,"핵심 조연","조연"))) -> 준주연 | R16: =IF(MAX(B16:N16)<=개요!$C$6,"OK","확인") -> OK | S16: —
... A18: Isabel | B18: 1 | C18: 1 | D18: 2 | E18: 1 | F18: 2 | G18: 4 | H18: 7 | I18: 8 | J18: 6 | K18: 7 | L18: 6 | M18: 2 | N18: 7 | O18: =SUM(B18:N18) -> 54 | P18: =O18/개요!$C$7 -> 0.34615385 | Q18: =IF(P18>=$B$23,"주연",IF(P18>=$B$24,"준주연",IF(P18>=$B$25,"핵심 조연","조연"))) -> 조연 | R18: =IF(MAX(B18:N18)<=개요!$C$6,"OK","확인") -> OK | S18: —
A19: 부별 연인원 (합계) | B19: =SUM(B5:B18) -> 67 | C19: =SUM(C5:C18) -> 36 | D19: =SUM(D5:D18) -> 39 | E19: =SUM(E5:E18) -> 42 | F19: =SUM(F5:F18) -> 40 | G19: =SUM(G5:G18) -> 102 | H19: =SUM(H5:H18) -> 126 | I19: =SUM(I5:I18) -> 116 | ... O19: =SUM(O5:O18) -> 1054 | S19: =SUM(S5:S18) -> 0
A23: 주연 | B23: 0.69 | C23: ← 기준값은 등급 구분(주연 4 / 준주연 1 / 핵심 조연 4 / 조연 5)을 재현하도록 정한 제안값입니다.
A24: 준주연 | B24: 0.6
A25: 핵심 조연 | B25: 0.4
A26: 조연 | B26: 그 미만
A28: 배분 원칙
A29: 1. 1부는 개소 1개월 후 시점: Larissa·Marta가 전 화에, 주력 4인은 사건별로 2~3인씩 교대 등장(전원 겹치지 않음). Dom Pedro 4화, Freire 3화(1·2·11화)로 자주 얼굴을 비추고 '이번 겨울이 마지막' 복선을 1화부터 깐다. 나머지는 사건마다 다른 조합으로 카메오.
A30: 2. 2~5부: 각 주인공이 자기 부 12화 전부에 나오고, 다른 주력 3인은 3화씩 스쳐 지나가며 6부 만남을 예고. Larissa는 4화씩 '사무소에서 이야기를 듣는 프레임'으로 등장해 회상을 잇는다.
A31: 3. 자문단은 과거와 겹치는 곳에만 배치: Edson-5부(Juliana의 구조조정 현장), Sérgio·Dumont-4부(Bruno의 감사 사건), Isabel-3부·5부(트라우마·번아웃 상담).
A32: 4. 자문단 본격 비중은 7~10부에서 최고치: 7부 Dumont·Edson(공론화·현장 조직), 8부 Machado·Isabel·Zumbi(선언문·메시지·캠프), 10부 Machado·Dumont·Freire(취임 연설·딥페이크 대응·출처).
A33: 5. 11부(국정 I)는 Dom Pedro가 9~12화에서 브뤼셀 직접 협상을 이끌며 최고치(9화)를 찍고 12화에서 사망한다. Sérgio는 앞선 주거·금융 국내 현안 화에서 정점.
A34: 6. 12부(국정 II)는 Dom Pedro 사후: 1화 장례식에서 Zumbi·Freire·Camila가 몰리고, Bruno·Machado가 유작 메모를 이어받는 3화에서 비중이 오른다.
A35: 7. 13부(귀환)는 원형 구조: Larissa 12화 전부, Marta 10화. Dom Pedro는 유언장·회상으로 3화, Rafael·Camila·Bruno·Juliana는 목요일 밤 브라질리아에서 돌아온 손님으로 9~10화 등장.
A36: 8. Dom Pedro는 11부 12화(브뤼셀 승리 직후, 귀국 직후)에서 사망한다. 12부 1화 장례식, 2·3화 유작 메모 승계, 13부 2화 유언장까지 이어진다.
A37: 9. 등장 화 수와 대사량은 다르다: Larissa는 약 67%지만 문장이 짧아 대사량은 Rafael의 절반 이하가 되게 하고, Dom Pedro·Machado는 화당 대사가 길어도 된다.
A38: 10. 조연 9인은 화 전체의 중심이 되는 에피소드를 각자 2개 이상 배정(S열 목표). 자기 이야기가 한 번도 없으면 얇은 인물이 된다.
A39: 11. Dumont·Isabel이 가장 얇다(약 35%): 7부 공론화·10부 딥페이크(Dumont), 3·5부 상담과 12부 청년 정신건강(Isabel)을 늘려 서사를 넓히는 안을 검토.

Sheet 턴_설계
A1: 대화량 설계: 화당 120턴
A2: 한 화 = 대화 120턴. 점유율·평균 단어/턴·배율·낭독 속도는 가정값(파란 숫자)이며 수정하면 아래 표가 자동 갱신됩니다. (현재 표는 1~12부 열 기준 — 13부 열 추가는 미결)
A4: 1. 기본 설정
A5: 화당 대화 턴 | B5: 120
A6: 낭독 속도 (단어/분, 가정) | B6: 130
A7: 총 화 수 | B7: =개요!$C$7 -> 156
A8: 총 대화 턴 | B8: =B5*B7 -> 18720
A9: 턴 정의 | B9: 화자 표기 한 줄 = 1턴 (화자가 바뀌면 새 턴). 연설·조항·기사 낭독처럼 긴 발화도 1턴으로 센다.
A11: 2. 부별 화자 점유율 (턴 기준, 각 부의 합 = 100%)
A12: 인물 | B12: 평균 단어/턴 | C12: 1부 | D12: 2부 | E12: 3부 | F12: 4부 | G12: 5부 | H12: 6부 | I12: 7부 | J12: 8부 | K12: 9부 | L12: 10부 | M12: 11부 | N12: 12부
A13: Rafael | B13: 13 | C13: 0.13 | D13: 0.48 | E13: 0.03 | F13: 0.02 | G13: 0.02 | H13: 0.13 | I13: 0.14 | J13: 0.15 | K13: 0.08 | L13: 0.18 | M13: 0.15 | N13: 0.07
A14: Camila | B14: 8 | C14: 0.12 | D14: 0.03 | E14: 0.46 | F14: 0.04 | G14: 0.03 | H14: 0.12 | I14: 0.07 | J14: 0.08 | K14: 0.11 | L14: 0.06 | M14: 0.09 | N14: 0.06
A15: Bruno | B15: 11 | C15: 0.12 | D15: 0.04 | E15: 0.04 | F15: 0.46 | G15: 0.04 | H15: 0.12 | I15: 0.1 | J15: 0.09 | K15: 0.15 | L15: 0.08 | M15: 0.11 | N15: 0.07
A16: Juliana | B16: 12 | C16: 0.12 | D16: 0.05 | E16: 0.03 | F16: 0.03 | G16: 0.46 | H16: 0.12 | I16: 0.06 | J16: 0.09 | K16: 0.08 | L16: 0.11 | M16: 0.08 | N16: 0.07
A17: Dom Pedro | B17: 14 | C17: 0.08 | D17: 0.04 | E17: 0.04 | F17: 0.04 | G17: 0.04 | H17: 0.04 | I17: 0.06 | J17: 0.05 | K17: 0.04 | L17: 0.06 | M17: 0.04 | N17: 0.02
A18: Zumbi | B18: 7 | C18: 0.02 | D18: 0.01 | E18: 0.01 | F18: 0.01 | G18: 0.01 | H18: 0.05 | I18: 0.06 | J18: 0.06 | K18: 0.04 | L18: 0.08 | M18: 0.07 | N18: 0.06
A19: Freire | B19: 9 | C19: 0.02 | D19: 0.01 | E19: 0.01 | F19: 0.01 | G19: 0.01 | H19: 0.03 | I19: 0.06 | J19: 0.03 | K19: 0.04 | L19: 0.03 | M19: 0.05 | N19: 0.08
A20: Dumont | B20: 10 | C20: 0.02 | D20: 0.01 | E20: 0.03 | F20: 0.04 | G20: 0.01 | H20: 0.03 | I20: 0.08 | J20: 0.06 | K20: 0.07 | L20: 0.05 | M20: 0.06 | N20: 0.05
A21: Isabel | B21: 9 | C21: 0.01 | D21: 0.01 | E21: 0.04 | F21: 0.01 | G21: 0.04 | H21: 0.03 | I21: 0.05 | J21: 0.06 | K21: 0.04 | L21: 0.05 | M21: 0.04 | N21: 0.05
A22: Marta | B22: 9 | C22: 0.12 | D22: 0.04 | E22: 0.03 | F22: 0.03 | G22: 0.03 | H22: 0.05 | I22: 0.04 | J22: 0.05 | K22: 0.03 | L22: 0.04 | M22: 0.04 | N22: 0.13
A23: Edson | B23: 10 | C23: 0.01 | D23: 0.02 | E23: 0.01 | F23: 0.01 | G23: 0.09 | H23: 0.05 | I23: 0.06 | J23: 0.08 | K23: 0.08 | L23: 0.06 | M23: 0.05 | N23: 0.05
A24: Machado | B24: 12 | C24: 0.02 | D24: 0.01 | E24: 0.01 | F24: 0.01 | G24: 0.01 | H24: 0.03 | I24: 0.03 | J24: 0.08 | K24: 0.05 | L24: 0.07 | M24: 0.05 | N24: 0.05
... A27: 엑스트라(가상) | B27: 10 | C27: 0.03 | D27: 0.15 | E27: 0.17 | F27: 0.13 | G27: 0.12 | H27: 0.07 | I27: 0.07 | J27: 0.03 | K27: 0.05 | L27: 0.05 | M27: 0.04 | N27: 0.04
A28: 합계 | C28: =SUM(C13:C27) -> 1 | D28: =SUM(D13:D27) -> 1 | E28: =SUM(E13:E27) -> 1 | F28: =SUM(F13:F27) -> 1 | G28: =SUM(G13:G27) -> 1 | H28: =SUM(H13:H27) -> 1 | I28: =SUM(I13:I27) -> 1 | J28: =SUM(J13:J27) -> 1 | ... N28: =SUM(N13:N27) -> 1
A29: 검증 | C29: =IF(ROUND(C28,4)=1,"OK","확인") -> OK | D29: =IF(ROUND(D28,4)=1,"OK","확인") -> OK | E29: =IF(ROUND(E28,4)=1,"OK","확인") -> OK | F29: =IF(ROUND(F28,4)=1,"OK","확인") -> OK | G29: =IF(ROUND(G28,4)=1,"OK","확인") -> OK | H29: =IF(ROUND(H28,4)=1,"OK","확인") -> OK | I29: =IF(ROUND(I28,4)=1,"OK","확인") -> OK | J29: =IF(ROUND(J28,4)=1,"OK","확인") -> OK | ... N29: =IF(ROUND(N28,4)=1,"OK","확인") -> OK
A31: 3. 부별 턴·단어·낭독 시간 (수식)
A32: 부 | B32: 난이도 배율 | C32: 화당 턴 | D32: 부 총 턴 | E32: 평균 단어/턴 | F32: 화당 단어 | G32: 부 총 단어 | H32: 화당 낭독 (분) | I32: 부 총 낭독 (시간)
A33: 1부 | B33: 0.8 | C33: =$B$5 -> 120 | D33: =C33*개요!$C$6 -> 1440 | E33: =SUMPRODUCT(C$13:C$27,$B$13:$B$27)*B33 -> 8.128 | F33: =C33*E33 -> 975.36 | G33: =F33*개요!$C$6 -> 11704.32 | H33: =F33/$B$6 -> 7.5027692 | I33: =H33*개요!$C$6/60 -> 1.5005538
A34: 2부 | B34: 1 | C34: =$B$5 -> 120 | D34: =C34*개요!$C$6 -> 1440 | E34: =SUMPRODUCT(D$13:D$27,$B$13:$B$27)*B34 -> 11.39 | F34: =C34*E34 -> 1366.8 | G34: =F34*개요!$C$6 -> 16401.6 | H34: =F34/$B$6 -> 10.513846 | I34: =H34*개요!$C$6/60 -> 2.1027692
A35: 3부 | B35: 1 | C35: =$B$5 -> 120 | D35: =C35*개요!$C$6 -> 1440 | E35: =SUMPRODUCT(E$13:E$27,$B$13:$B$27)*B35 -> 9.11 | F35: =C35*E35 -> 1093.2 | G35: =F35*개요!$C$6 -> 13118.4 | H35: =F35/$B$6 -> 8.4092308 | I35: =H35*개요!$C$6/60 -> 1.6818462
A36: 4부 | B36: 1 | C36: =$B$5 -> 120 | D36: =C36*개요!$C$6 -> 1440 | E36: =SUMPRODUCT(F$13:F$27,$B$13:$B$27)*B36 -> 10.44 | F36: =C36*E36 -> 1252.8 | G36: =F36*개요!$C$6 -> 15033.6 | H36: =F36/$B$6 -> 9.6369231 | I36: =H36*개요!$C$6/60 -> 1.9273846
A37: 5부 | B37: 1 | C37: =$B$5 -> 120 | D37: =C37*개요!$C$6 -> 1440 | E37: =SUMPRODUCT(G$13:G$27,$B$13:$B$27)*B37 -> 10.8 | F37: =C37*E37 -> 1296 | G37: =F37*개요!$C$6 -> 15552 | H37: =F37/$B$6 -> 9.9692308 | I37: =H37*개요!$C$6/60 -> 1.9938462
A38: 6부 | B38: 1 | C38: =$B$5 -> 120 | D38: =C38*개요!$C$6 -> 1440 | E38: =SUMPRODUCT(H$13:H$27,$B$13:$B$27)*B38 -> 10.16 | F38: =C38*E38 -> 1219.2 | G38: =F38*개요!$C$6 -> 14630.4 | H38: =F38/$B$6 -> 9.3784615 | I38: =H38*개요!$C$6/60 -> 1.8756923
A39: 7부 | B39: 1 | C39: =$B$5 -> 120 | D39: =C39*개요!$C$6 -> 1440 | E39: =SUMPRODUCT(I$13:I$27,$B$13:$B$27)*B39 -> 10.35 | F39: =C39*E39 -> 1242 | G39: =F39*개요!$C$6 -> 14904 | H39: =F39/$B$6 -> 9.5538462 | I39: =H39*개요!$C$6/60 -> 1.9107692
A40: 8부 | B40: 1.1 | C40: =$B$5 -> 120 | D40: =C40*개요!$C$6 -> 1440 | E40: =SUMPRODUCT(J$13:J$27,$B$13:$B$27)*B40 -> 11.495 | F40: =C40*E40 -> 1379.4 | G40: =F40*개요!$C$6 -> 16552.8 | H40: =F40/$B$6 -> 10.610769 | I40: =H40*개요!$C$6/60 -> 2.1221538
A41: 9부 | B41: 1.1 | C41: =$B$5 -> 120 | D41: =C41*개요!$C$6 -> 1440 | E41: =SUMPRODUCT(K$13:K$27,$B$13:$B$27)*B41 -> 11.154 | F41: =C41*E41 -> 1338.48 | G41: =F41*개요!$C$6 -> 16061.76 | H41: =F41/$B$6 -> 10.296 | I41: =H41*개요!$C$6/60 -> 2.0592
A42: 10부 | B42: 1.2 | C42: =$B$5 -> 120 | D42: =C42*개요!$C$6 -> 1440 | E42: =SUMPRODUCT(L$13:L$27,$B$13:$B$27)*B42 -> 12.744 | F42: =C42*E42 -> 1529.28 | G42: =F42*개요!$C$6 -> 18351.36 | H42: =F42/$B$6 -> 11.763692 | I42: =H42*개요!$C$6/60 -> 2.3527385
A43: 11부 | B43: 1.2 | C43: =$B$5 -> 120 | D43: =C43*개요!$C$6 -> 1440 | E43: =SUMPRODUCT(M$13:M$27,$B$13:$B$27)*B43 -> 12.324 | F43: =C43*E43 -> 1478.88 | G43: =F43*개요!$C$6 -> 17746.56 | H43: =F43/$B$6 -> 11.376 | I43: =H43*개요!$C$6/60 -> 2.2752
A44: 12부 | B44: 0.8 | C44: =$B$5 -> 120 | D44: =C44*개요!$C$6 -> 1440 | E44: =SUMPRODUCT(N$13:N$27,$B$13:$B$27)*B44 -> 7.616 | F44: =C44*E44 -> 913.92 | G44: =F44*개요!$C$6 -> 10967.04 | H44: =F44/$B$6 -> 7.0301538 | I44: =H44*개요!$C$6/60 -> 1.4060308
A45: 전체 | D45: =SUM(D33:D44) -> 17280 | E45: =G45/D45 -> 10.475917 | F45: =AVERAGE(F33:F44) -> 1257.11 | G45: =SUM(G33:G44) -> 181023.84 | H45: =AVERAGE(H33:H44) -> 9.6700769 | I45: =SUM(I33:I44) -> 23.208185
...

Sheet 12부_구성
A1: 13부 구성 (13부 × 12화 = 156화)
A2: 정치 파트(8~12부)는 브라질의 현실 정치 제도(대통령제·연방제·개방형 명부)에 맞춰 재설계했습니다. 화별 목차는 '화별목차_전체', 제도 근거는 '정치제도' 시트.
A4: 부 | B4: 제목 (PT-BR) | C4: 한국어 | D4: 배경 | E4: 핵심 내용 | F4: 난이도 (CEFR) | G4: 반영 제도·전문 영역 | H4: 시점
A5: 1 | B5: O Escritório do Bixiga | C5: 비시가 사무소 | D5: Bixiga의 작은 사무실 (1층은 Bar da Marta), 개소 1개월 후 | E5: 이미 한 달째 좌충우돌 중인 팀이 이웃들의 사건 6개를 2화씩(도입→해결) 풀어 간다. 자기소개 대신 '이 사람들이 어쩌다 이렇게 됐지?' 하는 궁금증(In medias res)으로 시작. | F5: B1 | G5: 생활 법률·노동·의료·금융 기초 어휘(임대차법, 인턴법, SUS, Pix), 반복되는 말다툼, Larissa 1차 폭발(6화) | H5: 현재(개소 후 1개월)
A6: 2 | B6: O Advogado | C6: 변호사 | D6: Avenida Faria Lima의 대형 로펌 | E6: 승소율 100%의 이면: 강제 퇴거 사건이 Rafael의 결핍이 된다. | F6: B2~C1 | G6: 민사소송, 퇴거 절차(임대차법·CPC), 부동산 등기 | H6: 과거
A7: 3 | B7: A Médica | C7: 의사 | D7: Hospital Municipal São Bartolomeu 응급실 (가상, OSS 위탁) | E7: 예산 삭감과 위탁 운영 압박 속에서 치료받지 못하는 환자들. Camila의 이름 목록. | F7: B2~C1 | G7: 응급의학·보건행정, SUS와 시 보건국, 사회조직 위탁 운영(OSS) | H7: 과거
A8: 4 | B8: O Auditor | C8: 회계사 | D8: Barros & Teixeira Auditores (가상) | E8: 역외 펀드·자금세탁 정황을 발견하지만 조직의 묵인 압박. 서명하지 않겠다는 다짐의 기원. | F8: B2~C1 | G8: 감사·세무, 자금세탁방지법(Lei 9.613/1998), 감사인 순환(CVM) | H8: 과거
A9: 5 | B9: A Consultora | C9: 컨설턴트 | D9: Zênite Consultoria (가상), Faria Lima 32층 | E9: 구조조정 스프레드시트 한 칸이 수백 명의 실직이었음을 깨닫는다. Edson과의 첫 접점. | F9: B2~C1 | G9: 경영 전략, 대량 해고와 사전 노조 협상, 노동법(CLT) | H9: 과거
A10: 6 | B10: O Encontro | C10: 운명적 만남 | D10: Brás의 낡은 임대 건물 '14번 블록', 작은 바 | E10: 강제 퇴거와 의료 방치가 한 건으로 얽힌 사건에서 네 사람이 만나 사무소를 차리기로 한다. | F10: B2 | G10: 협상·설득 구어체 | H10: 현재로 수렴
A11: 7 | B11: A Rede de Resistência | C11: 사무소 2탄: 전면전 | D11: 법원, 시청 앞, 상파울루 전역 | E11: 부당 해고·의료 사고·탈세 대기업 상대 집단 대응. 내부 제보자를 보호하고 공익소송과 검찰 고발로 맞선다. | F11: B2~C1 | G11: 공익소송(ação civil pública), 연방검찰, 내부고발자 보호(Lei 13.608/2018), 위법 수집 증거 | H11: 과거→현재
A12: 8 | B12: O Despertar Cívico | C12: 정치적 각성과 창당 | D12: Avenida Paulista(MASP 앞), 시민 집회 | E12: 국민발안이 좌초하자 스스로 정당 «Casa Comum»을 창당해 첫 시장·시의원 선거에 나선다. | F12: B2~C1 | G12: 집회 사전 통지, 국민발안, 정당 창당·TSE 등록, 정당 재정, 개방형 명부 선거 | H12: 정치
A13: 9 | B13: Na Câmara Municipal | C13: 시의회 | D13: Palácio Anchieta(상파울루 시의회), 당사 | E13: Bruno는 재정위원회에서 예산을, Camila는 보건위원회에서 위탁 계약을 파고든다. 스캔들 폭로와 Larissa의 2차 폭발. | F13: C1 | G13: 본회의·위원회, 시 예산, 공공조달법, 시 감사원, CPI, 시민소송 | H13: 정치
A14: 10 | B14: Rumo ao Planalto | C14: 대선에서 대통령 취임까지 | D14: 전국 유세 → 상파울루 개표의 밤 → 브라질리아 Congresso Nacional·Palácio do Planalto | E14: 전당대회·후보 등록·45일 유세·TV 토론·1차 투표 2위·결선 지지 협상·딥페이크·결선 역전·1월 5일 취임. | F14: C1~C2 | G14: 대통령 선거(헌법 제77조), 무료 선거방송, 딥페이크 금지, 정권 인수, 취임 선서(헌법 제78조) | H14: 정치
A15: 11 | B15: A Grande Batalha Social I | C15: 사회 현안 전투 I | D15: 브라질리아(Planalto·에스플라나다), 상파울루(주말의 식탁), 브뤼셀 | E15: 연립 정부로 주거·보건·이민·청년·물가 국내 현안을 돌파한 뒤, Dom Pedro가 직접 브뤼셀 협상(Mercosul–EU 협정·EUDR)에 나서 승리하고 귀국 직후 사망한다. | F15: C1~C2 | G15: 장관회의, SUS 3자 협의체, 임시조치의 세금 제한, 조약 체결·비준, Mercosul–EU·EUDR | H15: 정치
A16: 12 | B16: A Grande Batalha Social II | C16: 사회 현안 전투 II | D16: 브라질리아, 상파울루, 브뤼셀, 남부 홍수 현장 | E16: 장례식으로 열고 Dom Pedro의 유작 메모로 브뤼셀 후속 협상을 마무리한다. 앱 노동·정보기관 사찰·청년 정신건강과 온라인 도박 등 새 현안과 탄핵 청구 방어, 대홍수, 예산안까지. | F16: C1~C2 | G16: 메모 승계, 정보청 통제(CCAI), 탄핵(헌법 제85·86조), 민방위·공공재난사태, 재정규칙·예산 | H16: 정치
A17: 13 | B17: De Volta ao Bixiga | C17: 귀환 | D17: Bixiga, Bar da Marta | E17: 1부 1화와 같은 대사로 시작해 원을 닫는다. Dom Pedro의 유언장, 새 인턴, 이제 설명하는 쪽이 된 Larissa. | F17: B1~B2 | G17: 공정증서 유언(cartório, testamenteiro), 공직자 이해충돌, 재단 전환, 원형 구조 | H17: 귀환
A19: 흐름: 현재(1) → 과거(2~5) → 교차(6) → 전면전(7) → 정치(8 창당·시장/시의원 선거 → 9 시의회 → 10 대선·취임) → 정부(11~12, 브라질리아·상파울루) → 귀환(13, 원형 구조). 난이도는 B1 → C1/C2 → B1~B2로 올라갔다 내려와 마무리가 부드럽고, 13부에서 1부 장면을 다시 읽으면 낭독 실력의 성장을 스스로 확인할 수 있다.

Sheet 아크_구성계획
A1: 아크별 구성 계획 (1~13부)
A2: 각 부(아크)의 서사 기능, 변화, 비트(발단→결말), 인물 아크, 복선, 현안·제도, 언어 설계를 한 블록으로 정리. 화별 세부는 '화별목차_전체', 복선 추적은 '복선_회수'.
A4: 1부 | B4: O Escritório do Bixiga — 비시가 사무소 | 난이도 B1 | 사무소 개소 1개월 후(6부 12화로부터 약 4주). 상파울루 Bixiga(이탈리아 이민자와 삼바 학교의 동네)의 사무소와 1층 Bar da Marta.
A5: 서사 기능 | B5: 독자 진입 장치. 이미 굴러가는(그러나 여전히 좌충우돌하는) 사무소를 보여 주어 '이 사람들이 어쩌다 이렇게 됐지?' 하는 궁금증을 만든다. 자기소개 대신 여섯 사건을 통해 인물의 습관과 리듬을 익히게 한다.
A6: 로그라인 | B6: 개소 한 달째, 여전히 순서 하나 못 정하고 매번 다투는 네 전문가와 팀이 그래도 이웃들의 사건 여섯 개를 하나씩 해결해 나가지만, 마지막 사건의 서류에서 Rafael의 옛 로펌 이름이 튀어나온다.
A7: 변화 (시작 → 끝) | B7: '한 달이나 됐는데 아직도 이 모양' → 그래도 매번 어떻게든 해결하는 팀이라는 신뢰. 그러나 각자의 과거는 여전히 미해결이고, 옛 로펌 이름이 도착한다.
A8: 핵심 갈등 | B8: 전문가의 말투 vs 이웃의 삶 / 여전히 못 정한 방법 / 각자 숨기는 과거
A9: 비트 1 | B9: 사건1 임대료 인상, 1~2화(Fátima): 도입에서 여전히 자리 못 잡은 한 달 차 팀의 말다툼을 보여 주고, 해결에서 Freire의 카드 #1(임대차법·연 1회 조정)로 IGP-M을 들이댄 부당 인상을 막는다.
A10: 비트 2 | B10: 사건2 퇴거 집행, 3~4화: 밤 여덟 시 급보 → 아침 집행 저지. Zumbi·Edson 첫 카메오, 넷의 역할 분담(서류·건강·숫자·동선)이 처음으로 손발이 맞는다.
A11: 비트 3 | B11: 사건3 인턴 착취·임금 체불, 5~6화: Juliana의 컨설팅 용어가 청년 노동자를 지치게 하고, 협상 중 Larissa가 1차 폭발한다. 폭발 후 쉬운 말로 다시 협상해 해결.
A12: 비트 4 | B12: 사건4 의료 접근, 7~8화: 서류 없는 이주민 가족의 아이가 보건소에서 돌려보내진다. Isabel·Machado 카메오, Dom Pedro의 가짜 무릎이 진짜 아픈 아이 앞에서 조용해지는 대비.
A13: 비트 5 | B13: 사건5 금융 사기, 9~10화: 저축을 잃은 이웃을 두고 Bruno가 장부를, 낯선 Sérgio가 계좌 흐름을 추적하고 Pix 반환 절차(MED)로 일부를 되찾는다. Dumont 카메오. Sérgio는 설명 없이 사라지고 Bruno는 은행 이름에 말없이 굳는다.
A14: 비트 6 | B14: 사건6 오래된 서류·훅, 11~12화: 수십 년 전 퇴거 서류의 절차 오류를 바로잡다가 서명란에서 Rafael의 옛 로펌 이름을 발견한다. Rafael이 얼어붙고 금요일 이야기(2부)가 예고된다.
A15: 인물 아크 | B15: Larissa=독자의 대리인(질문), 한 달이 지나도 Rafael에게 'o senhor' 유지. Dom Pedro=심술과 복선(매년 하는 소리라는 게 드러남). Marta=정서적 중심. 카메오는 사건별로 분산: Freire(1·2·11화), Zumbi·Edson(3·4화), Isabel·Machado(7화), Sérgio·Dumont(9·10·11화). 폭발 화(6화)에는 Zumbi·Marta·Freire의 고정 반응만 남기고 Edson의 욕은 9부 2차 폭발로 이관해 과밀을 해소.
... A19: 언어 설계 | B19: B1. 한 줄 15단어 이내, 현재·명령형·간단한 과거(pretérito perfeito). você·vocês 중심. 낭독: 빠른 티키타카로 입 풀기. Rafael·Dom Pedro의 격식체(o senhor, 19세기식 대명사 후치)는 한두 줄 맛보기. 매 사건 2화(도입→해결) 리듬을 반복해 구조를 익히게 한다.
A20: 대화량 (화당 120턴) | B20: ="화당 "&턴_설계!$B$5&"턴 · 부 총 "&TEXT(턴_설계!D33,"#,##0")&"턴 · 화당 약 "&TEXT(턴_설계!F33,"#,##0")&"단어 · 낭독 약 "&TEXT(턴_설계!H33,"0.0")&"분 (평균 "&TEXT(턴_설계!E33,"0.0")&"단어/턴)" -> 화당 120턴 · 부 총 1,440턴 · 화당 약 975단어 · 낭독 약 7.5분 (평균 8.1단어/턴)
A21: Larissa 질문·Freire 카드 | B21: Larissa: 임대·노동·의료·금융 기초 용어(caução, carteira assinada, estágio, cartão do SUS, conta, Pix). 카드: 임대차법(Lei 8.245/1991), 사전(VOLP·Michaelis).
A22: 다음 부 연결 | B22: 2부: 금요일마다 한 명씩 과거를 이야기하는 규칙 — 첫 번째는 Rafael.
A24: 2부 | B24: O Advogado — 변호사 | 난이도 B2~C1 | 프레임: 1부와 같은 첫 겨울의 금요일 밤. 과거: 약 5년 전, Avenida Faria Lima의 대형 로펌.
A25: 서사 기능 | B25: 첫 과거 회상. 공동 악역 Grupo Meridiano를 도입하고 '법을 잘 쓰는 것과 옳은 것은 다르다'는 이 이야기의 첫 질문을 던진다. 프레임(Marta의 식탁)과 과거를 오가는 구조 실험.
A26: 로그라인 | B26: 승소율 100%의 파트너 후보가 대형 고객의 주택 포트폴리오를 비우는 조항을 설계해 재판에서 이기고, 그 승리가 한 노인의 죽음이 되었음을 알게 된다.
A27: 변화 (시작 → 끝) | B27: 자랑스러운 승자 → 자기 승리에 사직서를 낸 사람.
A28: 핵심 갈등 | B28: 잘 쓰는 법 vs 옳은 것 / 파트너 승진 vs 양심
A29: 비트 1 | B29: 발단(1~3화): 금요일 프레임, 파리아 리마의 월요일, VIP 고객 Quintela.
A30: 비트 2 | B30: 전개(4~5화): 실사에서 Bixiga 건물 발견 / 프레임에서 그곳이 Marta의 거리였음이 드러남.
A31: 비트 3 | B31: 미드포인트(6화): 조항 설계 — Rafael이 스스로 함정(공사 사유 회수 조항)을 만든다.
A32: 비트 4 | B32: 위기(7~9화): 주민 총회(Dona Conceição), 재판 승소, 프레임에서 Rafael의 말이 막힘.
A33: 비트 5 | B33: 절정(10~11화): 자르딘스 축하 만찬 중 부고, 손녀 Marina의 방문.
... A39: 언어 설계 | B39: B2~C1. 접속법 현재·과거, 수동태, 법률 문어체. 과거 장면은 격식 문어, 프레임 장면은 B1로 두어 톤을 대비. 발성: 또박또박, 중저음.
A40: 대화량 (화당 120턴) | B40: ="화당 "&턴_설계!$B$5&"턴 · 부 총 "&TEXT(턴_설계!D34,"#,##0")&"턴 · 화당 약 "&TEXT(턴_설계!F34,"#,##0")&"단어 · 낭독 약 "&TEXT(턴_설계!H34,"0.0")&"분 (평균 "&TEXT(턴_설계!E34,"0.0")&"단어/턴)" -> 화당 120턴 · 부 총 1,440턴 · 화당 약 1,367단어 · 낭독 약 10.5분 (평균 11.4단어/턴)
A41: Larissa 질문·Freire 카드 | B41: Larissa: petição·sentença·cláusula 등 법률 용어. 카드: 부동산 등기소(Cartório de Registro de Imóveis), 임대차법, 민사소송법(CPC)의 퇴거 절차.
A42: 다음 부 연결 | B42: 3부: 응급실에서 쓰러진 Rafael — 다음 금요일은 Camila의 이야기.
A44: 3부 | B44: A Médica — 의사 | 난이도 B2~C1 | 프레임: 금요일 밤. 과거: 약 4년 전, Hospital Municipal São Bartolomeu(가상) 응급실.
A45: 서사 기능 | B45: 인간의 생명과 공공 보건이라는 정서적 무게. Grupo Meridiano의 두 번째 얼굴(병원 위탁 운영 OSS)을 보여 주고, 폭염·고령 환자·서류 없는 이주민 환자 등 현안을 응급실에서 체감하게 한다.
A46: 로그라인 | B46: 응급의가 예산 삭감과 병원 위탁 운영 속에서 환자를 잃기 시작하고, 이름을 적어 두다가 내부 보고를 올리지만 징계로 돌아온다.
A47: 변화 (시작 → 끝) | B47: 시스템을 믿는 의사 → 이름 명단만 든 사직자.
A48: 핵심 갈등 | B48: 의료 윤리 vs 관리 효율 / 침묵하는 동료들
A49: 비트 1 | B49: 발단(1~3화): 금요일 프레임, 야간 당직(Rafael 진료), 폭염 환자 폭증.
A50: 비트 2 | B50: 전개(4~5화): 위탁 운영 발표(컨설턴트 Juliana 등장), 프레임에서 수첩 명단과 Dom Pedro의 부은 발목.
A51: 비트 3 | B51: 미드포인트(6화): '명단의 첫 번째' — 서류 없는 이주민 봉제 노동자가 병상 배정 지연으로 숨진다.
...

Sheet 화별목차_전체
A1: 전체 화별 목차 (1~13부, 156화)
A2: 현실 제도와 현안(ID는 '현안_배치' 시트)을 반영한 초안. 의석 수·결과는 가상 수치. 모든 화는 지문 없이 대화문으로만 진행한다.
A4: 부 | B4: 화 | C4: 서사 기능 | D4: 제목 (PT-BR) | E4: 한국어 | F4: 핵심 사건 | G4: 반영 제도·전문 영역 | H4: 주요 인물 | I4: 반영 현안 (ID) | J4: 턴 수
A5: 1 | B5: 1 | C5: 사건1 도입 | D5: Mais uma carta | E5: 또 한 통의 편지 | F5: 사무소 개소 1개월 후, 오후 다섯 시. 아직도 일하는 순서 하나 못 정한 채 매일 다투는 팀. Fátima가 두 번째로 찾아와 집주인의 새 임대료 인상 통지서를 보인다. Larissa는 여전히 Rafael에게 'o senhor'를 쓴다. Freire가 지나가며 «계약서에 적힌 지수를 읽어 보라»는 힌트만 던지고, 계약서가 없어 다음 날로 미뤄진다. | G5: 생활 법률 구어체, 반복되는 말다툼 (B1) | H5: Marta, Rafael, Camila, Bruno, Juliana, Larissa, Dom Pedro, Fátima, Freire | I5: E1 | J5: =턴_설계!$B$5 -> 120
A6: 1 | B6: 2 | C6: 사건1 해결 | D6: O reajuste que não sobe | E6: 오르지 않는 인상률 | F6: [사건1 해결] Fátima와 Larissa가 계약서를 가져온다. Freire의 카드 #1(임대차법·연 1회 조정 규정)로 계약서의 지수는 IPCA인데 집주인이 IGP-M 급등분을 들이댔다는 것을 확인하고, 기한 안에 반박 통지를 쓴다. 사무소의 첫 번째 규칙(가난한 이웃에겐 돈을 받지 않는다)이 확인된다. | G6: 임대차법(Lei 8.245/1991), 연 1회 조정(Lei 10.192/2001), IPCA vs IGP-M, 기한·통지 | H6: Rafael, Bruno, Juliana, Fátima, Freire, Larissa, Marta | I6: E1 | J6: =턴_설계!$B$5 -> 120
A7: 1 | B7: 3 | C7: 사건2 도입 | D7: Aviso das oito | E7: 여덟 시의 통지 | F7: [사건2 도입] 밤 여덟 시, 다음 날 아침 집행관(oficial de justiça)이 퇴거를 집행하러 온다는 급보. Zumbi가 주민을 조직하고 Edson이 이웃들을 모은다. 네 사람이 각자 서류·건강·숫자·동선을 맡아 밤새 준비하지만 승산은 불투명하다. | G7: 퇴거 집행 명령(mandado de despejo), 긴급 동원, 이웃 조직 | H7: Rafael, Camila, Bruno, Juliana, Zumbi, Edson, Larissa, Marta | I7: S1 | J7: =턴_설계!$B$5 -> 120
A8: 1 | B8: 4 | C8: 사건2 해결 | D8: O caminhão que não chegou | E8: 오지 않은 이삿짐 트럭 | F8: [사건2 해결] 집행 당일 아침. Rafael의 긴급 가처분(tutela de urgência) 신청, Camila의 취약계층(노인·아동) 진단서, Bruno의 금액 계산, Juliana의 동선 배치가 맞물려 집행이 연기되고 사건이 TJSP 토지분쟁 조정위원회로 넘어간다. Zumbi의 «Sem novidade no quilombo» 보고로 마무리된다. | G8: tutela de urgência(CPC 제300조), 취약계층 퇴거 조정(STF ADPF 828 이후 조정위원회), 집행관 대응 | H8: Rafael, Camila, Bruno, Juliana, Zumbi, Edson, Larissa, Marta | I8: S1 | J8: =턴_설계!$B$5 -> 120
A9: 1 | B9: 5 | C9: 사건3 도입 | D9: O estagiário da fábrica | E9: 공장의 인턴 | F9: [사건3 도입] 인턴(estagiário) 계약으로 풀타임 생산라인에 투입되고 임금까지 밀린 청년 Álvaro(가상)가 찾아온다. Juliana가 컨설팅 용어로 상황을 분석하려 하고 Larissa가 통역하듯 애쓰지만 Álvaro는 점점 지쳐 간다. | G9: 인턴법(Lei 11.788/2008) 위반, 무등록 고용(sem carteira assinada), 초과근무, 경영 용어의 벽 | H9: Juliana, Larissa, Bruno, Marta, Álvaro(가상) | I9: S1 | J9: =턴_설계!$B$5 -> 120
A10: 1 | B10: 6 | C10: 사건3 해결(폭발) | D10: Chega! | E10: 그만! | F10: [사건3 해결] 협상 자리에서 Juliana의 용어가 한 시간째 이어지자 Larissa가 폭발한다(1차 폭발). Camila·Zumbi·Marta·Freire의 고정 반응, Dom Pedro의 «Mentecapta… Pergunte.», Bruno의 «Deixa que eu traduzo.» 이후 쉬운 말로 다시 협상해 밀린 임금과 정식 고용 전환에 합의한다. | G10: 감정 표현, 전문 용어 → 쉬운 말, 임금 체불·고용 전환 합의 | H10: Larissa, Juliana, Bruno, Camila, Dom Pedro, Zumbi, Marta, Freire, Álvaro(가상) | I10: S1 | J10: =턴_설계!$B$5 -> 120
A11: 1 | B11: 7 | C11: 사건4 도입 | D11: A menina com febre | E11: 열이 나는 아이 | F11: [사건4 도입] 서류가 없는 이주민 가족이 동네 보건소(UBS)에서 '주소 증명과 SUS 카드가 없으면 안 된다'며 돌려보내졌다. Camila가 나서고 Isabel이 들러 «E como isso faz você se sentir?»를 처음 선보인다. 마침 들른 Machado는 Dom Pedro에게 원고를 놀림받다 «Não é ruim.»이라는 최고의 칭찬을 듣는다. 정작 진짜 아픈 아이 앞에서 Dom Pedro는 자기 무릎 타령을 멈춘다. | G11: SUS의 보편 접근권(헌법 제196조), 현장의 서류 요구, 증상 표현 | H11: Camila, Isabel, Dom Pedro, Machado, Larissa, Marta, 가족(가상) | I11: S2 | J11: =턴_설계!$B$5 -> 120
A12: 1 | B12: 8 | C12: 사건4 해결 | D12: Um cartão SUS para todos | E12: 모두를 위한 SUS 카드 | F12: [사건4 해결] Rafael과 Camila가 서류 없이도 SUS 카드(Cartão Nacional de Saúde)를 발급받는 경로를 찾아내 아이가 진료를 받는다. Dom Pedro가 평소와 달리 조용히 커피를 마신다. | G12: SUS 카드 발급, 이주민 보건 접근권(이민법 Lei 13.445/2017 제4조), 진료 의뢰 | H12: Camila, Rafael, Larissa, Marta, 가족(가상) | I12: S2 | J12: =턴_설계!$B$5 -> 120
A13: 1 | B13: 9 | C13: 사건5 도입 | D13: A viúva do quinto andar | E13: 5층의 미망인 | F13: [사건5 도입] '고수익 투자' 사기와 Pix 송금으로 저축을 잃은 노년의 이웃 Dona Cida(가상)가 찾아온다. Bruno가 장부를 살피는 동안, 양복 입은 낯선 남자 Sérgio가 나타나 은행 쪽 흐름을 봐 주겠다고 하면서도 자기 이야기는 하지 않는다. Dumont이 냄새를 맡고 기웃거린다. | G13: 투자 사기·금융 피라미드, Pix, 은행 계좌 기초 어휘 | H13: Bruno, Sérgio, Dumont, Larissa, Marta, Dona Cida(가상) | I13: E3 | J13: =턴_설계!$B$5 -> 120
A14: 1 | B14: 10 | C14: 사건5 해결 | D14: Siga o dinheiro | E14: 돈을 따라가라 | F14: [사건5 해결] Sérgio의 계좌 흐름 추적과 Bruno의 장부 대조로 사기 계좌를 찾고, Pix 특별 반환 절차(MED)로 돈 일부를 되찾는다. Sérgio는 설명 없이 떠나고, Bruno는 «Banco Atlântico»라는 이름에 말없이 굳는다. | G14: Pix 특별 반환 절차(MED, 중앙은행), 자금 흐름 추적, 계좌·송금 어휘 | H14: Bruno, Sérgio, Larissa, Marta, Dona Cida(가상) | I14: E3 | J14: =턴_설계!$B$5 -> 120
A15: 1 | B15: 11 | C15: 사건6 도입 | D15: Um papel de anos atrás | E15: 수년 전 서류 | F15: [사건6 도입] Fátima의 남편 Seu Jurandir(가상)가 수십 년 전 다른 건물에서 받은 낡은 퇴거 서류를 들고 온다. 당장 급한 사안은 아니지만 오래된 절차 하자가 보인다. Dumont이 취재 각도로 흥미를 보이며 «Preciso de duas fontes.» | G15: 오래된 서류 판독, 절차 하자 | H15: Rafael, Dumont, Larissa, Marta, Seu Jurandir(가상) | I15: E1 | J15: =턴_설계!$B$5 -> 120
A16: 1 | B16: 12 | C16: 사건6 해결(훅) | D16: A assinatura | E16: 서명 | F16: [사건6 해결·훅] 절차 하자를 바로잡아 오래된 기록을 정정하지만, 진짜 충격은 서류 맨 아래: Rafael의 옛 로펌 «Aguiar & Salgado»의 서명이다. Rafael이 얼어붙고 Marta가 «Senta aí, que eu trago alguma coisa.»로 분위기를 잇는다. 금요일에는 Rafael의 이야기가 시작된다. | G16: 서명·기록 정정, 이름 확인 | H16: Rafael, Marta, Larissa, Dom Pedro, Seu Jurandir(가상) | I16: E1 | J16: =턴_설계!$B$5 -> 120
A17: 2 | B17: 1 | C17: 발단 | D17: Sexta de histórias | E17: 금요일의 이야기 | F17: (프레임) Marta의 식탁에서 금요일마다 한 사람이 과거를 이야기하는 규칙이 시작된다. Larissa가 Rafael에게 왜 로펌을 그만뒀느냐고 묻고 Rafael은 «Vamos por partes.»로 시작한다. | G17: 격식체(o senhor)와 você의 대비, 과거 이야기 도입 | H17: Larissa, Rafael, Marta, Dom Pedro | I17: E1 | J17: =턴_설계!$B$5 -> 120
A18: 2 | B18: 2 | C18: 발단 | D18: Uma segunda-feira na Faria Lima | E18: 파리아 리마의 월요일 | F18: (과거) 승소율 100%의 파트너 후보 Rafael의 하루. 새벽 편의점 앞에서 신문을 사러 나온 Machado와 마주친다(부활 직후의 Machado는 '오늘 자 신문'에 집착한다). 상사 Salgado(가상)가 파트너 승진을 암시한다. | G18: 로펌 어휘: sócio, honorários, carteira de clientes | H18: Rafael, Machado, Salgado(가상) | J18: =턴_설계!$B$5 -> 120
A19: 2 | B19: 3 | C19: 발단 | D19: O cliente estrela | E19: VIP 고객 | F19: 대형 고객 Grupo Meridiano의 회장 Quintela(가상)를 소개받는다. 회의석에는 고객 측 컨설턴트 Juliana와 매각 은행 지점장 Sérgio가 있다. | G19: 인수합병 어휘: aquisição, carteira, cláusula | H19: Rafael, Juliana, Sérgio, Quintela(가상) | I19: E1 | J19: =턴_설계!$B$5 -> 120
A20: 2 | B20: 4 | C20: 전개 | D20: A carteira do Bixiga | E20: 비시가 자산 포트폴리오 | F20: 실사(due diligence). 포트폴리오에 Bixiga 건물 12채가 들어 있다. 감사인 Bruno가 «Isso não fecha.»를 흘리고, 헌책방(sebo)에서 등기 자료를 찾던 Rafael에게 Freire가 «Procure você.» | G20: 실사, 부동산 등기(Cartório de Registro de Imóveis, matrícula), 임차인 명부 | H20: Rafael, Bruno, Freire | I20: E1 | J20: =턴_설계!$B$5 -> 120
A21: 2 | B21: 5 | C21: 전개 | D21: Sexta: a rua da Marta | E21: 금요일: Marta의 거리 | F21: (프레임) 그 포트폴리오에 Marta의 옛 가게가 있던 건물이 들어 있었음이 밝혀진다. Larissa는 놀라 'o senhor'를 놓치고 Rafael은 잠시 침묵한다. | G21: 감정 표현, 놀람 | H21: Marta, Rafael, Larissa | I21: E1 | J21: =턴_설계!$B$5 -> 120
A22: 2 | B22: 6 | C22: 미드포인트 | D22: A cláusula | E22: 조항 | F22: 임차인을 비우는 가장 '깨끗한' 방법으로 Rafael이 «retomada para obras»(리모델링·재건축을 이유로 한 계약 해지) 조항을 설계한다. Juliana의 재무 모델이 이를 뒷받침한다. | G22: 임대 해지(denúncia), 공사 사유 회수(임대차법 제47조), 통지 요건 | H22: Rafael, Juliana, Salgado(가상) | I22: E1 | J22: =턴_설계!$B$5 -> 120
A23: 2 | B23: 7 | C23: 위기 | D23: A assembleia dos moradores | E23: 주민 총회 | F23: 세입자들이 총회를 연다. 노조 출신 Edson이 이끌고, 응급의 Camila가 공황을 일으킨 노인을 돌본다. Rafael은 78세 Dona Conceição(가상)를 만난다. | G23: 총회·발언·동의, 항의 표현 | H23: Rafael, Edson, Camila, Dona Conceição(가상) | I23: E1 | J23: =턴_설계!$B$5 -> 120
A24: 2 | B24: 8 | C24: 위기 | D24: O julgamento | E24: 재판 | F24: 심리(audiência)와 판결. Rafael이 승소한다. 취재하던 Dumont이 «O senhor está orgulhoso?»라고 묻는다. 감사인 Bruno는 고객의 장부를 보고 고개를 젓는다. | G24: 소송 어휘: petição inicial, audiência, sentença, custas | H24: Rafael, Dumont, Bruno, 판사(가상) | I24: E1·P3 | J24: =턴_설계!$B$5 -> 120
A25: 2 | B25: 9 | C25: 위기 | D25: Sexta: continua | E25: 금요일: 계속해 | F25: (프레임) Rafael이 말을 잇지 못하자 Dom Pedro가 «Quando eu reinava…»로 시간을 벌어 주고 Marta가 «Continua.»라고 한다. Larissa는 «E ela?»라고 묻는다. | G25: 위로·재촉 표현 | H25: Rafael, Dom Pedro, Marta, Larissa | J25: =턴_설계!$B$5 -> 120
A26: 2 | B26: 10 | C26: 절정 | D26: Um jantar nos Jardins | E26: 자르딘스의 저녁 | F26: 승소 축하 만찬. 파트너들이 건배하는 동안 Quintela가 다음 포트폴리오를 건넨다. Rafael의 휴대전화가 울린다. | G26: 고급 식당 표현, 건배·축하 | H26: Rafael, Salgado(가상), Quintela(가상), Bruno | J26: =턴_설계!$B$5 -> 120
A27: 2 | B27: 11 | C27: 절정 | D27: A neta de Dona Conceição | E27: Dona Conceição의 손녀 | F27: Dona Conceição가 퇴거 석 달 뒤 세상을 떠났다는 소식. 손녀 Marina(가상)가 사무실로 찾아와 조용히 묻는다: «O senhor ganhou?» | G27: 조의·항의, 문서 vs 사람 | H27: Rafael, Marina(가상) | I27: E1 | J27: =턴_설계!$B$5 -> 120
A28: 2 | B28: 12 | C28: 결말·훅 | D28: Sexta: a demissão | E28: 금요일: 사직 | F28: (프레임+과거) Rafael이 다음 포트폴리오 서명을 거부하고 사직서를 낸다. 짐 상자를 든 채 응급실 대기실에서 쓰러지고 Camila가 그를 진료한다. Larissa는 여전히 'o senhor'를 쓴다. | G28: 사직·거절 표현, 접속법 | H28: Rafael, Camila, Larissa, Marta | J28: =턴_설계!$B$5 -> 120
A29: 3 | B29: 1 | C29: 발단 | D29: Sexta: os nomes | E29: 금요일: 이름들 | F29: (프레임) Camila가 «Isso não é estatística, é uma pessoa.»라며 이야기를 시작한다. Dom Pedro가 계단을 오르내리다 숨을 고르는 것을 Camila가 흘끗 본다. | G29: 의학 어휘 도입 | H29: Camila, Larissa, Dom Pedro, Marta | J29: =턴_설계!$B$5 -> 120
A30: 3 | B30: 2 | C30: 발단 | D30: Plantão noturno | E30: 야간 당직 | F30: (과거) São Bartolomeu 응급실(pronto-socorro)의 야간 당직. 위험도 분류(맨체스터 프로토콜), 병상, 간호사 Rosângela(가상)와의 호흡. 가슴 통증으로 실려 온 Rafael을 진료한다. | G30: classificação de risco, sinais vitais, maca, box | H30: Camila, Rosângela(가상), Rafael | J30: =턴_설계!$B$5 -> 120
A31: 3 | B31: 3 | C31: 발단 | D31: A onda de calor | E31: 폭염 | F31: 기록적 폭염에 고령 환자가 몰려 응급실이 넘친다. 산소·수액·얼음. Camila는 밤새 환자 이름을 외운다. | G31: 열사병(insolação), 탈수, 고령 환자 | H31: Camila, Rosângela(가상) | I31: S4·S3 | J31: =턴_설계!$B$5 -> 120
A32: 3 | B32: 4 | C32: 전개 | D32: Um contrato que ninguém lê | E32: 아무도 읽지 않는 계약 | F32: 시가 병원 운영을 사회조직(OSS) Meridiano Saúde에 위탁한다고 발표한다. 원장 회의에서 컨설턴트 Juliana가 '효율' 발표를 한다. | G32: 사회조직 위탁 운영(OSS, Lei 9.637/1998), 관리계약(contrato de gestão), 예산 | H32: Camila, 원장(가상), Juliana | I32: S3 | J32: =턴_설계!$B$5 -> 120
A33: 3 | B33: 5 | C33: 전개 | D33: Sexta: a lista | E33: 금요일: 명단 | F33: (프레임) Larissa가 Camila의 수첩 명단을 본다. Camila는 «Já vi coisa pior numa terça qualquer.»로 넘긴다. Dom Pedro는 발목이 부었냐는 물음에 «É o sapato.» | G33: 명단·숫자 읽기 | H33: Camila, Larissa, Dom Pedro | J33: =턴_설계!$B$5 -> 120
A34: 3 | B34: 6 | C34: 미드포인트 | D34: A primeira da lista | E34: 명단의 첫 번째 | F34: 서류 없는 20대 볼리비아 출신 봉제 노동자가 패혈증으로 실려 오지만 병상 배정(regulação)이 아홉 시간 지연되어 숨진다. 위탁 업체가 '비용 검토' 중이었다. Camila가 수첩에 첫 이름을 쓴다. | G34: 패혈증(sepse), 병상 배정 규제(regulação de vagas), SUS는 서류와 무관한 보편 접근권 | H34: Camila, Rosângela(가상), 원장(가상) | I34: S2·S3 | J34: =턴_설계!$B$5 -> 120
A35: 3 | B35: 7 | C35: 위기 | D35: Os números do diretor | E35: 원장의 숫자 | F35: 원장이 '대기 시간 개선' 통계를 발표한다. 위탁 업체의 재무를 자문하는 Bruno가 배석한다. Camila가 내부 사망 사례 보고서를 제출한다. | G35: 통계 읽기, 보고서 어휘 | H35: Camila, 원장(가상), Bruno | I35: P3 | J35: =턴_설계!$B$5 -> 120
A36: 3 | B36: 8 | C36: 위기 | D36: A sindicância | E36: 징계 조사 | F36: 보고서 유출 의혹으로 징계 조사(sindicância)가 시작된다. 취재하는 Dumont에게 Camila가 «Isso não sai daqui.»라는 말을 듣는다. | G36: 징계 조사·행정 징계 절차(PAD), 의료윤리(CRM), 비밀유지 | H36: Camila, Dumont, 원장(가상) | I36: P3 | J36: =턴_설계!$B$5 -> 120
A37: 3 | B37: 9 | C37: 위기 | D37: Sexta: e como isso faz você se sentir? | E37: 금요일: 기분이 어때요? | F37: (프레임) Isabel이 Camila에게 감정을 되묻는다. Camila는 «Primeiro, respira.»로 받아친다. Larissa가 Isabel의 화법을 흉내 낸다. | G37: 감정 표현, 되받기 화법 | H37: Camila, Isabel, Larissa | J37: =턴_설계!$B$5 -> 120
A38: 3 | B38: 10 | C38: 절정 | D38: Uma noite sem leitos | E38: 병상 없는 밤 | F38: 버스 사고와 폭염이 겹친 밤. 병상이 없어 복도까지 환자가 찬다. Camila가 즉흥으로 일곱 명을 살리고 한 명을 잃는다. | G38: 다수 사상자(múltiplas vítimas), 우선순위, 명령형 | H38: Camila, Rosângela(가상) | I38: S4 | J38: =턴_설계!$B$5 -> 120
A39: 3 | B39: 11 | C39: 절정 | D39: A demissão da doutora | E39: 의사의 사직 | F39: 징계 통보와 마지막 근무. 수첩을 덮고 사직서를 낸다. Rosângela가 «Doutora, não vai embora.» | G39: 사직서, 작별 | H39: Camila, Rosângela(가상), 원장(가상) | J39: =턴_설계!$B$5 -> 120
A40: 3 | B40: 12 | C40: 결말·훅 | D40: Sexta: uma assinatura | E40: 금요일: 한 사람의 서명 | F40: (프레임) Camila가 «O parecer da auditoria do contrato tinha uma assinatura.»라고 말한다. Bruno가 조용히 «Minha vez.» | G40: 서명·책임 표현 | H40: Camila, Bruno, Larissa, Dom Pedro | J40: =턴_설계!$B$5 -> 120
A41: 4 | B41: 1 | C41: 발단 | D41: Sexta: eu assinei | E41: 금요일: 내가 서명했다 | F41: (프레임) Bruno가 «Deixa eu ver os papéis.»를 습관처럼 하다가 «Eu assinei.»라고 시작한다. Larissa가 숫자를 못 읽어 질문한다. | G41: 회계 어휘 도입 | H41: Bruno, Larissa, Camila, Dom Pedro | J41: =턴_설계!$B$5 -> 120
...

Sheet 복선_회수
A1: 복선 설치와 회수 (Setup → Payoff)
A2: 설치 부와 회수 부의 간격(부 수)은 수식으로 계산됩니다. 간격이 클수록 오래 기다린 복선이라 낭독 시 기억에 남습니다.
A4: No | B4: 복선(설치) | C4: 유형 | D4: 설치 부 | E4: 설치 위치 | F4: 회수 부 | G4: 간격(부) | H4: 회수 위치와 효과 | I4: 관련 인물
A5: 1 | B5: Dom Pedro의 «Este será o meu último inverno» 반복 | C5: 대사 | D5: 1 | E5: 1부 1화 | F5: 11 | G5: =F5-D5 -> 10 | H5: 11부 12화 — 양치기 소년 개그가 진짜 죽음이 되는 낙차 | I5: Dom Pedro
A6: 2 | B6: Dom Pedro가 Larissa에게 우산(garoa용)을 물려준다고 말한다 | C6: 소품 | D6: 1 | E6: 1부 1화 | F6: 13 | G6: =F6-D6 -> 12 | H6: 13부 2화 — 유언장에서 우산이 진짜 유산으로 돌아옴 | I6: Dom Pedro, Larissa
A7: 3 | B7: Dom Pedro의 부은 발목·숨참 | C7: 설정 | D7: 3 | E7: 3부 1·5화 | F7: 11 | G7: =F7-D7 -> 8 | H7: 11부 6·11~12화 — Camila가 진단을 알고도 침묵한 이유가 드러남 | I7: Camila, Dom Pedro
A8: 4 | B8: Dom Pedro의 최고 칭찬 «Não é ruim.» | C8: 대사 | D8: 1 | E8: 1부 7화(Machado에게 1회) | F8: 11 | G8: =F8-D8 -> 10 | H8: 11부 12화 — Larissa에게 처음이자 마지막 칭찬, 브뤼셀 승리 직후라 더 무겁다 | I8: Dom Pedro, Larissa
A9: 5 | B9: Larissa의 1차 폭발 | C9: 사건 | D9: 1 | E9: 1부 6화 | F9: 9 | G9: =F9-D9 -> 8 | H9: 9부 6화 — 몰라서 화내던 Larissa → 알아서 화내는 Larissa | I9: Larissa
A10: 6 | B10: Larissa의 'o senhor' (Dom Pedro에게) | C10: 호칭 | D10: 1 | E10: 1부 1화 | F10: 12 | G10: =F10-D10 -> 11 | H10: 12부 1화 — 조사에서 처음 'você' — 호칭 전환이 곧 애도 | I10: Larissa, Dom Pedro
A11: 7 | B11: Freire의 카드 #1과 «Procure você.» | C11: 대사 | D11: 1 | E11: 1부 2화 | F11: 13 | G11: =F11-D11 -> 12 | H11: 13부 10화 — 끝까지 결론을 말하지 않던 그가 처음 답을 말함 | I11: Freire, Larissa
A12: 8 | B12: Rafael의 조항 «retomada para obras» | C12: 사건 | D12: 2 | E12: 2부 6화 | F12: 11 | G12: =F12-D12 -> 9 | H12: 11부 3화 — 자기가 만든 조항을 국정에서 폐지 | I12: Rafael
A13: 9 | B13: Bruno의 «Isso não fecha» | C13: 대사 | D13: 2 | E13: 2부 4화 | F13: 4 | G13: =F13-D13 -> 2 | H13: 4부 4화 — 감사인의 눈이 처음 이상을 발견한 순간의 원점 | I13: Bruno
A14: 10 | B14: Bruno의 복사본 USB | C14: 소품 | D14: 4 | E14: 4부 10화 | F14: 7 | G14: =F14-D14 -> 3 | H14: 7부 5~6화 — 서명의 죄가 고소의 증거로 바뀜 | I14: Bruno, Rafael
A15: 11 | B15: Bruno의 «다시는 서명하지 않는다» | C15: 인물 | D15: 4 | E15: 4부 11화 | F15: 12 | G15: =F15-D15 -> 8 | H15: 12부 3화 — «Eu só assino o que verifiquei» — 브뤼셀 2차 협상에서 숫자 서명의 회수 | I15: Bruno
A16: 12 | B16: Juliana의 C47 셀 | C16: 소품 | D16: 5 | E16: 5부 6화 | F16: 11 | G16: =F16-D16 -> 6 | H16: 11부 6화 — 사람을 지우던 셀이 해고 없는 통합 모델로 | I16: Juliana
... A32: 28 | B32: Dumont의 «Preciso de duas fontes» | C32: 대사 | D32: 1 | E32: 1부 11화 | F32: 9 | G32: =F32-D32 -> 8 | H32: 9부 8화 — 폭로 기사에서 두 개의 출처를 갖추는 장면 | I32: Dumont, Freire
B34: 평균 간격(부) | G34: =AVERAGE(G5:G32) -> 7.3928571
B35: 가장 긴 복선(부) | G35: =MAX(G5:G32) -> 12
B36: 복선 개수 | G36: =COUNTA(B5:B32) -> 28

Sheet 현안_배치
A1: 브라질 현안 18개 배치표
A2: 현재 브라질의 쟁점을 이야기 곳곳에 녹이는 계획. 현실의 정당·정치인·참사 희생자는 특정하지 않고 가상 설정으로 각색하며, 제도와 통계만 현실 기준으로 쓴다.
A4: ID | B4: 분야 | C4: 현안 | D4: 포르투갈어 키워드 | E4: 이야기 속 가상 설정 | F4: 주요 배치 (전용 화) | G4: 곁가지 배치 | H4: 주요 인물 | I4: 권한 소재 | J4: 관련 제도·법 | K4: 낭독 어휘 | L4: 균형·민감도 유의 | M4: 현실 기준값·확인
A5: P1 | B5: 정치 | C5: 연립 대통령제와 의회 거래(Centrão) | D5: presidencialismo de coalizão, Centrão, base aliada, cargos, emendas | E5: 대통령은 직선이지만 의회 과반은 수십 개 정당으로 쪼개져 있다. 법안마다 장관직·예산 수정(emendas)을 주고받는 거래 비용이 든다. Casa Comum도 하원 48석으로 중도 연합(PCN)과 지역정당을 끌어안아야 한다. | F5: 9부 5화 불편한 동맹, 10부 11화 정권 인수·연립 협상, 12부 7화 합쳐지지 않는 탄핵 | G5: 8부 6화(왜 새 정당인가: 거래 정치 피로), 13부 | H5: Juliana, Rafael, Edson | I5: 연방의회·시의회 | J5: 헌법 제84·85·86조, 예산 수정 규정(헌법 제166조), 정당 간 합의 | K5: base aliada, governabilidade, fisiologismo, emenda parlamentar, bancada | L5: 특정 실존 정당·인물을 비난하는 대사 금지. 가상 정당(UCN·PPS·PCN·HU·TA·TB)으로만. | M5: 현실의 하원은 20개 안팎의 정당으로 나뉘어 있다(반영 전 확인). 이야기에는 실제 정당명을 쓰지 않음
A6: P2 | B6: 정치 | C6: 연방 갈등: 주 정부 부채 재협상·재정 분권 | D6: pacto federativo, dívida dos estados, renegociação, ICMS, compensação | E6: 지역정당 연합 TB가 지지의 대가로 자기 주의 연방 부채 재협상(사실상 탕감)과 조세개혁 보상 확대를 요구한다. 결선 지지와 탄핵 표결이 여기에 걸린다. | F6: 10부 11화 정권 인수·연립 협상 | G6: 10부 3화(TV 토론 공격), 12부 7화(탄핵 표결에서 TB의 기권) | H6: Rafael, Dom Pedro, Edson, Juliana | I6: 연방·주·연방상원 | J6: 헌법 제52조(상원의 부채 한도 권한), 주 부채 재협상 프로그램(LC 212/2025, 확인), 조세개혁(헌법 개정 132/2023) | K6: dívida, renegociação, compensação, repartição de receitas | L6: 가장 민감. 부채가 많은 주와 성실히 갚은 주의 논거를 각 인물이 나눠 말하게 하고 결론은 열어 둔다(Rafael은 형평 우려, Edson은 주민 복지, Juliana는 현실 협상). | M6: 주 부채 재협상 제도의 최신 상황은 반영 전 확인
A7: P3 | B7: 정치 | C7: 사법 지연·사법–정치 충돌과 공권력 남용 | D7: morosidade, STF, decisão monocrática, abuso de autoridade, violência policial | E7: 연방대법원(STF)과 의회가 권한을 두고 부딪히는 사이 스캔들 수사는 표류하고, 사무소의 고발은 법원에서 지연된다. 사무소를 향한 보복에는 경찰의 과잉 단속도 섞여 있다. | F7: 7부(공익소송·기소 수리·보복), 9부 9화 고발장 | G7: 2부 8화(재판), 3부(징계·위탁), 4부 7화, 10부 11화(연립 조건), 12부 7화(교착) | H7: Rafael, Dumont, Freire | I7: 사법부·연방의회·주 경찰 | J7: 헌법 제5조, 직권남용법(Lei 13.869/2019), 연방대법원 권한(헌법 제102조) | K7: morosidade, prescrição, foro privilegiado, abuso de autoridade | L7: 여야 모두가 사법부를 압박한다는 비판을 각각 담는다. 실제 재판 결과를 단정하지 않는다. | M7: STF 권한 논쟁(단독 결정 제한 개헌안 등)의 최신 상황 확인
A8: E1 | B8: 경제 | C8: 주거난: 도심 공실·강제퇴거·단기 임대 | D8: moradia, despejo, ocupação, aluguel, Airbnb, gentrificação | E8: 월세가 최저임금보다 빨리 오르고, 도심에는 빈 건물과 점거(ocupação)가, 옛 동네에는 단기 임대용 신축이 늘어난다. 소규모 임대인의 입장(Marta의 친구)도 대사에 넣는다. | F8: 2부 6화(조항 설계), 6부 1·3·8·10화(Brás), 9부 6화(임대료 보조 삭감·용도지역 조항), 11부 2·3화 | G8: 1부 1·2화(Fátima), 8부 1·9화, 13부 | H8: Marta, Larissa, Bruno, Rafael | I8: 시(도시계획·용도지역), 연방(임대차법·주택 재원), 주(주택공사) | J8: 임대차법(Lei 8.245/1991), 도시법(Lei 10.257/2001), 주거 지원(Lei 14.620/2023), 퇴거 조정(ADPF 828) | K8: aluguel, despejo, ocupação, auxílio-aluguel, pequeno proprietário | L8: 임차인만 피해자로 그리지 않는다. 소규모 임대인·대형 보유자·점거 운동을 구분해서 말한다. | M8: 단기 임대 규제는 시·콘도미니엄 단위로 제각각(확인)
A9: E2 | B9: 경제 | C9: 비공식 경제·영세 사업자와 저생산성 | D9: informalidade, MEI, microempresa, produtividade, crédito | E9: Juliana가 컨설팅한 규모의 경제 없는 영세 제조업체들: 신용 접근도, 정식 고용도 어려웠던 과거. 11부에서 영세 사업자 통합·기술 전환 사업을 설계한다. | F9: 5부 3화 Tavares 공방 | G9: 8부 9화(골목 상권), 11부 6화, 12부 9화 | H9: Juliana, Marta, Edson | I9: 연방·주 | J9: 개인 소사업자 제도(MEI, LC 123/2006), 단순과세(Simples Nacional) | K9: informalidade, formalizar, produtividade, crédito, escalar | L9: '영세 사업자가 문제'라는 낙인 대신 구조 문제로 설명한다. | M9: 비공식 고용률 통계는 반영 전 확인(IBGE)
A10: E3 | B10: 경제 | C10: 공공부채·재정규칙과 고금리 | D10: dívida pública, arcabouço fiscal, meta de resultado primário, Selic, previdência | E10: 재정규칙의 지출 상한과 높은 기준금리 사이에서 연금·보건 지출이 늘어난다. Bruno가 숫자로 설명하고 Larissa가 되묻는다. | F10: 11부 8화(초고소득 과세), 12부 11·12화(예산안) | G10: 12부 9화 | H10: Bruno, Dom Pedro(메모), Sérgio | I10: 연방·중앙은행 | J10: 재정규칙(LC 200/2023), 재정책임법(LC 101/2000), 예산(헌법 제165~166조) | K10: dívida, déficit, meta fiscal, juros, sustentabilidade | L10: 긴축 vs 확대 양쪽 논거를 모두 숫자로 제시한다. | M10: 일반정부 총부채 GDP 대비 약 78~80%, 기준금리 두 자릿수(중앙은행, 반영 전 확인)
A11: S1 | B11: 사회 | C11: 청년 고용 불안: 비공식·인턴 착취·PJ화 | D11: estágio, informalidade, pejotização, nem-nem, salário mínimo | E11: 인턴 계약과 앱 노동, PJ 계약으로 청년의 자립이 늦어진다. Larissa가 그 당사자이자 질문자다. | F11: 11부 6화, 12부 4·6화 | G11: 1부(Larissa·Álvaro), 5부(Juliana의 인력 감축), 8부, 10부 3화 | H11: Larissa, Edson, Juliana | I11: 연방(노동법)·사회적 대화 | J11: 인턴법(Lei 11.788/2008), 노동법(CLT), 청년 견습(Lei 10.097/2000) | K11: estágio, carteira assinada, bico, precariedade, nem-nem | L11: 청년 vs 기성세대 구도로 몰지 않는다(Edson도 Dom Pedro도 청년의 편에서 돕는다). | M11: 18~24세 실업률은 전체의 약 2배(IBGE PNAD Contínua, 반영 전 확인)
A12: S2 | B12: 사회 | C12: 이주민·난민 수용과 노동 착취 | D12: imigrante, refugiado, acolhida, interiorização, trabalho análogo à escravidão | E12: Brás의 봉제 공장에는 서류 없는 볼리비아·파라과이 출신 노동자가, 북부 국경에는 베네수엘라 난민이 몰린다. 쉼터 과부하와 주 간 떠넘기기, 봉제 공장의 노예 노동 유사 조건. | F12: 6부 8·9화(퇴거 저지·서류 없는 이웃), 7부 4화(체류 허가·노동 착취), 11부 5화 분담 | G12: 1부 7~8화, 3부 6화(서류 없는 환자), 8부(투표권 없는 이웃), 10부 3화, 12부 | H12: Marta, Camila, Rafael, Edson, Isabel | I12: 연방(이민·국경), 주·시(쉼터·아동 보호) | J12: 이민법(Lei 13.445/2017), 난민법(Lei 9.474/1997), 형법 제149조(노예 노동 유사 조건) | K12: autorização de residência, refúgio, acolhida, oficina de costura | L12: 반이민 여론(HU)과 수용 부담 지역의 실제 어려움을 함께 담고, 이주민을 배경이 아닌 화자로 세운다. | M12: 국경 수용·분산 정책의 현재 규모 확인
A13: S3 | B13: 사회 | C13: 고령화와 지역 의료 격차 | D13: envelhecimento, SUS, fila de espera, vazio assistencial, Mais Médicos | E13: 상파울루 외곽 보건소가 문을 닫고 시는 병원 위탁을 늘린다(9부). Zumbi가 캠프를 이끌며 지나가는 내륙·북동부 마을에는 의사가 없고, 일자리·의료·연금 문제가 되풀이된다(10부). | F13: 9부 7화 시의회의 보건 | G13: 3부(응급실 고령 환자), 10부 2화(의사 없는 마을), 11부 4화, 12부 | H13: Zumbi, Camila, Larissa | I13: 시·주·연방(SUS 3자 분담) | J13: SUS 기본법(Lei 8.080/1990), 의사 파견(Lei 12.871/2013), 노인법(Lei 10.741/2003) | K13: envelhecimento, fila, posto de saúde, médico de família | L13: '외딴 마을'을 동정하지 않고 마을 사람들이 직접 말하게 한다. | M13: 인구·고령화 통계는 반영 전 확인(IBGE)
A14: S4 | B14: 사회 | C14: 폭염·가뭄과 에너지 전환 부담 | D14: onda de calor, seca, estiagem, crise hídrica, queimadas, transição energética | E14: 폭염에 응급실이 넘치고(3부), 저수지가 마른 마을을 지나며(10부), 산불 연기가 도시를 덮는다. 초고소득 과세 재원을 전환 비용에 쓸지 논쟁한다(11부). | F14: 3부 3·10화(폭염 응급실) | G14: 10부 2화, 11부 4·8·11화, 12부 | H14: Camila, Zumbi, Bruno | I14: 연방·주·유역위원회 | J14: 기후변화 국가정책(Lei 12.187/2009), 수자원법(Lei 9.433/1997) | K14: seca, onda de calor, INMET, reservatório, transição energética | L14: 기후를 정치적 구호로 쓰지 않고 현장 사건으로 보여 준다. | M14: 최신 가뭄·폭염 통계 확인(INMET·Cemaden)
A15: N1 | B15: 재난 | C15: 대홍수와 방재 체계 | D15: enchente, chuva extrema, alerta, Defesa Civil, calamidade pública, desabrigados | E15: 남부에 가상의 폭우·대홍수가 덮친다. 경보 지연, 주–연방 책임 공방, 공공재난사태 인정, 군 투입, 이재민 쉼터와 복구 재원. | F15: 12부 8화 As águas | G15: 13부(복구 결산) | H15: Zumbi, Camila, Rafael, Dumont, Machado | I15: 시·주(1차 대응), 연방(재난 인정·군·특별 예산) | J15: 국가 민방위 정책(Lei 12.608/2012), 특별 예산(헌법 제167조 3항), 휴대전화 긴급 경보 | K15: Defesa Civil, alerta, calamidade pública, desabrigados, reconstrução | L15: 실제 참사와 희생자를 연상시키므로 추모의 톤을 지키고, 특정 정치인 비난 없이 제도의 공백을 보여 준다. | M15: 2024년 남부 대홍수 이후 제도 변화(부채 유예 등)는 반영 전 확인
... A22: N8 | B22: 사회 | C22: 청년 정신건강 위기와 온라인 도박 | D22: saúde mental, ansiedade, fila, CAPS, bets, endividamento | E22: 청년 정신건강 상담 대기가 몇 달씩 밀리고, 온라인 도박(bets) 빚이 불안을 키운다. CVV 자원봉사자 Isabel이 현장에서, Larissa가 자신의 불안을 처음 인정하며 함께 부딪힌다. | F22: 12부 6화 As filas de espera | G22: 1부(Larissa의 폭발과 연결 가능, 곁가지) | H22: Isabel, Larissa, Camila | I22: 시(CAPS)·연방(재원·도박 규제) | J22: 정신보건법(Lei 10.216/2001), 정신보건 네트워크(RAPS), 온라인 도박 규제법(Lei 14.790/2023) | K22: saúde mental, ansiedade, terapia, fila de espera, aposta | L22: 청년 정신건강을 극적 소재로만 소비하지 않는다. 낙인 없이, 도움을 구하는 것이 자연스럽다는 톤으로. | M22: 온라인 도박 규제 이후 통계는 반영 전 확인
A24: 현실 기준값 (브라질판 전환 시 재확인 필요 — 수치는 반영 전 최신 통계로 교체)
A25: No | B25: 구분 | C25: 항목 | D25: 값 | E25: 출처·비고
A26: 1 | B26: 경제 | C26: 일반정부 총부채 / GDP | D26: 약 78~80% (반영 전 확인) | E26: 브라질 중앙은행(BCB) 재정 통계. 스페인판의 약 100%와 달리 비율은 낮지만 금리가 높아 이자 부담이 크다.
A27: 2 | B27: 사회 | C27: 18~24세 실업률 | D27: 전체 실업률의 약 2배 (반영 전 확인) | E27: IBGE 연속 가계조사(PNAD Contínua). 비공식 고용 비중도 함께 확인.
A28: 3 | B28: 정치 | C28: 정부 형태 | D28: 대통령제 + 다당 연립(연립 대통령제) | E28: 이야기에는 실존 정당·인물을 쓰지 않는다. 표현은 '여소야대'가 아니라 '연립 정부의 과반 관리'.
A29: 4 | B29: 확인 필요 | C29: 변동이 잦은 항목 | D29: 주 부채 재협상, 앱 노동 법안, Mercosul–EU 비준, EUDR 시행 일정, 초고소득 과세법, 의원 예산 투명성 규정 | E29: 교재에 넣기 직전 최신 상태를 확인한다.

Sheet 현안_분포
A1: 현안 분포표 (부 × 현안)
A2: ● = 그 화의 주된 사건(전용 화), ○ = 곁가지(대사·서브플롯). 기호를 바꾸면 아래 집계가 자동 갱신됩니다.
A4: ID | B4: 현안 | C4: 1부 | D4: 2부 | E4: 3부 | F4: 4부 | G4: 5부 | H4: 6부 | I4: 7부 | J4: 8부 | K4: 9부 | L4: 10부 | M4: 11부 | N4: 12부 | O4: 13부 | P4: ● 수 | Q4: ○ 수
A5: P1 | B5: 연립 대통령제·의회 거래 | I5: ○ | J5: ○ | N5: ● | O5: ○ | P5: =COUNTIF(C5:O5,"●") -> 1 | Q5: =COUNTIF(C5:O5,"○") -> 3
A6: P2 | B6: 연방 갈등·주 부채 재협상 | N6: ● | O6: ○ | P6: =COUNTIF(C6:O6,"●") -> 1 | Q6: =COUNTIF(C6:O6,"○") -> 1
A7: P3 | B7: 사법 지연·공권력 남용 | D7: ○ | E7: ○ | F7: ○ | I7: ● | K7: ● | N7: ○ | P7: =COUNTIF(C7:O7,"●") -> 2 | Q7: =COUNTIF(C7:O7,"○") -> 4
A8: E1 | B8: 주거난·퇴거·단기 임대 | C8: ○ | D8: ● | H8: ● | I8: ○ | J8: ○ | M8: ● | O8: ○ | P8: =COUNTIF(C8:O8,"●") -> 3 | Q8: =COUNTIF(C8:O8,"○") -> 4
A9: E2 | B9: 비공식 경제·영세 사업자 | C9: ○ | G9: ● | J9: ○ | N9: ○ | O9: ○ | P9: =COUNTIF(C9:O9,"●") -> 1 | Q9: =COUNTIF(C9:O9,"○") -> 4
A10: E3 | B10: 부채·재정규칙·고금리 | M10: ● | N10: ● | O10: ○ | P10: =COUNTIF(C10:O10,"●") -> 2 | Q10: =COUNTIF(C10:O10,"○") -> 1
A11: S1 | B11: 청년 고용 불안 | C11: ○ | G11: ○ | H11: ○ | I11: ○ | J11: ○ | O11: ● | P11: =COUNTIF(C11:O11,"●") -> 1 | Q11: =COUNTIF(C11:O11,"○") -> 5
A12: S2 | B12: 이주민·난민·노동 착취 | C12: ○ | E12: ○ | H12: ● | I12: ● | J12: ○ | M12: ● | P12: =COUNTIF(C12:O12,"●") -> 3 | Q12: =COUNTIF(C12:O12,"○") -> 3
A13: S3 | B13: 고령화·지역 의료 격차 | E13: ○ | K13: ● | O13: ○ | P13: =COUNTIF(C13:O13,"●") -> 1 | Q13: =COUNTIF(C13:O13,"○") -> 2
A14: S4 | B14: 폭염·가뭄·에너지 전환 | E14: ● | N14: ○ | O14: ○ | P14: =COUNTIF(C14:O14,"●") -> 1 | Q14: =COUNTIF(C14:O14,"○") -> 2
A15: N1 | B15: 대홍수·방재 | N15: ● | O15: ○ | P15: =COUNTIF(C15:O15,"●") -> 1 | Q15: =COUNTIF(C15:O15,"○") -> 1
A16: N2 | B16: 의원 예산 불투명 집행 | K16: ● | O16: ○ | P16: =COUNTIF(C16:O16,"●") -> 1 | Q16: =COUNTIF(C16:O16,"○") -> 1
A17: N3 | B17: Mercosul–EU·관세 | M17: ● | N17: ○ | O17: ○ | P17: =COUNTIF(C17:O17,"●") -> 1 | Q17: =COUNTIF(C17:O17,"○") -> 2
A18: N4 | B18: 젠더 폭력·부모소외법 | I18: ● | J18: ○ | P18: =COUNTIF(C18:O18,"●") -> 1 | Q18: =COUNTIF(C18:O18,"○") -> 1
A19: N5 | B19: 녹색 대 녹색(풍력단지) | L19: ● | M19: ○ | N19: ○ | P19: =COUNTIF(C19:O19,"●") -> 1 | Q19: =COUNTIF(C19:O19,"○") -> 2
A20: N6 | B20: 앱 노동 | N20: ● | P20: =COUNTIF(C20:O20,"●") -> 1 | Q20: =COUNTIF(C20:O20,"○") -> 0
A21: N7 | B21: 정보기관 사찰 스캔들 | N21: ● | P21: =COUNTIF(C21:O21,"●") -> 1 | Q21: =COUNTIF(C21:O21,"○") -> 0
A22: N8 | B22: 청년 정신건강·온라인 도박 | N22: ● | P22: =COUNTIF(C22:O22,"●") -> 1 | Q22: =COUNTIF(C22:O22,"○") -> 0
B23: 부별 ● 수 | C23: =COUNTIF(C5:C22,"●") -> 0 | D23: =COUNTIF(D5:D22,"●") -> 1 | E23: =COUNTIF(E5:E22,"●") -> 1 | F23: =COUNTIF(F5:F22,"●") -> 0 | G23: =COUNTIF(G5:G22,"●") -> 1 | H23: =COUNTIF(H5:H22,"●") -> 2 | I23: =COUNTIF(I5:I22,"●") -> 3 | J23: =COUNTIF(J5:J22,"●") -> 0 | ... O23: =COUNTIF(O5:O22,"●") -> 1 | P23: =SUM(P5:P22) -> 24
B24: 부별 ○ 수 | C24: =COUNTIF(C5:C22,"○") -> 4 | D24: =COUNTIF(D5:D22,"○") -> 1 | E24: =COUNTIF(E5:E22,"○") -> 3 | F24: =COUNTIF(F5:F22,"○") -> 1 | G24: =COUNTIF(G5:G22,"○") -> 1 | H24: =COUNTIF(H5:H22,"○") -> 1 | I24: =COUNTIF(I5:I22,"○") -> 3 | J24: =COUNTIF(J5:J22,"○") -> 6 | ... O24: =COUNTIF(O5:O22,"○") -> 10 | Q24: =SUM(Q5:Q22) -> 36
A26: 읽는 법: 1~5부는 곁가지 중심이라 B1~B2 난이도를 지키고, 8·9·11·12부에서 전용 화가 몰린다. 화당 전용 현안은 1개(+곁가지 1~2개)로 제한해 낭독 분량을 지킨다. N6~N8은 12부의 신규 현안으로 각 1개 전용 화를 받는다.
A27: 현안 ID와 설명은 '현안_배치' 시트, 화별 반영은 '화별목차_전체'의 '반영 현안' 열을 참고.

Sheet 정치제도
A1: 현실 정치 제도 기준표 (브라질)
A2: 8~13부에 반영한 실제 제도. 정당·정치인은 전부 가상이며 실존 정치인의 대사는 쓰지 않는다. 확인 상태가 '기획 시점 지식'인 항목은 교재 반영 전 Planalto 법령 사이트·선거법원(TSE) 자료로 확인한다.
A4: 영역 | B4: 제도·규칙 | C4: 핵심 내용 | D4: 근거 | E4: 이야기 반영 | F4: 낭독 어휘 | G4: 확인 상태
A5: 정당·선거 | B5: 정당 창당 | C5: 창립자들이 창립 문서와 정관을 민사 등기소(브라질리아)에 등록해 법인격을 얻은 뒤, 2년 안에 직전 하원선거 유효표의 0.5% 이상에 해당하는 비당원 유권자 지지 서명을 9개 주 이상(각 주 유권자 0.1% 이상)에서 모아 선거법원(TSE)에 등록해야 선거에 나갈 수 있다. | D5: 정당법(Lei 9.096/1995) 제7~9조, TSE 정당 등록 결의 | E5: 8부 5화 | F5: ata de fundação, estatuto, apoiamento, registro no TSE | G5: 기획 시점 지식 — Planalto 현행본 확인 필요
A6: 정당·선거 | B6: 정당 자율과 내부 운영 | C6: 정당은 내부 조직·운영을 자율로 정하되, 정관에 당원 규율과 충실 의무를 둔다. 전국적 성격을 가져야 한다. | D6: 헌법 제17조 | E6: 8부 6화 | F6: autonomia partidária, filiado, fidelidade partidária | G6: 기획 시점 지식 — Planalto 현행본 확인 필요
