Workbook

Sheet 개요
A1: Madrid 스페인어 낭독 교재 — 캐릭터 바이블 (Biblia de Personajes)
A2: v20.0 · 2026-09-22 · 마드리드 배경 13부작 옴니버스(156화) · 1·2부 전체(24화) 대본 완성 · 화당 120턴 | C2: v26.0 · 2026-09-25 · 마드리드 배경 13부작 옴니버스(156화) · 1~8부 전체(96화) + 9부 1화 완성 · 1~6부 화당 120턴 · 7부부터 화당 180턴 · 다음: 9부 2화 · 다른 대화창에서 이어 쓰려면 '이어쓰기_가이드' 시트부터
B4: 기본 설정
B5: 부 수 | C5: 13 | D5: 1 사무소(개소 1개월 후, 6사건×2화) → 2~5 각자의 과거 → 6 만남 → 7 전면전 → 8 창당 → 9 시의회·자치의회 → 10 총선·총리 선출 → 11 국정 I(브뤼셀·Anselmo 사망) → 12 국정 II(장례·메모 승계) → 13 귀환(원형 구조)
B6: 부당 화 수 | C6: 12 | D6: 각 부 12화
B7: 총 화 수 | C7: =C5*C6 | D7: 부 수 × 부당 화 수 (자동 계산)
B8: 등장인물 수 | C8: =COUNTA(캐릭터!$D$5:$D$19) | D8: 캐릭터 시트의 약칭 개수
B9: 남성 인물 수 | C9: =COUNTIF(캐릭터!$G$5:$G$19,"남") | D9: 음색이 다양할수록 화자 구분이 쉬워 남 9 : 여 6으로 배분
B10: 여성 인물 수 | C10: =COUNTIF(캐릭터!$G$5:$G$19,"여")
B11: 1부→11부 경과 연수 (가정) | C11: 6 | D11: 가정값: Anselmo가 1부 74세 → 11부 약 80세가 되도록 잡음. 확정 시 이 셀만 수정하면 캐릭터 시트의 나이가 자동 갱신. (캐릭터 시트 '나이(11부)' 열)
B12: 배경·언어 | C12: 마드리드 | D12: 스페인 본토 스페인어: 친한 사이 vosotros, 공식 석상은 ustedes / señorías.
B13: 형식 | C13: 전 화 100% 대화문, 화당 120턴(7부부터 180턴, 8·9부도 180턴 유지) | D13: ="지문(Narración) 없음. 화당 "&턴_설계!$B$5&"턴 × "&C7&"화 = "&TEXT(C7*턴_설계!$B$5,"#,##0")&"턴. 상세는 '대화문규칙'·'턴_설계' 시트."
B15: 그룹별 인원
B16: 주력 4인 | C16: =COUNTIF(캐릭터!$B$5:$B$19,B16) | D16: Mateo(변호사) · Javier(의사) · Sofía(회계사) · Diego(컨설턴트)
B17: 올드보이 자문단 | C17: =COUNTIF(캐릭터!$B$5:$B$19,B17) | D17: Anselmo(외교관) · Ramón(장군) · Raimundo(전 CNI) · Inés(기자) · Lucía(심리학자) ※ La Vieja Guardia = Anselmo · Ramón · Raimundo
B18: 서민·청년 | C18: =COUNTIF(캐릭터!$B$5:$B$19,B18) | D18: Pepa(바 사장) · Nieves(노조위원장) · Tomás(작가 지망생) · Carmen(인턴)
B19: 금융 | C19: =COUNTIF(캐릭터!$B$5:$B$19,B19) | D19: Gonzalo(전 은행 지점장)
B20: 특별 인물 | C20: =COUNTIF(캐릭터!$B$5:$B$19,B20) | D20: Cervantes(부활한 소설가, 3부부터 사무소 합류)
B22: 시트 안내 (클릭하면 이동)
B23: 캐릭터 | C23: 기준표 | D23: 15인의 이름·나이·결핍·말투·시그니처·낭독 포인트·대화문 장치·직책·현안 담당
B24: 등장비중 | C24: 기준표 | D24: 13부 배분표, 합계·비중·등급(수식), 조연 단독 중심 화 목표
B25: 턴_설계 | C25: 기준표 | D25: 화당 120턴 설계: 부별 화자 점유율(턴 기준), 평균 단어/턴, 화당 단어·낭독 시간(수식), 화 유형별 턴 구성, 집필 규칙
B26: 12부_구성 | C26: 구조 | D26: 12부 한눈에 보기: 배경·핵심 내용·난이도(CEFR)·반영 제도
B27: 아크_구성계획 | C27: 구성 계획 | D27: 1~12부 아크별 구성 계획: 서사 기능·로그라인·비트·인물 아크·복선·현안·언어 설계
B28: 화별목차_전체 | C28: 목차 | D28: 1~12부 144화의 서사 기능·제목·핵심 사건·반영 제도·인물·현안 (필터 가능)
B29: 복선_회수 | C29: 구성 계획 | D29: 복선 설치→회수 50건과 간격(부)을 수식으로 계산 (34~50번: 5·6부 신규, 회수 완료분은 H열에 표시)
B30: 현안_배치 | C30: 현안 | D30: 스페인 현안 15개를 어느 화에 어떻게 녹일지 배치, 균형 유의, 현실 기준값
B31: 현안_분포 | C31: 현안 | D31: 부 × 현안 분포표: 전용 화(●)와 곁가지(○)를 수식으로 집계
B32: 정치제도 | C32: 현실 제도 | D32: 정당·선거·의회·정부·자치주·사법·EU 제도 기준표 (확인 상태 표시)
B33: 정치경로_의석 | C33: 현실 제도 | D33: 창당→총리 경로와 가상 의석·표결 시뮬레이션(수식): investidura 1·2차, 불신임안
B34: 호칭규칙 | C34: 규칙 | D34: tú / usted / vosotros / ustedes, 의회·국왕·시의회 공식 호칭
... B41: 이어쓰기_가이드 | C41: 관리 | D41: 새 대화창 인수인계: 진행 상황, docx 형식, 화자 색, 5·6부 확정 설정·수치, 호칭 현황, 7부 집필 메모(Picasso 합류), 5·6부 가상 인물 부록
B42: 범례
B43: 파란 글씨 | C43: 직접 입력한 값 (수정 가능)
B44: 노란 배경 | C44: 가정 · 확정이 필요한 값
B45: 검정 글씨 | C45: 수식으로 계산되는 값 (직접 수정하지 말 것)
B47: 주의: 성별·나이·기관명은 기획용 가상 설정입니다. 법령 번호·조항은 교재에 넣기 전에 BOE(boe.es)의 현행 텍스트(texto consolidado)로 확인하세요.

Sheet 이어쓰기_가이드
A1: 이어쓰기 가이드 — 새 대화창에서 이어 쓰기
A2: v26.0 · 2026-09-25 기준. 새 대화창에서는 이 시트를 먼저 읽고, '시작 방법'대로 파일을 올린다.
A5: 1. 진행 상황
A6: 항목 | B6: 내용 | C6: 비고
A7: 완성 | B7: 1~8부 전체 96화 + 9부 1화 (총 97화) | C7: 7부 대본: 7부N화_*.docx (N=1~12, 8~12화는 v26 작업분) · 8부: 8부N화_*.docx (N=1~12) · 9부: 9부1화_La_constitucion_de_la_Corporacion.docx
A8: 다음 작업 | B8: 9부 2화 「El primer Pleno」 — 화별목차_전체 9부 2행 + 아래 11번 9부 집필 메모 | C8: 9부 2화 도입(22턴) 초안만 작성된 상태에서 중단 — 새로 쓰거나 이어 쓰기
A9: 시간 구조 | B9: 6부(약 1년 전) → 6부 12화 «Mañana, a las cinco» → 1부 1화(개소 1개월 후) → 2~5부 프레임(1부 직후 금요일들) → 7부 | C9: 6부 11화 제비뽑기 순서 Mateo→Javier→Sofía→Diego가 2~5부 프레임 순서
A10: 워크북 갱신 방침 | B10: 부가 끝날 때 또는 요청 시 갱신 | C10: v25 = 7부 1~5화 반영 + 턴 120→180 · v26 = 7부 8~12화·8부 전체·9부 1화 반영, 색·가상 인물·복선·의석 보강
A12: 2. 새 대화창 시작 방법
A13: 순서 | B13: 내용 | C13: 비고
A14: ① 올릴 파일 | B14: 이 워크북(v26) + 형식 틀 docx 1편(예: 9부1화_La_constitucion_de_la_Corporacion.docx 또는 7부7화_Represalias.docx) | C14: 7부부터는 프레임 없는 본편 → 직전 화 docx를 틀로. 연속성이 중요하면 직전 2~3화도 함께
A15: ② 요청 예시 | B15: "7부 1화 만들어. 형식은 첨부한 6부12화 docx와 똑같이. 설정은 워크북 이어쓰기_가이드 참고."
A16: ③ 작업 방식 | B16: 틀 docx 패키지(스타일·머리글·바닥글)를 복사해 document.xml 본문만 새로 생성. 머리글 «Madrid — N부 · N화 · 제목»과 core.xml 제목만 교체 | C16: 5·6부 24편 모두 이 방식
A17: ④ 점검 | B17: 1~6부: 120턴(15·30·30·30·15) · 7~9부: 180턴(표준 22·45·45·45·23, 8부는 사용자 확정, 9부 1화도 180) · 같은 화자 연속 없음(섹션 경계 포함) · 대사 약 22단어 이하(낭독 턴 예외: 기사·조문·선서문·연설) · 한국어 대역 누락 없음 · docx 유효성 검사 | C17: 화자명에 악센트가 있으면(RAMÓN 등) 턴 수 셀 때 정규식에 포함 · 7부 표지 «대사 180턴»으로 표기
A19: 3. 대본 docx 형식 사양
A20: 요소 | B20: 사양 | C20: 비고
A21: 파일명 | B21: N부M화_Titulo_con_guiones.docx (악센트 제거) | C21: 예: 6부12화_El_rotulo.docx
A22: 표지 | B22: MADRID / 스페인어 낭독 교재 / N부 · M화 / 제목(굵은 이탤릭 20pt, 1F3864) / 부제 / «대사 N턴 · 난이도 … · 배경: …»(N=120, 7부부터 180) / «지문 없이 대사만으로 구성 · 스페인어 본문 + 한국어 대역» / 등장인물(이름 굵게 + 설명) / ※ 도입 설명(표현 초점 포함 가능) | C22: 부제 — 본편: «한국어 제목 · 시점, 장소» / 프레임: «한국어 제목 · 프레임 — N부의 N번째 금요일»
A23: 섹션 | B23: «도입 — …», «장면 1 — …», «장면 2 — …», «장면 3 — …», «마무리 — …» (스페인어 대문자). 남색 굵게 12pt + 밑줄 | C23: 턴 수로 경계를 잡되, 경계 앞뒤 같은 화자 금지
A24: 대사 1턴 | B24: ① 화자명(대문자, 굵게, 화자 색, 10pt) + 공백 3칸 + 스페인어(11pt, 1A1A1A) ② 한국어 대역(9pt, 808080 이탤릭), 들여쓰기 200 | C24: 지문 없음 — 시간·장소는 대사로 (Pepa·Ramón의 «Informo»가 주로 담당)
A25: 마지막 쪽 | B25: 쪽 나눔 → «다음 화 예고» + 한 줄 | C25: 부의 마지막 화는 다음 부 1화를 예고
A26: 난이도 | B26: 1부 B1 · 2~5부 B2~C1 · 6부 B2 · 7부 이후 아크_구성계획 기준 | C26: 6부 화별 표현 초점을 ※ 줄에 적음
A28: 4. 화자 색 (7부부터 고정 팔레트)
A29: 화자 | B29: 색 (hex) | C29: 비고
A30: DIEGO | B30: 2E75B6
A31: MATEO | B31: C55A11
A32: JAVIER | B32: 525252
A33: SOFÍA | B33: 38761D
A34: CARMEN | B34: 0B5394
A35: PEPA | B35: AA3939
A36: ANSELMO | B36: 6D4C41 | C36: 5부 프레임은 7F6000, 6부 4화는 8E24AA였음
A37: RAMÓN | B37: 7F6000 | C37: Anselmo와 같은 화에 나오면 Anselmo를 6D4C41로
A38: NIEVES | B38: 8E24AA
A39: RAIMUNDO | B39: 7F7F7F
A40: INÉS | B40: C00000
A41: TOMÁS | B41: BF8F00 | C41: 6부 9화만 8E24AA
A42: LUCÍA | B42: B45F06
A43: GONZALO | B43: 0E7C86
A44: CERVANTES | B44: 제안: 1F3864 계열 피하고 4E342E
A45: PICASSO (7부~) | B45: 제안: E69138
...

Sheet 캐릭터
A1: 캐릭터 바이블 — 15인
A2: La Vieja Guardia = Anselmo · Ramón · Raimundo | '대화문 장치' 열: 지문이 없으므로 이 인물이 말로 상황을 전달한다 | 등장 화 수·등급은 '등장비중' 시트에서 자동 조회 | 직책은 현실 직제 기준 제안 | 현안 담당 ID는 '현안_배치' 시트
A4: No | B4: 그룹 | C4: 이름 | D4: 약칭 | E4: 나이 (1부) | F4: 나이 (11부) | G4: 성별 | H4: 직업·신분 | I4: 전 소속 (가상) | J4: 결핍 (Herida) | K4: 말투 | L4: 시그니처 표현 | M4: 낭독 포인트 | N4: 대화문 장치 (지문 대체) | O4: 정치 직책 (8~12부, 제안) | P4: 1부 등장 방식 | Q4: 등장 화 수 | R4: 등급 | S4: 현안 담당 (ID)
A5: 1 | B5: 주력 4인 | C5: Mateo Ferrer Alcántara | D5: Mateo | E5: 39 | F5: =E5+개요!$C$11 | G5: 남 | H5: 변호사 (M&A·규제 전문) | I5: Aguirre & Salvat Abogados (전 파트너 후보) | J5: 승소율은 높지만, 자신이 이긴 강제 퇴거 사건 하나가 계속 마음에 걸린다. | K5: 문장이 완결되고 접속법이 정확한 격식체. 초반엔 차갑고 조항을 인용, 후반엔 연설가로 성장해 문장이 따뜻해진다. | L5: Vayamos por partes. Con todo respeto, eso no es lo que dice el artículo. (후반) No les pido que crean en mí. Les pido que lean el texto. (8~13부, 정치 연설) Caminante, no hay camino, se hace camino al andar. (Machado) | M5: 또박또박, 중저음. 쉼표마다 정확히 숨을 쉰다. | N5: 조항을 소리 내어 읽어 법적 상황을 설명한다 (예: «Artículo 24: …»). | O5: 당 대표(8부) → 하원의원·총리 후보(10부) → 총리 (Presidente del Gobierno) | P5: 본격 | Q5: =INDEX(등장비중!$O$5:$O$18,MATCH($D5,등장비중!$A$5:$A$18,0)) | R5: =INDEX(등장비중!$Q$5:$Q$18,MATCH($D5,등장비중!$A$5:$A$18,0)) | S5: P2·P3·N4
A6: 2 | B6: 주력 4인 | C6: Javier Molina Ríos | D6: Javier | E6: 41 | F6: =E6+개요!$C$11 | G6: 남 | H6: 응급의학과 전문의 | I6: Hospital Universitario San Bartolomé (가상) | J6: 살리지 못한 환자의 이름을 전부 외우고 있다. | K6: 문장이 짧고 명령형이 많다. 블랙유머. 화가 나면 오히려 조용해진다. | L6: Eso no es una estadística; es una persona. Primero, respira. He visto cosas peores un martes cualquiera. | M6: 빠른 템포, 짧은 호흡. 1부에서 B1 문장 길이를 지켜 주는 핵심 화자. | N6: 명령형으로 행동을 말하며 진행한다 (예: «Tensión, oxígeno, sala dos.»). 행동 묘사 지문을 대신한다. | O6: 자치의회 의원(9부) → 보건부 장관 (Ministro de Sanidad) | P6: 본격 | Q6: =INDEX(등장비중!$O$5:$O$18,MATCH($D6,등장비중!$A$5:$A$18,0)) | R6: =INDEX(등장비중!$Q$5:$Q$18,MATCH($D6,등장비중!$A$5:$A$18,0)) | S6: S3·S4·S2·N1
A7: 3 | B7: 주력 4인 | C7: Sofía Lozano Prieto | D7: Sofía | E7: 37 | F7: =E7+개요!$C$11 | G7: 여 | H7: 회계사 (감사·세무) | I7: Ochoa & Ruiz Auditores (전 시니어 파트너) | J7: 부정을 발견하고도 서명했던 기억. 다시는 서명하지 않겠다고 다짐한 사람. | K7: 건조하고 정확. 숫자를 정확한 단위로 읽는다. 비꼬는 유머. | L7: A ver los papeles. Esto no cuadra. Enséñame los números y te diré quién eres. | M7: 숫자를 읽을 때 속도를 일정하게 유지, 결론 문장에서 톤을 낮춘다. | N7: 숫자를 소리 내어 읽으며 상황을 전달하고, 어려운 말을 '번역'해 준다 (예: «Lo traduzco yo.»). | O7: 시의원(9부) → 부총리 겸 재무부 장관 (Hacienda) | P7: 본격 | Q7: =INDEX(등장비중!$O$5:$O$18,MATCH($D7,등장비중!$A$5:$A$18,0)) | R7: =INDEX(등장비중!$Q$5:$Q$18,MATCH($D7,등장비중!$A$5:$A$18,0)) | S7: E3·N2·E1
A8: 4 | B8: 주력 4인 | C8: Diego Navarro Beltrán | D8: Diego | E8: 36 | F8: =E8+개요!$C$11 | G8: 남 | H8: 전략 컨설턴트 (조직·정책 설계) | I8: Cenit Consultores (전 소속) | J8: 자신이 만든 구조조정 엑셀 한 칸이 수백 명의 실직이었음을 뒤늦게 알게 된다. | K8: 영어식 경영 용어가 섞인 빠른 말투 (alinear, escalable, impacto, stakeholders). 성장하며 쉬운 말로 바뀐다 — 이 변화 자체가 학습 포인트. | L8: Pongámoslo en una matriz. (후반) Vale, sin diapositivas: ¿qué necesitas? | M8: 초반엔 숨 가쁜 프레젠테이션 톤, 후반엔 느리고 솔직한 톤. | N8: 프레젠테이션식 브리핑으로 계획과 상황을 설명한다. | O8: 캠프 참모(8~10부) → 대통령실장 (Director del Gabinete de la Presidencia) | P8: 본격 | Q8: =INDEX(등장비중!$O$5:$O$18,MATCH($D8,등장비중!$A$5:$A$18,0)) | R8: =INDEX(등장비중!$Q$5:$Q$18,MATCH($D8,등장비중!$A$5:$A$18,0)) | S8: P1·E2·S1·N2
A9: 5 | B9: 올드보이 자문단 | C9: Anselmo Vidal de Arteaga | D9: Anselmo | E9: 74 | F9: =E9+개요!$C$11 | G9: 남 | H9: 은퇴 외교관 (전 주EU 대사) | I9: 외교부 (전 주EU 대사) — 파벌 싸움에 밀려 은퇴 | J9: 초대장이 오지 않는 전화기를 본다. 엄살 뒤에 진짜 병(만성 심부전)을 숨기고 있다. | K9: 우아하고 완곡. 조건법·접속법 과거를 자주 쓴다. 정중하게 독을 뿌리는 '가장 까칠하고 심술 맞은' 인물. 여럿에게는 ustedes. | L9: Permítame una precisión. Cuando yo era embajador… Discrepo, con todo el cariño. Qué manera de estropear un buen café. En mis tiempos, esto se arreglaba con una llamada. No está mal. (최고의 칭찬 — 복선) Este será mi último invierno. / Anótenlo en mi testamento. (고전 인용) Toda la vida es sueño, y los sueños, sueños son. (Calderón) — 11부: Nuestras vidas son los ríos que van a dar en la mar, que es el morir. (Manrique) | M9: 느리고 품위 있는 리듬. 문장 끝을 살짝 올리며 비꼰다. | N9: «Cuando yo era embajador…» 회상과 논평으로 분위기를 전달한다. 커피 불평으로 장소(Casa Pepa)를 알린다. | O9: 외교 자문 (11부 6화 사망) | P9: 준본격 (겨울 복선) | Q9: =INDEX(등장비중!$O$5:$O$18,MATCH($D9,등장비중!$A$5:$A$18,0)) | R9: =INDEX(등장비중!$Q$5:$Q$18,MATCH($D9,등장비중!$A$5:$A$18,0)) | S9: P2·E3
A10: 6 | B10: 올드보이 자문단 | C10: Ramón Iturbe Calleja | D10: Ramón | E10: 68 | F10: =E10+개요!$C$11 | G10: 남 | H10: 예편한 소장 (별 2개) | I10: 육군 (소장으로 예편) | J10: 방산 비리를 덮지 않아 별 하나를 더 달지 못했다. | K10: 단문과 명령형 중심. 군대식 보고 형식. | L10: Sin novedad. Esto se resuelve con logística, no con discursos. ¡Orden! | M10: 짧고 단단하게 끊는다. 볼륨보다 명료함. | N10: 보고 형식으로 현장 상황을 전달한다 (예: «Informo: …»). | O10: 캠프 총괄(8~10부) → 국가안보실장 (Departamento de Seguridad Nacional) | P10: 카메오 | Q10: =INDEX(등장비중!$O$5:$O$18,MATCH($D10,등장비중!$A$5:$A$18,0)) | R10: =INDEX(등장비중!$Q$5:$Q$18,MATCH($D10,등장비중!$A$5:$A$18,0)) | S10: N1·N3·S3·N5
A11: 7 | B11: 올드보이 자문단 | C11: Raimundo Salcedo Vera | D11: Raimundo | E11: 66 | F11: =E11+개요!$C$11 | G11: 남 | H11: 전 CNI 요원, 현 고서점 주인 | I11: CNI(국립정보센터) → 고서점 운영 | J11: 너무 많이 알아서 쫓겨났다. 지금은 고서점 안쪽 방에서 산다. | K11: 낮고 느리며, 결론을 직접 말하지 않고 '출처만 가리킨다'. 모두에게 tú — 그래서 더 위협적. 욕은 하지 않는다. | L11: Yo no he dicho nada. Pero mira en… No te lo digo. Te digo dónde está. Casi todo está en fuentes abiertas. Solo hay que saber leer. Búscalo tú. Eso no lo sabes por mí. Todo el mundo tiene un cajón que no abre. (고전 인용, 서지 톤) Polvo serán, mas polvo enamorado. Quevedo, soneto «Amor constante más allá de la muerte». | M11: 속삭이듯 낮은 음역. 문장 사이 호흡을 길게 둔다 (침묵 대신 출처 안내). | N11: 카드(ficha)를 구술한다 («Anota. Busca: … Dónde: …»). 손짓 대신 «Tercera balda, a tu izquierda.»처럼 서가 위치를 말한다. | O11: 정보기관 감독 개혁 자문 (CNI는 국방부 소속) | P11: 카메오 (고서점 주인·바 단골) | Q11: =INDEX(등장비중!$O$5:$O$18,MATCH($D11,등장비중!$A$5:$A$18,0)) | R11: =INDEX(등장비중!$Q$5:$Q$18,MATCH($D11,등장비중!$A$5:$A$18,0)) | S11: P3
A12: 8 | B12: 올드보이 자문단 | C12: Inés Carvajal | D12: Inés | E12: 52 | F12: =E12+개요!$C$11 | G12: 여 | H12: 탐사보도 기자 | I12: El Diario de la Capital (전 데스크) → 독립매체 La Hoja Abierta | J12: 진실을 쓰다 쫓겨났고, 독립매체는 늘 적자다. | K12: 질문형 문장이 많고 빠르고 정확. 취재할 때는 usted, 친해지면 tú. | L12: Necesito dos fuentes. Eso, ¿lo puedes probar? Esto no sale de aquí. | M12: 뉴스 앵커 톤과 취재 현장의 거친 톤을 오간다. | N12: 인터뷰 질문으로 사건의 경위와 시간 경과를 끌어낸다. | O12: 커뮤니케이션 국무차관 (Secretaría de Estado de Comunicación) | P12: 카메오 | Q12: =INDEX(등장비중!$O$5:$O$18,MATCH($D12,등장비중!$A$5:$A$18,0)) | R12: =INDEX(등장비중!$Q$5:$Q$18,MATCH($D12,등장비중!$A$5:$A$18,0)) | S12: P3·N1
A13: 9 | B13: 올드보이 자문단 | C13: Dra. Lucía Bermejo | D13: Lucía | E13: 49 | F13: =E13+개요!$C$11 | G13: 여 | H13: 임상심리학자 (시간강사) | I13: 대학 시간강사 (교수 임용 3회 낙방) | J13: 논문은 많은데 세상이 알아주지 않아 자기 확신이 흔들린다. | K13: 차분하고 천천히 말하며, 상대의 말을 되받아 정리한다. | L13: ¿Y cómo te hace sentir eso? (다들 질색하는 반복 개그) Fíjate en lo que no dice. | M13: 부드럽고 낮은 톤, 일정한 속도. | N13: 상대의 말을 되받아 요약해 준다 → 대화의 정리·복습 역할. | O13: 메시지·정신건강 정책 자문 | P13: 카메오 | Q13: =INDEX(등장비중!$O$5:$O$18,MATCH($D13,등장비중!$A$5:$A$18,0)) | R13: =INDEX(등장비중!$Q$5:$Q$18,MATCH($D13,등장비중!$A$5:$A$18,0)) | S13: N4·N5·S2
A14: 10 | B14: 서민·청년 | C14: Josefa «Pepa» Ortega | D14: Pepa | E14: 63 | F14: =E14+개요!$C$11 | G14: 여 | H14: 바 사장 (Casa Pepa, 30년 운영) | I14: Casa Pepa, Lavapiés → 사무소 1층으로 이전 | J14: 임대료 폭등으로 가게를 잃었다. 사무소 1층이 새 아지트가 된다. | K14: 마드리드 토박이 구어체. 누구에게나 tú, 'hijo/hija'라고 부른다. | L14: Sentaos, que os pongo algo. Con el estómago vacío no se piensa. ¡Anda ya! Invita la casa. (refranes) No hay mal que por bien no venga. / Dime con quién andas y te diré quién eres. | M14: 따뜻하고 넉넉한 톤. 1부 B1 대화의 기준점. | N14: 장면을 여는 사람: 시간·장소·식사를 말로 알린다 (예: «Son las cinco. Reunión en mi mesa.»). | O14: 소상공인 정책 자문 (비공식) | P14: 본격 | Q14: =INDEX(등장비중!$O$5:$O$18,MATCH($D14,등장비중!$A$5:$A$18,0)) | R14: =INDEX(등장비중!$Q$5:$Q$18,MATCH($D14,등장비중!$A$5:$A$18,0)) | S14: E1·S2·E2
A15: 11 | B15: 서민·청년 | C15: Nieves Barroso | D15: Nieves | E15: 55 | F15: =E15+개요!$C$11 | G15: 여 | H15: 전 대중교통 노조위원장 | I15: 마드리드 대중교통 노조 (파업 책임으로 해고·블랙리스트) | J15: 파업 책임으로 해고되어 블랙리스트에 올랐지만 후회하지 않는다. | K15: 거칠고 직설적. 구호형 문장. 청중에겐 «compañeros y compañeras». | L15: ¡Aquí no se rinde nadie! Esto se arregla en la calle. No me toques las narices. | M15: 큰 볼륨, 강한 억양. 문장 끝을 내리꽂는다. | N15: 구호와 함성으로 군중·현장의 분위기를 전달한다. | O15: 사회적 대화(Diálogo Social) 자문 | P15: 카메오 | Q15: =INDEX(등장비중!$O$5:$O$18,MATCH($D15,등장비중!$A$5:$A$18,0)) | R15: =INDEX(등장비중!$Q$5:$Q$18,MATCH($D15,등장비중!$A$5:$A$18,0)) | S15: S1·S2·E2
A16: 12 | B16: 서민·청년 | C16: Tomás Iglesias | D16: Tomás | E16: 44 | F16: =E16+개요!$C$11 | G16: 남 | H16: 20년째 작가 지망생 (연설문 작가) | I16: 편의점 야간 알바·대필 (원고를 다섯 번 갈아엎음) | J16: 자신의 첫 문장이 늘 불안하다. | K16: 은유를 남발하다가 핀잔을 듣는다. 결정적 순간에는 가장 단순한 문장이 나온다. | L16: Es que la primera frase lo es todo. Dejadme buscar una metáfora. (고전 인용, 도피처) Verde que te quiero verde. (Lorca) / ¿Qué es poesía?… Poesía… eres tú. (Bécquer) | M16: 시적일 때는 느리고 감정적, 평소엔 머뭇거리는 톤. | N16: 초고를 소리 내어 읽으며 연설·글의 내용을 보여 준다. | O16: 연설 담당관 (Gabinete) | P16: 카메오 (고서점 손님 — Raimundo와 연결) | Q16: =INDEX(등장비중!$O$5:$O$18,MATCH($D16,등장비중!$A$5:$A$18,0)) | R16: =INDEX(등장비중!$Q$5:$Q$18,MATCH($D16,등장비중!$A$5:$A$18,0)) | S16: N1·N5
... A18: 14 | B18: 금융 | C18: Gonzalo Arévalo Sanz | D18: Gonzalo | E18: 58 | F18: =E18+개요!$C$11 | G18: 남 | H18: 전 은행 지점장 | I18: Banco Ibérico (25년 근속) | J18: 불법 대출 공모를 내부 고발하다 해고되었고, 가족에게도 이유를 다 말하지 못했다. | K18: 정중하고 조심스러운 은행원식 완곡어법. 비유가 실무적 («돈은 물처럼 낮은 곳으로 흐릅니다»). | L18: Sigue el dinero. El dinero siempre deja huella. Cuando yo dirigía la sucursal… | M18: 차분하고 신중하게. 숫자와 계좌 경로를 설명할 때는 또렷하게. | N18: 돈의 경로를 «De A pasa a B…»식으로 말로 그려 준다. | O18: 금융 개혁 자문 | P18: 카메오 (의뢰인) | Q18: =INDEX(등장비중!$O$5:$O$18,MATCH($D18,등장비중!$A$5:$A$18,0)) | R18: =INDEX(등장비중!$Q$5:$Q$18,MATCH($D18,등장비중!$A$5:$A$18,0)) | S18: E3·N2
A19: 15 | B19: 특별 인물 | C19: Miguel de Cervantes Saavedra | D19: Cervantes | E19: 68 | F19: =E19+개요!$C$11 | G19: 남 | H19: 소설가·극작가 (부활 후 무직 → 사무소 자료실 담당) | I19: 무적함대 식량·세금 징수관 (역사적 배경, 가상 반영) → 1616년 사망 → 3부에서 부활 | J19: 살아서는 가난·투옥·인정받지 못함. 이제 모두가 이름은 아는데 아무도 그가 '그 사람'이라 믿지 않고, 왜 돌아왔는지 본인도 모른다. | K19: 어른에게는 vuestra merced(3인칭 동사), 젊은이에게는 vos(-áis/-éis). venta·brebaje·ingenio·mas·había de 등 옛 어휘. 철자는 현대식. | L19: Para servir a vuestras mercedes. Jamás escribí tal cosa. (고전 인용, 본인 작품만 정확히) «Cada uno es hijo de sus obras.» (Quijote 1부 4장) | M19: 정중한 고어체 리듬, 현대 철자로 알아듣기 쉽게. vuestra merced/vos 사용을 낭독 포인트로 삼는다. | N19: 현대 사물을 옛말로 묘사하면 주변 인물이 현대어로 정정해 준다 (양방향 어휘 학습 장치). 가짜 명언은 본인이 직접 교정한다. | O19: (7부) 민사등록·신원 회복 의뢰인 → (8부) 창당 발기인 → (10부) 하원의원(Madrid 명부) → (11~12부) 문화부 장관 (Ministro de Cultura), 12부 Anselmo 사후 외교 비공식 자문 겸임 | P19: 미등장 (3부 1화부터 등장) | Q19: =INDEX(등장비중!$O$5:$O$19,MATCH($D19,등장비중!$A$5:$A$19,0)) | R19: =INDEX(등장비중!$Q$5:$Q$19,MATCH($D19,등장비중!$A$5:$A$19,0)) | S19: —

Sheet 등장비중
A1: 인물별 등장 비중 (부별 등장 화 수)
A2: 등장 화 = 대사가 있는 화 수 (기획용 초안). 파란 숫자는 직접 입력값이며 수정하면 합계·비중·등급이 자동 갱신됩니다.
A4: 인물 (약칭) | B4: 1부 사무소 | C4: 2부 Mateo | D4: 3부 Javier | E4: 4부 Sofía | F4: 5부 Diego | G4: 6부 만남 | H4: 7부 전면전 | I4: 8부 창당 | J4: 9부 지방 의회 | K4: 10부 총선·총리 | L4: 11부 국정 I | M4: 12부 국정 II | N4: 13부 귀환 | O4: 합계 | P4: 비중 | Q4: 등급 | R4: 검증 (≤부당 화 수) | S4: 단독 중심 화 목표 (조연)
A5: Mateo | B5: 7 | C5: 12 | D5: 3 | E5: 3 | F5: 3 | G5: 12 | H5: 11 | I5: 12 | J5: 11 | K5: 11 | L5: 10 | M5: 3 | N5: 10 | O5: =SUM(B5:N5) | P5: =O5/개요!$C$7 | Q5: =IF(P5>=$B$23,"주연",IF(P5>=$B$24,"준주연",IF(P5>=$B$25,"핵심 조연","조연"))) | R5: =IF(MAX(B5:N5)<=개요!$C$6,"OK","확인") | S5: —
A6: Javier | B6: 6 | C6: 3 | D6: 12 | E6: 3 | F6: 3 | G6: 12 | H6: 10 | I6: 10 | J6: 8 | K6: 10 | L6: 10 | M6: 2 | N6: 9 | O6: =SUM(B6:N6) | P6: =O6/개요!$C$7 | Q6: =IF(P6>=$B$23,"주연",IF(P6>=$B$24,"준주연",IF(P6>=$B$25,"핵심 조연","조연"))) | R6: =IF(MAX(B6:N6)<=개요!$C$6,"OK","확인") | S6: —
A7: Sofía | B7: 7 | C7: 3 | D7: 3 | E7: 12 | F7: 3 | G7: 12 | H7: 11 | I7: 10 | J7: 10 | K7: 11 | L7: 10 | M7: 8 | N7: 9 | O7: =SUM(B7:N7) | P7: =O7/개요!$C$7 | Q7: =IF(P7>=$B$23,"주연",IF(P7>=$B$24,"준주연",IF(P7>=$B$25,"핵심 조연","조연"))) | R7: =IF(MAX(B7:N7)<=개요!$C$6,"OK","확인") | S7: —
A8: Diego | B8: 6 | C8: 3 | D8: 3 | E8: 3 | F8: 12 | G8: 12 | H8: 10 | I8: 11 | J8: 10 | K8: 10 | L8: 9 | M8: 3 | N8: 9 | O8: =SUM(B8:N8) | P8: =O8/개요!$C$7 | Q8: =IF(P8>=$B$23,"주연",IF(P8>=$B$24,"준주연",IF(P8>=$B$25,"핵심 조연","조연"))) | R8: =IF(MAX(B8:N8)<=개요!$C$6,"OK","확인") | S8: —
A9: Anselmo | B9: 4 | C9: 2 | D9: 2 | E9: 2 | F9: 2 | G9: 7 | H9: 9 | I9: 7 | J9: 9 | K9: 9 | L9: 9 | M9: 0 | N9: 3 | O9: =SUM(B9:N9) | P9: =O9/개요!$C$7 | Q9: =IF(P9>=$B$23,"주연",IF(P9>=$B$24,"준주연",IF(P9>=$B$25,"핵심 조연","조연"))) | R9: =IF(MAX(B9:N9)<=개요!$C$6,"OK","확인") | S9: 2
A10: Ramón | B10: 3 | C10: 1 | D10: 1 | E10: 1 | F10: 1 | G10: 6 | H10: 8 | I10: 9 | J10: 8 | K10: 8 | L10: 7 | M10: 4 | N10: 7 | O10: =SUM(B10:N10) | P10: =O10/개요!$C$7 | Q10: =IF(P10>=$B$23,"주연",IF(P10>=$B$24,"준주연",IF(P10>=$B$25,"핵심 조연","조연"))) | R10: =IF(MAX(B10:N10)<=개요!$C$6,"OK","확인") | S10: 2
A11: Raimundo | B11: 3 | C11: 1 | D11: 1 | E11: 2 | F11: 1 | G11: 5 | H11: 8 | I11: 6 | J11: 8 | K11: 8 | L11: 7 | M11: 3 | N11: 7 | O11: =SUM(B11:N11) | P11: =O11/개요!$C$7 | Q11: =IF(P11>=$B$23,"주연",IF(P11>=$B$24,"준주연",IF(P11>=$B$25,"핵심 조연","조연"))) | R11: =IF(MAX(B11:N11)<=개요!$C$6,"OK","확인") | S11: 2
A12: Inés | B12: 2 | C12: 1 | D12: 1 | E12: 3 | F12: 1 | G12: 5 | H12: 10 | I12: 7 | J12: 8 | K12: 8 | L12: 7 | M12: 3 | N12: 7 | O12: =SUM(B12:N12) | P12: =O12/개요!$C$7 | Q12: =IF(P12>=$B$23,"주연",IF(P12>=$B$24,"준주연",IF(P12>=$B$25,"핵심 조연","조연"))) | R12: =IF(MAX(B12:N12)<=개요!$C$6,"OK","확인") | S12: 2
A13: Lucía | B13: 1 | C13: 1 | D13: 2 | E13: 1 | F13: 2 | G13: 4 | H13: 7 | I13: 8 | J13: 6 | K13: 7 | L13: 6 | M13: 2 | N13: 7 | O13: =SUM(B13:N13) | P13: =O13/개요!$C$7 | Q13: =IF(P13>=$B$23,"주연",IF(P13>=$B$24,"준주연",IF(P13>=$B$25,"핵심 조연","조연"))) | R13: =IF(MAX(B13:N13)<=개요!$C$6,"OK","확인") | S13: 2
A14: Pepa | B14: 12 | C14: 2 | D14: 2 | E14: 2 | F14: 2 | G14: 5 | H14: 8 | I14: 6 | J14: 4 | K14: 5 | L14: 8 | M14: 3 | N14: 10 | O14: =SUM(B14:N14) | P14: =O14/개요!$C$7 | Q14: =IF(P14>=$B$23,"주연",IF(P14>=$B$24,"준주연",IF(P14>=$B$25,"핵심 조연","조연"))) | R14: =IF(MAX(B14:N14)<=개요!$C$6,"OK","확인") | S14: 2
A15: Nieves | B15: 2 | C15: 1 | D15: 2 | E15: 1 | F15: 3 | G15: 5 | H15: 9 | I15: 8 | J15: 6 | K15: 6 | L15: 7 | M15: 2 | N15: 6 | O15: =SUM(B15:N15) | P15: =O15/개요!$C$7 | Q15: =IF(P15>=$B$23,"주연",IF(P15>=$B$24,"준주연",IF(P15>=$B$25,"핵심 조연","조연"))) | R15: =IF(MAX(B15:N15)<=개요!$C$6,"OK","확인") | S15: 2
A16: Tomás | B16: 1 | C16: 1 | D16: 1 | E16: 1 | F16: 1 | G16: 4 | H16: 6 | I16: 9 | J16: 7 | K16: 9 | L16: 7 | M16: 4 | N16: 7 | O16: =SUM(B16:N16) | P16: =O16/개요!$C$7 | Q16: =IF(P16>=$B$23,"주연",IF(P16>=$B$24,"준주연",IF(P16>=$B$25,"핵심 조연","조연"))) | R16: =IF(MAX(B16:N16)<=개요!$C$6,"OK","확인") | S16: 2
A17: Carmen | B17: 12 | C17: 4 | D17: 4 | E17: 4 | F17: 4 | G17: 8 | H17: 10 | I17: 10 | J17: 9 | K17: 9 | L17: 10 | M17: 3 | N17: 12 | O17: =SUM(B17:N17) | P17: =O17/개요!$C$7 | Q17: =IF(P17>=$B$23,"주연",IF(P17>=$B$24,"준주연",IF(P17>=$B$25,"핵심 조연","조연"))) | R17: =IF(MAX(B17:N17)<=개요!$C$6,"OK","확인") | S17: —
A18: Gonzalo | B18: 2 | C18: 1 | D18: 1 | E18: 3 | F18: 1 | G18: 5 | H18: 8 | I18: 5 | J18: 7 | K18: 7 | L18: 9 | M18: 1 | N18: 6 | O18: =SUM(B18:N18) | P18: =O18/개요!$C$7 | Q18: =IF(P18>=$B$23,"주연",IF(P18>=$B$24,"준주연",IF(P18>=$B$25,"핵심 조연","조연"))) | R18: =IF(MAX(B18:N18)<=개요!$C$6,"OK","확인") | S18: 2
A19: Cervantes | B19: 0 | C19: 0 | D19: 4 | E19: 2 | F19: 2 | G19: 6 | H19: 6 | I19: 8 | J19: 5 | K19: 8 | L19: 6 | M19: 9 | N19: 8 | O19: =SUM(B19:N19) | P19: =O19/개요!$C$7 | Q19: =IF(P19>=$B$23,"주연",IF(P19>=$B$24,"준주연",IF(P19>=$B$25,"핵심 조연","조연"))) | R19: =IF(MAX(B19:N19)<=개요!$C$6,"OK","확인") | S19: 2
A20: 부별 연인원 (합계) | B20: =SUM(B5:B19) | C20: =SUM(C5:C19) | D20: =SUM(D5:D19) | E20: =SUM(E5:E19) | F20: =SUM(F5:F19) | G20: =SUM(G5:G19) | H20: =SUM(H5:H19) | I20: =SUM(I5:I19) | ... O20: =SUM(O5:O19) | S20: =SUM(S5:S19)
A22: 등급 기준 (비중 ≥)
A23: 주연 | B23: 0.69 | C23: ← 기준값은 등급 구분(주연 4 / 준주연 1 / 핵심 조연 4 / 조연 5)을 재현하도록 정한 제안값입니다.
A24: 준주연 | B24: 0.6
A25: 핵심 조연 | B25: 0.4
A26: 조연 | B26: 그 미만
A28: 배분 원칙
A29: 1. 1부는 개소 1개월 후 시점: Carmen·Pepa가 전 화에, 주력 4인은 사건별로 2~3인씩 교대 등장(전원 겹치지 않음). Anselmo 4화, Raimundo 3화(1·2·6화)로 자주 얼굴을 비추고 '이번 겨울이 마지막' 복선을 1화부터 깐다. 나머지는 사건마다 다른 조합으로 카메오.
A30: 2. 2~5부: 각 주인공이 자기 부 12화 전부에 나오고, 다른 주력 3인은 3화씩 스쳐 지나가며 6부 만남을 예고. Carmen은 4화씩 '사무소에서 이야기를 듣는 프레임'으로 등장해 회상을 잇는다.
A31: 3. 자문단은 과거와 겹치는 곳에만 배치: Nieves-5부(Diego의 구조조정 현장), Gonzalo·Inés-4부(Sofía의 감사 사건), Lucía-3부·5부(트라우마·번아웃 상담).
A32: 4. 자문단 본격 비중은 7~10부에서 최고치: 7부 Inés·Nieves(공론화·현장 조직), 8부 Tomás·Lucía·Ramón(선언문·메시지·캠프), 10부 Tomás·Inés·Raimundo(취임 연설·대변인·정보 감독).
A33: 5. 11부(국정 I)는 Anselmo가 9~12화에서 브뤼셀 직접 협상을 이끌며 최고치(9화)를 찍고 12화에서 사망한다. Gonzalo는 앞선 주거·금융 국내 현안 화에서 정점.
A34: 6. 12부(국정 II)는 Anselmo 사후: 1화 장례식에서 Ramón·Raimundo·Javier가 몰리고, Sofía·Tomás가 유작 메모를 이어받는 3화에서 비중이 오른다.
A35: 7. 13부(귀환, 구 12부)는 원형 구조: Carmen 12화 전부, Pepa 10화. Anselmo는 유언장·회상으로 3화, Mateo·Javier·Sofía·Diego는 사무소의 손님으로 9~10화 등장.
A36: 8. Anselmo는 11부 12화(브뤼셀 승리 직후)에서 사망한다. 12부 1화 장례식, 2·3화 유작 메모 승계, 13부 2화 유언장까지 이어진다.
A37: 9. 등장 화 수와 대사량은 다르다: Carmen은 약 67%지만 문장이 짧아 대사량은 Mateo의 절반 이하가 되게 하고, Anselmo·Tomás는 화당 대사가 길어도 된다.
A38: 10. 조연 9인은 화 전체의 중심이 되는 에피소드를 각자 2개 이상 배정(R열 목표). 자기 이야기가 한 번도 없으면 얇은 인물이 된다.
A39: 11. Lucía가 가장 얇다(약 36%): 3·5부 상담 장면을 늘리거나, 11부 Anselmo 애도 상담을 맡겨 서사를 넓히는 안을 검토.

Sheet 턴_설계
A1: 대화량 설계: 화당 120턴
A2: 한 화 = 대화 120턴, 전체 144화 = 17,280턴(기준값). 7부부터는 화당 180턴으로 상향(아래 39행 C39 참고). 점유율·평균 단어/턴·배율·낭독 속도는 가정값(파란 숫자)이며 수정하면 아래 표가 자동 갱신됩니다.
A4: 1. 기본 설정
A5: 화당 대화 턴 | B5: 120
A6: 낭독 속도 (단어/분, 가정) | B6: 130
A7: 총 화 수 | B7: =개요!$C$7
A8: 총 대화 턴 | B8: =B5*B7
A9: 턴 정의 | B9: 화자 표기 한 줄 = 1턴 (화자가 바뀌면 새 턴). 연설·조항·기사 낭독처럼 긴 발화도 1턴으로 센다.
A11: 2. 부별 화자 점유율 (턴 기준, 각 부의 합 = 100%)
A12: 인물 | B12: 평균 단어/턴 | C12: 1부 | D12: 2부 | E12: 3부 | F12: 4부 | G12: 5부 | H12: 6부 | I12: 7부 | J12: 8부 | K12: 9부 | L12: 10부 | M12: 11부 | N12: 12부
A13: Mateo | B13: 13 | C13: 0.13 | D13: 0.48 | E13: 0.03 | F13: 0.02 | G13: 0.02 | H13: 0.13 | I13: 0.14 | J13: 0.15 | K13: 0.08 | L13: 0.18 | M13: 0.15 | N13: 0.07
A14: Javier | B14: 8 | C14: 0.12 | D14: 0.03 | E14: 0.46 | F14: 0.04 | G14: 0.03 | H14: 0.12 | I14: 0.07 | J14: 0.08 | K14: 0.11 | L14: 0.06 | M14: 0.09 | N14: 0.06
A15: Sofía | B15: 11 | C15: 0.12 | D15: 0.04 | E15: 0.04 | F15: 0.46 | G15: 0.04 | H15: 0.12 | I15: 0.1 | J15: 0.09 | K15: 0.15 | L15: 0.08 | M15: 0.11 | N15: 0.07
A16: Diego | B16: 12 | C16: 0.12 | D16: 0.05 | E16: 0.03 | F16: 0.03 | G16: 0.46 | H16: 0.12 | I16: 0.06 | J16: 0.09 | K16: 0.08 | L16: 0.11 | M16: 0.08 | N16: 0.07
A17: Anselmo | B17: 14 | C17: 0.08 | D17: 0.04 | E17: 0.04 | F17: 0.04 | G17: 0.04 | H17: 0.04 | I17: 0.06 | J17: 0.05 | K17: 0.04 | L17: 0.06 | M17: 0.04 | N17: 0.02
A18: Ramón | B18: 7 | C18: 0.02 | D18: 0.01 | E18: 0.01 | F18: 0.01 | G18: 0.01 | H18: 0.05 | I18: 0.06 | J18: 0.06 | K18: 0.04 | L18: 0.08 | M18: 0.07 | N18: 0.06
A19: Raimundo | B19: 9 | C19: 0.02 | D19: 0.01 | E19: 0.01 | F19: 0.01 | G19: 0.01 | H19: 0.03 | I19: 0.06 | J19: 0.03 | K19: 0.04 | L19: 0.03 | M19: 0.05 | N19: 0.08
A20: Inés | B20: 10 | C20: 0.02 | D20: 0.01 | E20: 0.03 | F20: 0.04 | G20: 0.01 | H20: 0.03 | I20: 0.08 | J20: 0.06 | K20: 0.07 | L20: 0.05 | M20: 0.06 | N20: 0.05
A21: Lucía | B21: 9 | C21: 0.01 | D21: 0.01 | E21: 0.04 | F21: 0.01 | G21: 0.04 | H21: 0.03 | I21: 0.05 | J21: 0.06 | K21: 0.04 | L21: 0.05 | M21: 0.04 | N21: 0.05
A22: Pepa | B22: 9 | C22: 0.12 | D22: 0.04 | E22: 0.03 | F22: 0.03 | G22: 0.03 | H22: 0.05 | I22: 0.04 | J22: 0.05 | K22: 0.03 | L22: 0.04 | M22: 0.04 | N22: 0.13
A23: Nieves | B23: 10 | C23: 0.01 | D23: 0.02 | E23: 0.01 | F23: 0.01 | G23: 0.09 | H23: 0.05 | I23: 0.06 | J23: 0.08 | K23: 0.08 | L23: 0.06 | M23: 0.05 | N23: 0.05
A24: Tomás | B24: 12 | C24: 0.02 | D24: 0.01 | E24: 0.01 | F24: 0.01 | G24: 0.01 | H24: 0.03 | I24: 0.03 | J24: 0.08 | K24: 0.05 | L24: 0.07 | M24: 0.05 | N24: 0.05
... A27: 엑스트라(가상) | B27: 10 | C27: 0.03 | D27: 0.15 | E27: 0.17 | F27: 0.13 | G27: 0.12 | H27: 0.07 | I27: 0.07 | J27: 0.03 | K27: 0.05 | L27: 0.05 | M27: 0.04 | N27: 0.04
A28: 합계 | C28: =SUM(C13:C27) | D28: =SUM(D13:D27) | E28: =SUM(E13:E27) | F28: =SUM(F13:F27) | G28: =SUM(G13:G27) | H28: =SUM(H13:H27) | I28: =SUM(I13:I27) | J28: =SUM(J13:J27) | ... N28: =SUM(N13:N27)
A29: 검증 | C29: =IF(ROUND(C28,4)=1,"OK","확인") | D29: =IF(ROUND(D28,4)=1,"OK","확인") | E29: =IF(ROUND(E28,4)=1,"OK","확인") | F29: =IF(ROUND(F28,4)=1,"OK","확인") | G29: =IF(ROUND(G28,4)=1,"OK","확인") | H29: =IF(ROUND(H28,4)=1,"OK","확인") | I29: =IF(ROUND(I28,4)=1,"OK","확인") | J29: =IF(ROUND(J28,4)=1,"OK","확인") | ... N29: =IF(ROUND(N28,4)=1,"OK","확인")
A31: 3. 부별 턴·단어·낭독 시간 (수식)
A32: 부 | B32: 난이도 배율 | C32: 화당 턴 | D32: 부 총 턴 | E32: 평균 단어/턴 | F32: 화당 단어 | G32: 부 총 단어 | H32: 화당 낭독 (분) | I32: 부 총 낭독 (시간)
A33: 1부 | B33: 0.8 | C33: =$B$5 | D33: =C33*개요!$C$6 | E33: =SUMPRODUCT(C$13:C$27,$B$13:$B$27)*B33 | F33: =C33*E33 | G33: =F33*개요!$C$6 | H33: =F33/$B$6 | I33: =H33*개요!$C$6/60
A34: 2부 | B34: 1 | C34: =$B$5 | D34: =C34*개요!$C$6 | E34: =SUMPRODUCT(D$13:D$27,$B$13:$B$27)*B34 | F34: =C34*E34 | G34: =F34*개요!$C$6 | H34: =F34/$B$6 | I34: =H34*개요!$C$6/60
A35: 3부 | B35: 1 | C35: =$B$5 | D35: =C35*개요!$C$6 | E35: =SUMPRODUCT(E$13:E$27,$B$13:$B$27)*B35 | F35: =C35*E35 | G35: =F35*개요!$C$6 | H35: =F35/$B$6 | I35: =H35*개요!$C$6/60
A36: 4부 | B36: 1 | C36: =$B$5 | D36: =C36*개요!$C$6 | E36: =SUMPRODUCT(F$13:F$27,$B$13:$B$27)*B36 | F36: =C36*E36 | G36: =F36*개요!$C$6 | H36: =F36/$B$6 | I36: =H36*개요!$C$6/60
A37: 5부 | B37: 1 | C37: =$B$5 | D37: =C37*개요!$C$6 | E37: =SUMPRODUCT(G$13:G$27,$B$13:$B$27)*B37 | F37: =C37*E37 | G37: =F37*개요!$C$6 | H37: =F37/$B$6 | I37: =H37*개요!$C$6/60
A38: 6부 | B38: 1 | C38: =$B$5 | D38: =C38*개요!$C$6 | E38: =SUMPRODUCT(H$13:H$27,$B$13:$B$27)*B38 | F38: =C38*E38 | G38: =F38*개요!$C$6 | H38: =F38/$B$6 | I38: =H38*개요!$C$6/60
A39: 7부 | B39: 1 | C39: 180 | D39: =C39*개요!$C$6 | E39: =SUMPRODUCT(I$13:I$27,$B$13:$B$27)*B39 | F39: =C39*E39 | G39: =F39*개요!$C$6 | H39: =F39/$B$6 | I39: =H39*개요!$C$6/60
A40: 8부 | B40: 1.1 | C40: =$B$5 | D40: =C40*개요!$C$6 | E40: =SUMPRODUCT(J$13:J$27,$B$13:$B$27)*B40 | F40: =C40*E40 | G40: =F40*개요!$C$6 | H40: =F40/$B$6 | I40: =H40*개요!$C$6/60
A41: 9부 | B41: 1.1 | C41: =$B$5 | D41: =C41*개요!$C$6 | E41: =SUMPRODUCT(K$13:K$27,$B$13:$B$27)*B41 | F41: =C41*E41 | G41: =F41*개요!$C$6 | H41: =F41/$B$6 | I41: =H41*개요!$C$6/60
A42: 10부 | B42: 1.2 | C42: =$B$5 | D42: =C42*개요!$C$6 | E42: =SUMPRODUCT(L$13:L$27,$B$13:$B$27)*B42 | F42: =C42*E42 | G42: =F42*개요!$C$6 | H42: =F42/$B$6 | I42: =H42*개요!$C$6/60
A43: 11부 | B43: 1.2 | C43: =$B$5 | D43: =C43*개요!$C$6 | E43: =SUMPRODUCT(M$13:M$27,$B$13:$B$27)*B43 | F43: =C43*E43 | G43: =F43*개요!$C$6 | H43: =F43/$B$6 | I43: =H43*개요!$C$6/60
A44: 12부 | B44: 0.8 | C44: =$B$5 | D44: =C44*개요!$C$6 | E44: =SUMPRODUCT(N$13:N$27,$B$13:$B$27)*B44 | F44: =C44*E44 | G44: =F44*개요!$C$6 | H44: =F44/$B$6 | I44: =H44*개요!$C$6/60
A45: 전체 | D45: =SUM(D33:D44) | E45: =G45/D45 | F45: =AVERAGE(F33:F44) | G45: =SUM(G33:G44) | H45: =AVERAGE(H33:H44) | I45: =SUM(I33:I44)
...

Sheet 12부_구성
A1: 13부 구성 (13부 × 12화 = 156화)
A2: 정치 파트(8~11부)는 현실 정치 제도에 맞춰 재설계했습니다. 화별 목차는 '화별목차_전체', 제도 근거는 '정치제도' 시트.
A4: 부 | B4: 제목 (ES) | C4: 한국어 | D4: 배경 | E4: 핵심 내용 | F4: 난이도 (CEFR) | G4: 반영 제도·전문 영역 | H4: 시점
A5: 1 | B5: El Despacho de Lavapiés | C5: 라바피에스 사무소 | D5: Lavapiés의 작은 사무실 (1층은 Pepa의 바), 개소 1개월 후 | E5: 이미 한 달째 좌충우돌 중인 팀이 이웃들의 사건 6개를 2화씩(도입→해결) 풀어 간다. 자기소개 대신 '이 사람들이 어쩌다 이렇게 됐지?' 하는 궁금증(In medias res)으로 시작. | F5: B1 | G5: 생활 법률·노동·의료·금융 기초 어휘, 반복되는 말다툼, Carmen 1차 폭발(6화) | H5: 현재(개소 후 1개월)
A6: 2 | B6: El Abogado | C6: 변호사 | D6: Paseo de la Castellana의 대형 로펌 | E6: 승소율 100%의 이면: 강제 퇴거 사건이 Mateo의 결핍이 된다. | F6: B2~C1 | G6: 상법, 소송, 퇴거 절차(LEC) | H6: 과거
A7: 3 | B7: El Médico | C7: 의사 | D7: Hospital San Bartolomé 응급실 (가상) | E7: 예산 삭감과 외주 압박 속에서 치료받지 못하는 환자들. Javier의 이름 목록. | F7: B2~C1 | G7: 의학·보건행정, 자치주 보건 체계(SERMAS), 병원 외주(gestión indirecta) | H7: 과거
A8: 4 | B8: La Auditora | C8: 회계사 | D8: Ochoa & Ruiz Auditores (가상) | E8: 역외 탈세·자금세탁 정황을 발견하지만 조직의 묵인 압박. 서명하지 않겠다는 다짐의 기원. | F8: B2~C1 | G8: 감사·세무, 자금세탁방지법(Ley 10/2010), 감사법(ICAC) | H8: 과거
A9: 5 | B9: El Consultor | C9: 컨설턴트 | D9: Cenit Consultores (가상) | E9: 구조조정 엑셀 한 칸이 수백 명의 실직이었음을 깨닫는다. Nieves와의 첫 접점. | F9: B2~C1 | G9: 경영 전략, 집단해고(ERE), 노동법 | H9: 과거
A10: 6 | B10: El Encuentro | C10: 운명적 만남 | D10: Vallecas의 서민 주거 지역, 작은 카페 | E10: 강제 퇴거와 의료 방치가 한 건으로 얽힌 사건에서 네 사람이 만나 사무소를 차리기로 한다. | F10: B2 | G10: 협상·설득 구어체 | H10: 현재로 수렴
A11: 7 | B11: La Red de Resistencia | C11: 사무소 2탄: 전면전 | D11: 법원, 시청 앞, 마드리드 전역 | E11: 부당 해고·의료 사고·탈세 대기업 상대 집단 대응. 내부 제보자를 보호하고 acusación popular로 고소한다. | F11: B2~C1 | G11: querella, acusación popular, Fiscalía Anticorrupción, 내부고발자 보호법(Ley 2/2023) | H11: 과거→현재
A12: 8 | B12: El Despertar Cívico | C12: 정치적 각성과 창당 | D12: Puerta del Sol, 시민 집회 | E12: 시민 입법발의가 좌초하자 스스로 정당 «Casa Común»을 창당해 첫 지방·자치 선거에 나선다. | F12: B2~C1 | G12: 집회 신고, 정당 등록(Registro de Partidos Políticos), 정관, 정당 재정, 선거운동 규칙 | H12: 정치
A13: 9 | B13: En Cibeles y en la Asamblea | C13: 시의회와 자치의회 | D13: Palacio de Cibeles, Asamblea de Madrid(Vallecas 소재) | E13: Sofía는 시의회에서 예산을, Javier는 자치의회에서 보건을 파고든다. 스캔들 폭로와 Carmen의 2차 폭발. | F13: C1 | G13: Pleno, 예산 집행 규정, 공공계약, 자치주 권한(보건·주거), 조사·고소 | H13: 정치
A14: 10 | B14: Hacia La Moncloa | C14: 총선에서 총리 선출까지 | D14: Congreso de los Diputados, Zarzuela, La Moncloa | E14: 해산·총선·개원·국왕 협의·첫 후보 실패·2개월 시계·재선거·1표 차 총리 선출. | F14: C1~C2 | G14: 선거 절차, 개원, investidura(art. 99), 해산(art. 115), 국왕 앞 선서 | H14: 정치
A15: 11 | B15: La Gran Batalla Social I | C15: 사회 현안 전투 I | D15: La Moncloa, Consejo de Ministros, 브뤼셀 | E15: 소수 정부로 주거·보건·이민·청년·물가 국내 현안을 돌파한 뒤, Anselmo가 직접 브뤼셀 협상(NATO 방위비·EU 재정규칙)에 나서 승리하고 귀국 직후 사망한다. | F15: C1~C2 | G15: Consejo de Ministros, 자치주 협의체, NATO 방위비 목표(2025 헤이그 합의), EU 재정규칙 | H15: 정치
A16: 12 | B16: La Gran Batalla Social II | C16: 사회 현안 전투 II | D16: La Moncloa, 브뤼셀, 재난 현장 | E16: 장례식으로 열고 Anselmo의 유작 메모로 브뤼셀 후속 협상을 마무리한다. 플랫폼 노동·정보기관 사찰·청년 정신건강 등 새 현안과 건설적 불신임안 방어, DANA 재난, 예산안까지. | F16: C1~C2 | G16: 메모 승계, 법률 vs 긴급 칙령, 헌법재판소, 불신임안, DANA 민방위, 예산 | H16: 정치
A17: 13 | B17: De vuelta a Lavapiés | C17: 귀환 | D17: Lavapiés, Casa Pepa | E17: 1부 1화와 같은 대사로 시작해 원을 닫는다. Anselmo의 유언장, 새 인턴, 이제 설명하는 쪽이 된 Carmen. | F17: B1~B2 | G17: 유언(notaría, albacea), 고위직 겸직 제한, 재단 전환, 원형 구조 | H17: 귀환
A19: 흐름: 현재(1) → 과거(2~5) → 교차(6) → 전면전(7) → 정치(8 창당 → 9 지방 → 10 총선·총리) → 정부(11) → 귀환(12, 원형 구조). 난이도는 B1 → C1/C2 → B1~B2로 올라갔다 내려와 마무리가 부드럽고, 12부에서 1부 장면을 다시 읽으면 낭독 실력의 성장을 스스로 확인할 수 있다.

Sheet 아크_구성계획
A1: 아크별 구성 계획 (1~12부)
A2: 각 부(아크)의 서사 기능, 변화, 비트(발단→결말), 인물 아크, 복선, 현안·제도, 언어 설계를 한 블록으로 정리. 화별 세부는 '화별목차_전체', 복선 추적은 '복선_회수'.
A4: 1부 | B4: El Despacho de Lavapiés — 라바피에스 사무소 | 난이도 B1 | 사무소 개소 1개월 후(6부 12화로부터 약 4주). Lavapiés 사무소와 1층 Pepa의 바.
A5: 서사 기능 | B5: 독자 진입 장치. 이미 굴러가는(그러나 여전히 좌충우돌하는) 사무소를 보여 주어 '이 사람들이 어쩌다 이렇게 됐지?' 하는 궁금증을 만든다. 자기소개 대신 여섯 사건을 통해 인물의 습관과 리듬을 익히게 한다.
A6: 로그라인 | B6: 개소 한 달째, 여전히 순서 하나 못 정하고 매번 다투는 네 전문가와 팀이 그래도 이웃들의 사건 여섯 개를 하나씩 해결해 나가지만, 마지막 사건의 서류에서 Mateo의 옛 로펌 이름이 튀어나온다.
A7: 변화 (시작 → 끝) | B7: '한 달이나 됐는데 아직도 이 모양' → 그래도 매번 어떻게든 해결하는 팀이라는 신뢰. 그러나 각자의 과거는 여전히 미해결이고, 옛 로펌 이름이 도착한다.
A8: 핵심 갈등 | B8: 전문가의 말투 vs 이웃의 삶 / 여전히 못 정한 방법 / 각자 숨기는 과거
A9: 비트 1 | B9: 사건1 임대료 조작, 1~2화(Fátima): 도입에서 여전히 자리 못 잡은 한 달 차 팀의 말다툼을 보여 주고, 해결에서 Raimundo의 책·카드 #1(LAU)로 부당 인상을 막는다.
A10: 비트 2 | B10: 사건2 퇴거 집행, 3~4화: 밤 여덟 시 급보 → 아침 집행 저지. Ramón·Nieves 첫 카메오, 넷의 역할 분담(서류·건강·숫자·동선)이 처음으로 손발이 맞는다.
A11: 비트 3 | B11: 사건3 임금 체불, 5~6화: Diego의 컨설팅 용어가 청년 노동자를 지치게 하고, 협상 중 Carmen이 1차 폭발한다. 폭발 후 쉬운 말로 다시 협상해 해결.
A12: 비트 4 | B12: 사건4 의료 접근, 7~8화: 서류 없는 가족의 아이가 진료를 못 받는다. Lucía·Tomás 카메오, Anselmo의 가짜 무릎이 진짜 아픈 아이 앞에서 조용해지는 대비.
A13: 비트 5 | B13: 사건5 금융 사기, 9~10화: 저축을 잃은 이웃을 두고 Sofía가 장부를, 낯선 Gonzalo가 계좌 흐름을 추적한다. Inés 카메오. Gonzalo는 설명 없이 사라지고 Sofía는 은행 이름에 말없이 굳는다.
A14: 비트 6 | B14: 사건6 오래된 서류·훅, 11~12화: 수십 년 전 퇴거 서류의 절차 오류를 바로잡다가 서명란에서 Mateo의 옛 로펌 이름을 발견한다. Mateo가 얼어붙고 금요일 이야기(2부)가 예고된다.
A15: 인물 아크 | B15: Carmen=독자의 대리인(질문), 한 달이 지나도 Mateo에게 usted 유지. Anselmo=심술과 복선(매년 하는 소리라는 게 드러남). Pepa=정서적 중심. 카메오는 사건별로 분산: Raimundo(1·2·11화), Ramón·Nieves(3·4화), Lucía·Tomás(7화), Gonzalo·Inés(9·10·11화). 폭발 화(6화)에는 Ramón·Pepa·Raimundo의 고정 반응만 남기고 Nieves의 욕은 9부 2차 폭발로 이관해 과밀을 해소.
... A19: 언어 설계 | B19: B1. 한 줄 15단어 이내, 현재·명령형·간단한 과거. tú·vosotros 중심. 낭독: 빠른 티키타카로 입 풀기. Mateo·Anselmo의 격식체는 한두 줄 맛보기. 매 사건 2화(도입→해결) 리듬을 반복해 구조를 익히게 한다.
A20: 대화량 (화당 120턴) | B20: ="화당 "&턴_설계!$B$5&"턴 · 부 총 "&TEXT(턴_설계!D33,"#,##0")&"턴 · 화당 약 "&TEXT(턴_설계!F33,"#,##0")&"단어 · 낭독 약 "&TEXT(턴_설계!H33,"0.0")&"분 (평균 "&TEXT(턴_설계!E33,"0.0")&"단어/턴)"
A21: Carmen 질문·Raimundo 카드 | B21: Carmen: 임대·노동·의료·금융 기초 용어(fianza, contrato temporal, padrón, cuenta bancaria). 카드: LAU(Ley 29/1994), 사전(DLE·DPEJ).
A22: 다음 부 연결 | B22: 2부: 금요일마다 한 명씩 과거를 이야기하는 규칙 — 첫 번째는 Mateo.
A24: 2부 | B24: El Abogado — 변호사 | 난이도 B2~C1 | 프레임: 1부와 같은 첫 겨울의 금요일 밤. 과거: 약 5년 전, Paseo de la Castellana의 대형 로펌.
A25: 서사 기능 | B25: 첫 과거 회상. 공동 악역 Grupo Meridiano를 도입하고 '법을 잘 쓰는 것과 옳은 것은 다르다'는 이 이야기의 첫 질문을 던진다. 프레임(Pepa의 식탁)과 과거를 오가는 구조 실험.
A26: 로그라인 | B26: 승소율 100%의 파트너 후보가 대형 고객의 주택 포트폴리오를 비우는 조항을 설계해 재판에서 이기고, 그 승리가 한 노인의 죽음이 되었음을 알게 된다.
A27: 변화 (시작 → 끝) | B27: 자랑스러운 승자 → 자기 승리에 사직서를 낸 사람.
A28: 핵심 갈등 | B28: 잘 쓰는 법 vs 옳은 것 / 파트너 승진 vs 양심
A29: 비트 1 | B29: 발단(1~3화): 금요일 프레임, 카스티야나의 월요일, VIP 고객 Quintana.
A30: 비트 2 | B30: 전개(4~5화): 실사에서 Lavapiés 건물 발견 / 프레임에서 그곳이 Pepa의 거리였음이 드러남.
A31: 비트 3 | B31: 미드포인트(6화): 조항 설계 — Mateo가 스스로 함정을 만든다.
A32: 비트 4 | B32: 위기(7~9화): 주민 총회(Remedios), 재판 승소, 프레임에서 Mateo의 말이 막힘.
A33: 비트 5 | B33: 절정(10~11화): 살라망카 축하 만찬 중 부고, 손녀 Marina의 방문.
... A39: 언어 설계 | B39: B2~C1. 접속법 현재·과거, 수동태, 법률 문어체. 과거 장면은 격식 문어, 프레임 장면은 B1로 두어 톤을 대비. 발성: 또박또박, 중저음.
A40: 대화량 (화당 120턴) | B40: ="화당 "&턴_설계!$B$5&"턴 · 부 총 "&TEXT(턴_설계!D34,"#,##0")&"턴 · 화당 약 "&TEXT(턴_설계!F34,"#,##0")&"단어 · 낭독 약 "&TEXT(턴_설계!H34,"0.0")&"분 (평균 "&TEXT(턴_설계!E34,"0.0")&"단어/턴)"
A41: Carmen 질문·Raimundo 카드 | B41: Carmen: demanda·sentencia·cláusula 등 법률 용어. 카드: Registro de la Propiedad, LAU, LEC 퇴거 절차.
A42: 다음 부 연결 | B42: 3부: 응급실에서 쓰러진 Mateo — 다음 금요일은 Javier의 이야기.
A44: 3부 | B44: El Médico — 의사 | 난이도 B2~C1 | 프레임: 금요일 밤. 과거: 약 4년 전, Hospital San Bartolomé(가상) 응급실.
A45: 서사 기능 | B45: 인간의 생명과 공공 보건이라는 정서적 무게. Grupo Meridiano의 두 번째 얼굴(병원 외주)을 보여 주고, 폭염·고령 환자·서류 없는 환자 등 현안을 응급실에서 체감하게 한다.
A46: 로그라인 | B46: 응급의가 예산 삭감과 병원 외주 속에서 환자를 잃기 시작하고, 이름을 적어 두다가 내부 보고를 올리지만 징계로 돌아온다.
A47: 변화 (시작 → 끝) | B47: 시스템을 믿는 의사 → 이름 명단만 든 사직자.
A48: 핵심 갈등 | B48: 의료 윤리 vs 관리 효율 / 침묵하는 동료들
A49: 비트 1 | B49: 발단(1~3화): 금요일 프레임, 야간 근무(Mateo 진료), 폭염 환자 폭증.
A50: 비트 2 | B50: 전개(4~5화): 병원 외주 발표(컨설턴트 Diego 등장), 프레임에서 수첩 명단과 Anselmo의 부은 발목.
A51: 비트 3 | B51: 미드포인트(6화): '명단의 첫 번째' — 서류 없는 환자가 병상 지연으로 숨진다.
...

Sheet 화별목차_전체
A1: 전체 화별 목차 (1~12부, 144화)
A2: 현실 제도와 현안(ID는 '현안_배치' 시트)을 반영한 초안. 의석 수·결과는 가상 수치. 모든 화는 지문 없이 대화문으로만 진행한다.
A4: 부 | B4: 화 | C4: 서사 기능 | D4: 제목 (ES) | E4: 한국어 | F4: 핵심 사건 | G4: 반영 제도·전문 영역 | H4: 주요 인물 | I4: 반영 현안 (ID) | J4: 턴 수
A5: 1 | B5: 1 | C5: 사건1 도입 | D5: Otra carta más | E5: 또 다른 편지 | F5: 사무소 개소 1개월 후. 다섯 시, 여전히 방법을 못 정한 채 매일 다투는 팀. Fátima가 두 번째로 찾아와 새 퇴거 예고장을 보인다. Carmen은 여전히 Mateo에게 usted를 쓴다. Raimundo가 지나가며 «날짜를 세어 보라»는 힌트만 던지고, 계약서가 없어 다음 날로 미뤄진다. | G5: 생활 법률 구어체, 반복되는 말다툼 (B1) | H5: Pepa, Mateo, Javier, Sofía, Diego, Carmen, Anselmo, Fátima, Raimundo | I5: E1 | J5: =턴_설계!$B$5
A6: 1 | B6: 2 | C6: 사건1 해결 | D6: La cláusula que no sube | E6: 오르지 않는 조항 | F6: [사건1 해결] Fátima와 Carmen이 계약서를 가져온다. Raimundo의 카드 #1(LAU 조항)로 인상률이 부당함을 확인하고, 열흘의 기한 안에 답장을 쓴다. 사무소의 첫 번째 규칙(가난한 이웃에겐 돈을 받지 않는다)이 확인된다. | G6: 임대차(LAU), 소비자물가지수 조정, 기한·답변 | H6: Mateo, Sofía, Diego, Fátima, Raimundo, Carmen, Pepa | I6: E1 | J6: =턴_설계!$B$5
A7: 1 | B7: 3 | C7: 사건2 도입 | D7: Aviso de las ocho | E7: 여덟 시의 통지 | F7: [사건2 도입] 밤 여덟 시, 퇴거 집행이 다음 날 아침으로 잡혔다는 급보가 온다. Ramón이 주민을 조직하고 Nieves가 이웃들을 모은다. 네 사람이 각자 서류·건강·숫자·동선을 맡아 밤새 준비하지만 승산은 불투명하다. | G7: 퇴거 집행 예고, 긴급 동원, 이웃 조직 | H7: Mateo, Javier, Sofía, Diego, Ramón, Nieves, Carmen, Pepa | I7: S1 | J7: =턴_설계!$B$5
A8: 1 | B8: 4 | C8: 사건2 해결 | D8: El furgón que no llegó | E8: 오지 않은 트럭 | F8: [사건2 해결] 집행 당일 아침. Mateo의 긴급 신청, Javier의 취약계층 진단서, Sofía의 금액 계산, Diego의 동선 배치가 맞물려 집행이 연기된다. Ramón의 «Sin novedad» 보고로 마무리된다. | G8: 가처분 신청, 취약계층 유예, 집행관 대응 | H8: Mateo, Javier, Sofía, Diego, Ramón, Nieves, Carmen, Pepa | I8: S1 | J8: =턴_설계!$B$5
A9: 1 | B9: 5 | C9: 사건3 도입 | D9: El becario de la fábrica | E9: 공장의 인턴 | F9: [사건3 도입] 임금 체불과 부당한 초과근무에 지친 청년 노동자 Álvaro(가상)가 찾아온다. Diego가 컨설팅 용어로 상황을 분석하려 하고 Carmen이 통역하듯 애쓰지만 Álvaro는 점점 지쳐 간다. | G9: 임시 계약, 초과근무, 경영 용어의 벽 | H9: Diego, Carmen, Sofía, Pepa, Álvaro(가상) | I9: S1 | J9: =턴_설계!$B$5
A10: 1 | B10: 6 | C10: 사건3 해결(폭발) | D10: ¡Basta! | E10: 그만! | F10: [사건3 해결] 협상 자리에서 Diego의 용어가 한 시간째 이어지자 Carmen이 폭발한다(1차 폭발). Javier·Ramón·Pepa·Raimundo의 고정 반응, Anselmo의 «Mentecata… Pregunta.», Sofía의 «Lo traduzco yo.» 이후 쉬운 말로 다시 협상해 밀린 임금 지급에 합의한다. | G10: 감정 표현, 전문 용어 → 쉬운 말, 임금 체불 합의 | H10: Carmen, Diego, Sofía, Javier, Anselmo, Ramón, Pepa, Raimundo, Álvaro(가상) | I10: S1 | J10: =턴_설계!$B$5
A11: 1 | B11: 7 | C11: 사건4 도입 | D11: La niña con fiebre | E11: 열이 나는 아이 | F11: [사건4 도입] 서류가 없어 소아과 예약을 못 잡는 가족이 찾아온다. Javier가 나서고 Lucía가 친구로 들러 «¿Y cómo te hace sentir eso?»를 처음 선보인다. 마침 들른 Tomás는 Anselmo에게 원고를 놀림받다 «No está mal.»라는 최고의 칭찬을 듣는다. 정작 진짜 아픈 아이 앞에서 Anselmo는 자기 무릎 타령을 멈춘다. | G11: 서류 없는 가족의 의료 접근, 증상 표현 | H11: Javier, Lucía, Anselmo, Tomás, Carmen, Pepa, 가족(가상) | I11: S2 | J11: =턴_설계!$B$5
A12: 1 | B12: 8 | C12: 사건4 해결 | D12: Un volante para todos | E12: 모두를 위한 진료 의뢰서 | F12: [사건4 해결] Mateo와 Javier가 주민등록(padrón) 경로를 찾아내 아이가 진료를 받는다. Anselmo가 평소와 달리 조용히 커피를 마신다. | G12: 주민등록·거주 등록 경로, 진료 의뢰서 | H12: Javier, Mateo, Carmen, Pepa, 가족(가상) | I12: S2 | J12: =턴_설계!$B$5
A13: 1 | B13: 9 | C13: 사건5 도입 | D13: La viuda del quinto | E13: 5층의 미망인 | F13: [사건5 도입] 가짜 투자에 저축을 잃은 노년의 이웃 Encarna(가상)가 찾아온다. Sofía가 장부를 살피는 동안, 양복 입은 낯선 남자 Gonzalo가 나타나 은행 쪽 흐름을 봐 주겠다고 하면서도 자기 이야기는 하지 않는다. Inés가 냄새를 맡고 기웃거린다. | G13: 저축·투자 사기, 은행 계좌 기초 어휘 | H13: Sofía, Gonzalo, Inés, Carmen, Pepa, Encarna(가상) | I13: E3 | J13: =턴_설계!$B$5
A14: 1 | B14: 10 | C14: 사건5 해결 | D14: Sigue el dinero | E14: 돈을 따라가라 | F14: [사건5 해결] Gonzalo의 계좌 흐름 추적과 Sofía의 장부 대조로 사기 계좌를 찾아 돈 일부를 되찾는다. Gonzalo는 설명 없이 떠나고, Sofía는 «Banco Ibérico»라는 이름에 말없이 굳는다. | G14: 자금 흐름 추적, 계좌·송금 어휘 | H14: Sofía, Gonzalo, Carmen, Pepa, Encarna(가상) | I14: E3 | J14: =턴_설계!$B$5
A15: 1 | B15: 11 | C15: 사건6 도입 | D15: Un papel de hace años | E15: 수년 전 서류 | F15: [사건6 도입] Fátima의 남편이 수십 년 전 다른 건물에서 받은 낡은 퇴거 서류를 들고 온다. 당장 급한 사안은 아니지만 오래된 절차 오류가 보인다. Inés가 취재 각도로 흥미를 보인다. | G15: 오래된 서류 판독, 절차 하자 | H15: Mateo, Inés, Carmen, Pepa, Fátima의 남편(가상) | I15: E1 | J15: =턴_설계!$B$5
A16: 1 | B16: 12 | C16: 사건6 해결(훅) | D16: La firma | E16: 서명 | F16: [사건6 해결·훅] 절차 오류를 바로잡아 오래된 기록을 정정하지만, 진짜 충격은 서류 맨 아래: Mateo의 옛 로펌 «Aguirre & Salvat»의 서명이다. Mateo가 얼어붙고 Pepa가 «Sentaos, que os pongo algo.»로 분위기를 잇는다. 금요일에는 Mateo의 이야기가 시작된다. | G16: 서명·기록 정정, 이름 확인 | H16: Mateo, Pepa, Carmen, Anselmo, Fátima의 남편(가상) | I16: E1 | J16: =턴_설계!$B$5
A17: 2 | B17: 1 | C17: 발단 | D17: Viernes de historias | E17: 금요일의 이야기 | F17: (프레임) Pepa의 식탁에서 금요일마다 한 사람이 과거를 이야기하는 규칙이 시작된다. Carmen이 Mateo에게 왜 로펌을 그만뒀느냐고 묻고 Mateo는 «Vayamos por partes.»로 시작한다. | G17: 격식체(usted)와 tú의 대비, 과거 이야기 도입 | H17: Carmen, Mateo, Pepa, Anselmo | I17: E1 | J17: =턴_설계!$B$5
A18: 2 | B18: 2 | C18: 발단 | D18: Un lunes en la Castellana | E18: 카스티야나의 월요일 | F18: (과거) 승소율 100%의 파트너 후보 Mateo의 하루. 새벽 편의점에서 야간 점원 Tomás와 마주친다. 상사 Salvat(가상)이 파트너 승진을 암시한다. | G18: 로펌 어휘: socio, honorarios, cartera de clientes | H18: Mateo, Tomás, Salvat(가상) | J18: =턴_설계!$B$5
A19: 2 | B19: 3 | C19: 발단 | D19: El cliente estrella | E19: VIP 고객 | F19: 대형 고객 Grupo Meridiano의 회장 Quintana(가상)를 소개받는다. 회의석에는 고객 측 컨설턴트 Diego와 매각 은행 지점장 Gonzalo가 있다. | G19: 인수합병 어휘: adquisición, cartera, cláusula | H19: Mateo, Diego, Gonzalo, Quintana(가상) | I19: E1 | J19: =턴_설계!$B$5
A20: 2 | B20: 4 | C20: 전개 | D20: La cartera de Lavapiés | E20: 라바피에스 자산 포트폴리오 | F20: 실사(due diligence). 포트폴리오에 Lavapiés 건물 12채가 들어 있다. 감사인 Sofía가 «Esto no cuadra»를 흘리고, 고서점에서 등기 자료를 찾던 Mateo에게 Raimundo가 «Búscalo tú.» | G20: 실사, 등기(Registro de la Propiedad), 임차인 명부 | H20: Mateo, Sofía, Raimundo | I20: E1 | J20: =턴_설계!$B$5
A21: 2 | B21: 5 | C21: 전개 | D21: Viernes: la calle de Pepa | E21: 금요일: Pepa의 거리 | F21: (프레임) 그 포트폴리오에 Pepa의 가게가 있던 건물이 들어 있었음이 밝혀진다. Carmen은 놀라 usted를 놓치고 Mateo는 잠시 침묵한다. | G21: 감정 표현, 놀람 | H21: Pepa, Mateo, Carmen | I21: E1 | J21: =턴_설계!$B$5
A22: 2 | B22: 6 | C22: 미드포인트 | D22: La cláusula | E22: 조항 | F22: 임차인을 비우는 가장 '깨끗한' 방법으로 Mateo가 «resolución por obras de rehabilitación» 조항을 설계한다. Diego의 재무 모델이 이를 뒷받침한다. | G22: 임대 해지, 리모델링 사유, 통지 요건 | H22: Mateo, Diego, Salvat(가상) | I22: E1 | J22: =턴_설계!$B$5
A23: 2 | B23: 7 | C23: 위기 | D23: La asamblea de vecinos | E23: 주민 총회 | F23: 세입자들이 총회를 연다. 노조 출신 Nieves가 이끌고, 응급실 의사 Javier가 공황을 일으킨 노인을 돌본다. Mateo는 78세 Remedios(가상)를 만난다. | G23: 총회·발언·동의, 항의 표현 | H23: Mateo, Nieves, Javier, Remedios(가상) | I23: E1 | J23: =턴_설계!$B$5
A24: 2 | B24: 8 | C24: 위기 | D24: El juicio | E24: 재판 | F24: 심리(vista)와 판결. Mateo가 승소한다. 취재하던 Inés가 «¿Está orgulloso?»라고 묻는다. 감사인 Sofía는 고객의 장부를 보고 고개를 젓는다. | G24: 소송: demanda, vista, sentencia, costas | H24: Mateo, Inés, Sofía, 판사(가상) | I24: E1·P3 | J24: =턴_설계!$B$5
A25: 2 | B25: 9 | C25: 위기 | D25: Viernes: sigue | E25: 금요일: 계속해 | F25: (프레임) Mateo가 말을 잇지 못하자 Anselmo가 «Cuando yo era embajador…»로 시간을 벌어 주고 Pepa가 «Sigue.»라고 한다. Carmen은 «¿Y ella?»라고 묻는다. | G25: 위로·재촉 표현 | H25: Mateo, Anselmo, Pepa, Carmen | J25: =턴_설계!$B$5
A26: 2 | B26: 10 | C26: 절정 | D26: Una cena en Salamanca | E26: 살라망카의 저녁 | F26: 승소 축하 만찬. 파트너들이 건배하는 동안 Quintana가 다음 포트폴리오를 건넨다. Mateo의 휴대전화가 울린다. | G26: 고급 식당 표현, 건배·축하 | H26: Mateo, Salvat(가상), Quintana(가상), Sofía | J26: =턴_설계!$B$5
A27: 2 | B27: 11 | C27: 절정 | D27: La nieta de Remedios | E27: Remedios의 손녀 | F27: Remedios가 퇴거 석 달 뒤 세상을 떠났다는 소식. 손녀 Marina(가상)가 사무실로 찾아와 조용히 묻는다: «¿Usted ganó?» | G27: 조의·항의, 문서 vs 사람 | H27: Mateo, Marina(가상) | I27: E1 | J27: =턴_설계!$B$5
A28: 2 | B28: 12 | C28: 결말·훅 | D28: Viernes: la renuncia | E28: 금요일: 사직 | F28: (프레임+과거) Mateo가 다음 포트폴리오 서명을 거부하고 사직서를 낸다. 짐 상자를 든 채 응급실 대기실에서 쓰러지고 Javier가 그를 진료한다. Carmen은 여전히 usted를 쓴다. | G28: 사직·거절 표현, 접속법 | H28: Mateo, Javier, Carmen, Pepa | J28: =턴_설계!$B$5
A29: 3 | B29: 1 | C29: 발단 | D29: Viernes: los nombres | E29: 금요일: 이름들 | F29: (프레임) Javier가 «Eso no es una estadística; es una persona.»라며 이야기를 시작한다. Anselmo가 계단을 오르내리다 숨을 고르는 것을 Javier가 흘끗 본다. | G29: 의학 어휘 도입 | H29: Javier, Carmen, Anselmo, Pepa, Cervantes(신규) | J29: =턴_설계!$B$5
A30: 3 | B30: 2 | C30: 발단 | D30: Turno de noche | E30: 야간 근무 | F30: (과거) San Bartolomé 응급실의 야간 근무. 분류(triaje), 병상, 간호사 Marisol(가상)과의 호흡. 가슴 통증으로 실려 온 Mateo를 진료한다. | G30: triaje, constantes, camilla, box | H30: Javier, Marisol(가상), Mateo, Lucas(가상), Nacho(가상) | J30: =턴_설계!$B$5
A31: 3 | B31: 3 | C31: 발단 | D31: La ola de calor | E31: 폭염 | F31: 폭염에 고령 환자가 몰려 응급실이 넘친다. 산소·수액·얼음. Javier는 밤새 환자 이름을 외운다. | G31: 열사병(golpe de calor), 탈수, 고령 환자 | H31: Javier, Marisol(가상), Lucas(가상), Nacho(가상), Rosa·Julián·Carmela·Pilar(가상) | I31: S4·S3 | J31: =턴_설계!$B$5
A32: 3 | B32: 4 | C32: 전개 | D32: Un contrato que no se lee | E32: 읽히지 않는 계약 | F32: 병원이 검사·병상 관리를 Meridiano Salud에 외주한다고 발표한다. 원장 회의에서 컨설턴트 Diego가 '효율' 발표를 한다. | G32: 외주(gestión indirecta), 예산, 입찰 | H32: Javier, Diego, 원장(가상), Marisol(가상), Lucas(가상), Nacho(가상), Amparo(가상) | I32: S3 | J32: =턴_설계!$B$5
A33: 3 | B33: 5 | C33: 전개 | D33: Viernes: la lista | E33: 금요일: 명단 | F33: (프레임) Carmen이 Javier의 수첩 명단을 본다. Javier는 «He visto cosas peores un martes cualquiera.»로 넘긴다. Anselmo는 발목이 부었냐는 물음에 «Es el calzado.» | G33: 명단·숫자 읽기 | H33: Javier, Carmen, Anselmo, Pepa, Cervantes | J33: =턴_설계!$B$5
A34: 3 | B34: 6 | C34: 미드포인트 | D34: La primera de la lista | E34: 명단의 첫 번째 | F34: 서류 없는 20대 여성이 패혈증으로 실려 오지만 병상 배정이 아홉 시간 지연되어 숨진다. 외주 병상관리가 '비용 검토' 중이었다. Javier가 수첩에 첫 이름을 쓴다. | G34: 패혈증(sepsis), 병상 관리, 서류 없는 환자의 접근권(확인) | H34: Javier, Marisol(가상), Nilda·Teresa(가상), Lucas(가상), 원장(가상) | I34: S2·S3 | J34: =턴_설계!$B$5
A35: 3 | B35: 7 | C35: 위기 | D35: Las cifras del director | E35: 원장의 숫자 | F35: 원장이 '대기 시간 개선' 통계를 발표한다. 외주 업체의 재무를 자문하는 Sofía가 배석한다. Javier가 내부 사망 사례 보고서를 제출한다. | G35: 통계 읽기, 보고서 어휘 | H35: Javier, 원장(가상), Sofía, Lucas·Marisol(가상) | I35: P3 | J35: =턴_설계!$B$5
A36: 3 | B36: 8 | C36: 위기 | D36: El expediente | E36: 징계 절차 | F36: 보고서 유출 의혹으로 징계 절차가 시작된다. 취재하는 Inés에게 Javier가 «Esto no sale de aquí.»를 듣는다. | G36: 징계(expediente disciplinario), 비밀유지 | H36: Javier, Inés, 원장(가상), Clara(가상), Lucas·Marisol(가상) | I36: P3 | J36: =턴_설계!$B$5
A37: 3 | B37: 9 | C37: 위기 | D37: Viernes: ¿y cómo te hace sentir? | E37: 금요일: 기분이 어때요? | F37: (프레임) Lucía가 Javier에게 감정을 되묻는다. Javier는 «Primero, respira.»로 받아친다. Carmen이 Lucía의 화법을 흉내 낸다. | G37: 감정 표현, 되받기 화법 | H37: Javier, Lucía, Carmen, Anselmo, Pepa, Cervantes | J37: =턴_설계!$B$5
A38: 3 | B38: 10 | C38: 절정 | D38: Una noche sin camas | E38: 병상 없는 밤 | F38: 버스 사고와 폭염이 겹친 밤. 병상이 없어 복도까지 환자가 찬다. Javier가 즉흥으로 일곱 명을 살리고 한 명을 잃는다. | G38: 대량 환자(catástrofe), 우선순위, 명령형 | H38: Javier, Marisol(가상), Nacho(가상), Aurora·Rubén·Sara(가상) | I38: S4 | J38: =턴_설계!$B$5
A39: 3 | B39: 11 | C39: 절정 | D39: La renuncia del doctor | E39: 의사의 사직 | F39: 징계 통보와 마지막 근무. 수첩을 덮고 사직서를 낸다. Marisol이 «Doctor, no se vaya.» | G39: 사직서, 작별 | H39: Javier, Marisol(가상), 원장(가상), Lucas·Nacho(가상) | J39: =턴_설계!$B$5
A40: 3 | B40: 12 | C40: 결말·훅 | D40: Viernes: una firma | E40: 금요일: 한 사람의 서명 | F40: (프레임) Javier가 «El informe de auditoría del contrato llevaba una firma.»라고 말한다. Sofía가 조용히 «Mi turno.» | G40: 서명·책임 표현 | H40: Javier, Sofía, Carmen, Anselmo, Pepa, Cervantes | J40: =턴_설계!$B$5
A41: 4 | B41: 1 | C41: 발단 | D41: Viernes: yo firmé | E41: 금요일: 내가 서명했다 | F41: (프레임) Sofía가 «A ver los papeles.»를 습관처럼 하다가 «Yo firmé.»라고 시작한다. Carmen이 숫자를 못 읽어 질문한다. | G41: 회계 어휘 도입 | H41: Sofía, Carmen, Javier, Anselmo | J41: =턴_설계!$B$5
...

Sheet 복선_회수
A1: 복선 설치와 회수 (Setup → Payoff)
A2: 설치 부와 회수 부의 간격(부 수)은 수식으로 계산됩니다. 간격이 클수록 오래 기다린 복선이라 낭독 시 기억에 남습니다.
A4: No | B4: 복선(설치) | C4: 유형 | D4: 설치 부 | E4: 설치 위치 | F4: 회수 부 | G4: 간격(부) | H4: 회수 위치와 효과 | I4: 관련 인물
A5: 1 | B5: Anselmo의 «Este será mi último invierno» 반복 | C5: 대사 | D5: 1 | E5: 1부 1화 | F5: 11 | G5: =F5-D5 | H5: 11부 12화 — 양치기 소년 개그가 진짜 죽음이 되는 낙차 | I5: Anselmo
A6: 2 | B6: Anselmo가 Carmen에게 우산을 물려준다고 말한다 | C6: 소품 | D6: 1 | E6: 1부 1화 | F6: 13 | G6: =F6-D6 | H6: 13부 2화 — 유언장에서 우산이 진짜 유산으로 돌아옴 | I6: Anselmo, Carmen
A7: 3 | B7: Anselmo의 부은 발목·숨참 | C7: 설정 | D7: 3 | E7: 3부 1·5화 | F7: 11 | G7: =F7-D7 | H7: 11부 4~6화 — Javier가 진단을 알고도 침묵한 이유가 드러남 | I7: Javier, Anselmo
A8: 4 | B8: Anselmo의 최고 칭찬 «No está mal.» | C8: 대사 | D8: 1 | E8: 1부 7화(Tomás에게 1회) | F8: 11 | G8: =F8-D8 | H8: 11부 12화 — Carmen에게 처음이자 마지막 칭찬, 브뤼셀 승리 직후라 더 무겁다 | I8: Anselmo, Carmen
A9: 5 | B9: Carmen의 1차 폭발 | C9: 사건 | D9: 1 | E9: 1부 6화 | F9: 9 | G9: =F9-D9 | H9: 9부 6화 — 몰라서 화내던 Carmen → 알아서 화내는 Carmen | I9: Carmen
A10: 6 | B10: Carmen의 usted (Anselmo에게) | C10: 호칭 | D10: 1 | E10: 1부 1화 | F10: 11 | G10: =F10-D10 | H10: 11부 7화 — 조사에서 처음 tú — 호칭 전환이 곧 애도 | I10: Carmen, Anselmo
A11: 7 | B11: Raimundo의 카드 #1과 «Búscalo tú.» | C11: 대사 | D11: 1 | E11: 1부 2화 | F11: 13 | G11: =F11-D11 | H11: 13부 10화 — 끝까지 결론을 말하지 않던 그가 처음 답을 말함 | I11: Raimundo, Carmen
A12: 8 | B12: Mateo의 조항 «resolución por obras» | C12: 사건 | D12: 2 | E12: 2부 6화 | F12: 11 | G12: =F12-D12 | H12: 11부 3화 — 자기가 만든 조항을 국정에서 폐지 | I12: Mateo
A13: 9 | B13: Sofía의 «Esto no cuadra» | C13: 대사 | D13: 2 | E13: 2부 4화 | F13: 4 | G13: =F13-D13 | H13: 4부 4화 — 감사인의 눈이 처음 이상을 발견한 순간의 원점 | I13: Sofía
A14: 10 | B14: Mateo와 Sofía, tú로 전환 | C14: 관계 | D14: 2 | E14: 2부 10화 | F14: 6 | G14: =F14-D14 | H14: 6부 — 레스토랑 테라스에서 «같은 배를 탄 사람들끼린 말을 놓는다»며 처음 tú 사용 — 6부 재회 시 이미 tú인 이유 | I14: Mateo, Sofía
A15: 11 | B15: Sofía의 복사본 USB | C15: 소품 | D15: 4 | E15: 4부 10화 | F15: 7 | G15: =F15-D15 | H15: 7부 5~6화 — 서명의 죄가 고소의 증거로 바뀜 | I15: Sofía, Mateo
A16: 12 | B16: Sofía의 «다시는 서명하지 않는다» | C16: 인물 | D16: 4 | E16: 4부 11화 | F16: 11 | G16: =F16-D16 | H16: 11부 9화 — «Yo solo firmo lo que he verificado» — 숫자 서명의 회수 | I16: Sofía
... A63: 59 | B63: Iker — 7부 2화 가짜 인턴 의뢰인 | C63: 인물 | D63: 7 | E63: 7부 2화 | F63: 9 | G63: =F63-D63 | H63: [회수 완료 v26] 9부 1화 최연소 시의원·연령 의장단 | I63: Iker, Sofía
B65: 평균 간격(부) | G65: =AVERAGE(G5:G63)
B66: 가장 긴 복선(부) | G66: =MAX(G5:G63)
B67: 복선 개수 | G67: =COUNTA(B5:B63)

Sheet 현안_배치
A1: 스페인 현안 15개 배치표
A2: 현재 스페인의 쟁점을 이야기 곳곳에 녹이는 계획. 현실의 정당·정치인·참사 희생자는 특정하지 않고 가상 설정으로 각색하며, 제도와 통계만 현실 기준으로 쓴다.
A4: ID | B4: 분야 | C4: 현안 | D4: 스페인어 키워드 | E4: 이야기 속 가상 설정 | F4: 주요 배치 (전용 화) | G4: 곁가지 배치 | H4: 주요 인물 | I4: 권한 소재 | J4: 관련 제도·법 | K4: 낭독 어휘 | L4: 균형·민감도 유의 | M4: 현실 기준값·확인
A5: P1 | B5: 정치 | C5: 정치 파편화와 연정 불안정 | D5: fragmentación, pacto, apoyo puntual, geometría variable | E5: 어떤 정당도 과반이 안 되는 의회. 법안마다 협상 비용이 든다. Casa Común도 소수 정부로 표결마다 다른 파트너를 찾아야 한다. | F5: 9부 5화 불편한 동맹, 10부 8화 두 달의 시계, 11부 10화 합쳐지지 않는 불신임안 | G5: 8부 6화(왜 새 정당인가: 양당 피로), 12부 7화 | H5: Diego, Mateo, Nieves | I5: 하원·시의회 | J5: 헌법 제99·113·134조, 정당 간 협약 | K5: fragmentación, pacto de investidura, cesión, mayoría, bloqueo | L5: 특정 실존 정당·인물을 비난하는 대사 금지. 가상 정당(UCN·PPS·HU·TA·TB)으로만. | M5: 현 정부는 소수 연립 + 지역정당 지지 의존(2026-09 확인). 이야기에는 쓰지 않음
A6: P2 | B6: 정치 | C6: 지역 갈등·사면·재정 분권 | D6: amnistía, indulto, financiación autonómica, Tribunal Constitucional | E6: 지역정당 연합 TB가 지지의 대가로 과거 '독립 추진' 사건 관련자의 사면과 재정 분권을 요구한다. 총리 지명이 여기에 걸린다. | F6: 10부 11화 총리 지명 협상 | G6: 10부 3화(TV 토론 공격), 11부 10화(불신임안에서 TB의 기권), 12부 7화 | H6: Mateo, Anselmo, Nieves, Diego | I6: 하원, 헌법재판소, 자치주 | J6: 헌법 제62조 i, 사면법(LO 1/2024), LOFCA·CPFF | K6: amnistía vs indulto, soberanía, cupo, compensación | L6: 가장 민감. 찬성·반대 논거를 각 인물이 나눠 말하게 하고 결론은 열어 둔다(Mateo는 헌법 우려, Nieves는 지역 간 형평, Diego는 현실 협상). | M6: 사면법 후폭풍과 사법 절차 진행 상황은 반영 전 확인
A7: P3 | B7: 정치 | C7: 사법부 독립과 정치적 대립 | D7: CGPJ, renovación, dilaciones indebidas, instrucción | E7: 사법평의회 갱신이 정당 대립으로 막혀 스캔들 수사가 표류한다. 사무소의 고소가 법원에서 지연된다. | F7: 7부(고소·법원 결정·보복), 9부 9화 고소장 | G7: 2부 8화(재판), 3부(징계·외주), 4부 7화, 10부 11화(협상 조건), 11부 10화(교착) | H7: Mateo, Inés, Raimundo | I7: 하원·상원(위원 선출), 사법부 | J7: 헌법 제122조, LOPJ, 3/5 다수 | K7: renovación, mayoría de tres quintos, dilaciones, instrucción | L7: 여야 모두가 사법부를 압박한다는 비판을 각각 담는다. 실제 재판 결과를 단정하지 않는다. | M7: 최신 갱신 상황 확인
A8: E1 | B8: 경제 | C8: 주거난과 단기 관광 임대 | D8: vivienda, zona tensionada, vivienda turística, gran tenedor, licencia | E8: 월세가 임금보다 빨리 오르고 관광 아파트가 동네를 비운다. 소규모 임대인의 입장(Pepa의 친구)도 대사에 넣는다. | F8: 2부 6화(조항 설계), 6부 1·3·8·10화(Vallecas), 9부 6화(임대 보조 삭감·관광 아파트 조항), 11부 2·3화 | G8: 1부 1·2화(Fátima), 8부 1·9화, 12부 | H8: Pepa, Carmen, Sofía, Mateo | I8: 자치주(주거), 시(도시계획·인허가), 국가(기본 조건·세제) | J8: LAU, Ley 12/2023, 단기임대 등록제(2025, 확인) | K8: vivienda turística, zona tensionada, alquiler de temporada, pequeño propietario | L8: 임차인만 피해자로 그리지 않는다. 소규모 임대인·대형 보유자를 구분해서 말한다. | M8: 단기임대 규제 세부는 확인
A9: E2 | B9: 경제 | C9: 저생산성과 영세 기업 구조 | D9: microempresa, pyme, productividad, I+D, tamaño empresarial | E9: Diego가 컨설팅한 규모의 경제 없는 영세 제조업체들: 해고 없이 살릴 길을 못 찾았던 과거. 11부에서 영세 기업 통합·R&D 전환 사업을 설계한다. | F9: 5부 3화 Rueda 공방 | G9: 8부 9화(골목 상권), 11부 9화, 12부 7화 | H9: Diego, Pepa, Nieves | I9: 국가·자치주 | J9: R&D 세액공제·사회보험(확인), ERE | K9: productividad, escalar, consolidación, I+D+i | L9: '영세 기업이 문제'라는 식의 낙인 대신 구조 문제로 설명한다. | M9: 통계 수치는 반영 전 확인
A10: E3 | B10: 경제 | C10: 국가 부채와 재정 건전성 | D10: deuda pública, regla de gasto, pensiones, revalorización | E10: 부채를 줄이라는 EU 압박과 연금·보건 지출 증가 사이의 줄타기. Sofía가 숫자로 설명하고 Carmen이 되묻는다. | F10: 11부 9화(EU 재정규칙), 11부 12화(예산안) | G10: 12부 7화 | H10: Sofía, Anselmo(메모), Gonzalo | I10: 국가·EU | J10: 중기 재정구조계획, TFUE 126, Pacto de Toledo | K10: deuda, déficit, regla de gasto, sostenibilidad | L10: 긴축 vs 확대 양쪽 논거를 모두 숫자로 제시한다. | M10: 부채는 GDP 대비 약 100% (2026.7 99.9%, 6월 101.5%, 스페인은행)
A11: S1 | B11: 사회 | C11: 청년 고용 불안 | D11: becario, contrato temporal, contrato formativo, SMI | E11: 임시 계약과 저임금으로 청년의 자립이 늦어진다. Carmen이 그 당사자이자 질문자다. | F11: 11부 6화, 12부 5·6화 | G11: 1부(Carmen), 5부(Diego의 인력 감축), 8부, 10부 3화 | H11: Carmen, Nieves, Diego | I11: 국가(노동법)·사회적 대화 | J11: 사회적 대화, 인턴 사회보험(2023 개정, 확인) | K11: becario, contrato, salario mínimo, precariedad | L11: 청년 vs 기성세대 구도로 몰지 않는다(Nieves도 Anselmo도 청년의 편에서 돕는다). | M11: 25세 미만 실업률 23.8%(2026 2분기), 전체 9.9%, 약 2.4배 (INE EPA 2026-09 확인)
A12: S2 | B12: 사회 | C12: 이민·난민과 수용 분담 | D12: arraigo, permiso de residencia, menor no acompañado, acogida, asilo | E12: Lavapiés는 다국적 동네다. 서류 없는 이웃, 체류 자격 사건, 도착 지역의 수용 과부하와 자치주 간 떠넘기기. | F12: 6부 8·9화(퇴거 저지·서류 없는 이웃), 7부 4화(체류 자격), 11부 5화 분담 | G12: 1부 2화, 3부 6화(서류 없는 환자), 8부(투표권 없는 이웃), 10부 3화, 12부 | H12: Pepa, Javier, Mateo, Nieves, Lucía | I12: 국가(외국인법·국경), 자치주(아동 보호·수용) | J12: LO 4/2000, Ley 12/2009, 이주 아동 분산 조치(2025, 확인) | K12: arraigo, acogida, menor no acompañado, solicitud de asilo | L12: 반이민 여론(HU)과 수용 부담 지역의 실제 어려움을 함께 담고, 이주민을 배경이 아닌 화자로 세운다. | M12: 2025년 분산 수용 조치의 현재 상태 확인
A13: S3 | B13: 사회 | C13: 고령화와 텅 빈 스페인(España Vaciada) | D13: despoblación, envejecimiento, natalidad, pensiones | E13: 농촌 진료소가 문을 닫고 자치주는 병원 외주를 늘린다(9부). Ramón의 고향은 학교도 병원도 문을 닫은 내륙 마을이고, 캠페인이 그곳을 지나며 일자리·의료·연금 문제가 되풀이된다(10부). | F13: 9부 7화 자치의회에서의 보건 | G13: 3부(응급실 고령 환자), 10부 2화(Ramón의 고향 마을), 11부 4화, 12부 | H13: Ramón, Javier, Carmen | I13: 자치주·시·국가 | J13: 헌법 제68조 2항(선거구 최소 의석), Pacto de Toledo | K13: despoblación, envejecimiento, natalidad, consultorio rural | L13: '텅 빈 스페인'을 동정하지 않고 마을 사람들이 직접 말하게 한다. | M13: 인구·출생 통계는 반영 전 확인
A14: S4 | B14: 사회 | C14: 가뭄·폭염과 에너지 전환 부담 | D14: sequía, ola de calor, embalse, restricciones de agua | E14: 폭염에 응급실이 넘치고(3부), 저수지가 마른 마을을 지나며(10부), 횡재세 재원을 전환 비용에 쓸지 논쟁한다(11부). | F14: 3부 3·10화(폭염 응급실) | G14: 10부 2화, 11부 4·8·11화, 12부 | H14: Javier, Ramón, Sofía | I14: 국가·자치주·유역기관 | J14: 폭염 경보, 수자원 관리(확인) | K14: sequía, ola de calor, AEMET, embalse, transición energética | L14: 기후를 정치적 구호로 쓰지 않고 현장 사건으로 보여 준다. | M14: 최신 가뭄·폭염 통계 확인
A15: N1 | B15: 재난 | C15: DANA와 방재 체계 | D15: DANA, gota fría, aviso rojo, ES-Alert, UME, damnificados | E15: 지중해 연안에 가상의 DANA 폭우가 덮친다. 경보 지연, 자치주–중앙정부 책임 공방, 긴급사태 선언 여부, 군 투입, 복구와 보험 보상. | F15: 11부 11화 La Gota Fría | G15: 12부(복구 결산) | H15: Ramón, Javier, Mateo, Inés, Tomás | I15: 자치주(1차 대응), 국가(긴급사태·군), EU | J15: Ley 17/2015, 보험보상 기구, EU 연대기금 | K15: protección civil, aviso rojo, emergencia de interés nacional, damnificados | L15: 실제 참사와 희생자를 연상시키므로 추모의 톤을 지키고, 특정 정치인 비난 없이 제도의 공백을 보여 준다. | M15: 실제 사건의 후속 조치·재판은 반영 전 확인
... A22: N8 | B22: 사회 | C22: 청년 정신건강 위기 | D22: salud mental, ansiedad, lista de espera, terapia | E22: 청년 정신건강 상담 대기가 몇 달씩 밀린다. Lucía가 진료 현장에서, Carmen이 자신의 불안을 처음 인정하며 함께 부딪힌다. | F22: 12부 6화 Las Listas de Espera | G22: 1부(Carmen의 폭발과 연결 가능, 곁가지) | H22: Lucía, Carmen, Javier | I22: 자치주(공공 심리 지원) | J22: 정신건강 상담 접근성, 공공 예산 | K22: salud mental, ansiedad, terapia, lista de espera | L22: 청년 정신건강을 극적 소재로만 소비하지 않는다. 낙인 없이, 도움을 구하는 것이 자연스럽다는 톤으로. | M22: 청년 불안장애·상담 대기 증가는 스페인에서 널리 보도된 추세. 최신 통계는 확인 필요
A24: 현실 기준값 (확인일 2026-09-22)
A25: No | B25: 구분 | C25: 항목 | D25: 값 | E25: 출처·비고
A26: 1 | B26: 경제 | C26: 정부 부채 / GDP | D26: 약 100% (2026.7 99.9%, 6월 101.5%) | E26: 스페인은행(Banco de España) 월간 통계. 붙여 주신 자료의 97~99%보다 조금 높다.
A27: 2 | B27: 사회 | C27: 25세 미만 실업률 | D27: 23.8% (2026 2분기), 전체 9.9% | E27: INE 경제활동인구조사(EPA). 청년 실업은 전체의 약 2.4배.
A28: 3 | B28: 정치 | C28: 현 정부 형태 | D28: 소수 연립 + 지역정당 지지 의존 | E28: 이야기에는 실존 정당·인물을 쓰지 않는다. 표현은 '여소야대'가 아니라 '소수 정부'.
A29: 4 | B29: 확인 필요 | C29: 변동이 잦은 항목 | D29: 사면법 절차, DANA 후속, NATO 목표, 이주 아동 분산, 회복기금 시한 | E29: 교재에 넣기 직전 최신 상태를 확인한다.

Sheet 현안_분포
A1: 현안 분포표 (부 × 현안)
A2: ● = 그 화의 주된 사건(전용 화), ○ = 곁가지(대사·서브플롯). 기호를 바꾸면 아래 집계가 자동 갱신됩니다.
A4: ID | B4: 현안 | C4: 1부 | D4: 2부 | E4: 3부 | F4: 4부 | G4: 5부 | H4: 6부 | I4: 7부 | J4: 8부 | K4: 9부 | L4: 10부 | M4: 11부 | N4: 12부 | O4: 13부 | P4: ● 수 | Q4: ○ 수
A5: P1 | B5: 정치 파편화·연정 불안정 | I5: ○ | J5: ○ | N5: ● | O5: ○ | P5: =COUNTIF(C5:O5,"●") | Q5: =COUNTIF(C5:O5,"○")
A6: P2 | B6: 지역 갈등·사면·재정 분권 | N6: ● | O6: ○ | P6: =COUNTIF(C6:O6,"●") | Q6: =COUNTIF(C6:O6,"○")
A7: P3 | B7: 사법부 독립·정치 대립 | D7: ○ | E7: ○ | F7: ○ | I7: ● | K7: ● | N7: ○ | P7: =COUNTIF(C7:O7,"●") | Q7: =COUNTIF(C7:O7,"○")
A8: E1 | B8: 주거난·단기 관광 임대 | C8: ○ | D8: ● | H8: ● | I8: ○ | J8: ○ | M8: ● | O8: ○ | P8: =COUNTIF(C8:O8,"●") | Q8: =COUNTIF(C8:O8,"○")
A9: E2 | B9: 저생산성·영세 기업 | C9: ○ | G9: ● | J9: ○ | N9: ○ | O9: ○ | P9: =COUNTIF(C9:O9,"●") | Q9: =COUNTIF(C9:O9,"○")
A10: E3 | B10: 부채·재정·연금 | M10: ● | N10: ● | O10: ○ | P10: =COUNTIF(C10:O10,"●") | Q10: =COUNTIF(C10:O10,"○")
A11: S1 | B11: 청년 고용 불안 | C11: ○ | G11: ○ | H11: ○ | I11: ○ | J11: ○ | O11: ● | P11: =COUNTIF(C11:O11,"●") | Q11: =COUNTIF(C11:O11,"○")
A12: S2 | B12: 이민·난민·수용 분담 | C12: ○ | E12: ○ | H12: ● | I12: ● | J12: ○ | M12: ● | P12: =COUNTIF(C12:O12,"●") | Q12: =COUNTIF(C12:O12,"○")
A13: S3 | B13: 고령화·텅 빈 스페인 | E13: ○ | K13: ● | O13: ○ | P13: =COUNTIF(C13:O13,"●") | Q13: =COUNTIF(C13:O13,"○")
A14: S4 | B14: 가뭄·폭염·에너지 전환 | E14: ● | N14: ○ | O14: ○ | P14: =COUNTIF(C14:O14,"●") | Q14: =COUNTIF(C14:O14,"○")
A15: N1 | B15: DANA·방재 | N15: ● | O15: ○ | P15: =COUNTIF(C15:O15,"●") | Q15: =COUNTIF(C15:O15,"○")
A16: N2 | B16: 회복기금 집행 | K16: ● | O16: ○ | P16: =COUNTIF(C16:O16,"●") | Q16: =COUNTIF(C16:O16,"○")
A17: N3 | B17: 국방비·NATO | M17: ● | N17: ○ | O17: ○ | P17: =COUNTIF(C17:O17,"●") | Q17: =COUNTIF(C17:O17,"○")
A18: N4 | B18: 성평등·성폭력 법 | I18: ● | J18: ○ | P18: =COUNTIF(C18:O18,"●") | Q18: =COUNTIF(C18:O18,"○")
A19: N5 | B19: 녹색 대 녹색 | L19: ● | M19: ○ | N19: ○ | P19: =COUNTIF(C19:O19,"●") | Q19: =COUNTIF(C19:O19,"○")
A20: N6 | B20: 플랫폼 노동(라이더법) | N20: ● | P20: =COUNTIF(C20:O20,"●") | Q20: =COUNTIF(C20:O20,"○")
A21: N7 | B21: 정보기관 사찰 스캔들 | N21: ● | P21: =COUNTIF(C21:O21,"●") | Q21: =COUNTIF(C21:O21,"○")
A22: N8 | B22: 청년 정신건강 | N22: ● | P22: =COUNTIF(C22:O22,"●") | Q22: =COUNTIF(C22:O22,"○")
B23: 부별 ● 수 | C23: =COUNTIF(C5:C22,"●") | D23: =COUNTIF(D5:D22,"●") | E23: =COUNTIF(E5:E22,"●") | F23: =COUNTIF(F5:F22,"●") | G23: =COUNTIF(G5:G22,"●") | H23: =COUNTIF(H5:H22,"●") | I23: =COUNTIF(I5:I22,"●") | J23: =COUNTIF(J5:J22,"●") | ... O23: =COUNTIF(O5:O22,"●") | P23: =SUM(P5:P22)
B24: 부별 ○ 수 | C24: =COUNTIF(C5:C22,"○") | D24: =COUNTIF(D5:D22,"○") | E24: =COUNTIF(E5:E22,"○") | F24: =COUNTIF(F5:F22,"○") | G24: =COUNTIF(G5:G22,"○") | H24: =COUNTIF(H5:H22,"○") | I24: =COUNTIF(I5:I22,"○") | J24: =COUNTIF(J5:J22,"○") | ... O24: =COUNTIF(O5:O22,"○") | Q24: =SUM(Q5:Q22)
A26: 읽는 법: 1~5부는 곁가지 중심이라 B1~B2 난이도를 지키고, 8·9·11·12부에서 전용 화가 몰린다. 화당 전용 현안은 1개(+곁가지 1~2개)로 제한해 낭독 분량을 지킨다. N6~N8은 12부의 신규 현안으로 각 1개 전용 화를 받는다.
A27: 현안 ID와 설명은 '현안_배치' 시트, 화별 반영은 '화별목차_전체'의 '반영 현안' 열을 참고.

Sheet 정치제도
A1: 현실 정치 제도 기준표 (스페인)
A2: 8~12부에 반영한 실제 제도. 정당·정치인은 전부 가상이며 실존 정치인의 대사는 쓰지 않는다. '검색 확인' 표시는 2026-09-22 기준 자료로 확인한 항목.
A4: 영역 | B4: 제도·규칙 | C4: 핵심 내용 | D4: 근거 | E4: 이야기 반영 | F4: 낭독 어휘 | G4: 확인 상태
A5: 정당·선거 | B5: 정당 창당 | C5: 정당은 창립자들이 서명한 acta fundacional(창립 문서)을 내무부의 Registro de Partidos Políticos에 제출·등록해야 법인격을 얻는다. | D5: LO 6/2002 (정당법) 제3조 | E5: 8부 5화 | F5: acta fundacional, estatutos, inscripción, personalidad jurídica | G5: 검색 확인 (2026-09-22)
A6: 정당·선거 | B6: 정당의 민주적 내부 운영 | C6: 정당의 내부 조직과 운영은 민주적이어야 한다. | D6: 헌법 제6조 | E6: 8부 6화 | F6: estructura interna, democrático, afiliado | G6: 기획 시점 지식 — BOE 확인 필요
