Workbook

Sheet 개요
A1: Paris 프랑스어 낭독 교재 — 캐릭터 바이블 (부활자 특별편)
A2: v1.0 · 파리 배경 13부작 옴니버스(156화) · 부활 7인 = Napoléon·Voltaire·Olympe·Jeanne·Sartre·Curie·Hugo
B4: 기본 설정
B5: 부 수 | C5: 13 | D5: 1 사무소(Belleville, 개소 1개월 후, 6사건×2화) → 2~5 각자의 과거 → 6 만남 → 7 전면전 → 8 창당·파리 시의회 선거 → 9 파리 시의회(Hôtel de Ville) → 10 대선·대통령 취임·총선(Élysée) → 11 국정 I(EU 협상·Napoléon 사망) → 12 국정 II(장례·유작 메모 승계) → 13 귀환(원형 구조)
B6: 부당 화 수 | C6: 12 | D6: 각 부 12화
B7: 총 화 수 | C7: =C5*C6 -> 156 | D7: 부 수 × 부당 화 수 (자동 계산)
B8: 등장인물 수 | C8: =COUNTA(캐릭터!$D$5:$D$19) -> 15 | D8: 캐릭터 시트의 약칭 개수
B9: 남성 인물 수 | C9: =COUNTIF(캐릭터!$G$5:$G$19,"남") -> 8 | D9: 음색이 다양할수록 화자 구분이 쉬워 남 8 : 여 7로 배분 (Olympe 포함)
B10: 여성 인물 수 | C10: =COUNTIF(캐릭터!$G$5:$G$19,"여") -> 7
B11: 1부→11부 경과 연수 (가정) | C11: 6 | D11: 가정값: Napoléon이 1부 51세(부활 시 외형 나이) → 11부 약 57세가 되도록 잡음. 확정 시 이 셀만 수정하면 캐릭터 시트의 나이가 자동 갱신. (캐릭터 시트 '나이(11부)' 열)
B12: 배경·언어 | C12: 파리 (벨빌) | D12: 표준 프랑스어: 친한 사이 tu, 공식 석상은 vous/공식 호칭.
B13: 형식 | C13: 전 화 100% 대화문, 화당 120턴 | D13: ="지문(didascalies) 없음. 화당 "&턴_설계!$B$5&"턴 × "&C7&"화 = "&TEXT(C7*턴_설계!$B$5,"#,##0")&"턴. 상세는 '대화문규칙'·'턴_설계' 시트." -> 지문(didascalies) 없음. 화당 120턴 × 156화 = 18,720턴. 상세는 '대화문규칙'·'턴_설계' 시트.
B15: 그룹별 인원
B16: 주력 4인 | C16: =COUNTIF(캐릭터!$B$5:$B$19,B16) -> 4 | D16: Nicolas(변호사)·Camille(의사)·Julien(회계사)·Léa(컨설턴트)
B17: 부활 7인 | C17: =COUNTIF(캐릭터!$B$5:$B$19,B17) -> 7 | D17: Napoléon(전 황제)·Voltaire(계몽사상가)·Olympe(여성인권가)·Jeanne(전사)·Sartre(철학자)·Curie(과학자)·Hugo(문호) ※ 각자의 시대에 죽었다가 이유 없이 현재 파리에 되살아나 사무소에 합류 (부활 시점은 인물마다 다름 — 2~5부 과거 장면에 카메오로 나오는 인물은 그때 이미 파리에 살고 있음)
B18: 서민·청년 | C18: =COUNTIF(캐릭터!$B$5:$B$19,B18) -> 3 | D18: Monique(비스트로 사장)·Karim(노조위원장)·Manon(인턴)
B19: 금융 | C19: =COUNTIF(캐릭터!$B$5:$B$19,B19) -> 1 | D19: Philippe(전 은행 지점장)
B22: 시트 안내 (클릭하면 이동)
B23: 캐릭터 | C23: 기준표 | D23: 14인의 이름·나이·결핍·말투·시그니처·낭독 포인트·대화문 장치·직책·현안 담당
B24: 등장비중 | C24: 기준표 | D24: 13부 배분표, 합계·비중·등급(수식), 조연 단독 중심 화 목표
B25: 턴_설계 | C25: 기준표 | D25: 화당 120턴 설계: 부별 화자 점유율(턴 기준), 평균 단어/턴, 화당 단어·낭독 시간(수식), 화 유형별 턴 구성, 집필 규칙
B26: 13부_구성 | C26: 구조 | D26: 13부 한눈에 보기: 배경·핵심 내용·난이도(CEFR)·반영 제도
B27: 아크_구성계획 | C27: 구성 계획 | D27: 1~13부 아크별 구성 계획: 서사 기능·로그라인·비트·인물 아크·복선·현안·언어 설계
B28: 화별목차_전체 | C28: 목차 | D28: 1~13부 156화의 서사 기능·제목(FR)·핵심 사건·반영 제도·인물·현안 (필터 가능)
B29: 복선_회수 | C29: 구성 계획 | D29: 복선 설치→회수 28건과 간격(부)을 수식으로 계산
B30: 현안_배치 | C30: 현안 | D30: 프랑스 현안 18개를 어느 화에 어떻게 녹일지 배치, 균형 유의, 현실 기준값
B31: 현안_분포 | C31: 현안 | D31: 부 × 현안 분포표: 전용 화(●)와 곁가지(○)를 수식으로 집계
B32: 정치제도 | C32: 현실 제도 | D32: 제5공화국 제도 기준표: 정당·선거·대통령·의회·정부·지방자치·사법·EU (확인 상태 표시)
B33: 정치경로_의석 | C33: 현실 제도 | D33: 창당→대통령 경로와 가상 득표·의석·표결 시뮬레이션(수식): 대선 1차·결선, 총선 577석, 불신임안(motion de censure)
B34: 호칭규칙 | C34: 규칙 | D34: tu / vous(단수 존칭) / vous(복수), 의회·대통령·시의회 공식 호칭
... B40: 변경이력_미결 | C40: 관리 | D40: 지금까지의 변경 이력과 확정이 필요한 미결 사항
B42: 범례
B43: 파란 글씨 | C43: 직접 입력한 값 (수정 가능)
B44: 노란 배경 | C44: 가정 · 확정이 필요한 값
B45: 검정 글씨 | C45: 수식으로 계산되는 값 (직접 수정하지 말 것)
B47: 주의: 성별·나이·기관명은 기획용 가상 설정입니다. 법령 번호·조항은 교재에 넣기 전에 Légifrance(legifrance.gouv.fr)의 현행 텍스트(version en vigueur)로 확인하세요.

Sheet 캐릭터
A1: 캐릭터 바이블 — 15인 (Paris 프랑스어 낭독 교재 — 캐릭터 바이블 (부활자 특별편))
A2: v1.0 · 파리 배경 13부작 옴니버스(156화) · 부활 7인 = Napoléon·Voltaire·Olympe·Jeanne·Sartre·Curie·Hugo
A4: No | B4: 그룹 | C4: 이름 | D4: 약칭 | E4: 나이 (1부) | F4: 나이 (11부) | G4: 성별 | H4: 직업·신분 | I4: 전 소속 (가상) | J4: 결핍 (Blessure) | K4: 말투 | L4: 시그니처 표현 | M4: 낭독 포인트 | N4: 대화문 장치 (지문 대체) | O4: 정치 직책 (8~13부, 제안) | P4: 1부 등장 방식 | Q4: 등장 화 수 | R4: 등급 | S4: 현안 담당 (ID)
A5: 1 | B5: 주력 4인 | C5: Nicolas Lefevre | D5: Nicolas | E5: 39 | F5: =E5+개요!$C$11 -> 45 | G5: 남 | H5: 변호사 (기업·규제 전문) | I5: Vasseur & Delorme Avocats (전 파트너 후보) | J5: 승소율은 높지만, 강제퇴거 소송에서 이긴 사건 하나가 계속 마음에 걸린다. | K5: 문장이 완결되고 격식체(접속법 사용). 초반엔 차갑게 조항을 인용, 후반엔 연설가로 성장. | L5: Procédons dans l'ordre.\nAvec tout le respect que je vous dois, ce n'est pas ce que dit la loi.\n(후반) Je ne vous demande pas de me croire. Je vous demande de lire le texte. | M5: 또박또박, 중저음. | N5: 법조문을 소리 내어 읽어 상황을 설명한다. | O5: 당 대표(8부) → 대선 후보(9부 12화) → 대통령(10부 8화 취임) | P5: 본격 | Q5: =INDEX(등장비중!$O$5:$O$19,MATCH($D5,등장비중!$A$5:$A$19,0)) -> 108 | R5: =INDEX(등장비중!$Q$5:$Q$19,MATCH($D5,등장비중!$A$5:$A$19,0)) -> 주연 | S5: P1·P3·E1
A6: 2 | B6: 주력 4인 | C6: Camille Girard | D6: Camille | E6: 41 | F6: =E6+개요!$C$11 -> 47 | G6: 여 | H6: 응급의학과 전문의 | I6: Hôpital Saint-Bernard 응급실 (가상) | J6: 살리지 못한 환자의 이름을 전부 외우고 있다. | K6: 짧고 명령형, 블랙유머. | L6: Ce n'est pas une statistique, c'est une personne.\nD'abord, respire.\nJ'ai vu pire un mardi ordinaire. | M6: 빠른 템포, 짧은 호흡. | N6: 명령형으로 행동을 말하며 진행한다. | O6: 파리 시의원·AP-HP 감독위원(9부) → 보건부 장관(11부~) | P6: 본격 | Q6: =INDEX(등장비중!$O$5:$O$19,MATCH($D6,등장비중!$A$5:$A$19,0)) -> 98 | R6: =INDEX(등장비중!$Q$5:$Q$19,MATCH($D6,등장비중!$A$5:$A$19,0)) -> 준주연 | S6: S3·S4·N8
A7: 3 | B7: 주력 4인 | C7: Julien Moreau | D7: Julien | E7: 37 | F7: =E7+개요!$C$11 -> 43 | G7: 남 | H7: 공인회계사 (감사) | I7: Bertin & Roux Audit (가상, 전 시니어 파트너) | J7: 부정을 발견하고도 서명했던 기억. | K7: 건조하고 정확, 비꼬는 유머. | L7: Montrez-moi les documents.\nÇa ne colle pas.\nMontrez-moi les chiffres, je vous dirai qui vous êtes. | M7: 일정한 속도, 결론에서 톤을 낮춘다. | N7: 숫자를 소리 내어 읽는다. | O7: 파리 시의원·예산 담당(9부) → 경제·재정부 장관(Bercy, 11부~) | P7: 본격 | Q7: =INDEX(등장비중!$O$5:$O$19,MATCH($D7,등장비중!$A$5:$A$19,0)) -> 110 | R7: =INDEX(등장비중!$Q$5:$Q$19,MATCH($D7,등장비중!$A$5:$A$19,0)) -> 주연 | S7: E3·N2
A8: 4 | B8: 주력 4인 | C8: Léa Dubois | D8: Léa | E8: 36 | F8: =E8+개요!$C$11 -> 42 | G8: 여 | H8: 전략 컨설턴트 | I8: Zénith Consulting (가상, La Défense) | J8: 구조조정 표 한 칸이 수백 명의 해고였음을 뒤늦게 안다. | K8: 영어식 경영 용어가 섞인 빠른 말투, 후반 쉬운 말로 성장. | L8: Mettons ça dans une matrice.\n(후반) Bon, sans slides : de quoi tu as vraiment besoin ? | M8: 초반 숨 가쁜 톤, 후반 솔직한 톤. | N8: 프레젠테이션식 브리핑. | O8: 선거캠프 총괄 참모(8~10부) → 엘리제궁 비서실장(secrétaire générale de l'Élysée) | P8: 본격 | Q8: =INDEX(등장비중!$O$5:$O$19,MATCH($D8,등장비중!$A$5:$A$19,0)) -> 101 | R8: =INDEX(등장비중!$Q$5:$Q$19,MATCH($D8,등장비중!$A$5:$A$19,0)) -> 준주연 | S8: E2·P1
A9: 5 | B9: 부활 7인 | C9: Napoléon Bonaparte | D9: Napoléon | E9: 51 | F9: =E9+개요!$C$11 -> 57 | G9: 남 | H9: 부활한 황제·전략가 (1769–1821) | I9: 프랑스 제1제국 황제, 세인트헬레나 유배지에서 사망 | J9: 자신의 몰락까지 전략적으로 복기하는 버릇이 있다 — 패배조차 전술적으로 설명하려 든다. 세인트헬레나에서 자신을 죽인 위(胃)의 병이 되살아났다는 것만은 숨긴다. | K9: 단호하고 명령조, 짧고 강한 문장. 자신의 전투를 예시로 모든 걸 설명한다. | L9: Impossible n'est pas français — enfin, plus maintenant, apparemment.\n(현대 용어 오해) Un « serveur » ? Un valet qui ne dort jamais. Très impérial.\n« Pare-feu » ? Nous appelions ça un siège. | M9: 짧고 단호한 톤, 명령형. | N9: 자신의 옛 전투와 현재 상황을 비교해 설명한다. | O9: 대통령 특사(외교·안보) — 11부 9~11화 브뤼셀 협상, 11부 12화 두 번째 죽음 | P9: 준본격 (겨울 복선) | Q9: =INDEX(등장비중!$O$5:$O$19,MATCH($D9,등장비중!$A$5:$A$19,0)) -> 65 | R9: =INDEX(등장비중!$Q$5:$Q$19,MATCH($D9,등장비중!$A$5:$A$19,0)) -> 핵심 조연 | S9: N3·E3
A10: 6 | B10: 부활 7인 | C10: Voltaire | D10: Voltaire | E10: 83 | F10: =E10+개요!$C$11 -> 89 | G10: 남 | H10: 부활한 계몽사상가·풍자가 (1694–1778) | I10: 『캉디드』 저자, 바스티유 투옥 경험 | J10: 자신이 그렇게 싸운 관용과 이성이 오늘날에도 여전히 부족하다는 걸 매일 확인하며 냉소로 버틴다. | K10: 신랄하고 재치 있는 풍자, 팜플렛 문체. | L10: (고전 인용) Il faut cultiver notre jardin.\n(현대 용어 재해석) « Fake news » ? Nous appelions ça la censure royale — au moins, aujourd'hui, tout le monde peut mentir également. | M10: 빠르고 재치있는 톤. | N10: 현재 사안을 풍자적 우화로 요약해 설명한다. | O10: 엘리제궁 공보·메시지 자문 | P10: 카메오 | Q10: =INDEX(등장비중!$O$5:$O$19,MATCH($D10,등장비중!$A$5:$A$19,0)) -> 63 | R10: =INDEX(등장비중!$Q$5:$Q$19,MATCH($D10,등장비중!$A$5:$A$19,0)) -> 핵심 조연 | S10: P3·N7
A11: 7 | B11: 부활 7인 | C11: Olympe de Gouges | D11: Olympe | E11: 45 | F11: =E11+개요!$C$11 -> 51 | G11: 여 | H11: 부활한 여성인권 운동가 (1748–1793) | I11: 『여성과 여성시민의 권리선언』 저자, 단두대에서 처형 | J11: 자신이 요구한 권리들이 200년이 지나서야 겨우 이뤄지는 걸 보며 조급해한다 — '이번엔 기다리지 않는다'. | K11: 열정적이고 논리적, 선언문 낭독하듯 말한다. | L11: La femme a le droit de monter à l'échafaud, elle doit avoir également celui de monter à la tribune.\n(현대 용어 오해) « Cancel culture » ? Enfin — qui déchoit-on en premier ? | M11: 빠르고 격정적, 선언문 낭독조. | N11: 선언문 형식으로 상황과 요구사항을 정리해 전달한다. | O11: 창당 전략가(8부) → 총리(Première ministre, 10부 11화 임명) | P11: 7부 1화 합류 (1부 미등장) | Q11: =INDEX(등장비중!$O$5:$O$19,MATCH($D11,등장비중!$A$5:$A$19,0)) -> 59 | R11: =INDEX(등장비중!$Q$5:$Q$19,MATCH($D11,등장비중!$A$5:$A$19,0)) -> 조연 | S11: N4·P2
A12: 8 | B12: 부활 7인 | C12: Jeanne d'Arc | D12: Jeanne | E12: 19 | F12: =E12+개요!$C$11 -> 25 | G12: 여 | H12: 부활한 전사·신비주의자 (1412–1431) | I12: 백년전쟁 프랑스군 지휘, 화형으로 처형 | J12: 아무도 믿어주지 않았던 목소리를 들었던 소녀 — 지금도 자기 확신을 의심받으면 참지 못한다. | K12: 단순하고 확신에 찬 문장, 나이답지 않게 단호하다. | L12: (현대 용어 오해) Une notification sur le téléphone ? Est-ce... une nouvelle voix ?\nJ'ai déjà mené une armée à dix-neuf ans. Une réunion, je peux gérer. | M12: 맑고 단호한 톤, 어린 목소리지만 흔들림 없다. | N12: 확신에 찬 짧은 선언으로 상황을 정리한다. | O12: 현장 조직(7부) → 대선 캠프 로지스틱스 총괄(10부) → 대통령 특별참모(위기 대응) | P12: 카메오 | Q12: =INDEX(등장비중!$O$5:$O$19,MATCH($D12,등장비중!$A$5:$A$19,0)) -> 56 | R12: =INDEX(등장비중!$Q$5:$Q$19,MATCH($D12,등장비중!$A$5:$A$19,0)) -> 조연 | S12: S3·N1
A13: 9 | B13: 부활 7인 | C13: Jean-Paul Sartre | D13: Sartre | E13: 74 | F13: =E13+개요!$C$11 -> 80 | G13: 남 | H13: 부활한 실존주의 철학자 (1905–1980) | I13: 레지스탕스 참여, 『존재와 무』 저자 | J13: 자유가 무겁다는 걸 누구보다 잘 알아서, 선택을 회피하는 사람을 보면 참지 못한다. | K13: 낮고 분석적, 인간의 자유와 책임으로 모든 상황을 재해석한다. | L13: (고전 인용) L'homme est condamné à être libre.\n(현대 용어 재해석) « Algorithme » ? Une nouvelle mauvaise foi — on choisit, mais on prétend que la machine a choisi. | M13: 느리고 낮은 톤, 담배 연기처럼 여운이 길다. | N13: 상황을 '누가 자유를 회피하고 있는가'로 짚어 설명한다. | O13: 사회·문화 정책 자문 (청년 정신건강 담당) | P13: 카메오 (카페 단골) | Q13: =INDEX(등장비중!$O$5:$O$19,MATCH($D13,등장비중!$A$5:$A$19,0)) -> 45 | R13: =INDEX(등장비중!$Q$5:$Q$19,MATCH($D13,등장비중!$A$5:$A$19,0)) -> 조연 | S13: N8·S2
A14: 10 | B14: 부활 7인 | C14: Marie Curie | D14: Curie | E14: 66 | F14: =E14+개요!$C$11 -> 72 | G14: 여 | H14: 부활한 물리·화학자 (1867–1934) | I14: 노벨상 2회 수상, 방사선 연구 중 피폭으로 사망 | J14: 자신을 죽인 바로 그 연구를 후회하지 않는다는 게 주변을 불편하게 한다 — 위험을 대수롭지 않게 여긴다. | K14: 차분하고 정확, 겸손하지만 권위에 굴하지 않는다. | L14: (현대 용어 오해) « Radiation Wi-Fi » ? Non, non — laissez-moi vous expliquer la vraie radioactivité.\nOn n'a rien à craindre dans la vie, il faut seulement comprendre. | M14: 차분하고 신중한 톤. | N14: 정확한 데이터와 실험으로 상황을 설명한다. | O14: 과학·교육 정책 자문 (12부 사찰 스캔들 기술 검증) | P14: 카메오 | Q14: =INDEX(등장비중!$O$5:$O$19,MATCH($D14,등장비중!$A$5:$A$19,0)) -> 64 | R14: =INDEX(등장비중!$Q$5:$Q$19,MATCH($D14,등장비중!$A$5:$A$19,0)) -> 핵심 조연 | S14: N7·N5
A15: 11 | B15: 서민·청년 | C15: Monique Rousseau | D15: Monique | E15: 63 | F15: =E15+개요!$C$11 -> 69 | G15: 여 | H15: 비스트로 사장 (Chez Monique, 30년 운영) | I15: Chez Monique, Belleville → 사무소 1층으로 이전 | J15: 임대료 폭등으로 가게를 잃었다. | K15: 파리 서민 구어체, 누구에게나 tu, 'mon/ma petit(e)'. | L15: Asseyez-vous, je vous apporte quelque chose.\nLe ventre vide, on ne réfléchit pas bien.\nC'est la maison qui offre. | M15: 따뜻하고 넉넉한 톤. | N15: 시간·장소·식사를 말로 알린다. | O15: 소상공인 정책 자문 (비공식) | P15: 본격 | Q15: =INDEX(등장비중!$O$5:$O$19,MATCH($D15,등장비중!$A$5:$A$19,0)) -> 69 | R15: =INDEX(등장비중!$Q$5:$Q$19,MATCH($D15,등장비중!$A$5:$A$19,0)) -> 핵심 조연 | S15: E1·S2
A16: 12 | B16: 서민·청년 | C16: Karim Belkacem | D16: Karim | E16: 55 | F16: =E16+개요!$C$11 -> 61 | G16: 남 | H16: 전 대중교통 노조위원장 | I16: RATP 버스 노조 → 노선 경쟁 입찰로 이관된 Méridien Mobilité(가상) 노조 대표, 파업 책임으로 해고 | J16: 파업 책임으로 해고되어 블랙리스트에 올랐지만 후회하지 않는다. | K16: 거칠고 직설적, 구호형 문장. | L16: Ici, personne ne se rend !\nÇa se règle dans la rue.\nÇa suffit, là. | M16: 큰 볼륨, 강한 억양. | N16: 구호와 함성으로 현장 분위기를 전달한다. | O16: 사회적 대화 자문 | P16: 카메오 | Q16: =INDEX(등장비중!$O$5:$O$19,MATCH($D16,등장비중!$A$5:$A$19,0)) -> 58 | R16: =INDEX(등장비중!$Q$5:$Q$19,MATCH($D16,등장비중!$A$5:$A$19,0)) -> 조연 | S16: S1·N6
... A19: 15 | B19: 부활 7인 | C19: Victor Hugo | D19: Hugo | E19: 83 | F19: =E19+개요!$C$11 -> 89 | G19: 남 | H19: 부활한 문호 (1802–1885) | I19: 『레미제라블』 저자, 망명 경험 | J19: 자신이 그린 빈곤과 불의가 150년 뒤에도 형태만 바뀐 채 그대로라는 걸 보며 분노를 감추지 못한다. | K19: 장엄하고 도덕적 열변, 사회정의 이야기만 나오면 톤이 올라간다. | L19: (고전 인용) Rien n'est plus puissant qu'une idée dont le temps est venu.\n(현대 용어 오해) « Influenceur » ? On dirait un nouveau vendeur d'indulgences — j'en ai déjà mis un dans mes romans. | M19: 느리고 웅장한 톤, 감정이 격해지면 목소리가 커진다. | N19: 사회 부조리를 목격한 이야기로 현재 상황을 은유한다. | O19: 연설·메시지 자문 (대통령 연설문 담당) | P19: 카메오 | Q19: =INDEX(등장비중!$O$5:$O$19,MATCH($D19,등장비중!$A$5:$A$19,0)) -> 58 | R19: =INDEX(등장비중!$Q$5:$Q$19,MATCH($D19,등장비중!$A$5:$A$19,0)) -> 조연 | S19: N5·N1

Sheet 등장비중
A1: 인물별 등장 비중 (부별 등장 화 수)
A2: 등장 화 = 대사가 있는 화 수 (기획용 초안). 파란 숫자는 직접 입력값이며 수정하면 합계·비중·등급이 자동 갱신됩니다.
A4: 인물 (약칭) | B4: 1부 사무소 | C4: 2부 Nicolas | D4: 3부 Camille | E4: 4부 Julien | F4: 5부 Léa | G4: 6부 만남 | H4: 7부 전면전 | I4: 8부 창당 | J4: 9부 파리 시의회 | K4: 10부 대선·대통령 | L4: 11부 국정 I | M4: 12부 국정 II | N4: 13부 귀환 | O4: 합계 | P4: 비중 | Q4: 등급 | R4: 검증 (≤부당 화 수) | S4: 단독 중심 화 목표 (조연)
A5: Nicolas | B5: 7 | C5: 12 | D5: 3 | E5: 3 | F5: 3 | G5: 12 | H5: 11 | I5: 12 | J5: 11 | K5: 11 | L5: 10 | M5: 3 | N5: 10 | O5: =SUM(B5:N5) -> 108 | P5: =O5/개요!$C$7 -> 0.69230769 | Q5: =IF(P5>=$B$23,"주연",IF(P5>=$B$24,"준주연",IF(P5>=$B$25,"핵심 조연","조연"))) -> 주연 | R5: =IF(MAX(B5:N5)<=개요!$C$6,"OK","확인") -> OK | S5: —
A6: Camille | B6: 6 | C6: 3 | D6: 12 | E6: 3 | F6: 3 | G6: 12 | H6: 10 | I6: 10 | J6: 8 | K6: 10 | L6: 10 | M6: 2 | N6: 9 | O6: =SUM(B6:N6) -> 98 | P6: =O6/개요!$C$7 -> 0.62820513 | Q6: =IF(P6>=$B$23,"주연",IF(P6>=$B$24,"준주연",IF(P6>=$B$25,"핵심 조연","조연"))) -> 준주연 | R6: =IF(MAX(B6:N6)<=개요!$C$6,"OK","확인") -> OK | S6: —
A7: Julien | B7: 8 | C7: 3 | D7: 3 | E7: 12 | F7: 3 | G7: 12 | H7: 11 | I7: 10 | J7: 10 | K7: 11 | L7: 10 | M7: 8 | N7: 9 | O7: =SUM(B7:N7) -> 110 | P7: =O7/개요!$C$7 -> 0.70512821 | Q7: =IF(P7>=$B$23,"주연",IF(P7>=$B$24,"준주연",IF(P7>=$B$25,"핵심 조연","조연"))) -> 주연 | R7: =IF(MAX(B7:N7)<=개요!$C$6,"OK","확인") -> OK | S7: —
A8: Léa | B8: 6 | C8: 3 | D8: 3 | E8: 3 | F8: 12 | G8: 12 | H8: 10 | I8: 11 | J8: 10 | K8: 10 | L8: 9 | M8: 3 | N8: 9 | O8: =SUM(B8:N8) -> 101 | P8: =O8/개요!$C$7 -> 0.6474359 | Q8: =IF(P8>=$B$23,"주연",IF(P8>=$B$24,"준주연",IF(P8>=$B$25,"핵심 조연","조연"))) -> 준주연 | R8: =IF(MAX(B8:N8)<=개요!$C$6,"OK","확인") -> OK | S8: —
A9: Napoléon | B9: 4 | C9: 2 | D9: 2 | E9: 2 | F9: 2 | G9: 7 | H9: 9 | I9: 7 | J9: 9 | K9: 9 | L9: 9 | M9: 0 | N9: 3 | O9: =SUM(B9:N9) -> 65 | P9: =O9/개요!$C$7 -> 0.41666667 | Q9: =IF(P9>=$B$23,"주연",IF(P9>=$B$24,"준주연",IF(P9>=$B$25,"핵심 조연","조연"))) -> 핵심 조연 | R9: =IF(MAX(B9:N9)<=개요!$C$6,"OK","확인") -> OK | S9: —
A10: Voltaire | B10: 2 | C10: 1 | D10: 1 | E10: 3 | F10: 1 | G10: 5 | H10: 10 | I10: 7 | J10: 8 | K10: 8 | L10: 7 | M10: 3 | N10: 7 | O10: =SUM(B10:N10) -> 63 | P10: =O10/개요!$C$7 -> 0.40384615 | Q10: =IF(P10>=$B$23,"주연",IF(P10>=$B$24,"준주연",IF(P10>=$B$25,"핵심 조연","조연"))) -> 핵심 조연 | R10: =IF(MAX(B10:N10)<=개요!$C$6,"OK","확인") -> OK | S10: —
A11: Olympe | B11: 0 | C11: 0 | D11: 1 | E11: 0 | F11: 0 | G11: 3 | H11: 8 | I11: 9 | J11: 6 | K11: 9 | L11: 9 | M11: 8 | N11: 6 | O11: =SUM(B11:N11) -> 59 | P11: =O11/개요!$C$7 -> 0.37820513 | Q11: =IF(P11>=$B$23,"주연",IF(P11>=$B$24,"준주연",IF(P11>=$B$25,"핵심 조연","조연"))) -> 조연 | R11: =IF(MAX(B11:N11)<=개요!$C$6,"OK","확인") -> OK | S11: —
A12: Jeanne | B12: 3 | C12: 1 | D12: 2 | E12: 1 | F12: 2 | G12: 4 | H12: 7 | I12: 8 | J12: 6 | K12: 7 | L12: 6 | M12: 2 | N12: 7 | O12: =SUM(B12:N12) -> 56 | P12: =O12/개요!$C$7 -> 0.35897436 | Q12: =IF(P12>=$B$23,"주연",IF(P12>=$B$24,"준주연",IF(P12>=$B$25,"핵심 조연","조연"))) -> 조연 | R12: =IF(MAX(B12:N12)<=개요!$C$6,"OK","확인") -> OK | S12: —
A13: Sartre | B13: 1 | C13: 1 | D13: 1 | E13: 2 | F13: 1 | G13: 4 | H13: 6 | I13: 6 | J13: 5 | K13: 6 | L13: 6 | M13: 1 | N13: 5 | O13: =SUM(B13:N13) -> 45 | P13: =O13/개요!$C$7 -> 0.28846154 | Q13: =IF(P13>=$B$23,"주연",IF(P13>=$B$24,"준주연",IF(P13>=$B$25,"핵심 조연","조연"))) -> 조연 | R13: =IF(MAX(B13:N13)<=개요!$C$6,"OK","확인") -> OK | S13: —
A14: Curie | B14: 3 | C14: 1 | D14: 1 | E14: 1 | F14: 1 | G14: 6 | H14: 8 | I14: 9 | J14: 8 | K14: 8 | L14: 7 | M14: 4 | N14: 7 | O14: =SUM(B14:N14) -> 64 | P14: =O14/개요!$C$7 -> 0.41025641 | Q14: =IF(P14>=$B$23,"주연",IF(P14>=$B$24,"준주연",IF(P14>=$B$25,"핵심 조연","조연"))) -> 핵심 조연 | R14: =IF(MAX(B14:N14)<=개요!$C$6,"OK","확인") -> OK | S14: —
A15: Monique | B15: 12 | C15: 2 | D15: 2 | E15: 2 | F15: 2 | G15: 5 | H15: 8 | I15: 6 | J15: 4 | K15: 5 | L15: 8 | M15: 3 | N15: 10 | O15: =SUM(B15:N15) -> 69 | P15: =O15/개요!$C$7 -> 0.44230769 | Q15: =IF(P15>=$B$23,"주연",IF(P15>=$B$24,"준주연",IF(P15>=$B$25,"핵심 조연","조연"))) -> 핵심 조연 | R15: =IF(MAX(B15:N15)<=개요!$C$6,"OK","확인") -> OK | S15: —
A16: Karim | B16: 2 | C16: 1 | D16: 2 | E16: 1 | F16: 3 | G16: 5 | H16: 9 | I16: 8 | J16: 6 | K16: 6 | L16: 7 | M16: 2 | N16: 6 | O16: =SUM(B16:N16) -> 58 | P16: =O16/개요!$C$7 -> 0.37179487 | Q16: =IF(P16>=$B$23,"주연",IF(P16>=$B$24,"준주연",IF(P16>=$B$25,"핵심 조연","조연"))) -> 조연 | R16: =IF(MAX(B16:N16)<=개요!$C$6,"OK","확인") -> OK | S16: —
... A19: Hugo | B19: 1 | C19: 1 | D19: 1 | E19: 1 | F19: 1 | G19: 4 | H19: 6 | I19: 9 | J19: 7 | K19: 9 | L19: 7 | M19: 4 | N19: 7 | O19: =SUM(B19:N19) -> 58 | P19: =O19/개요!$C$7 -> 0.37179487 | Q19: =IF(P19>=$B$23,"주연",IF(P19>=$B$24,"준주연",IF(P19>=$B$25,"핵심 조연","조연"))) -> 조연 | R19: =IF(MAX(B19:N19)<=개요!$C$6,"OK","확인") -> OK | S19: —
A20: 부별 연인원 (합계) | B20: =SUM(B5:B19) -> 69 | C20: =SUM(C5:C19) -> 36 | D20: =SUM(D5:D19) -> 39 | E20: =SUM(E5:E19) -> 41 | F20: =SUM(F5:F19) -> 39 | G20: =SUM(G5:G19) -> 104 | H20: =SUM(H5:H19) -> 131 | I20: =SUM(I5:I19) -> 127 | ... O20: =SUM(O5:O19) -> 1109 | S20: =SUM(S5:S19) -> 0
A23: 주연 | B23: 0.69 | C23: ← 기준값은 제안값입니다. 인원 재배정(총리 Olympe 신설) 후 등급은 수식이 자동 계산합니다.
A24: 준주연 | B24: 0.6
A25: 핵심 조연 | B25: 0.4
A26: 조연 | B26: 그 미만
A28: 배분 원칙
A29: 1. 1부는 개소 1개월 후 시점: Manon·Monique가 전 화에, 주력 4인은 사건별로 2~3인씩 교대 등장(전원 겹치지 않음). Napoléon 4화, Curie 3화(1·2·6화)로 자주 얼굴을 비추고 '이번 겨울이 마지막' 복선을 1화부터 깐다. 나머지는 사건마다 다른 조합으로 카메오.
A30: 2. 2~5부: 각 주인공이 자기 부 12화 전부에 나오고, 다른 주력 3인은 3화씩 스쳐 지나가며 6부 만남을 예고. Manon은 4화씩 '사무소에서 이야기를 듣는 프레임'으로 등장해 회상을 잇는다.
A31: 3. 조연은 과거와 겹치는 곳에만 배치: Karim-5부(Léa의 구조조정 현장), Philippe·Voltaire-4부(Julien의 감사 사건), Sartre-3부·5부(카페에서의 되묻기).
A32: 4. 조연 본격 비중은 7~10부에서 최고치: 7부 Voltaire·Karim·Olympe(공론화·현장 조직·피해자 사건), 8부 Hugo·Sartre·Jeanne·Olympe(선언문·메시지·캠프·창당), 10부 Hugo·Voltaire·Curie(취임 연설·공보·출처).
A33: 5. 11부(국정 I)는 Napoléon이 9~12화에서 브뤼셀 직접 협상을 이끌며 최고치(9화)를 찍고 12화에서 사망한다. Philippe는 앞선 주거·금융 국내 현안 화에서 정점. 총리 Olympe는 11~12부 내내 의회 전선을 맡는다.
A34: 6. 12부(국정 II)는 Napoléon 사후: 1화 장례식에서 Jeanne·Curie·Camille가 몰리고, Julien·Hugo가 유작 메모를 이어받는 3화에서 비중이 오른다.
A35: 7. 13부(귀환)는 원형 구조: Manon 12화 전부, Monique 10화. Napoléon은 유언장·회상으로 3화, Nicolas·Camille·Julien·Léa는 사무소의 손님으로 9~10화 등장.
A36: 8. Napoléon은 11부 12화(브뤼셀 승리 직후)에서 사망한다. 12부 1화 장례식, 2·3화 유작 메모 승계, 13부 2화 유언장까지 이어진다.
A37: 9. 등장 화 수와 대사량은 다르다: Manon은 등장이 많지만 문장이 짧아 대사량은 Nicolas의 절반 이하가 되게 하고, Napoléon·Hugo는 화당 대사가 길어도 된다.
A38: 10. 조연은 화 전체의 중심이 되는 에피소드를 각자 2개 이상 배정(S열 목표). 자기 이야기가 한 번도 없으면 얇은 인물이 된다.
A39: 11. Sartre가 가장 얇다: 3·5부 카페 장면을 늘리거나, 12부 Napoléon 애도 장면을 맡겨 서사를 넓히는 안을 검토.

Sheet 턴_설계
A1: 대화량 설계: 화당 120턴
A2: 한 화 = 대화 120턴, 전체 156화 = 18,720턴. 점유율·평균 단어/턴·배율·낭독 속도는 가정값(파란 숫자)이며 수정하면 아래 표가 자동 갱신됩니다.
A4: 1. 기본 설정
A5: 화당 대화 턴 | B5: 120
A6: 낭독 속도 (단어/분, 가정) | B6: 130
A7: 총 화 수 | B7: =개요!$C$7 -> 156
A8: 총 대화 턴 | B8: =B5*B7 -> 18720
A9: 턴 정의 | B9: 화자 표기 한 줄 = 1턴 (화자가 바뀌면 새 턴). 연설·조항·기사 낭독처럼 긴 발화도 1턴으로 센다.
A11: 2. 부별 화자 점유율 (턴 기준, 각 부의 합 = 100%)
A12: 인물 | B12: 평균 단어/턴 | C12: 1부 | D12: 2부 | E12: 3부 | F12: 4부 | G12: 5부 | H12: 6부 | I12: 7부 | J12: 8부 | K12: 9부 | L12: 10부 | M12: 11부 | N12: 12부 | O12: 13부
A13: Nicolas | B13: 13 | C13: 0.13 | D13: 0.48 | E13: 0.03 | F13: 0.02 | G13: 0.02 | H13: 0.13 | I13: 0.14 | J13: 0.11 | K13: 0.08 | L13: 0.15 | M13: 0.11 | N13: 0.11 | O13: 0.06
A14: Camille | B14: 8 | C14: 0.12 | D14: 0.03 | E14: 0.46 | F14: 0.04 | G14: 0.03 | H14: 0.12 | I14: 0.07 | J14: 0.08 | K14: 0.11 | L14: 0.06 | M14: 0.09 | N14: 0.09 | O14: 0.06
A15: Julien | B15: 11 | C15: 0.12 | D15: 0.04 | E15: 0.04 | F15: 0.46 | G15: 0.04 | H15: 0.12 | I15: 0.1 | J15: 0.09 | K15: 0.15 | L15: 0.08 | M15: 0.11 | N15: 0.13 | O15: 0.07
A16: Léa | B16: 12 | C16: 0.12 | D16: 0.05 | E16: 0.03 | F16: 0.03 | G16: 0.46 | H16: 0.12 | I16: 0.06 | J16: 0.09 | K16: 0.08 | L16: 0.11 | M16: 0.08 | N16: 0.08 | O16: 0.07
A17: Napoléon | B17: 14 | C17: 0.08 | D17: 0.04 | E17: 0.04 | F17: 0.04 | G17: 0.04 | H17: 0.04 | I17: 0.06 | J17: 0.05 | K17: 0.04 | L17: 0.06 | M17: 0.04 | N17: 0 | O17: 0.02
A18: Olympe | B18: 11 | C18: 0 | D18: 0 | E18: 0.01 | F18: 0 | G18: 0 | H18: 0.02 | I18: 0.05 | J18: 0.05 | K18: 0.03 | L18: 0.06 | M18: 0.06 | N18: 0.06 | O18: 0.03
A19: Jeanne | B19: 7 | C19: 0.02 | D19: 0.01 | E19: 0.01 | F19: 0.01 | G19: 0.01 | H19: 0.05 | I19: 0.06 | J19: 0.06 | K19: 0.04 | L19: 0.08 | M19: 0.07 | N19: 0.07 | O19: 0.06
A20: Curie | B20: 9 | C20: 0.02 | D20: 0.01 | E20: 0.01 | F20: 0.01 | G20: 0.01 | H20: 0.03 | I20: 0.06 | J20: 0.03 | K20: 0.04 | L20: 0.03 | M20: 0.05 | N20: 0.05 | O20: 0.08
A21: Voltaire | B21: 10 | C21: 0.02 | D21: 0.01 | E21: 0.03 | F21: 0.04 | G21: 0.01 | H21: 0.03 | I21: 0.08 | J21: 0.06 | K21: 0.07 | L21: 0.05 | M21: 0.06 | N21: 0.06 | O21: 0.05
A22: Sartre | B22: 9 | C22: 0.01 | D22: 0.01 | E22: 0.04 | F22: 0.01 | G22: 0.04 | H22: 0.03 | I22: 0.05 | J22: 0.06 | K22: 0.04 | L22: 0.05 | M22: 0.04 | N22: 0.04 | O22: 0.05
A23: Monique | B23: 9 | C23: 0.12 | D23: 0.04 | E23: 0.03 | F23: 0.03 | G23: 0.03 | H23: 0.05 | I23: 0.04 | J23: 0.05 | K23: 0.03 | L23: 0.04 | M23: 0.04 | N23: 0.04 | O23: 0.13
A24: Karim | B24: 10 | C24: 0.01 | D24: 0.02 | E24: 0.01 | F24: 0.01 | G24: 0.09 | H24: 0.05 | I24: 0.06 | J24: 0.08 | K24: 0.08 | L24: 0.06 | M24: 0.05 | N24: 0.05 | O24: 0.05
... A28: 엑스트라(가상) | B28: 10 | C28: 0.03 | D28: 0.15 | E28: 0.16 | F28: 0.13 | G28: 0.12 | H28: 0.05 | I28: 0.02 | J28: 0.02 | K28: 0.02 | L28: 0.02 | M28: 0.02 | N28: 0.02 | O28: 0.02
A29: 합계 | C29: =SUM(C13:C28) -> 1 | D29: =SUM(D13:D28) -> 1 | E29: =SUM(E13:E28) -> 1 | F29: =SUM(F13:F28) -> 1 | G29: =SUM(G13:G28) -> 1 | H29: =SUM(H13:H28) -> 1 | I29: =SUM(I13:I28) -> 1 | J29: =SUM(J13:J28) -> 1 | ... O29: =SUM(O13:O28) -> 1
A30: 검증 | C30: =IF(ROUND(C29,4)=1,"OK","확인") -> OK | D30: =IF(ROUND(D29,4)=1,"OK","확인") -> OK | E30: =IF(ROUND(E29,4)=1,"OK","확인") -> OK | F30: =IF(ROUND(F29,4)=1,"OK","확인") -> OK | G30: =IF(ROUND(G29,4)=1,"OK","확인") -> OK | H30: =IF(ROUND(H29,4)=1,"OK","확인") -> OK | I30: =IF(ROUND(I29,4)=1,"OK","확인") -> OK | J30: =IF(ROUND(J29,4)=1,"OK","확인") -> OK | ... O30: =IF(ROUND(O29,4)=1,"OK","확인") -> OK
A32: 3. 부별 턴·단어·낭독 시간 (수식)
A33: 부 | B33: 난이도 배율 | C33: 화당 턴 | D33: 부 총 턴 | E33: 평균 단어/턴 | F33: 화당 단어 | G33: 부 총 단어 | H33: 화당 낭독 (분) | I33: 부 총 낭독 (시간)
A34: 1부 | B34: 0.8 | C34: =$B$5 -> 120 | D34: =C34*개요!$C$6 -> 1440 | E34: =SUMPRODUCT(C$13:C$28,$B$13:$B$28)*B34 -> 8.128 | F34: =C34*E34 -> 975.36 | G34: =F34*개요!$C$6 -> 11704.32 | H34: =F34/$B$6 -> 7.5027692 | I34: =H34*개요!$C$6/60 -> 1.5005538
A35: 2부 | B35: 1 | C35: =$B$5 -> 120 | D35: =C35*개요!$C$6 -> 1440 | E35: =SUMPRODUCT(D$13:D$28,$B$13:$B$28)*B35 -> 11.39 | F35: =C35*E35 -> 1366.8 | G35: =F35*개요!$C$6 -> 16401.6 | H35: =F35/$B$6 -> 10.513846 | I35: =H35*개요!$C$6/60 -> 2.1027692
A36: 3부 | B36: 1 | C36: =$B$5 -> 120 | D36: =C36*개요!$C$6 -> 1440 | E36: =SUMPRODUCT(E$13:E$28,$B$13:$B$28)*B36 -> 9.12 | F36: =C36*E36 -> 1094.4 | G36: =F36*개요!$C$6 -> 13132.8 | H36: =F36/$B$6 -> 8.4184615 | I36: =H36*개요!$C$6/60 -> 1.6836923
A37: 4부 | B37: 1 | C37: =$B$5 -> 120 | D37: =C37*개요!$C$6 -> 1440 | E37: =SUMPRODUCT(F$13:F$28,$B$13:$B$28)*B37 -> 10.44 | F37: =C37*E37 -> 1252.8 | G37: =F37*개요!$C$6 -> 15033.6 | H37: =F37/$B$6 -> 9.6369231 | I37: =H37*개요!$C$6/60 -> 1.9273846
A38: 5부 | B38: 1 | C38: =$B$5 -> 120 | D38: =C38*개요!$C$6 -> 1440 | E38: =SUMPRODUCT(G$13:G$28,$B$13:$B$28)*B38 -> 10.8 | F38: =C38*E38 -> 1296 | G38: =F38*개요!$C$6 -> 15552 | H38: =F38/$B$6 -> 9.9692308 | I38: =H38*개요!$C$6/60 -> 1.9938462
A39: 6부 | B39: 1 | C39: =$B$5 -> 120 | D39: =C39*개요!$C$6 -> 1440 | E39: =SUMPRODUCT(H$13:H$28,$B$13:$B$28)*B39 -> 10.18 | F39: =C39*E39 -> 1221.6 | G39: =F39*개요!$C$6 -> 14659.2 | H39: =F39/$B$6 -> 9.3969231 | I39: =H39*개요!$C$6/60 -> 1.8793846
A40: 7부 | B40: 1 | C40: =$B$5 -> 120 | D40: =C40*개요!$C$6 -> 1440 | E40: =SUMPRODUCT(I$13:I$28,$B$13:$B$28)*B40 -> 10.4 | F40: =C40*E40 -> 1248 | G40: =F40*개요!$C$6 -> 14976 | H40: =F40/$B$6 -> 9.6 | I40: =H40*개요!$C$6/60 -> 1.92
A41: 8부 | B41: 1.1 | C41: =$B$5 -> 120 | D41: =C41*개요!$C$6 -> 1440 | E41: =SUMPRODUCT(J$13:J$28,$B$13:$B$28)*B41 -> 11.418 | F41: =C41*E41 -> 1370.16 | G41: =F41*개요!$C$6 -> 16441.92 | H41: =F41/$B$6 -> 10.539692 | I41: =H41*개요!$C$6/60 -> 2.1079385
A42: 9부 | B42: 1.1 | C42: =$B$5 -> 120 | D42: =C42*개요!$C$6 -> 1440 | E42: =SUMPRODUCT(K$13:K$28,$B$13:$B$28)*B42 -> 11.187 | F42: =C42*E42 -> 1342.44 | G42: =F42*개요!$C$6 -> 16109.28 | H42: =F42/$B$6 -> 10.326462 | I42: =H42*개요!$C$6/60 -> 2.0652923
A43: 10부 | B43: 1.2 | C43: =$B$5 -> 120 | D43: =C43*개요!$C$6 -> 1440 | E43: =SUMPRODUCT(L$13:L$28,$B$13:$B$28)*B43 -> 12.708 | F43: =C43*E43 -> 1524.96 | G43: =F43*개요!$C$6 -> 18299.52 | H43: =F43/$B$6 -> 11.730462 | I43: =H43*개요!$C$6/60 -> 2.3460923
A44: 11부 | B44: 1.2 | C44: =$B$5 -> 120 | D44: =C44*개요!$C$6 -> 1440 | E44: =SUMPRODUCT(M$13:M$28,$B$13:$B$28)*B44 -> 12.252 | F44: =C44*E44 -> 1470.24 | G44: =F44*개요!$C$6 -> 17642.88 | H44: =F44/$B$6 -> 11.309538 | I44: =H44*개요!$C$6/60 -> 2.2619077
A45: 12부 | B45: 1.2 | C45: =$B$5 -> 120 | D45: =C45*개요!$C$6 -> 1440 | E45: =SUMPRODUCT(N$13:N$28,$B$13:$B$28)*B45 -> 12.132 | F45: =C45*E45 -> 1455.84 | G45: =F45*개요!$C$6 -> 17470.08 | H45: =F45/$B$6 -> 11.198769 | I45: =H45*개요!$C$6/60 -> 2.2397538
A46: 13부 | B46: 0.8 | C46: =$B$5 -> 120 | D46: =C46*개요!$C$6 -> 1440 | E46: =SUMPRODUCT(O$13:O$28,$B$13:$B$28)*B46 -> 7.616 | F46: =C46*E46 -> 913.92 | G46: =F46*개요!$C$6 -> 10967.04 | H46: =F46/$B$6 -> 7.0301538 | I46: =H46*개요!$C$6/60 -> 1.4060308
...

Sheet 13부_구성
A1: 13부 구성 (13부 × 12화 = 156화)
A2: 정치 파트(8~12부)는 프랑스 제5공화국 제도에 맞춰 재설계했습니다. 화별 목차는 '화별목차_전체', 제도 근거는 '정치제도' 시트.
A4: 부 | B4: 제목 (FR) | C4: 한국어 | D4: 배경 | E4: 핵심 내용 | F4: 난이도 (CEFR) | G4: 반영 제도·전문 영역 | H4: 시점
A5: 1 | B5: Le Cabinet de Belleville | C5: 벨빌 사무소 | D5: Belleville의 작은 사무실 (1층은 Monique의 비스트로), 개소 1개월 후 | E5: 이미 한 달째 좌충우돌 중인 팀이 이웃들의 사건 6개를 2화씩(도입→해결) 풀어 간다. 자기소개 대신 '이 사람들이 어쩌다 이렇게 됐지?' 하는 궁금증(in medias res)으로 시작. | F5: B1 | G5: 생활 법률·노동·의료·금융 기초 어휘, 반복되는 말다툼, Manon 1차 폭발(6화) | H5: 현재(개소 후 1개월)
A6: 2 | B6: L'Avocat | C6: 변호사 | D6: 8구 avenue George-V의 대형 로펌 | E6: 승소율 100%의 이면: 강제퇴거 사건이 Nicolas의 결핍이 된다. | F6: B2~C1 | G6: 임대차(1989년 법), 퇴거 절차, 소송(assignation, audience, jugement) | H6: 과거
A7: 3 | B7: La Médecin | C7: 의사 | D7: Hôpital Saint-Bernard 응급실 (가상) | E7: 예산 압박과 컨설팅·외주 속에서 치료받지 못하는 환자들. Camille의 이름 목록. | F7: B2~C1 | G7: 응급의학·병원 행정, ARS·AP-HP 체계, 병원 외주(externalisation)와 컨설팅 계약 | H7: 과거
A8: 4 | B8: L'Auditeur | C8: 회계감사인 | D8: Bertin & Roux Audit (가상) | E8: 룩셈부르크 지주회사를 통한 탈세·자금세탁 정황을 발견하지만 조직의 묵인 압박. 다시는 서명하지 않겠다는 다짐의 기원. | F8: B2~C1 | G8: 법정감사(commissaire aux comptes), 자금세탁방지(TRACFIN), 감사인 독립성(H2A) | H8: 과거
A9: 5 | B9: La Consultante | C9: 컨설턴트 | D9: Zénith Consulting (가상), La Défense 32층 | E9: 구조조정 엑셀 한 칸이 수백 명의 실직이었음을 깨닫는다. Karim과의 첫 접점. | F9: B2~C1 | G9: 경영 전략, 고용보호계획(PSE), 노동법(Code du travail) | H9: 과거
A10: 6 | B10: La Rencontre | C10: 운명적 만남 | D10: Saint-Denis의 서민 주거 단지(cité), 작은 카페 | E10: 강제퇴거와 의료 방치가 한 건으로 얽힌 사건에서 네 사람이 만나 사무소를 차리기로 한다. | F10: B2 | G10: 협상·설득 구어체 | H10: 현재로 수렴
A11: 7 | B11: Le Réseau de résistance | C11: 사무소 2탄: 전면전 | D11: 법원, 시청 앞, 파리 전역 | E11: 부당 해고·의료 사고·탈세 대기업 상대 집단 대응. 내부고발자를 보호하고 반부패 단체의 사소(私訴, partie civile)로 고소한다. | F11: B2~C1 | G11: plainte avec constitution de partie civile, 국가금융검찰(PNF), 내부고발자 보호(Sapin II·2022년 법) | H11: 과거→현재
A12: 8 | B12: L'Éveil citoyen | C12: 정치적 각성과 창당 | D12: Place de la République, 시민 집회 | E12: 하원 시민청원이 본회의 토론에서 멈추자 스스로 정당 «Maison Commune»을 창당해 파리 시의회 선거(municipales)에 나선다. | F12: B2~C1 | G12: 시위 사전 신고, 하원 시민청원(pétition), 정당 결성(1901년 결사법·1988년 정치자금법), 선거운동 규칙 | H12: 정치
A13: 9 | B13: À l'Hôtel de Ville | C13: 파리 시의회 | D13: Hôtel de Ville(파리 시청), Conseil de Paris, AP-HP 감독위원회 | E13: Julien은 예산을, Camille는 보건(시립 보건센터·AP-HP)을 파고든다. 스캔들 폭로와 Manon의 2차 폭발. 마지막 화에서 Nicolas가 대선 출마를 선언한다. | F13: C1 | G13: Conseil de Paris, 예산·결산(CFU), 공공조달(Code de la commande publique), 지방재정감사원(CRC) | H13: 정치
A14: 10 | B14: Vers l'Élysée | C14: 대선에서 대통령 취임까지 | D14: Conseil constitutionnel, TV 토론 스튜디오, Élysée, Assemblée nationale | E14: 추천서 500장 → 1차 투표 2위 → 결선 승리 → 취임 → 국회 해산·총선(상대다수) → 총리 Olympe 임명 → 불신임안 1표 차 부결. | F14: C1~C2 | G14: 대선 2회 투표제(헌법 제6·7조), 추천서(parrainages), 해산(제12조), 총리 임명(제8조), 불신임안(제49조) | H14: 정치
A15: 11 | B15: La Grande Bataille sociale I | C15: 사회 현안 전투 I | D15: Élysée, Matignon, 국무회의(Conseil des ministres), 브뤼셀 | E15: 상대다수 정부로 주거·보건·이민·청년·물가 국내 현안을 돌파한 뒤, Napoléon이 대통령 특사로 브뤼셀 협상(NATO 방위비·EU 재정규칙)에 나서 승리하고 귀국 직후 사망한다. | F15: C1~C2 | G15: 국무회의(수요일), 대통령–총리 권한 분담, NATO 방위비 목표(2025 헤이그 합의), EU 과도한 적자 절차 | H15: 정치
A16: 12 | B16: La Grande Bataille sociale II | C16: 사회 현안 전투 II | D16: Élysée, Matignon, 브뤼셀, 재난 현장 | E16: 장례식으로 열고 Napoléon의 유작 메모로 브뤼셀 후속 협상을 마무리한다. 플랫폼 노동·정보기관 사찰·청년 정신건강 등 새 현안과 불신임안 방어, 남부 급류 재난, 예산안까지. | F16: C1~C2 | G16: 메모 승계, 법률 vs 명령(ordonnance·décret), 헌법재판소(Conseil constitutionnel), 불신임안, ORSEC 재난 체계, 예산(제47조) | H16: 정치
A17: 13 | B17: Retour à Belleville | C17: 귀환 | D17: Belleville, Chez Monique | E17: 1부 1화와 같은 대사로 시작해 원을 닫는다. Napoléon의 유언장(이각모), 새 인턴, 이제 설명하는 쪽이 된 Manon. | F17: B1~B2 | G17: 유언(notaire, exécuteur testamentaire), 고위공직 겸직 제한(HATVP), 재단 전환, 원형 구조 | H17: 귀환
A19: 흐름: 현재(1) → 과거(2~5) → 교차(6) → 전면전(7) → 정치(8 창당·시의회 선거 → 9 파리 시의회 → 10 대선·대통령·총선) → 정부(11~12) → 귀환(13, 원형 구조). 난이도는 B1 → C1/C2 → B1~B2로 올라갔다 내려와 마무리가 부드럽고, 13부에서 1부 장면을 다시 읽으면 낭독 실력의 성장을 스스로 확인할 수 있다.

Sheet 아크_구성계획
A1: 아크별 구성 계획 (1~13부)
A2: 각 부(아크)의 서사 기능, 변화, 비트(발단→결말), 인물 아크, 복선, 현안·제도, 언어 설계를 한 블록으로 정리. 화별 세부는 '화별목차_전체', 복선 추적은 '복선_회수'.
A4: 1부 | B4: Le Cabinet de Belleville — 벨빌 사무소 | 난이도 B1 | 사무소 개소 1개월 후(6부 12화로부터 약 4주). Belleville 사무소와 1층 Monique의 비스트로.
A5: 서사 기능 | B5: 독자 진입 장치. 이미 굴러가는(그러나 여전히 좌충우돌하는) 사무소를 보여 주어 '이 사람들이 어쩌다 이렇게 됐지?' 하는 궁금증을 만든다. 자기소개 대신 여섯 사건을 통해 인물의 습관과 리듬을 익히게 한다.
A6: 로그라인 | B6: 개소 한 달째, 여전히 순서 하나 못 정하고 매번 다투는 네 전문가와 팀이 그래도 이웃들의 사건 여섯 개를 하나씩 해결해 나가지만, 마지막 사건의 서류에서 Nicolas의 옛 로펌 이름이 튀어나온다.
A7: 변화 (시작 → 끝) | B7: '한 달이나 됐는데 아직도 이 모양' → 그래도 매번 어떻게든 해결하는 팀이라는 신뢰. 그러나 각자의 과거는 여전히 미해결이고, 옛 로펌 이름이 도착한다.
A8: 핵심 갈등 | B8: 전문가의 말투 vs 이웃의 삶 / 여전히 못 정한 방법 / 각자 숨기는 과거
A9: 비트 1 | B9: 사건1 임대료 인상, 1~2화(Fatima): 도입에서 여전히 자리 못 잡은 한 달 차 팀의 말다툼을 보여 주고, 해결에서 Curie의 카드 #1(1989년 임대차법·IRL)로 부당 인상을 막는다.
A10: 비트 2 | B10: 사건2 퇴거 집행, 3~4화: 겨울 퇴거 유예가 끝나는 밤의 급보 → 아침 집행 저지. Jeanne·Karim 첫 카메오, 넷의 역할 분담(서류·건강·숫자·동선)이 처음으로 손발이 맞는다.
A11: 비트 3 | B11: 사건3 임금 체불, 5~6화: Léa의 컨설팅 용어가 청년 노동자를 지치게 하고, 협상 중 Manon이 1차 폭발한다. 폭발 후 쉬운 말로 다시 협상해 해결.
A12: 비트 4 | B12: 사건4 의료 접근, 7~8화: 서류 없는 가족의 아이가 진료를 못 받는다. Sartre·Hugo 카메오, Napoléon의 가짜 무릎 통증이 진짜 아픈 아이 앞에서 조용해지는 대비.
A13: 비트 5 | B13: 사건5 금융 사기, 9~10화: 저축을 잃은 이웃을 두고 Julien이 장부를, 낯선 Philippe가 계좌 흐름을 추적한다. Voltaire 카메오. Philippe는 설명 없이 사라지고 Julien은 은행 이름에 말없이 굳는다.
A14: 비트 6 | B14: 사건6 오래된 서류·훅, 11~12화: 수십 년 전 퇴거 서류의 절차 하자를 바로잡다가 서명란에서 Nicolas의 옛 로펌 이름을 발견한다. Nicolas가 얼어붙고 금요일 이야기(2부)가 예고된다.
A15: 인물 아크 | B15: Manon=독자의 대리인(질문), 한 달이 지나도 Nicolas에게 vous 유지. Napoléon=심술과 복선(매년 하는 소리라는 게 드러남). Monique=정서적 중심. 카메오는 사건별로 분산: Curie(1·2·6화), Jeanne·Karim(3·4화), Sartre·Hugo(7화), Philippe·Voltaire(9·10·11화). 폭발 화(6화)에는 Jeanne·Monique·Curie의 고정 반응만 남기고 Karim의 욕은 9부 2차 폭발로 이관해 과밀을 해소.
... A19: 언어 설계 | B19: B1. 한 줄 15단어 이내, 현재·명령형·복합과거(passé composé). tu·vous 대비 중심. 낭독: 빠른 티키타카로 입 풀기. Nicolas·Napoléon의 격식체는 한두 줄 맛보기. 매 사건 2화(도입→해결) 리듬을 반복해 구조를 익히게 한다.
A20: 대화량 (화당 120턴) | B20: ="화당 "&턴_설계!$B$5&"턴 · 부 총 "&TEXT(턴_설계!D34,"#,##0")&"턴 · 화당 약 "&TEXT(턴_설계!F34,"#,##0")&"단어 · 낭독 약 "&TEXT(턴_설계!H34,"0.0")&"분 (평균 "&TEXT(턴_설계!E34,"0.0")&"단어/턴)" -> 화당 120턴 · 부 총 1,440턴 · 화당 약 975단어 · 낭독 약 7.5분 (평균 8.1단어/턴)
A21: Manon 질문·Curie 카드 | B21: Manon: 임대·노동·의료·금융 기초 용어(dépôt de garantie, CDD, domiciliation, compte bancaire). 카드: 1989년 7월 6일 법, 사전(아카데미 프랑세즈 사전·CNRTL).
A22: 다음 부 연결 | B22: 2부: 금요일마다 한 명씩 과거를 이야기하는 규칙 — 첫 번째는 Nicolas.
A24: 2부 | B24: L'Avocat — 변호사 | 난이도 B2~C1 | 프레임: 1부와 같은 첫 겨울의 금요일 밤. 과거: 약 5년 전, 8구 avenue George-V의 대형 로펌.
A25: 서사 기능 | B25: 첫 과거 회상. 공동 악역 Groupe Méridien을 도입하고 '법을 잘 쓰는 것과 옳은 것은 다르다'는 이 이야기의 첫 질문을 던진다. 프레임(Monique의 식탁)과 과거를 오가는 구조 실험.
A26: 로그라인 | B26: 승소율 100%의 파트너 후보가 대형 고객의 주택 포트폴리오를 비우는 조항을 설계해 재판에서 이기고, 그 승리가 한 노인의 죽음이 되었음을 알게 된다.
A27: 변화 (시작 → 끝) | B27: 자랑스러운 승자 → 자기 승리에 사직서를 낸 사람.
A28: 핵심 갈등 | B28: 잘 쓰는 법 vs 옳은 것 / 파트너 승진 vs 양심
A29: 비트 1 | B29: 발단(1~3화): 금요일 프레임, 조르주5세 거리의 월요일, VIP 고객 Verdier.
A30: 비트 2 | B30: 전개(4~5화): 실사에서 Belleville 건물 발견 / 프레임에서 그곳이 Monique의 거리였음이 드러남.
A31: 비트 3 | B31: 미드포인트(6화): 조항 설계 — Nicolas가 스스로 함정을 만든다.
A32: 비트 4 | B32: 위기(7~9화): 세입자 총회(Madeleine), 재판 승소, 프레임에서 Nicolas의 말이 막힘.
A33: 비트 5 | B33: 절정(10~11화): 16구 축하 만찬 중 부고, 손녀 Chloé의 방문.
... A39: 언어 설계 | B39: B2~C1. 접속법 현재·과거, 수동태, 법률 문어체. 과거 장면은 격식 문어, 프레임 장면은 B1로 두어 톤을 대비. 발성: 또박또박, 중저음.
A40: 대화량 (화당 120턴) | B40: ="화당 "&턴_설계!$B$5&"턴 · 부 총 "&TEXT(턴_설계!D35,"#,##0")&"턴 · 화당 약 "&TEXT(턴_설계!F35,"#,##0")&"단어 · 낭독 약 "&TEXT(턴_설계!H35,"0.0")&"분 (평균 "&TEXT(턴_설계!E35,"0.0")&"단어/턴)" -> 화당 120턴 · 부 총 1,440턴 · 화당 약 1,367단어 · 낭독 약 10.5분 (평균 11.4단어/턴)
A41: Manon 질문·Curie 카드 | B41: Manon: assignation·jugement·clause 등 법률 용어. 카드: 부동산 공시(service de la publicité foncière), 1989년 임대차법, 민사집행법전(CPCE)의 퇴거 절차.
A42: 다음 부 연결 | B42: 3부: 응급실에서 쓰러진 Nicolas — 다음 금요일은 Camille의 이야기.
A44: 3부 | B44: La Médecin — 의사 | 난이도 B2~C1 | 프레임: 금요일 밤. 과거: 약 4년 전, Hôpital Saint-Bernard(가상) 응급실.
A45: 서사 기능 | B45: 인간의 생명과 공공 보건이라는 정서적 무게. Groupe Méridien의 두 번째 얼굴(병원 외주·컨설팅)을 보여 주고, 폭염·고령 환자·서류 없는 환자 등 현안을 응급실에서 체감하게 한다.
A46: 로그라인 | B46: 응급의가 예산 압박과 병원 외주 속에서 환자를 잃기 시작하고, 이름을 적어 두다가 내부 보고를 올리지만 징계로 돌아온다.
A47: 변화 (시작 → 끝) | B47: 시스템을 믿는 의사 → 이름 명단만 든 사직자.
A48: 핵심 갈등 | B48: 의료 윤리 vs 관리 효율 / 침묵하는 동료들
A49: 비트 1 | B49: 발단(1~3화): 금요일 프레임, 야간 근무(Nicolas 진료), 폭염 환자 폭증.
A50: 비트 2 | B50: 전개(4~5화): 병원 외주 발표(컨설턴트 Léa 등장), 프레임에서 수첩 명단과 Napoléon이 움켜쥐는 배.
A51: 비트 3 | B51: 미드포인트(6화): '명단의 첫 번째' — 서류 없는 환자가 병상 지연으로 들것 위에서 숨진다.
...

Sheet 화별목차_전체
A1: 전체 화별 목차 (1~13부, 156화)
A2: 프랑스 제5공화국 제도와 현안(ID는 '현안_배치' 시트)을 반영한 초안. 득표율·의석 수·결과는 가상 수치. 모든 화는 지문 없이 대화문으로만 진행한다.
A4: 부 | B4: 화 | C4: 서사 기능 | D4: 제목 (FR) | E4: 한국어 | F4: 핵심 사건 | G4: 반영 제도·전문 영역 | H4: 주요 인물 | I4: 반영 현안 (ID) | J4: 턴 수
A5: 1 | B5: 1 | C5: 사건1 도입 | D5: Encore une lettre | E5: 또 한 통의 편지 | F5: 사무소 개소 1개월 후. 다섯 시, 여전히 방법을 못 정한 채 매일 다투는 팀. Fatima가 두 번째로 찾아와 새 임대료 인상 통지서를 보인다. Manon은 여전히 Nicolas에게 vous를 쓴다. Curie가 지나가며 «날짜를 세어 보라»는 힌트만 던지고, 임대차 계약서가 없어 다음 날로 미뤄진다. | G5: 생활 법률 구어체, 반복되는 말다툼 (B1) | H5: Monique, Nicolas, Camille, Julien, Léa, Manon, Napoléon, Fatima, Curie | I5: E1 | J5: =턴_설계!$B$5 -> 120
A6: 1 | B6: 2 | C6: 사건1 해결 | D6: La clause qui n'augmente pas | E6: 오르지 않는 조항 | F6: [사건1 해결] Fatima와 Manon이 계약서를 가져온다. Curie의 카드 #1(1989년 임대차법 제17-1조, 임대료 기준지수 IRL)로 인상률이 부당함을 확인하고, 기한 안에 등기우편(lettre recommandée)으로 답장을 쓴다. 사무소의 첫 번째 규칙(가난한 이웃에겐 돈을 받지 않는다)이 확인된다. | G6: 임대차(1989년 7월 6일 법), 임대료 기준지수(IRL), 파리 임대료 상한(encadrement des loyers) | H6: Nicolas, Julien, Léa, Fatima, Curie, Manon, Monique | I6: E1 | J6: =턴_설계!$B$5 -> 120
A7: 1 | B7: 3 | C7: 사건2 도입 | D7: La fin de la trêve | E7: 겨울 휴전의 끝 | F7: [사건2 도입] 3월 31일 밤, 겨울 퇴거 유예(trêve hivernale)가 끝나는 다음 날 아침으로 퇴거 집행이 잡혔다는 급보가 온다. Jeanne이 주민을 조직하고 Karim이 이웃들을 모은다. 네 사람이 각자 서류·건강·숫자·동선을 맡아 밤새 준비하지만 승산은 불투명하다. | G7: 겨울 퇴거 유예(11월 1일~3월 31일), 퇴거 명령(commandement de quitter les lieux), 이웃 조직 | H7: Nicolas, Camille, Julien, Léa, Jeanne, Karim, Manon, Monique | I7: S1 | J7: =턴_설계!$B$5 -> 120
A8: 1 | B8: 4 | C8: 사건2 해결 | D8: Le fourgon qui n'est pas venu | E8: 오지 않은 경찰 승합차 | F8: [사건2 해결] 집행 당일 아침. Nicolas의 긴급 가처분(référé)과 유예 기간 신청, Camille의 취약성 진단서, Julien의 채무 계산, Léa의 동선 배치가 맞물리고, 도청(préfecture)이 경찰 지원(concours de la force publique)을 미뤄 집행이 연기된다. Jeanne의 «Rien à signaler.» 보고로 마무리된다. | G8: 보호소송 판사(juge des contentieux de la protection), 유예 기간, 경찰 지원 거부와 국가 배상 | H8: Nicolas, Camille, Julien, Léa, Jeanne, Karim, Manon, Monique | I8: S1 | J8: =턴_설계!$B$5 -> 120
A9: 1 | B9: 5 | C9: 사건3 도입 | D9: Le stagiaire de l'usine | E9: 공장의 인턴 | F9: [사건3 도입] 임금 체불과 부당한 초과근무에 지친 청년 노동자 Théo(가상)가 찾아온다. Léa가 컨설팅 용어로 상황을 분석하려 하고 Manon이 통역하듯 애쓰지만 Théo는 점점 지쳐 간다. | G9: 기간제 계약(CDD), 초과근무, 경영 용어의 벽 | H9: Léa, Manon, Julien, Monique, Théo(가상) | I9: S1 | J9: =턴_설계!$B$5 -> 120
A10: 1 | B10: 6 | C10: 사건3 해결(폭발) | D10: Ça suffit ! | E10: 그만! | F10: [사건3 해결] 협상 자리에서 Léa의 용어가 한 시간째 이어지자 Manon이 폭발한다(1차 폭발). Camille·Jeanne·Monique·Curie의 고정 반응, Napoléon의 «Bécasse… Demande.», Julien의 «Je traduis.» 이후 쉬운 말로 다시 협상해 노동법원(prud'hommes)에 가기 전에 밀린 임금 지급에 합의한다. | G10: 감정 표현, 전문 용어 → 쉬운 말, 임금 체불 합의(노동법원 전 화해) | H10: Manon, Léa, Julien, Camille, Napoléon, Jeanne, Monique, Curie, Théo(가상) | I10: S1 | J10: =턴_설계!$B$5 -> 120
A11: 1 | B11: 7 | C11: 사건4 도입 | D11: La petite qui a de la fièvre | E11: 열이 나는 아이 | F11: [사건4 도입] 체류 서류가 없어 소아과 예약을 못 잡는 가족이 찾아온다. Camille가 나서고 Sartre가 카페에서 건너와 «Et toi, qu'est-ce que tu choisis ?»를 처음 선보인다. 마침 들른 Hugo는 Napoléon에게 원고를 놀림받다 «Pas mal.»이라는 최고의 칭찬을 듣는다. 정작 진짜 아픈 아이 앞에서 Napoléon은 자기 무릎 타령을 멈춘다. | G11: 서류 없는 가족의 의료 접근(국가의료지원 AME, 모자보건센터 PMI), 증상 표현 | H11: Camille, Sartre, Napoléon, Hugo, Manon, Monique, 가족(가상) | I11: S2 | J11: =턴_설계!$B$5 -> 120
A12: 1 | B12: 8 | C12: 사건4 해결 | D12: L'AME pour Amina | E12: Amina를 위한 AME | F12: [사건4 해결] Nicolas와 Camille가 행정 거주지 등록(domiciliation, CCAS) 경로를 찾아내고, 미성년자는 3개월 거주 요건 없이 AME를 받을 수 있음을 확인해 아이가 진료를 받는다. Napoléon이 평소와 달리 조용히 커피를 마신다. | G12: 행정 거주지 등록(domiciliation), AME의 미성년자 특례, 진료 의뢰 | H12: Camille, Nicolas, Manon, Monique, 가족(가상) | I12: S2 | J12: =턴_설계!$B$5 -> 120
A13: 1 | B13: 9 | C13: 사건5 도입 | D13: La veuve du cinquième | E13: 5층의 미망인 | F13: [사건5 도입] 가짜 적금 상품(faux livret)에 저축을 잃은 노년의 이웃 Josette(가상)가 찾아온다. Julien이 장부를 살피는 동안, 양복 입은 낯선 남자 Philippe가 나타나 은행 쪽 흐름을 봐 주겠다고 하면서도 자기 이야기는 하지 않는다. Voltaire가 냄새를 맡고 기웃거린다. | G13: 투자 사기(arnaque aux faux placements), 은행 계좌 기초 어휘 | H13: Julien, Philippe, Voltaire, Manon, Monique, Josette(가상) | I13: E3 | J13: =턴_설계!$B$5 -> 120
A14: 1 | B14: 10 | C14: 사건5 해결 | D14: Suivez l'argent | E14: 돈을 따라가라 | F14: [사건5 해결] Philippe의 계좌 흐름 추적과 Julien의 장부 대조로 사기 계좌를 찾아 은행에 이의 제기를 하고 돈 일부를 되찾는다. Philippe는 설명 없이 떠나고, Julien은 «Banque Atlantique»라는 이름에 말없이 굳는다. | G14: 자금 흐름 추적, 무권한 송금 이의 제기, 계좌·송금 어휘 | H14: Julien, Philippe, Manon, Monique, Josette(가상) | I14: E3 | J14: =턴_설계!$B$5 -> 120
A15: 1 | B15: 11 | C15: 사건6 도입 | D15: Un papier d'il y a des années | E15: 수년 전 서류 | F15: [사건6 도입] Fatima의 남편 Rachid가 수십 년 전 다른 건물에서 받은 낡은 퇴거 서류를 들고 온다. 당장 급한 사안은 아니지만 오래된 절차 하자가 보인다. Voltaire가 풍자 기사 각도로 흥미를 보인다. | G15: 오래된 서류 판독, 절차 하자 | H15: Nicolas, Voltaire, Manon, Monique, Rachid(가상) | I15: E1 | J15: =턴_설계!$B$5 -> 120
A16: 1 | B16: 12 | C16: 사건6 해결(훅) | D16: La Signature | E16: 서명 | F16: [사건6 해결·훅] 절차 하자를 바로잡아 오래된 기록을 정정하지만, 진짜 충격은 서류 맨 아래: Nicolas의 옛 로펌 «Vasseur & Delorme»의 서명이다. Nicolas가 얼어붙고 Monique가 «Asseyez-vous, je vous apporte quelque chose.»로 분위기를 잇는다. 금요일에는 Nicolas의 이야기가 시작된다. | G16: 서명·기록 정정, 이름 확인 | H16: Nicolas, Monique, Manon, Napoléon, Rachid(가상) | I16: E1 | J16: =턴_설계!$B$5 -> 120
A17: 2 | B17: 1 | C17: 발단 | D17: Les histoires du vendredi | E17: 금요일의 이야기 | F17: (프레임) Monique의 식탁에서 금요일마다 한 사람이 과거를 이야기하는 규칙이 시작된다. Manon이 Nicolas에게 왜 로펌을 그만뒀느냐고 묻고 Nicolas는 «Procédons dans l'ordre.»로 시작한다. | G17: 존칭 vous와 tu의 대비, 과거 이야기 도입(passé composé·imparfait) | H17: Manon, Nicolas, Monique, Napoléon | I17: E1 | J17: =턴_설계!$B$5 -> 120
A18: 2 | B18: 2 | C18: 발단 | D18: Un lundi avenue George-V | E18: 조르주5세 거리의 월요일 | F18: (과거) 승소율 100%의 파트너 후보 Nicolas의 하루. 새벽 편의점에서 영수증 뒷면에 시를 쓰는 야간 점원 Hugo와 마주친다. 상사 Delorme(가상)이 파트너 승진을 암시한다. | G18: 로펌 어휘: associé, honoraires, portefeuille de clients | H18: Nicolas, Hugo, Delorme(가상) | J18: =턴_설계!$B$5 -> 120
A19: 2 | B19: 3 | C19: 발단 | D19: Le client vedette | E19: VIP 고객 | F19: 대형 고객 Groupe Méridien의 회장 Verdier(가상)를 소개받는다. 회의석에는 고객 측 컨설턴트 Léa와 매각 은행 지점장 Philippe가 있다. | G19: 인수합병 어휘: acquisition, portefeuille, clause | H19: Nicolas, Léa, Philippe, Verdier(가상) | I19: E1 | J19: =턴_설계!$B$5 -> 120
A20: 2 | B20: 4 | C20: 전개 | D20: Le portefeuille de Belleville | E20: 벨빌 자산 포트폴리오 | F20: 실사(due diligence). 포트폴리오에 Belleville 건물 12채가 들어 있다. 감사인 Julien이 «Ça ne colle pas.»를 흘리고, 센 강변 헌책방(bouquinistes)에서 부동산 등기 자료를 찾던 Nicolas에게 Curie가 «Cherche toi-même.» | G20: 실사, 부동산 공시(service de la publicité foncière), 임차인 명부 | H20: Nicolas, Julien, Curie | I20: E1 | J20: =턴_설계!$B$5 -> 120
A21: 2 | B21: 5 | C21: 전개 | D21: Vendredi : la rue de Monique | E21: 금요일: Monique의 거리 | F21: (프레임) 그 포트폴리오에 Monique의 가게가 있던 건물이 들어 있었음이 밝혀진다. Manon은 놀라 vous를 놓치고 Nicolas는 잠시 침묵한다. | G21: 감정 표현, 놀람 | H21: Monique, Nicolas, Manon | I21: E1 | J21: =턴_설계!$B$5 -> 120
A22: 2 | B22: 6 | C22: 미드포인트 | D22: La Clause | E22: 조항 | F22: 임차인을 비우는 가장 '깨끗한' 방법으로 Nicolas가 '대규모 에너지 리노베이션'을 '정당하고 중대한 사유(motif légitime et sérieux)'로 삼는 해지 조항을 설계한다. Léa의 재무 모델이 이를 뒷받침한다. | G22: 임대인의 해지 통지(congé), 정당하고 중대한 사유, 에너지 성능 진단(DPE) | H22: Nicolas, Léa, Delorme(가상) | I22: E1 | J22: =턴_설계!$B$5 -> 120
A23: 2 | B23: 7 | C23: 위기 | D23: L'assemblée des locataires | E23: 세입자 총회 | F23: 세입자들이 총회를 연다. 버스 노조 출신 Karim이 이끌고, 응급실 의사 Camille가 공황을 일으킨 노인을 돌본다. Nicolas는 78세 Madeleine(가상)을 만난다. | G23: 총회·발언·동의, 항의 표현 | H23: Nicolas, Karim, Camille, Madeleine(가상) | I23: E1 | J23: =턴_설계!$B$5 -> 120
A24: 2 | B24: 8 | C24: 위기 | D24: Le Procès | E24: 재판 | F24: 심리(audience)와 판결. Nicolas가 승소한다. 풍자 칼럼을 쓰던 Voltaire가 «Vous êtes fier ?»라고 묻는다. 감사인 Julien은 고객의 장부를 보고 고개를 젓는다. | G24: 소송: assignation, audience, jugement, dépens | H24: Nicolas, Voltaire, Julien, 판사(가상) | I24: E1·P3 | J24: =턴_설계!$B$5 -> 120
A25: 2 | B25: 9 | C25: 위기 | D25: Vendredi : continue | E25: 금요일: 계속해 | F25: (프레임) Nicolas가 말을 잇지 못하자 Napoléon이 «Quand j'étais empereur…»로 시간을 벌어 주고 Monique가 «Continue.»라고 한다. Manon은 «Et elle ?»라고 묻는다. | G25: 위로·재촉 표현 | H25: Nicolas, Napoléon, Monique, Manon | J25: =턴_설계!$B$5 -> 120
A26: 2 | B26: 10 | C26: 절정 | D26: Un dîner dans le 16e | E26: 16구의 저녁 | F26: 승소 축하 만찬. 파트너들이 건배하는 동안 Verdier가 다음 포트폴리오를 건넨다. Nicolas의 휴대전화가 울린다. | G26: 고급 식당 표현, 건배·축하 | H26: Nicolas, Delorme(가상), Verdier(가상), Julien | J26: =턴_설계!$B$5 -> 120
A27: 2 | B27: 11 | C27: 절정 | D27: La petite-fille de Madeleine | E27: Madeleine의 손녀 | F27: Madeleine이 퇴거 석 달 뒤 세상을 떠났다는 소식. 손녀 Chloé(가상)가 사무실로 찾아와 조용히 묻는다: «Vous avez gagné ?» | G27: 조의·항의, 문서 vs 사람 | H27: Nicolas, Chloé(가상) | I27: E1 | J27: =턴_설계!$B$5 -> 120
A28: 2 | B28: 12 | C28: 결말·훅 | D28: Vendredi : la démission | E28: 금요일: 사직 | F28: (프레임+과거) Nicolas가 다음 포트폴리오 서명을 거부하고 사직서를 낸다. 짐 상자를 든 채 응급실 대기실에서 쓰러지고 Camille가 그를 진료한다. Manon은 여전히 vous를 쓴다. | G28: 사직·거절 표현, 접속법(subjonctif) | H28: Nicolas, Camille, Manon, Monique | J28: =턴_설계!$B$5 -> 120
A29: 3 | B29: 1 | C29: 발단 | D29: Vendredi : les noms | E29: 금요일: 이름들 | F29: (프레임) Camille가 «Ce n'est pas une statistique, c'est une personne.»라며 이야기를 시작한다. Napoléon이 식사를 거르고 배를 움켜쥐는 것을 Camille가 흘끗 본다. | G29: 의학 어휘 도입 | H29: Camille, Manon, Napoléon, Monique | J29: =턴_설계!$B$5 -> 120
A30: 3 | B30: 2 | C30: 발단 | D30: Garde de nuit | E30: 야간 근무 | F30: (과거) Saint-Bernard 응급실의 야간 근무. 분류 간호사(IOA)의 트리아주, 들것(brancard), 간호사 Sandrine(가상)과의 호흡. 가슴 통증으로 실려 온 Nicolas를 진료한다. | G30: tri, constantes, brancard, box | H30: Camille, Sandrine(가상), Nicolas | J30: =턴_설계!$B$5 -> 120
A31: 3 | B31: 3 | C31: 발단 | D31: La Canicule | E31: 폭염 | F31: 폭염에 고령 환자가 몰려 응급실이 넘친다. 산소·수액·얼음. Camille는 밤새 환자 이름을 외운다. | G31: 열사병(coup de chaleur), 탈수, 고령 환자, 폭염 경보 계획(plan canicule) | H31: Camille, Sandrine(가상) | I31: S4·S3 | J31: =턴_설계!$B$5 -> 120
A32: 3 | B32: 4 | C32: 전개 | D32: Un contrat que personne ne lit | E32: 아무도 읽지 않는 계약 | F32: 병원이 병상 관리·검사 물류를 Méridien Santé에 외주하고 컨설팅 회사에 '효율화'를 맡긴다고 발표한다. 원장 회의에서 컨설턴트 Léa가 '효율' 발표를 한다. | G32: 외주(externalisation), 공공조달, 공공부문 컨설팅 계약 논란 | H32: Camille, 원장(가상), Léa | I32: S3 | J32: =턴_설계!$B$5 -> 120
A33: 3 | B33: 5 | C33: 전개 | D33: Vendredi : la liste | E33: 금요일: 명단 | F33: (프레임) Manon이 Camille의 수첩 명단을 본다. Camille는 «J'ai vu pire un mardi ordinaire.»로 넘긴다. Napoléon은 배가 아프냐는 물음에 «C'est la cuisine anglaise. Sainte-Hélène m'a laissé des souvenirs.» | G33: 명단·숫자 읽기 | H33: Camille, Manon, Napoléon | J33: =턴_설계!$B$5 -> 120
A34: 3 | B34: 6 | C34: 미드포인트 | D34: La première de la liste | E34: 명단의 첫 번째 | F34: 서류 없는 20대 여성이 패혈증으로 실려 오지만 병상 배정이 아홉 시간 지연되어 들것 위에서 숨진다. 외주 병상관리가 '비용 검토' 중이었다. Camille가 수첩에 첫 이름을 쓴다. | G34: 패혈증(sepsis), 병상 관리, 들것 위의 사망, 서류 없는 환자의 응급 진료권 | H34: Camille, Sandrine(가상), 원장(가상) | I34: S2·S3 | J34: =턴_설계!$B$5 -> 120
A35: 3 | B35: 7 | C35: 위기 | D35: Les chiffres du directeur | E35: 원장의 숫자 | F35: 원장이 '대기 시간 개선' 통계를 발표한다. 외주 업체의 재무를 자문하는 Julien이 배석한다. Camille가 내부 사망 사례 보고서(déclaration d'événement indésirable grave)를 제출한다. | G35: 통계 읽기, 중대 부작용 사례 보고 | H35: Camille, 원장(가상), Julien | I35: P3 | J35: =턴_설계!$B$5 -> 120
A36: 3 | B36: 8 | C36: 위기 | D36: La Procédure disciplinaire | E36: 징계 절차 | F36: 보고서 유출 의혹으로 징계 절차가 시작된다. 취재하러 온 Voltaire에게 Camille가 «Ça ne sort pas d'ici.»라고 못 박는다. | G36: 공무원 징계(procédure disciplinaire), 직업상 비밀 유지 | H36: Camille, Voltaire, 원장(가상) | I36: P3 | J36: =턴_설계!$B$5 -> 120
A37: 3 | B37: 9 | C37: 위기 | D37: Vendredi : et qu'est-ce que tu choisis ? | E37: 금요일: 그래서 넌 뭘 선택하지? | F37: (프레임) Sartre가 Camille에게 «Et toi, qu'est-ce que tu choisis ?»라고 되묻는다. Camille는 «D'abord, respire.»로 받아친다. Manon이 Sartre의 화법을 흉내 낸다. | G37: 선택·책임 표현, 되받기 화법 | H37: Camille, Sartre, Manon | J37: =턴_설계!$B$5 -> 120
A38: 3 | B38: 10 | C38: 절정 | D38: Une nuit sans lits | E38: 병상 없는 밤 | F38: 버스 사고와 폭염이 겹친 밤. 백색 계획(plan blanc)이 발동되지만 병상이 없어 복도까지 환자가 찬다. Camille가 즉흥으로 일곱 명을 살리고 한 명을 잃는다. | G38: 대량 환자, 백색 계획(plan blanc), 우선순위, 명령형 | H38: Camille, Sandrine(가상) | I38: S4 | J38: =턴_설계!$B$5 -> 120
A39: 3 | B39: 11 | C39: 절정 | D39: La démission de la docteure | E39: 의사의 사직 | F39: 징계 통보와 마지막 근무. 수첩을 덮고 사직서를 낸다. Sandrine이 «Docteure, ne partez pas.» | G39: 사직서, 작별 | H39: Camille, Sandrine(가상), 원장(가상) | J39: =턴_설계!$B$5 -> 120
A40: 3 | B40: 12 | C40: 결말·훅 | D40: Vendredi : une signature | E40: 금요일: 한 사람의 서명 | F40: (프레임) Camille가 «Le rapport d'audit du contrat portait une signature.»라고 말한다. Julien이 조용히 «À moi.» | G40: 서명·책임 표현 | H40: Camille, Julien, Manon, Napoléon | J40: =턴_설계!$B$5 -> 120
A41: 4 | B41: 1 | C41: 발단 | D41: Vendredi : j'ai signé | E41: 금요일: 내가 서명했다 | F41: (프레임) Julien이 «Montrez-moi les documents.»를 습관처럼 하다가 «J'ai signé.»라고 시작한다. Manon이 숫자를 못 읽어 질문한다. | G41: 회계 어휘 도입 | H41: Julien, Manon, Camille, Napoléon | J41: =턴_설계!$B$5 -> 120
...

Sheet 복선_회수
A1: 복선 설치와 회수 (Setup → Payoff)
A2: 설치 부와 회수 부의 간격(부 수)은 수식으로 계산됩니다. 간격이 클수록 오래 기다린 복선이라 낭독 시 기억에 남습니다.
A4: No | B4: 복선(설치) | C4: 유형 | D4: 설치 부 | E4: 설치 위치 | F4: 회수 부 | G4: 간격(부) | H4: 회수 위치와 효과 | I4: 관련 인물
A5: 1 | B5: Napoléon의 «Cet hiver sera mon dernier» 반복 | C5: 대사 | D5: 1 | E5: 1부 1화 | F5: 11 | G5: =F5-D5 -> 10 | H5: 11부 12화 — 양치기 소년 개그가 진짜 죽음이 되는 낙차 | I5: Napoléon
A6: 2 | B6: Napoléon이 Manon에게 이각모(bicorne)를 물려준다고 말한다 | C6: 소품 | D6: 1 | E6: 1부 1화 | F6: 13 | G6: =F6-D6 -> 12 | H6: 13부 2화 — 유언장에서 이각모가 진짜 유산으로 돌아옴 | I6: Napoléon, Manon
A7: 3 | B7: Napoléon의 복통·식사 거름 | C7: 설정 | D7: 3 | E7: 3부 1·5화 | F7: 11 | G7: =F7-D7 -> 8 | H7: 11부 6~12화 — Camille가 진단을 알고도 침묵한 이유가 드러남 | I7: Camille, Napoléon
A8: 4 | B8: Napoléon의 최고 칭찬 «Pas mal.» | C8: 대사 | D8: 1 | E8: 1부 7화(Hugo에게 1회) | F8: 11 | G8: =F8-D8 -> 10 | H8: 11부 12화 — Manon에게 처음이자 마지막 칭찬, 브뤼셀 승리 직후라 더 무겁다 | I8: Napoléon, Manon
A9: 5 | B9: Manon의 1차 폭발 | C9: 사건 | D9: 1 | E9: 1부 6화 | F9: 9 | G9: =F9-D9 -> 8 | H9: 9부 6화 — 몰라서 화내던 Manon → 알아서 화내는 Manon | I9: Manon
A10: 6 | B10: Manon의 vous (Napoléon에게) | C10: 호칭 | D10: 1 | E10: 1부 1화 | F10: 12 | G10: =F10-D10 -> 11 | H10: 12부 1화 — 추도사에서 처음 tu — 호칭 전환이 곧 애도 | I10: Manon, Napoléon
A11: 7 | B11: Curie의 카드 #1과 «Cherche toi-même.» | C11: 대사 | D11: 1 | E11: 1부 2화 | F11: 13 | G11: =F11-D11 -> 12 | H11: 13부 10화 — 끝까지 결론을 말하지 않던 그녀가 처음 답을 말함 | I11: Curie, Manon
A12: 8 | B12: Nicolas의 '리노베이션 해지' 조항 | C12: 사건 | D12: 2 | E12: 2부 6화 | F12: 11 | G12: =F12-D12 -> 9 | H12: 11부 3화 — 자기가 만든 조항을 국정에서 폐지 | I12: Nicolas
A13: 9 | B13: Julien의 «Ça ne colle pas» | C13: 대사 | D13: 2 | E13: 2부 4화 | F13: 4 | G13: =F13-D13 -> 2 | H13: 4부 4화 — 감사인의 눈이 처음 이상을 발견한 순간의 원점 | I13: Julien
A14: 10 | B14: Julien의 복사본 USB | C14: 소품 | D14: 4 | E14: 4부 10화 | F14: 7 | G14: =F14-D14 -> 3 | H14: 7부 5~6화 — 서명의 죄가 고소의 증거로 바뀜 | I14: Julien, Nicolas
A15: 11 | B15: Julien의 «다시는 서명하지 않는다» | C15: 인물 | D15: 4 | E15: 4부 11화 | F15: 11 | G15: =F15-D15 -> 7 | H15: 11부 10화 — 브뤼셀에서 «Je ne signe que ce que j'ai vérifié» — 숫자 서명의 회수 | I15: Julien
A16: 12 | B16: Léa의 C47 셀 | C16: 소품 | D16: 5 | E16: 5부 6화 | F16: 11 | G16: =F16-D16 -> 6 | H16: 11부 6화 — 사람을 지우던 셀이 해고 없는 통합 모델로 | I16: Léa
... A32: 28 | B32: Voltaire의 «Il me faut deux sources.» | C32: 대사 | D32: 1 | E32: 1부 11화 | F32: 9 | G32: =F32-D32 -> 8 | H32: 9부 8화 — 폭로 기사에서 두 개의 출처를 갖추는 장면 | I32: Voltaire, Curie
B34: 평균 간격(부) | G34: =AVERAGE(G5:G32) -> 7.3928571
B35: 가장 긴 복선(부) | G35: =MAX(G5:G32) -> 12
B36: 복선 개수 | G36: =COUNTA(B5:B32) -> 28

Sheet 현안_배치
A1: 프랑스 현안 18개 배치표
A2: 현재 프랑스의 쟁점을 이야기 곳곳에 녹이는 계획. 현실의 정당·정치인·참사 희생자는 특정하지 않고 가상 설정으로 각색하며, 제도와 통계만 현실 기준으로 쓴다.
A4: ID | B4: 분야 | C4: 현안 | D4: 프랑스어 키워드 | E4: 이야기 속 가상 설정 | F4: 주요 배치 (전용 화) | G4: 곁가지 배치 | H4: 주요 인물 | I4: 권한 소재 | J4: 관련 제도·법 | K4: 낭독 어휘 | L4: 균형·민감도 유의 | M4: 현실 기준값·확인
A5: P1 | B5: 정치 | C5: 상대다수 의회와 정부 불안정 | D5: Assemblée fracturée, majorité relative, 49.3, motion de censure, coalition | E5: 2024년 조기 총선 이후처럼 어떤 진영도 과반이 없는 하원. 법안마다 협상 비용이 들고 불신임안이 상시 위협이다. Maison Commune 정부도 표결마다 다른 파트너를 찾아야 한다. | F5: 9부 5화 불편한 동맹, 10부 9~12화 해산·총선·불신임안, 12부 7화 두 번째 불신임안 | G5: 8부 6화(왜 새 정당인가: 정치 피로), 7부 12화, 11부 1화 | H5: Léa, Nicolas, Karim, Olympe | I5: 하원·파리 시의회 | J5: 헌법 제8·12·49조, 정당 간 협약 | K5: majorité relative, censure, compromis, blocage, 49.3 | L5: 특정 실존 정당·인물을 비난하는 대사 금지. 가상 정당(UCN·PPS·FS·AE·CT)으로만. | M5: 현실: 2024년 이후 하원은 3개 진영으로 분열, 2025년 9월 정부 신임 부결 뒤 Lecornu 정부(2026-09 확인). 이야기에는 쓰지 않음
A6: P2 | B6: 정치 | C6: 지역 자치 갈등(코르시카·누벨칼레도니) | D6: autonomie, Corse, Nouvelle-Calédonie, révision constitutionnelle | E6: 지역 정당 연합 CT가 지지의 대가로 코르시카 자치 개헌 협상 재개와 해외영토 협정 이행을 요구한다. 총리 인선과 첫 불신임안이 여기에 걸린다. | F6: 10부 11화 마티뇽 협상 | G6: 10부 3화(TV 토론 공격), 12부 7화(두 번째 불신임안에서 CT의 기권) | H6: Nicolas, Olympe, Karim, Léa | I6: 의회(개헌은 양원 동일 문안 + 양원합동회의 3/5 또는 국민투표), 헌법재판소 | J6: 헌법 제72·74·89조, 누벨칼레도니 관련 헌법 제13장 | K6: autonomie, unité de la République, statut, référendum | L6: 가장 민감. 찬성·반대 논거를 각 인물이 나눠 말하게 하고 결론은 열어 둔다(Nicolas는 공화국 불가분성 우려, Karim은 지역 형평, Léa는 현실 협상). | M6: 코르시카 자치 개헌안·누벨칼레도니 합의(2025) 진행 상황은 반영 전 확인
A7: P3 | B7: 정치 | C7: 사법부 독립과 정치적 대립 | D7: indépendance du parquet, CSM, PNF, attaques contre les juges, agrément anticorruption | E7: 검찰 인사 개혁은 개헌 교착으로 멈추고, 정치인 판결 뒤 판사를 향한 공격이 이어진다. 반부패 단체의 인가가 흔들리며 사무소의 고소가 표류한다. | F7: 7부(고소·예심·보복), 9부 9화 고소장 | G7: 2부 8화(재판), 3부(징계), 4부 7화, 10부 11화(협상 조건), 12부 7화(교착) | H7: Nicolas, Voltaire, Curie | I7: 사법부·최고사법관회의(CSM)·의회 | J7: 헌법 제64·65조, 형사소송법 제2-23조 | K7: indépendance, parquet, agrément, instruction, délais | L7: 여야 모두가 사법부를 압박한다는 비판을 각각 담는다. 실제 재판 결과를 단정하지 않는다. | M7: 검찰 독립 개헌·반부패 단체 인가 소송 최신 상황 확인
A8: E1 | B8: 경제 | C8: 주거난·임대료 상한·단기 관광 임대 | D8: logement, encadrement des loyers, meublé de tourisme, zone tendue, expulsion | E8: 월세가 임금보다 빨리 오르고 관광 단기임대가 동네를 비운다. 소규모 임대인의 입장(Monique의 친구)도 대사에 넣는다. | F8: 2부 6화(조항 설계), 6부 1·3·8·10화(Saint-Denis), 9부 6화(주거 보조 삭감·단기임대 조항), 11부 2·3화 | G8: 1부 1·2화(Fatima), 8부 1·9화, 13부 | H8: Monique, Manon, Julien, Nicolas | I8: 국가(임대차법·세제), 파리시(임대료 상한 신청·용도변경), 메트로폴 | J8: 1989년 임대차법, ELAN법(2018) 임대료 상한, 2024년 단기임대법(르뫼르법) | K8: meublé de tourisme, encadrement, petit propriétaire, trêve hivernale | L8: 임차인만 피해자로 그리지 않는다. 소규모 임대인·대형 보유자를 구분해서 말한다. | M8: 단기임대 규제 세부(연간 일수 상한 등)는 확인
A9: E2 | B9: 경제 | C9: 탈산업화와 영세 기업 구조 | D9: désindustrialisation, TPE, PME, productivité, réindustrialisation | E9: Léa가 컨설팅한 규모의 경제 없는 영세 제조업체들: 해고 없이 살릴 길을 못 찾았던 과거. 11부에서 영세 기업 통합·연구개발 전환 사업을 설계한다. | F9: 5부 3화 Garnier 공방 | G9: 8부 9화(골목 상권), 11부 6화, 13부 7화 | H9: Léa, Monique, Karim | I9: 국가·레지옹(경제 개발) | J9: 연구세액공제(CIR), 경제적 해고(PSE) | K9: productivité, scaler, consolidation, R&D | L9: '영세 기업이 문제'라는 식의 낙인 대신 구조 문제로 설명한다. | M9: 통계 수치는 반영 전 확인
A10: E3 | B10: 경제 | C10: 국가 부채·재정적자·연금 | D10: dette publique, déficit, procédure de déficit excessif, retraites | E10: 적자를 줄이라는 EU 절차와 연금·보건·국방 지출 증가 사이의 줄타기. Julien이 숫자로 설명하고 Manon이 되묻는다. | F10: 11부 10화(EU 재정규칙), 12부 11~12화(예산안) | G10: 10부 6화(결선 토론), 12부 3·9화, 13부 7화 | H10: Julien, Napoléon(메모), Philippe | I10: 국가·EU | J10: 헌법 제47조·LOLF, TFUE 제126조, 2023년 연금 개혁 | K10: dette, déficit, trajectoire, soutenabilité | L10: 긴축 vs 확대 양쪽 논거를 모두 숫자로 제시한다. | M10: 부채 GDP 대비 117.5% (2026년 1분기 말, INSEE). 2분기 수치는 2026-09-29 발표 예정
A11: S1 | B11: 사회 | C11: 청년 고용 불안 | D11: stage, CDD, intérim, apprentissage, précarité | E11: 기간제·인턴과 저임금으로 청년의 자립이 늦어진다. Manon이 그 당사자이자 질문자다. | F11: 1부 3~6화, 11부 6화, 13부 5·6화 | G11: 5부(Léa의 인력 감축), 6부, 7부, 8부, 10부 3화 | H11: Manon, Karim, Léa | I11: 국가(노동법)·사회적 대화 | J11: 노동법전, 인턴 수당(gratification), 견습 지원 | K11: stagiaire, contrat, SMIC, précarité | L11: 청년 vs 기성세대 구도로 몰지 않는다(Karim도 Napoléon도 청년의 편에서 돕는다). | M11: 15~24세 실업률 21.6%(2026 2분기), 전체 8.3%, 약 2.6배 (INSEE, 2026-09 확인)
A12: S2 | B12: 사회 | C12: 이민·난민과 수용 분담 | D12: titre de séjour, MNA, AME, asile, campement | E12: Belleville는 다국적 동네다. 서류 없는 이웃, 체류 자격 사건, 파리 북부 텐트촌과 보호자 없는 미성년 이주민을 둘러싼 도(département) 간 떠넘기기. | F12: 1부 7~8화(AME), 6부 8·9화, 7부 4화(체류 자격), 11부 5화 분담 | G12: 3부 6화(서류 없는 환자), 8부(투표권 없는 이웃), 10부 3화 | H12: Monique, Camille, Nicolas, Karim, Sartre | I12: 국가(체류·망명), 도(아동 보호 ASE) | J12: CESEDA, 2024년 이민법, EU 이민·망명 협약(2026 시행) | K12: titre de séjour, régularisation, mineur non accompagné, demande d'asile | L12: 반이민 여론(FS)과 수용 부담 지역의 실제 어려움을 함께 담고, 이주민을 배경이 아닌 화자로 세운다. | M12: 예외적 체류 허가 지침·EU 협약 시행 상태 확인
A13: S3 | B13: 사회 | C13: 고령화·농촌 공동화·의료 사막 | D13: désert médical, diagonale du vide, vieillissement, fermeture de services | E13: 시립 보건센터가 문을 닫고 파리 북동부·센생드니가 의료 사막이 된다(9부). Jeanne의 고향 근처 마을은 학교도 병원도 문을 닫았고, 추천서 순회가 그곳을 지나며 의료·일자리·연금 문제가 되풀이된다(10부). | F13: 9부 7화 시의회에서의 보건 | G13: 3부(응급실 고령 환자), 10부 2화(농촌 순회), 11부 4화, 13부 | H13: Jeanne, Camille, Manon | I13: 국가(ARS)·도·코뮌 | J13: 공중보건법전, 의사 배치 규제 논쟁 | K13: désert médical, vieillissement, maison de santé | L13: '시골'을 동정하지 않고 마을 사람들이 직접 말하게 한다. | M13: 인구·의사 밀도 통계는 반영 전 확인
A14: S4 | B14: 사회 | C14: 폭염·가뭄과 에너지 전환 부담 | D14: canicule, sécheresse, restrictions d'eau, transition énergétique | E14: 폭염에 응급실이 넘치고(3부), 저수지가 마른 마을을 지나며(10부), 초고액 자산 최저세 재원을 전환 비용에 쓸지 논쟁한다(11부). | F14: 3부 3·10화(폭염 응급실) | G14: 10부 2화, 11부 4·8화, 12부 8화 | H14: Camille, Jeanne, Julien | I14: 국가·도·유역기관 | J14: 폭염 경보 계획, 물 사용 제한 도지사 명령 | K14: canicule, sécheresse, Météo-France, transition énergétique | L14: 기후를 정치적 구호로 쓰지 않고 현장 사건으로 보여 준다. | M14: 최신 폭염·가뭄 통계 확인
A15: N1 | B15: 재난 | C15: 지중해성 폭우·급류와 방재 체계 | D15: épisode méditerranéen, crue éclair, vigilance rouge, FR-Alert, catastrophe naturelle | E15: 남부 해안 지방을 가상의 폭우와 급류가 덮친다. 경보·대피 명령을 둘러싼 도지사–시장 책임 공방, 자연재해 지정, 민방위 군부대 투입, 복구와 보험 보상. | F15: 12부 8화 L'Épisode méditerranéen | G15: 13부(복구 결산) | H15: Jeanne, Camille, Nicolas, Voltaire, Hugo | I15: 국가(도지사 ORSEC), 코뮌(시 보호계획), EU | J15: 국내안전법전, 자연재해 보상제도(CatNat), EU 연대기금 | K15: vigilance rouge, évacuation, sinistrés, catastrophe naturelle | L15: 실제 참사와 희생자를 연상시키므로 추모의 톤을 지키고, 특정 정치인 비난 없이 제도의 공백을 보여 준다. | M15: 실제 재난의 후속 조치·소송은 반영 전 확인
... A22: N8 | B22: 사회 | C22: 청년 정신건강 위기 | D22: santé mentale, anxiété, liste d'attente, Mon soutien psy, CMP | E22: 청년 정신건강 상담 대기가 몇 달씩 밀린다. Sartre가 카페의 청년들과, Manon이 자신의 불안을 처음 인정하며, Camille가 제도로 함께 부딪힌다. | F22: 12부 6화 Les Listes d'attente | G22: 1부(Manon의 폭발과 연결 가능, 곁가지) | H22: Sartre, Manon, Camille | I22: 국가(건강보험)·ARS | J22: 공공 심리상담 지원(Mon soutien psy), 의료심리센터(CMP) | K22: santé mentale, anxiété, psychologue, liste d'attente | L22: 청년 정신건강을 극적 소재로만 소비하지 않는다. 낙인 없이, 도움을 구하는 것이 자연스럽다는 톤으로. | M22: 정신건강은 2025년 '국가적 대의(grande cause nationale)'. 최신 통계 확인
A24: 현실 기준값 (확인일 2026-09-25)
A25: No | B25: 구분 | C25: 항목 | D25: 값 | E25: 출처·비고
A26: 1 | B26: 경제 | C26: 정부 부채 / GDP | D26: 117.5% (2026년 1분기 말) | E26: INSEE, 분기 부채 통계. 2분기 수치는 2026-09-29 발표 예정.
A27: 2 | B27: 사회 | C27: 15~24세 실업률 | D27: 21.6% (2026 2분기), 전체 8.3% | E27: INSEE 고용조사. 청년 실업은 전체의 약 2.6배.
A28: 3 | B28: 정치 | C28: 현 정부 형태 | D28: 과반 없는 하원(3개 진영) + 소수 정부 | E28: 이야기에는 실존 정당·인물을 쓰지 않는다. 표현은 '여소야대'가 아니라 '상대다수 정부'.
A29: 4 | B29: 확인 필요 | C29: 변동이 잦은 항목 | D29: 코르시카 자치 개헌, 누벨칼레도니 합의, 연금 개혁 유예, NATO 목표, EU 이민 협약 시행 | E29: 교재에 넣기 직전 최신 상태를 확인한다.

Sheet 현안_분포
A1: 현안 분포표 (부 × 현안)
A2: ● = 그 화의 주된 사건(전용 화), ○ = 곁가지(대사·서브플롯). 기호를 바꾸면 아래 집계가 자동 갱신됩니다.
A4: ID | B4: 현안 | C4: 1부 | D4: 2부 | E4: 3부 | F4: 4부 | G4: 5부 | H4: 6부 | I4: 7부 | J4: 8부 | K4: 9부 | L4: 10부 | M4: 11부 | N4: 12부 | O4: 13부 | P4: ● 수 | Q4: ○ 수
A5: P1 | B5: 상대다수 의회·정부 불안정 | I5: ○ | J5: ○ | K5: ● | L5: ● | M5: ○ | N5: ● | P5: =COUNTIF(C5:O5,"●") -> 3 | Q5: =COUNTIF(C5:O5,"○") -> 3
A6: P2 | B6: 지역 자치(코르시카·누벨칼레도니) | L6: ● | N6: ○ | P6: =COUNTIF(C6:O6,"●") -> 1 | Q6: =COUNTIF(C6:O6,"○") -> 1
A7: P3 | B7: 사법부 독립·정치 대립 | D7: ○ | E7: ○ | F7: ○ | I7: ● | K7: ● | L7: ○ | N7: ○ | P7: =COUNTIF(C7:O7,"●") -> 2 | Q7: =COUNTIF(C7:O7,"○") -> 5
A8: E1 | B8: 주거난·임대료 상한·단기임대 | C8: ● | D8: ● | H8: ● | J8: ○ | K8: ● | M8: ● | O8: ○ | P8: =COUNTIF(C8:O8,"●") -> 5 | Q8: =COUNTIF(C8:O8,"○") -> 2
A9: E2 | B9: 탈산업화·영세 기업 | G9: ● | J9: ○ | M9: ○ | O9: ○ | P9: =COUNTIF(C9:O9,"●") -> 1 | Q9: =COUNTIF(C9:O9,"○") -> 3
A10: E3 | B10: 부채·재정적자·연금 | L10: ○ | M10: ● | N10: ● | O10: ○ | P10: =COUNTIF(C10:O10,"●") -> 2 | Q10: =COUNTIF(C10:O10,"○") -> 2
A11: S1 | B11: 청년 고용 불안 | C11: ● | G11: ○ | H11: ○ | I11: ○ | J11: ○ | L11: ○ | M11: ● | O11: ● | P11: =COUNTIF(C11:O11,"●") -> 3 | Q11: =COUNTIF(C11:O11,"○") -> 5
A12: S2 | B12: 이민·난민·수용 분담 | C12: ● | E12: ○ | H12: ● | I12: ● | J12: ○ | L12: ○ | M12: ● | P12: =COUNTIF(C12:O12,"●") -> 4 | Q12: =COUNTIF(C12:O12,"○") -> 3
A13: S3 | B13: 고령화·농촌 공동화·의료 사막 | E13: ○ | K13: ● | L13: ○ | M13: ○ | O13: ○ | P13: =COUNTIF(C13:O13,"●") -> 1 | Q13: =COUNTIF(C13:O13,"○") -> 4
A14: S4 | B14: 폭염·가뭄·에너지 전환 | E14: ● | L14: ○ | M14: ○ | N14: ○ | P14: =COUNTIF(C14:O14,"●") -> 1 | Q14: =COUNTIF(C14:O14,"○") -> 3
A15: N1 | B15: 지중해성 폭우·방재 | N15: ● | O15: ○ | P15: =COUNTIF(C15:O15,"●") -> 1 | Q15: =COUNTIF(C15:O15,"○") -> 1
A16: N2 | B16: EU 회복기금 집행 | K16: ● | M16: ○ | O16: ○ | P16: =COUNTIF(C16:O16,"●") -> 1 | Q16: =COUNTIF(C16:O16,"○") -> 2
A17: N3 | B17: 국방비·NATO | L17: ○ | M17: ● | N17: ● | P17: =COUNTIF(C17:O17,"●") -> 2 | Q17: =COUNTIF(C17:O17,"○") -> 1
A18: N4 | B18: 성폭력·동의 개념 법 | I18: ● | J18: ○ | L18: ○ | P18: =COUNTIF(C18:O18,"●") -> 1 | Q18: =COUNTIF(C18:O18,"○") -> 2
A19: N5 | B19: 녹색 대 녹색 | L19: ● | M19: ○ | N19: ○ | O19: ○ | P19: =COUNTIF(C19:O19,"●") -> 1 | Q19: =COUNTIF(C19:O19,"○") -> 3
A20: N6 | B20: 플랫폼 노동 | G20: ○ | N20: ● | P20: =COUNTIF(C20:O20,"●") -> 1 | Q20: =COUNTIF(C20:O20,"○") -> 1
A21: N7 | B21: 정보기관 사찰 스캔들 | I21: ○ | N21: ● | P21: =COUNTIF(C21:O21,"●") -> 1 | Q21: =COUNTIF(C21:O21,"○") -> 1
A22: N8 | B22: 청년 정신건강 | C22: ○ | N22: ● | P22: =COUNTIF(C22:O22,"●") -> 1 | Q22: =COUNTIF(C22:O22,"○") -> 1
B23: 부별 ● 수 | C23: =COUNTIF(C5:C22,"●") -> 3 | D23: =COUNTIF(D5:D22,"●") -> 1 | E23: =COUNTIF(E5:E22,"●") -> 1 | F23: =COUNTIF(F5:F22,"●") -> 0 | G23: =COUNTIF(G5:G22,"●") -> 1 | H23: =COUNTIF(H5:H22,"●") -> 2 | I23: =COUNTIF(I5:I22,"●") -> 3 | J23: =COUNTIF(J5:J22,"●") -> 0 | ... O23: =COUNTIF(O5:O22,"●") -> 1 | P23: =SUM(P5:P22) -> 32
B24: 부별 ○ 수 | C24: =COUNTIF(C5:C22,"○") -> 1 | D24: =COUNTIF(D5:D22,"○") -> 1 | E24: =COUNTIF(E5:E22,"○") -> 3 | F24: =COUNTIF(F5:F22,"○") -> 1 | G24: =COUNTIF(G5:G22,"○") -> 2 | H24: =COUNTIF(H5:H22,"○") -> 1 | I24: =COUNTIF(I5:I22,"○") -> 3 | J24: =COUNTIF(J5:J22,"○") -> 6 | ... O24: =COUNTIF(O5:O22,"○") -> 7 | Q24: =SUM(Q5:Q22) -> 43
A26: 읽는 법: 1~5부는 곁가지 중심이라 B1~B2 난이도를 지키고, 9~12부에서 전용 화가 몰린다. 화당 전용 현안은 1개(+곁가지 1~2개)로 제한해 낭독 분량을 지킨다. N6~N8은 12부의 신규 현안으로 각 1개 전용 화를 받는다.
A27: 현안 ID와 설명은 '현안_배치' 시트, 화별 반영은 '화별목차_전체'의 '반영 현안' 열을 참고.

Sheet 정치제도
A1: 현실 정치 제도 기준표 (프랑스 제5공화국)
A2: 8~13부에 반영한 실제 제도. 정당·정치인은 전부 가상이며 실존 정치인의 대사는 쓰지 않는다. '검색 확인' 표시는 해당 날짜에 공개 자료로 확인한 항목.
A4: 영역 | B4: 제도·규칙 | C4: 핵심 내용 | D4: 근거 | E4: 이야기 반영 | F4: 낭독 어휘 | G4: 확인 상태
A5: 정당·선거 | B5: 정당 결성 | C5: 정당은 1901년 결사법상 단체로 자유롭게 결성한다(등록 의무 없음). 공적 보조·후원을 받으려면 정치자금 수탁 단체 또는 수탁자(mandataire financier)를 두고 CNCCFP 승인을 받아야 한다. | D5: 헌법 제4조, 1901년 7월 1일 법, 1988년 3월 11일 법(88-227) | E5: 8부 5화 | F5: association, statuts, mandataire financier, CNCCFP | G5: 기획 시점 지식 — Légifrance 확인 필요
A6: 정당·선거 | B6: 정당 내부 운영 | C6: 헌법은 정당의 자유·다원주의·남녀 동등 접근 기여만 규정하고, 내부 민주주의를 법적 의무로 두지 않는다(정관의 선택). | D6: 헌법 제4조 | E6: 8부 6화 | F6: pluralisme, adhérent, statuts | G6: 기획 시점 지식 — Légifrance 확인 필요
A7: 정당·선거 | B7: 정당 재정 | C7: 개인 후원은 1인당 연 7,500유로 상한(모든 정당 합산), 법인 후원은 금지. CNCCFP가 정당·선거 회계를 감독한다. | D7: 1988년 3월 11일 법 제11-4조 | E7: 8부 7화 | F7: don, plafond, comptes, CNCCFP | G7: 기획 시점 지식 — Légifrance 확인 필요
A8: 정당·선거 | B8: 계좌 개설권 | C8: 은행이 계좌 개설을 거부하면 프랑스은행(Banque de France)이 지정한 은행이 계좌를 열어 주어야 한다. | D8: 통화금융법전 L.312-1조 | E8: 8부 7화 | F8: droit au compte, Banque de France | G8: 기획 시점 지식 — Légifrance 확인 필요
